Workbook
Name Company_Name: 'Returns-Summary'!$D$7
Name Hist_Yr: 'Returns-Summary'!$D$8

Sheet Returns-Summary
B2: =Company_Name&" - Operating Model" -> Beacon Staffing Group Limited - Operating Model
B3: (all figures £m unless noted)
B5: BRIEF & INPUTS:
C7: Entity Name: | D7: Beacon Staffing Group Limited | H7: Equity Invested at Entry: | K7: 28.6166
C8: Final Actual Year: | D8: 42338 | H8: Ownership Acquired (%): | K8: 0.239925
C10: Prepare a fully integrated three-statement projection spanning five forecast years for Beacon Staffing Group, a specialist IT recruitment
C11: business based in the United Kingdom. Its purpose is to help a private-equity or growth-equity sponsor gauge the internal rate of return and cash-on-cash returns achievable
C12: on a minority growth-equity position.
E14: Actuals | H14: Forecast
B15: Investment Summary & Returns: | D15: Reporting Units: | E15: =EOMONTH(F15,-12) -> 41608 | F15: =EOMONTH(G15,-12) -> 41973 | G15: =Hist_Yr -> 42338 | H15: =EOMONTH(G15,12) -> 42704 | I15: =EOMONTH(H15,12) -> 43069 | J15: =EOMONTH(I15,12) -> 43434 | K15: =EOMONTH(J15,12) -> 43799 | L15: =EOMONTH(K15,12) -> 44165
B16: Leverage & Coverage Metrics:
C18: Revenue (Turnover): | D18: £ M | E18: ='Model-Build'!E83 -> 39.4 | F18: ='Model-Build'!F83 -> 62.472 | G18: ='Model-Build'!G83 -> 94.983 | H18: ='Model-Build'!H83 -> 146.60761 | I18: ='Model-Build'!I83 -> 202.15825 | J18: ='Model-Build'!J83 -> 279.17751 | K18: ='Model-Build'!K83 -> 353.96798 | L18: ='Model-Build'!L83 -> 423.07609
C19: Rate of Growth: | D19: % | E19: ='Model-Build'!E84 -> N/A | F19: ='Model-Build'!F84 -> 0.58558376 | G19: ='Model-Build'!G84 -> 0.52040914 | H19: ='Model-Build'!H84 -> 0.54351426 | I19: ='Model-Build'!I84 -> 0.37890688 | J19: ='Model-Build'!J84 -> 0.38098499 | K19: ='Model-Build'!K84 -> 0.26789576 | L19: ='Model-Build'!L84 -> 0.19523833
C21: EBITDA — | D21: £ M | E21: ='Model-Build'!E93 -> 5.3 | F21: ='Model-Build'!F93 -> 8.359 | G21: ='Model-Build'!G93 -> 14.775 | H21: ='Model-Build'!H93 -> 25.77206 | I21: ='Model-Build'!I93 -> 51.895812 | J21: ='Model-Build'!J93 -> 28.002143 | K21: ='Model-Build'!K93 -> 72.544353 | L21: ='Model-Build'!L93 -> 81.307159
C22: Rate of Growth: | D22: % | E22: =IFERROR(E21/D21-1,"N/A") -> N/A | F22: =IFERROR(F21/E21-1,"N/A") -> 0.57716981 | G22: =IFERROR(G21/F21-1,"N/A") -> 0.76755593 | H22: =IFERROR(H21/G21-1,"N/A") -> 0.74430188 | I22: =IFERROR(I21/H21-1,"N/A") -> 1.0136462 | J22: =IFERROR(J21/I21-1,"N/A") -> -0.46041613 | K22: =IFERROR(K21/J21-1,"N/A") -> 1.5906715 | L22: =IFERROR(L21/K21-1,"N/A") -> 0.1207924
C23: Margin (%): | D23: % | E23: =E21/E18 -> 0.13451777 | F23: =F21/F18 -> 0.13380394 | G23: =G21/G18 -> 0.15555415 | H23: =H21/H18 -> 0.17578937 | I23: =I21/I18 -> 0.25670885 | J23: =J21/J18 -> 0.10030229 | K23: =K21/K18 -> 0.20494609 | L23: =L21/L18 -> 0.19218093
C25: Interest Cost: | D25: £ M | E25: =-'Model-Build'!E95 -> 1.180592 | F25: =-'Model-Build'!F95 -> 3.101 | G25: =-'Model-Build'!G95 -> 3.36 | H25: =-'Model-Build'!H95 -> 2.1648983 | I25: =-'Model-Build'!I95 -> 2.1211706 | J25: =-'Model-Build'!J95 -> 2.123551 | K25: =-'Model-Build'!K95 -> 2.2003245 | L25: =-'Model-Build'!L95 -> 2.3755873
C26: Interest Paid in Cash: | D26: £ M | E26: =E25 -> 1.180592 | F26: =F25 -> 3.101 | G26: =G25 -> 3.36 | H26: ='Model-Build'!H41+'Model-Build'!H47 -> 1.6079955 | I26: ='Model-Build'!I41+'Model-Build'!I47 -> 1.5040755 | J26: ='Model-Build'!J41+'Model-Build'!J47 -> 1.4397578 | K26: ='Model-Build'!K41+'Model-Build'!K47 -> 1.4426242 | L26: ='Model-Build'!L41+'Model-Build'!L47 -> 1.5359917
C28: Debt — Total | D28: £ M | E28: ='Model-Build'!E124 -> 32.826583 | F28: ='Model-Build'!F124 -> 34.557 | G28: ='Model-Build'!G124 -> 33.953 | H28: ='Model-Build'!H124 -> 0 | I28: ='Model-Build'!I124 -> 0 | J28: ='Model-Build'!J124 -> 0 | K28: ='Model-Build'!K124 -> 0 | L28: ='Model-Build'!L124 -> 0
C29: Debt, Net: | D29: £ M | E29: ='Model-Build'!E124-'Model-Build'!E104 -> 30.002971 | F29: ='Model-Build'!F124-'Model-Build'!F104 -> 32.152 | G29: ='Model-Build'!G124-'Model-Build'!G104 -> 21.804 | H29: ='Model-Build'!H124-'Model-Build'!H104 -> 0 | I29: ='Model-Build'!I124-'Model-Build'!I104 -> 0 | J29: ='Model-Build'!J124-'Model-Build'!J104 -> 0 | K29: ='Model-Build'!K124-'Model-Build'!K104 -> 0 | L29: ='Model-Build'!L124-'Model-Build'!L104 -> 0
C31: EBITDA-to-Interest: | D31: x | E31: =E21/E25 -> 4.4892732 | F31: =F21/F25 -> 2.6955821 | G31: =G21/G25 -> 4.3973214 | H31: =H21/H25 -> 11.904513 | I31: =I21/I25 -> 24.465648 | J31: =J21/J25 -> 13.186471 | K31: =K21/K25 -> 32.969843 | L31: =L21/L25 -> 34.22613
C32: EBITDA-to-Cash-Interest: | D32: x | E32: =E21/E26 -> 4.4892732 | F32: =F21/F26 -> 2.6955821 | G32: =G21/G26 -> 4.3973214 | H32: =H21/H26 -> 16.027446 | I32: =I21/I26 -> 34.503463 | J32: =J21/J26 -> 19.449204 | K32: =K21/K26 -> 50.286384 | L32: =L21/L26 -> 52.934634
C33: Total-Debt-to-EBITDA: | D33: x | E33: =E28/E21 -> 6.1936949 | F33: =F28/F21 -> 4.134107 | G33: =G28/G21 -> 2.2980034 | H33: =H28/H21 -> 0 | I33: =I28/I21 -> 0 | J33: =J28/J21 -> 0 | K33: =K28/K21 -> 0 | L33: =L28/L21 -> 0
C34: Net-Debt-to-EBITDA: | D34: x | E34: =E29/E21 -> 5.6609379 | F34: =F29/F21 -> 3.8463931 | G34: =G29/G21 -> 1.475736 | H34: =H29/H21 -> 0 | I34: =I29/I21 -> 0 | J34: =J29/J21 -> 0 | K34: =K29/K21 -> 0 | L34: =L29/L21 -> 0
B36: Returns — Money Multiple & IRR:
C38: EBITDA in Exit Year: | D38: £ M | J38: =J21 -> 28.002143 | K38: =K21 -> 72.544353 | L38: =L21 -> 81.307159
C39: Times: Assumed Exit Multiple | D39: x | J39: 8.8896 | K39: 7.7414 | L39: 8.1905
C40: Enterprise Value at Exit: | D40: £ M | J40: =J38*J39 -> 248.92785 | K40: =K38*K39 -> 561.59485 | L40: =L38*L39 -> 665.94629
C41: Less: Net Debt | D41: £ M | J41: =-J29 -> 0 | K41: =-K29 -> 0 | L41: =-L29 -> 0
C42: Equity Value at Exit: | D42: £ M | J42: =J40+J41 -> 248.92785 | K42: =K40+K41 -> 561.59485 | L42: =L40+L41 -> 665.94629
C44: Investor Exit Proceeds: | D44: x | J44: =J42*$K$8 -> 59.724015 | K44: =K42*$K$8 -> 134.74065 | L44: =L42*$K$8 -> 159.77716
C45: Money-on-Money Multiple: | D45: x | J45: =J44/$K$7 -> 2.0870409 | K45: =K44/$K$7 -> 4.7084785 | L45: =L44/$K$7 -> 5.5833734
C46: IRR (Internal Rate of Return): | D46: % | J46: =POWER(J44/$K$7,1/3)-1 -> 0.27793958 | K46: =POWER(K44/$K$7,1/4)-1 -> 0.47305902 | L46: =POWER(L44/$K$7,1/5)-1 -> 0.41052028

Sheet Model-Build
E2: ='Returns-Summary'!$E$14 -> Actuals | H2: ='Returns-Summary'!$H$14 -> Forecast
B3: Operating & Financing Drivers: | D3: ='Returns-Summary'!$D$15 -> Reporting Units: | E3: ='Returns-Summary'!$E$15 -> 41608 | F3: ='Returns-Summary'!$F$15 -> 41973 | G3: ='Returns-Summary'!$G$15 -> 42338 | H3: ='Returns-Summary'!$H$15 -> 42704 | I3: ='Returns-Summary'!$I$15 -> 43069 | J3: ='Returns-Summary'!$J$15 -> 43434 | K3: ='Returns-Summary'!$K$15 -> 43799 | L3: ='Returns-Summary'!$L$15 -> 44165
B4: Revenue & Cost Drivers:
C6: Selling Staff: | D6: Headcount (#) | E6: 192 | F6: 271 | G6: 417 | H6: =G6*(1+H7) -> 627.32312 | I6: =H6*(1+I7) -> 839.60613 | J6: =I6*(1+J7) -> 1133.7286 | K6: =J6*(1+K7) -> 1411.0794 | L6: =K6*(1+L7) -> 1651.1604
C7: Growth (%): | D7: % | F7: =F6/E6-1 -> 0.41145833 | G7: =G6/F6-1 -> 0.53874539 | H7: 0.504372 | I7: 0.338395 | J7: 0.35031 | K7: 0.244636 | L7: 0.17014
C9: Productivity per Sales Rep: | D9: £ M | E9: =E83/E6 -> 0.20520833 | F9: =F83/F6 -> 0.23052399 | G9: =G83/G6 -> 0.22777698 | H9: =G9*(1+H10) -> 0.23370351 | I9: =H9*(1+I10) -> 0.24077748 | J9: =I9*(1+J10) -> 0.24624722 | K9: =J9*(1+K10) -> 0.25084909 | L9: =K9*(1+L10) -> 0.25622955
C10: Growth (%): | D10: % | F10: =F9/E9-1 -> 0.12336561 | G10: =G9/F9-1 -> -0.01191636 | H10: 0.026019 | I10: 0.030269 | J10: 0.022717 | K10: 0.018688 | L10: 0.021449
C12: Non-Selling Staff: | D12: Headcount (#) | E12: 53 | F12: 66 | G12: 88 | H12: =H13*H6 -> 135.8876 | I12: =I13*I6 -> 139.65337 | J12: =J13*J6 -> 183.68443 | K12: =K13*K6 -> 235.31724 | L12: =L13*L6 -> 277.12086
C13: Other Staff as % of Sales Reps: | D13: % | E13: =E12/E6 -> 0.27604167 | F13: =F12/F6 -> 0.24354244 | G13: =G12/G6 -> 0.21103118 | H13: 0.216615 | I13: 0.166332 | J13: 0.162018 | K13: 0.166764 | L13: 0.167834
C15: NFI Margin (%): | D15: % | E15: =E86/E83 -> 0.51269036 | F15: =F86/F83 -> 0.47949481 | G15: =G86/G83 -> 0.48428666 | H15: 0.493802 | I15: 0.556668 | J15: 0.39428 | K15: 0.501311 | L15: 0.489702
C17: Payroll Cost per Head: | D17: £ M | E17: =E89/(E6+E12) -> 0.040816327 | F17: =F89/(F6+F12) -> 0.048652819 | G17: =G89/(G6+G12) -> 0.050740594 | H17: =G17*(1+H18) -> 0.053366471 | I17: =H17*(1+I18) -> 0.055603059 | J17: =I17*(1+J18) -> 0.057404209 | K17: =J17*(1+K18) -> 0.059606866 | L17: =K17*(1+L18) -> 0.061626168
C18: Growth (%): | D18: % | F18: =F17/E17-1 -> 0.19199407 | G18: =G17/F17-1 -> 0.042911698 | H18: 0.051751 | I18: 0.04191 | J18: 0.032393 | K18: 0.038371 | L18: 0.033877
C20: Sundry SG&A: | D20: £ M | E20: =E90 -> 4.9 | F20: =F90 -> 5.2 | G20: =G90 -> 5.6 | H20: =G20*(1+H21) -> 5.8932104 | I20: =H20*(1+I21) -> 6.1893914 | J20: =I20*(1+J21) -> 6.4469134 | K20: =J20*(1+K21) -> 6.7671445 | L20: =K20*(1+L21) -> 7.0414642
C21: Growth (%): | D21: % | F21: =F20/E20-1 -> 0.06122449 | G21: =G20/F20-1 -> 0.076923077 | H21: 0.052359 | I21: 0.050258 | J21: 0.041607 | K21: 0.049672 | L21: 0.040537
C23: UK Corporation Tax Rate: | D23: % | H23: 0.232767 | I23: 0.162604 | J23: 0.166824 | K23: 0.209089 | L23: 0.168549
B25: Debt & Interest Schedule: | D25: Opening Balance: | E25: Spread (bps) / PIK %: | F25: Amortisation (% of Balance): | G25: PIK Flag?
C26: Bank Facility A: | D26: 11.4987 | E26: 378.076 | F26: 0.096761 | G26: 0
C27: Bank Facility B: | D27: 19.9396 | E27: 403.761 | F27: 0 | G27: 0
C28: Shareholder PIK Loan: | D28: 5.1525 | E28: 0.108084 | F28: 0 | G28: 1
C29: Cash Balance: | D29: =G104 -> 12.149 | E29: 51.3748
C31: Benchmark Rate (LIBOR): | D31: % | H31: 0.011711 | I31: 0.010101 | J31: 0.009724 | K31: 0.011708 | L31: 0.017209
C32: Bank Facility A — Interest | D32: % | H32: =H31+$E$26/10000 -> 0.0495186 | I32: =I31+$E$26/10000 -> 0.0479086 | J32: =J31+$E$26/10000 -> 0.0475316 | K32: =K31+$E$26/10000 -> 0.0495156 | L32: =L31+$E$26/10000 -> 0.0550166
C33: Bank Facility B — Interest | D33: % | H33: =H31+$E$27/10000 -> 0.0520871 | I33: =I31+$E$27/10000 -> 0.0504771 | J33: =J31+$E$27/10000 -> 0.0501001 | K33: =K31+$E$27/10000 -> 0.0520841 | L33: =L31+$E$27/10000 -> 0.0575851
C34: Shareholder PIK Loan — Interest | D34: % | H34: =$E$28 -> 0.108084 | I34: =$E$28 -> 0.108084 | J34: =$E$28 -> 0.108084 | K34: =$E$28 -> 0.108084 | L34: =$E$28 -> 0.108084
C35: Cash — Interest | D35: % | H35: =H31+$E$29/10000 -> 0.01684848 | I35: =I31+$E$29/10000 -> 0.01523848 | J35: =J31+$E$29/10000 -> 0.01486148 | K35: =K31+$E$29/10000 -> 0.01684548 | L35: =L31+$E$29/10000 -> 0.02234648
C37: Bank Facility A — Opening | D37: £ M | H37: =D26 -> 11.4987 | I37: =H39 -> 10.386074 | J37: =I39 -> 9.2734486 | K37: =J39 -> 8.1608229 | L37: =K39 -> 7.0481972
C38: Less: Amortisation | D38: £ M | H38: =-$D$26*$F$26 -> -1.1126257 | I38: =-$D$26*$F$26 -> -1.1126257 | J38: =-$D$26*$F$26 -> -1.1126257 | K38: =-$D$26*$F$26 -> -1.1126257 | L38: =-$D$26*$F$26 -> -1.1126257
C39: Bank Facility A — Closing | D39: £ M | H39: =SUM(H37:H38) -> 10.386074 | I39: =SUM(I37:I38) -> 9.2734486 | J39: =SUM(J37:J38) -> 8.1608229 | K39: =SUM(K37:K38) -> 7.0481972 | L39: =SUM(L37:L38) -> 5.9355714
C41: Bank Facility A — Interest | D41: £ M | H41: =H37*H32 -> 0.56939953 | I41: =I37*I32 -> 0.49758228 | J41: =J37*J32 -> 0.44078185 | K41: =K37*K32 -> 0.40408804 | L41: =L37*L32 -> 0.38776784
C43: Bank Facility B — Opening | D43: £ M | H43: =D27 -> 19.9396 | I43: =H45 -> 19.9396 | J43: =I45 -> 19.9396 | K43: =J45 -> 19.9396 | L43: =K45 -> 19.9396
C44: Less: Amortisation | D44: £ M | H44: =-$D$27*$F$27 -> 0 | I44: =-$D$27*$F$27 -> 0 | J44: =-$D$27*$F$27 -> 0 | K44: =-$D$27*$F$27 -> 0 | L44: =-$D$27*$F$27 -> 0
C45: Bank Facility B — Closing | D45: £ M | H45: =SUM(H43:H44) -> 19.9396 | I45: =SUM(I43:I44) -> 19.9396 | J45: =SUM(J43:J44) -> 19.9396 | K45: =SUM(K43:K44) -> 19.9396 | L45: =SUM(L43:L44) -> 19.9396
C47: Bank Facility B — Interest | D47: £ M | H47: =H43*H33 -> 1.0385959 | I47: =I43*I33 -> 1.0064932 | J47: =J43*J33 -> 0.99897595 | K47: =K43*K33 -> 1.0385361 | L47: =L43*L33 -> 1.1482239
C49: Shareholder Loan — Opening | D49: £ M | H49: =D28 -> 5.1525 | I49: =H52 -> 5.7094028 | J49: =I52 -> 6.3264979 | K49: =J52 -> 7.0102911 | L49: =K52 -> 7.7679914
C50: Less: Amortisation | D50: £ M | H50: =-$D$28*$F$28 -> 0 | I50: =-$D$28*$F$28 -> 0 | J50: =-$D$28*$F$28 -> 0 | K50: =-$D$28*$F$28 -> 0 | L50: =-$D$28*$F$28 -> 0
C51: Add: PIK Interest | D51: £ M | H51: =H49*H34 -> 0.55690281 | I51: =I49*I34 -> 0.61709509 | J51: =J49*J34 -> 0.6837932 | K51: =K49*K34 -> 0.7577003 | L51: =L49*L34 -> 0.83959558
C52: Shareholder Loan — Closing | D52: £ M | H52: =SUM(H49:H51) -> 5.7094028 | I52: =SUM(I49:I51) -> 6.3264979 | J52: =SUM(J49:J51) -> 7.0102911 | K52: =SUM(K49:K51) -> 7.7679914 | L52: =SUM(L49:L51) -> 8.607587
C54: Cash — Interest Income | D54: £ M | H54: =H35*G104 -> 0.20469218 | I54: =I35*H104 -> 0 | J54: =J35*I104 -> 0 | K54: =K35*J104 -> 0 | L54: =L35*K104 -> 0
B56: Balance-Sheet Assumptions:
C57: Receivables as % of Turnover: | D57: % | E57: =E105/E83 -> 0.13379406 | F57: =F105/F83 -> 0.19536752 | G57: =G105/G83 -> 0.13209732 | H57: 0.153214 | I57: 0.116453 | J57: 0.097187 | K57: 0.137171 | L57: 0.130161
...
