Workbook

Sheet Drivers
B1: ($ in millions)
B3: FY2025P - FY2035P Forecast Assumptions
B5: FY2025P Gross Bookings Growth (%)
B6: Mobility Segment | C6: 0.168179
B7: Delivery Segment | C7: 0.158327
B8: Freight Segment | C8: 0.017205
B10: FY2026P - FY2035P Annual Change in Gross Bookings Growth Rate (Percentage Points)
B11: Mobility Segment | C11: -0.009107
B12: Delivery Segment | C12: -0.010721
B13: Freight Segment | C13: -0.000934
B15: FY2025P - FY2035P Annual Change in Take Rate (Percentage Points)
B16: Mobility Segment | C16: 0.005363
B17: Delivery Segment | C17: -0.002573
B18: Freight Segment | C18: 0
B20: FY2025P - FY2035P Annual Change in Adjusted EBITDA Margin (Percentage Points)
B21: Mobility Segment | C21: 0.002805
B22: Delivery Segment | C22: 0.001166
B23: Freight Segment | C23: 0.009906
B25: FY2025P - FY2035P Corporate Overhead Annual Growth Rate (%)
B26: Corporate Overhead Annual Growth (%) | C26: 0.044104
B28: Effective Tax Rate (% of EBIT)
B29: Effective Tax Rate (% of EBIT) | C29: 0.236885
B31: Capital Expenditures (CapEx)
B32: CapEx (% of Aggregate Gross Bookings) | C32: 0.002006
B34: Depreciation and Amortization (D&A)
B35: Weighted-Avg Useful Life of CapEx (Years) | C35: 5
B36: Net Property & Equipment (Net PP&E) Balance, 12/31/2024 | C36: 1653
B37: Net Carrying Value of Intangibles, 12/31/2024 | C37: 914
B38: FY2025P Intangible Amortization | C38: 246
B39: FY2026P Intangible Amortization | C39: 185
B40: FY2027P Intangible Amortization | C40: 170
B41: FY2028P Intangible Amortization | C41: 127
B42: FY2029P Intangible Amortization | C42: 84
B43: FY2030P - FY2035P Intangible Amortization (Spread Evenly Across FY2030P - FY2035P) | C43: 102
B45: Change in Net Working Capital (NWC)
B46: Δ NWC (% of Y/Y change in Aggregate Gross Bookings) | C46: 0.025
B48: Stock-Based Compensation (SBC)
B49: SBC (% of Aggregate Gross Bookings) | C49: 0.0125
B52: Footnotes:
B53: • Fiscal year-end: December 31
...

Sheet Operating Valuation
B1: ($ in millions)
C4: Actuals | E4: Forecast | P4: Terminal Year
B5: Uber Technologies (FYE 12/31) | C5: FY2023A | D5: FY2024A | E5: FY2025P | F5: FY2026P | G5: FY2027P | H5: FY2028P | I5: FY2029P | J5: FY2030P | K5: FY2031P | L5: FY2032P | M5: FY2033P | N5: FY2034P | O5: FY2035P | P5: Value
B7: Gross Bookings Growth (%)
B8: Mobility Segment | D8: =IFERROR(D14/C14-1,"n/m") -> 0.20504521 | E8: =Drivers!C6 -> 0.168179 | F8: =E8+Drivers!$C$11 -> 0.159072 | G8: =F8+Drivers!$C$11 -> 0.149965 | H8: =G8+Drivers!$C$11 -> 0.140858 | I8: =H8+Drivers!$C$11 -> 0.131751 | J8: =I8+Drivers!$C$11 -> 0.122644 | K8: =J8+Drivers!$C$11 -> 0.113537 | L8: =K8+Drivers!$C$11 -> 0.10443 | M8: =L8+Drivers!$C$11 -> 0.095323 | ... O8: =N8+Drivers!$C$11 -> 0.077109
B9: Delivery Segment | D9: =IFERROR(D15/C15-1,"n/m") -> 0.17085648 | E9: =Drivers!C7 -> 0.158327 | F9: =E9+Drivers!$C$12 -> 0.147606 | G9: =F9+Drivers!$C$12 -> 0.136885 | H9: =G9+Drivers!$C$12 -> 0.126164 | I9: =H9+Drivers!$C$12 -> 0.115443 | J9: =I9+Drivers!$C$12 -> 0.104722 | K9: =J9+Drivers!$C$12 -> 0.094001 | L9: =K9+Drivers!$C$12 -> 0.08328 | M9: =L9+Drivers!$C$12 -> 0.072559 | ... O9: =N9+Drivers!$C$12 -> 0.051117
B10: Freight Segment | D10: =IFERROR(D16/C16-1,"n/m") -> -0.020225148 | E10: =Drivers!C8 -> 0.017205 | F10: =E10+Drivers!$C$13 -> 0.016271 | G10: =F10+Drivers!$C$13 -> 0.015337 | H10: =G10+Drivers!$C$13 -> 0.014403 | I10: =H10+Drivers!$C$13 -> 0.013469 | J10: =I10+Drivers!$C$13 -> 0.012535 | K10: =J10+Drivers!$C$13 -> 0.011601 | L10: =K10+Drivers!$C$13 -> 0.010667 | M10: =L10+Drivers!$C$13 -> 0.009733 | ... O10: =N10+Drivers!$C$13 -> 0.007865
B11: Aggregate Gross Bookings Annual Growth | D11: =IFERROR(D17/C17-1,"n/m") -> 0.18067806 | E11: =E17/D17-1 -> 0.15890014 | F11: =F17/E17-1 -> 0.14986453 | G11: =G17/F17-1 -> 0.14068923 | H11: =H17/G17-1 -> 0.13140671 | I11: =I17/H17-1 -> 0.12204308 | J11: =J17/I17-1 -> 0.11261946 | K11: =K17/J17-1 -> 0.10315308 | L11: =L17/K17-1 -> 0.093658094 | ... O11: =O17/N17-1 -> 0.065110054
B13: Gross Bookings ($ mm)
B14: Mobility Segment | C14: 68897 | D14: 83024 | E14: =D14*(1+E8) -> 96986.893 | F14: =E14*(1+F8) -> 112414.79 | G14: =F14*(1+G8) -> 129273.08 | H14: =G14*(1+H8) -> 147482.22 | I14: =H14*(1+I8) -> 166913.15 | J14: =I14*(1+J8) -> 187384.05 | K14: =J14*(1+K8) -> 208659.07 | L14: =K14*(1+L8) -> 230449.34 | ... O14: =N14*(1+O8) -> 295320.45
B15: Delivery Segment | C15: 63726 | D15: 74614 | E15: =D15*(1+E9) -> 86427.411 | F15: =E15*(1+F9) -> 99184.615 | G15: =F15*(1+G9) -> 112761.5 | H15: =G15*(1+H9) -> 126987.94 | I15: =H15*(1+I9) -> 141647.81 | J15: =I15*(1+J9) -> 156481.45 | K15: =J15*(1+K9) -> 171190.87 | L15: =K15*(1+L9) -> 185447.64 | ... O15: =N15*(1+O9) -> 221999.42
B16: Freight Segment | C16: 5241 | D16: 5135 | E16: =D16*(1+E10) -> 5223.3477 | F16: =E16*(1+F10) -> 5308.3368 | G16: =F16*(1+G10) -> 5389.7507 | H16: =G16*(1+H10) -> 5467.3793 | I16: =H16*(1+I10) -> 5541.0194 | J16: =I16*(1+J10) -> 5610.4761 | K16: =J16*(1+K10) -> 5675.5632 | L16: =K16*(1+L10) -> 5736.1045 | ... O16: =N16*(1+O10) -> 5888.8516
B17: Aggregate Gross Bookings | C17: =SUM(C14:C16) -> 137864 | D17: =SUM(D14:D16) -> 162773 | E17: =SUM(E14:E16) -> 188637.65 | F17: =SUM(F14:F16) -> 216907.74 | G17: =SUM(G14:G16) -> 247424.33 | H17: =SUM(H14:H16) -> 279937.55 | I17: =SUM(I14:I16) -> 314101.99 | J17: =SUM(J14:J16) -> 349475.98 | ... O17: =SUM(O14:O16) -> 523208.72 | P17: =O17 -> 523208.72
B18: Annual Growth (%) | D18: =D17/C17-1 -> 0.18067806 | E18: =E17/D17-1 -> 0.15890014 | F18: =F17/E17-1 -> 0.14986453 | G18: =G17/F17-1 -> 0.14068923 | H18: =H17/G17-1 -> 0.13140671 | I18: =I17/H17-1 -> 0.12204308 | J18: =J17/I17-1 -> 0.11261946 | K18: =K17/J17-1 -> 0.10315308 | ... O18: =O17/N17-1 -> 0.065110054
B20: Take Rate (% of Bookings)
B21: Mobility Segment | C21: =C27/C14 -> 0.28784998 | D21: =D27/D14 -> 0.30216564 | E21: =D21+Drivers!$C$16 -> 0.30752864 | F21: =E21+Drivers!$C$16 -> 0.31289164 | G21: =F21+Drivers!$C$16 -> 0.31825464 | H21: =G21+Drivers!$C$16 -> 0.32361764 | I21: =H21+Drivers!$C$16 -> 0.32898064 | J21: =I21+Drivers!$C$16 -> 0.33434364 | K21: =J21+Drivers!$C$16 -> 0.33970664 | L21: =K21+Drivers!$C$16 -> 0.34506964 | ... O21: =N21+Drivers!$C$16 -> 0.36115864
B22: Delivery Segment | C22: =C28/C15 -> 0.19150739 | D22: =D28/D15 -> 0.18428177 | E22: =D22+Drivers!$C$17 -> 0.18170877 | F22: =E22+Drivers!$C$17 -> 0.17913577 | G22: =F22+Drivers!$C$17 -> 0.17656277 | H22: =G22+Drivers!$C$17 -> 0.17398977 | I22: =H22+Drivers!$C$17 -> 0.17141677 | J22: =I22+Drivers!$C$17 -> 0.16884377 | K22: =J22+Drivers!$C$17 -> 0.16627077 | L22: =K22+Drivers!$C$17 -> 0.16369777 | ... O22: =N22+Drivers!$C$17 -> 0.15597877
B23: Freight Segment | C23: =C29/C16 -> 1.0007632 | D23: =D29/D16 -> 1.0011685 | E23: =D23+Drivers!$C$18 -> 1.0011685 | F23: =E23+Drivers!$C$18 -> 1.0011685 | G23: =F23+Drivers!$C$18 -> 1.0011685 | H23: =G23+Drivers!$C$18 -> 1.0011685 | I23: =H23+Drivers!$C$18 -> 1.0011685 | J23: =I23+Drivers!$C$18 -> 1.0011685 | K23: =J23+Drivers!$C$18 -> 1.0011685 | L23: =K23+Drivers!$C$18 -> 1.0011685 | ... O23: =N23+Drivers!$C$18 -> 1.0011685
B24: Blended Take Rate | C24: =C30/C17 -> 0.27041867 | D24: =D30/D17 -> 0.27017994 | E24: =E30/E17 -> 0.269089 | F24: =F30/F17 -> 0.26857363 | G24: =G30/G17 -> 0.268556 | H24: =H30/H17 -> 0.26897507 | I24: =I30/I17 -> 0.2697834 | J24: =J30/J17 -> 0.27094456 | ... O24: =O30/O17 -> 0.28130353
B26: Revenue ($ mm)
B27: Mobility Segment | C27: 19832 | D27: 25087 | E27: =E14*E21 -> 29826.247 | F27: =F14*F21 -> 35173.649 | G27: =G14*G21 -> 41141.756 | H27: =H14*H21 -> 47727.849 | I27: =I14*I21 -> 54911.196 | J27: =J14*J21 -> 62650.666 | K27: =K14*K21 -> 70882.873 | L27: =L14*L21 -> 79521.071 | ... O27: =O14*O21 -> 106657.53
B28: Delivery Segment | C28: 12204 | D28: 13750 | E28: =E15*E22 -> 15704.619 | F28: =F15*F22 -> 17767.512 | G28: =G15*G22 -> 19909.483 | H28: =H15*H22 -> 22094.603 | I28: =I15*I22 -> 24280.811 | J28: =J15*J22 -> 26420.919 | K28: =K15*K22 -> 28464.037 | L28: =L15*L22 -> 30357.366 | ... O28: =O15*O22 -> 34627.196
B29: Freight Segment | C29: 5245 | D29: 5141 | E29: =E16*E23 -> 5229.4509 | F29: =F16*F23 -> 5314.5393 | G29: =G16*G23 -> 5396.0484 | H29: =H16*H23 -> 5473.7677 | I29: =I16*I23 -> 5547.4939 | J29: =J16*J23 -> 5617.0317 | K29: =K16*K23 -> 5682.1949 | L29: =L16*L23 -> 5742.8068 | ... O29: =O16*O23 -> 5895.7324
B30: Consolidated Revenue | C30: =SUM(C27:C29) -> 37281 | D30: =SUM(D27:D29) -> 43978 | E30: =SUM(E27:E29) -> 50760.317 | F30: =SUM(F27:F29) -> 58255.7 | G30: =SUM(G27:G29) -> 66447.288 | H30: =SUM(H27:H29) -> 75296.22 | I30: =SUM(I27:I29) -> 84739.5 | J30: =SUM(J27:J29) -> 94688.616 | ... O30: =SUM(O27:O29) -> 147180.46 | P30: =O30 -> 147180.46
B31: Annual Growth (%) | D31: =D30/C30-1 -> 0.17963574 | E31: =E30/D30-1 -> 0.15422067 | F31: =F30/E30-1 -> 0.14766227 | G31: =G30/F30-1 -> 0.14061435 | H31: =H30/G30-1 -> 0.13317221 | I31: =I30/H30-1 -> 0.12541507 | J31: =J30/I30-1 -> 0.11740824 | K31: =K30/J30-1 -> 0.1092052 | ... O31: =O30/N30-1 -> 0.075188857
B33: Adj. EBITDA Margin (%)
B34: Mobility Segment | C34: =IFERROR(C41/C27,"n/m") -> 0.25025212 | D34: =IFERROR(D41/D27,"n/m") -> 0.25897875 | E34: =D34+Drivers!$C$21 -> 0.26178375 | F34: =E34+Drivers!$C$21 -> 0.26458875 | G34: =F34+Drivers!$C$21 -> 0.26739375 | H34: =G34+Drivers!$C$21 -> 0.27019875 | I34: =H34+Drivers!$C$21 -> 0.27300375 | J34: =I34+Drivers!$C$21 -> 0.27580875 | K34: =J34+Drivers!$C$21 -> 0.27861375 | L34: =K34+Drivers!$C$21 -> 0.28141875 | ... O34: =N34+Drivers!$C$21 -> 0.28983375
B35: Delivery Segment | C35: =IFERROR(C42/C28,"n/m") -> 0.12340216 | D35: =IFERROR(D42/D28,"n/m") -> 0.17970909 | E35: =D35+Drivers!$C$22 -> 0.18087509 | F35: =E35+Drivers!$C$22 -> 0.18204109 | G35: =F35+Drivers!$C$22 -> 0.18320709 | H35: =G35+Drivers!$C$22 -> 0.18437309 | I35: =H35+Drivers!$C$22 -> 0.18553909 | J35: =I35+Drivers!$C$22 -> 0.18670509 | K35: =J35+Drivers!$C$22 -> 0.18787109 | L35: =K35+Drivers!$C$22 -> 0.18903709 | ... O35: =N35+Drivers!$C$22 -> 0.19253509
B36: Freight Segment | C36: =IFERROR(C43/C29,"n/m") -> -0.012202097 | D36: =IFERROR(D43/D29,"n/m") -> -0.014394087 | E36: =D36+Drivers!$C$23 -> -0.0044880868 | F36: =E36+Drivers!$C$23 -> 0.0054179132 | G36: =F36+Drivers!$C$23 -> 0.015323913 | H36: =G36+Drivers!$C$23 -> 0.025229913 | I36: =H36+Drivers!$C$23 -> 0.035135913 | J36: =I36+Drivers!$C$23 -> 0.045041913 | K36: =J36+Drivers!$C$23 -> 0.054947913 | L36: =K36+Drivers!$C$23 -> 0.064853913 | ... O36: =N36+Drivers!$C$23 -> 0.094571913
B37: Corporate Overhead | C37: N/A | D37: N/A | E37: N/A | F37: N/A | G37: N/A | H37: N/A | I37: N/A | J37: N/A | K37: N/A | L37: N/A | M37: N/A | N37: N/A | O37: N/A
B38: Adj. EBITDA Margin | C38: =IFERROR(C45/C30,"n/m") -> 0.10868807 | D38: =IFERROR(D45/D30,"n/m") -> 0.14743736 | E38: =IFERROR(E45/E30,"n/m") -> 0.15974763 | F38: =IFERROR(F45/F30,"n/m") -> 0.17066989 | G38: =IFERROR(G45/G30,"n/m") -> 0.18041599 | H38: =IFERROR(H45/H30,"n/m") -> 0.18916796 | I38: =IFERROR(I45/I30,"n/m") -> 0.19708015 | J38: =IFERROR(J45/J30,"n/m") -> 0.20428209 | ... O38: =IFERROR(O45/O30,"n/m") -> 0.23279672
B40: Adjusted EBITDA ($ mm)
B41: Mobility Segment | C41: 4963 | D41: 6497 | E41: =E27*E34 -> 7808.027 | F41: =F27*F34 -> 9306.5519 | G41: =G27*G34 -> 11001.049 | H41: =H27*H34 -> 12896.005 | I41: =I27*I34 -> 14990.963 | J41: =J27*J34 -> 17279.602 | K41: =K27*K34 -> 19748.943 | L41: =L27*L34 -> 22378.721 | ... O41: =O27*O34 -> 30912.953
B42: Delivery Segment | C42: 1506 | D42: 2471 | E42: =E28*E35 -> 2840.5743 | F42: =F28*F35 -> 3234.4173 | G42: =G28*G35 -> 3647.5585 | H42: =H28*H35 -> 4073.6503 | I42: =I28*I35 -> 4505.0395 | J42: =J28*J35 -> 4932.92 | K42: =K28*K35 -> 5347.5698 | L42: =L28*L35 -> 5738.6681 | ... O42: =O28*O35 -> 6666.9503
B43: Freight Segment | C43: -64 | D43: -74 | E43: =E29*E36 -> -23.470229 | F43: =F29*F36 -> 28.793713 | G43: =G29*G36 -> 82.688577 | H43: =H29*H36 -> 138.10268 | I43: =I29*I36 -> 194.91626 | J43: =J29*J36 -> 253.00185 | K43: =K29*K36 -> 312.22475 | L43: =L29*L36 -> 372.4435 | ... O43: =O29*O36 -> 557.5707
B44: Corporate Overhead | C44: -2353 | D44: -2410 | E44: =D44*(1+Drivers!$C$26) -> -2516.2906 | F44: =E44*(1+Drivers!$C$26) -> -2627.2691 | G44: =F44*(1+Drivers!$C$26) -> -2743.1422 | H44: =G44*(1+Drivers!$C$26) -> -2864.1257 | I44: =H44*(1+Drivers!$C$26) -> -2990.4451 | J44: =I44*(1+Drivers!$C$26) -> -3122.3357 | K44: =J44*(1+Drivers!$C$26) -> -3260.0432 | L44: =K44*(1+Drivers!$C$26) -> -3403.8242 | ... O44: =N44*(1+Drivers!$C$26) -> -3874.346
B45: Adjusted EBITDA | C45: =SUM(C41:C44) -> 4052 | D45: =SUM(D41:D44) -> 6484 | E45: =SUM(E41:E44) -> 8108.8404 | F45: =SUM(F41:F44) -> 9942.4938 | G45: =SUM(G41:G44) -> 11988.154 | H45: =SUM(H41:H44) -> 14243.633 | I45: =SUM(I41:I44) -> 16700.473 | J45: =SUM(J41:J44) -> 19343.188 | ... O45: =SUM(O41:O44) -> 34263.128 | P45: =O45 -> 34263.128
B46: Annual Growth (%) | D46: =D45/C45-1 -> 0.60019743 | E46: =E45/D45-1 -> 0.25059229 | F46: =F45/E45-1 -> 0.22613016 | G46: =G45/F45-1 -> 0.20574916 | H46: =H45/G45-1 -> 0.18814232 | I46: =I45/H45-1 -> 0.17248695 | J46: =J45/I45-1 -> 0.15824191 | K46: =K45/J45-1 -> 0.14503847 | ... O46: =O45/N45-1 -> 0.098423096
B48: Less: D&A | E48: =-'D&A Schedule'!E51 -> -576.6 | F48: =-'D&A Schedule'!F51 -> -591.28143 | G48: =-'D&A Schedule'!G51 -> -663.30481 | H48: =-'D&A Schedule'!H51 -> -719.57145 | I48: =-'D&A Schedule'!I51 -> -788.8824 | J48: =-'D&A Schedule'!J51 -> -517.30011 | K48: =-'D&A Schedule'!K51 -> -581.82845 | L48: =-'D&A Schedule'!L51 -> -649.4779 | ... O48: =-'D&A Schedule'!O51 -> -861.51458
B50: EBIT | E50: =SUM(E45,E48) -> 7532.2404 | F50: =SUM(F45,F48) -> 9351.2124 | G50: =SUM(G45,G48) -> 11324.849 | H50: =SUM(H45,H48) -> 13524.061 | I50: =SUM(I45,I48) -> 15911.591 | J50: =SUM(J45,J48) -> 18825.888 | K50: =SUM(K45,K48) -> 21566.866 | L50: =SUM(L45,L48) -> 24436.53 | ... O50: =SUM(O45,O48) -> 33401.614
...

Sheet D&A Schedule
B1: ($ in millions)
D3: Actuals | E3: Forecast
D4: FY2024A | E4: FY2025P | F4: FY2026P | G4: FY2027P | H4: FY2028P | I4: FY2029P | J4: FY2030P | K4: FY2031P | L4: FY2032P | M4: FY2033P | N4: FY2034P | O4: FY2035P
B6: Weighted-Avg Useful Life of CapEx (Years) | C6: =Drivers!$C$35 -> 5
B8: Ending Net PP&E
B9: Vintage | C9: CapEx (Additions)
B10: Pre-FY2025P | D10: =Drivers!$C$36 -> 1653 | E10: =IF(D10+-$D10/$C$6<0,0,D10+-$D10/$C$6) -> 1322.4 | F10: =IF(E10+-$D10/$C$6<0,0,E10+-$D10/$C$6) -> 991.8 | G10: =IF(F10+-$D10/$C$6<0,0,F10+-$D10/$C$6) -> 661.2 | H10: =IF(G10+-$D10/$C$6<0,0,G10+-$D10/$C$6) -> 330.6 | I10: =IF(H10+-$D10/$C$6<0,0,H10+-$D10/$C$6) -> 0 | J10: =IF(I10+-$D10/$C$6<0,0,I10+-$D10/$C$6) -> 0 | K10: =IF(J10+-$D10/$C$6<0,0,J10+-$D10/$C$6) -> 0 | L10: =IF(K10+-$D10/$C$6<0,0,K10+-$D10/$C$6) -> 0 | ... O10: =IF(N10+-$D10/$C$6<0,0,N10+-$D10/$C$6) -> 0
B11: FY2025P | C11: {=TRANSPOSE('Operating Valuation'!E57:O57)} -> -378.40713 | E11: =-$C11 -> 378.40713 | F11: =IF(E11+$C11/$C$6<0,0,E11+$C11/$C$6) -> 302.7257 | G11: =IF(F11+$C11/$C$6<0,0,F11+$C11/$C$6) -> 227.04428 | H11: =IF(G11+$C11/$C$6<0,0,G11+$C11/$C$6) -> 151.36285 | I11: =IF(H11+$C11/$C$6<0,0,H11+$C11/$C$6) -> 75.681426 | J11: =IF(I11+$C11/$C$6<0,0,I11+$C11/$C$6) -> 0 | K11: =IF(J11+$C11/$C$6<0,0,J11+$C11/$C$6) -> 0 | L11: =IF(K11+$C11/$C$6<0,0,K11+$C11/$C$6) -> 0 | M11: =IF(L11+$C11/$C$6<0,0,L11+$C11/$C$6) -> 0 | ... O11: =IF(N11+$C11/$C$6<0,0,N11+$C11/$C$6) -> 0
B12: FY2026P | C12: -435.11694 | F12: =-$C12 -> 435.11694 | G12: =IF(F12+$C12/$C$6<0,0,F12+$C12/$C$6) -> 348.09355 | H12: =IF(G12+$C12/$C$6<0,0,G12+$C12/$C$6) -> 261.07016 | I12: =IF(H12+$C12/$C$6<0,0,H12+$C12/$C$6) -> 174.04677 | J12: =IF(I12+$C12/$C$6<0,0,I12+$C12/$C$6) -> 87.023387 | K12: =IF(J12+$C12/$C$6<0,0,J12+$C12/$C$6) -> 0 | L12: =IF(K12+$C12/$C$6<0,0,K12+$C12/$C$6) -> 0 | M12: =IF(L12+$C12/$C$6<0,0,L12+$C12/$C$6) -> 0 | N12: =IF(M12+$C12/$C$6<0,0,M12+$C12/$C$6) -> 0 | O12: =IF(N12+$C12/$C$6<0,0,N12+$C12/$C$6) -> 0
B13: FY2027P | C13: -496.3332 | G13: =-$C13 -> 496.3332 | H13: =IF(G13+$C13/$C$6<0,0,G13+$C13/$C$6) -> 397.06656 | I13: =IF(H13+$C13/$C$6<0,0,H13+$C13/$C$6) -> 297.79992 | J13: =IF(I13+$C13/$C$6<0,0,I13+$C13/$C$6) -> 198.53328 | K13: =IF(J13+$C13/$C$6<0,0,J13+$C13/$C$6) -> 99.266641 | L13: =IF(K13+$C13/$C$6<0,0,K13+$C13/$C$6) -> 0 | M13: =IF(L13+$C13/$C$6<0,0,L13+$C13/$C$6) -> 0 | N13: =IF(M13+$C13/$C$6<0,0,M13+$C13/$C$6) -> 0 | O13: =IF(N13+$C13/$C$6<0,0,N13+$C13/$C$6) -> 0
B14: FY2028P | C14: -561.55472 | H14: =-$C14 -> 561.55472 | I14: =IF(H14+$C14/$C$6<0,0,H14+$C14/$C$6) -> 449.24377 | J14: =IF(I14+$C14/$C$6<0,0,I14+$C14/$C$6) -> 336.93283 | K14: =IF(J14+$C14/$C$6<0,0,J14+$C14/$C$6) -> 224.62189 | L14: =IF(K14+$C14/$C$6<0,0,K14+$C14/$C$6) -> 112.31094 | M14: =IF(L14+$C14/$C$6<0,0,L14+$C14/$C$6) -> 0 | N14: =IF(M14+$C14/$C$6<0,0,M14+$C14/$C$6) -> 0 | O14: =IF(N14+$C14/$C$6<0,0,N14+$C14/$C$6) -> 0
B15: FY2029P | C15: -630.08858 | I15: =-$C15 -> 630.08858 | J15: =IF(I15+$C15/$C$6<0,0,I15+$C15/$C$6) -> 504.07087 | K15: =IF(J15+$C15/$C$6<0,0,J15+$C15/$C$6) -> 378.05315 | L15: =IF(K15+$C15/$C$6<0,0,K15+$C15/$C$6) -> 252.03543 | M15: =IF(L15+$C15/$C$6<0,0,L15+$C15/$C$6) -> 126.01772 | N15: =IF(M15+$C15/$C$6<0,0,M15+$C15/$C$6) -> 0 | O15: =IF(N15+$C15/$C$6<0,0,N15+$C15/$C$6) -> 0
B16: FY2030P | C16: -701.04882 | J16: =-$C16 -> 701.04882 | K16: =IF(J16+$C16/$C$6<0,0,J16+$C16/$C$6) -> 560.83906 | L16: =IF(K16+$C16/$C$6<0,0,K16+$C16/$C$6) -> 420.62929 | M16: =IF(L16+$C16/$C$6<0,0,L16+$C16/$C$6) -> 280.41953 | N16: =IF(M16+$C16/$C$6<0,0,M16+$C16/$C$6) -> 140.20976 | O16: =IF(N16+$C16/$C$6<0,0,N16+$C16/$C$6) -> 0
B17: FY2031P | C17: -773.36416 | K17: =-$C17 -> 773.36416 | L17: =IF(K17+$C17/$C$6<0,0,K17+$C17/$C$6) -> 618.69133 | M17: =IF(L17+$C17/$C$6<0,0,L17+$C17/$C$6) -> 464.0185 | N17: =IF(M17+$C17/$C$6<0,0,M17+$C17/$C$6) -> 309.34567 | O17: =IF(N17+$C17/$C$6<0,0,N17+$C17/$C$6) -> 154.67283
B18: FY2032P | C18: -845.79598 | L18: =-$C18 -> 845.79598 | M18: =IF(L18+$C18/$C$6<0,0,L18+$C18/$C$6) -> 676.63678 | N18: =IF(M18+$C18/$C$6<0,0,M18+$C18/$C$6) -> 507.47759 | O18: =IF(N18+$C18/$C$6<0,0,N18+$C18/$C$6) -> 338.31839
B19: FY2033P | C19: -916.96654 | M19: =-$C19 -> 916.96654 | N19: =IF(M19+$C19/$C$6<0,0,M19+$C19/$C$6) -> 733.57324 | O19: =IF(N19+$C19/$C$6<0,0,N19+$C19/$C$6) -> 550.17993
B20: FY2034P | C20: -985.39742 | N20: =-$C20 -> 985.39742 | O20: =IF(N20+$C20/$C$6<0,0,N20+$C20/$C$6) -> 788.31794
B21: FY2035P | C21: -1049.5567 | O21: =-$C21 -> 1049.5567
B22: Net PP&E (Total) | D22: =SUM(D10:D21) -> 1653 | E22: =SUM(E10:E21) -> 1700.8071 | F22: =SUM(F10:F21) -> 1729.6426 | G22: =SUM(G10:G21) -> 1732.671 | H22: =SUM(H10:H21) -> 1701.6543 | I22: =SUM(I10:I21) -> 1626.8605 | J22: =SUM(J10:J21) -> 1827.6092 | K22: =SUM(K10:K21) -> 2036.1449 | ... O22: =SUM(O10:O21) -> 2881.0458
B25: PP&E Depreciation
B26: Vintage
B27: Pre-FY2025P | E27: =IF(D10-E10<0,0,D10-E10) -> 330.6 | F27: =IF(E10-F10<0,0,E10-F10) -> 330.6 | G27: =IF(F10-G10<0,0,F10-G10) -> 330.6 | H27: =IF(G10-H10<0,0,G10-H10) -> 330.6 | I27: =IF(H10-I10<0,0,H10-I10) -> 330.6 | J27: =IF(I10-J10<0,0,I10-J10) -> 0 | K27: =IF(J10-K10<0,0,J10-K10) -> 0 | L27: =IF(K10-L10<0,0,K10-L10) -> 0 | ... O27: =IF(N10-O10<0,0,N10-O10) -> 0
B28: FY2025P | E28: =IF(D11-E11<0,0,D11-E11) -> 0 | F28: =IF(E11-F11<0,0,E11-F11) -> 75.681426 | G28: =IF(F11-G11<0,0,F11-G11) -> 75.681426 | H28: =IF(G11-H11<0,0,G11-H11) -> 75.681426 | I28: =IF(H11-I11<0,0,H11-I11) -> 75.681426 | J28: =IF(I11-J11<0,0,I11-J11) -> 75.681426 | K28: =IF(J11-K11<0,0,J11-K11) -> 0 | L28: =IF(K11-L11<0,0,K11-L11) -> 0 | ... O28: =IF(N11-O11<0,0,N11-O11) -> 0
B29: FY2026P | F29: =IF(E12-F12<0,0,E12-F12) -> 0 | G29: =IF(F12-G12<0,0,F12-G12) -> 87.023387 | H29: =IF(G12-H12<0,0,G12-H12) -> 87.023387 | I29: =IF(H12-I12<0,0,H12-I12) -> 87.023387 | J29: =IF(I12-J12<0,0,I12-J12) -> 87.023387 | K29: =IF(J12-K12<0,0,J12-K12) -> 87.023387 | L29: =IF(K12-L12<0,0,K12-L12) -> 0 | M29: =IF(L12-M12<0,0,L12-M12) -> 0 | ... O29: =IF(N12-O12<0,0,N12-O12) -> 0
B30: FY2027P | G30: =IF(F13-G13<0,0,F13-G13) -> 0 | H30: =IF(G13-H13<0,0,G13-H13) -> 99.266641 | I30: =IF(H13-I13<0,0,H13-I13) -> 99.266641 | J30: =IF(I13-J13<0,0,I13-J13) -> 99.266641 | K30: =IF(J13-K13<0,0,J13-K13) -> 99.266641 | L30: =IF(K13-L13<0,0,K13-L13) -> 99.266641 | M30: =IF(L13-M13<0,0,L13-M13) -> 0 | N30: =IF(M13-N13<0,0,M13-N13) -> 0 | O30: =IF(N13-O13<0,0,N13-O13) -> 0
B31: FY2028P | H31: =IF(G14-H14<0,0,G14-H14) -> 0 | I31: =IF(H14-I14<0,0,H14-I14) -> 112.31094 | J31: =IF(I14-J14<0,0,I14-J14) -> 112.31094 | K31: =IF(J14-K14<0,0,J14-K14) -> 112.31094 | L31: =IF(K14-L14<0,0,K14-L14) -> 112.31094 | M31: =IF(L14-M14<0,0,L14-M14) -> 112.31094 | N31: =IF(M14-N14<0,0,M14-N14) -> 0 | O31: =IF(N14-O14<0,0,N14-O14) -> 0
B32: FY2029P | I32: =IF(H15-I15<0,0,H15-I15) -> 0 | J32: =IF(I15-J15<0,0,I15-J15) -> 126.01772 | K32: =IF(J15-K15<0,0,J15-K15) -> 126.01772 | L32: =IF(K15-L15<0,0,K15-L15) -> 126.01772 | M32: =IF(L15-M15<0,0,L15-M15) -> 126.01772 | N32: =IF(M15-N15<0,0,M15-N15) -> 126.01772 | O32: =IF(N15-O15<0,0,N15-O15) -> 0
B33: FY2030P | J33: =IF(I16-J16<0,0,I16-J16) -> 0 | K33: =IF(J16-K16<0,0,J16-K16) -> 140.20976 | L33: =IF(K16-L16<0,0,K16-L16) -> 140.20976 | M33: =IF(L16-M16<0,0,L16-M16) -> 140.20976 | N33: =IF(M16-N16<0,0,M16-N16) -> 140.20976 | O33: =IF(N16-O16<0,0,N16-O16) -> 140.20976
B34: FY2031P | K34: =IF(J17-K17<0,0,J17-K17) -> 0 | L34: =IF(K17-L17<0,0,K17-L17) -> 154.67283 | M34: =IF(L17-M17<0,0,L17-M17) -> 154.67283 | N34: =IF(M17-N17<0,0,M17-N17) -> 154.67283 | O34: =IF(N17-O17<0,0,N17-O17) -> 154.67283
B35: FY2032P | L35: =IF(K18-L18<0,0,K18-L18) -> 0 | M35: =IF(L18-M18<0,0,L18-M18) -> 169.1592 | N35: =IF(M18-N18<0,0,M18-N18) -> 169.1592 | O35: =IF(N18-O18<0,0,N18-O18) -> 169.1592
B36: FY2033P | M36: =IF(L19-M19<0,0,L19-M19) -> 0 | N36: =IF(M19-N19<0,0,M19-N19) -> 183.39331 | O36: =IF(N19-O19<0,0,N19-O19) -> 183.39331
B37: FY2034P | N37: =IF(M20-N20<0,0,M20-N20) -> 0 | O37: =IF(N20-O20<0,0,N20-O20) -> 197.07948
B38: FY2035P | O38: =IF(N21-O21<0,0,N21-O21) -> 0
B39: Total PP&E Depreciation | E39: =SUM(E27:E38) -> 330.6 | F39: =SUM(F27:F38) -> 406.28143 | G39: =SUM(G27:G38) -> 493.30481 | H39: =SUM(H27:H38) -> 592.57145 | I39: =SUM(I27:I38) -> 704.8824 | J39: =SUM(J27:J38) -> 500.30011 | K39: =SUM(K27:K38) -> 564.82845 | L39: =SUM(L27:L38) -> 632.4779 | ... O39: =SUM(O27:O38) -> 844.51458
B42: Intangible Amortization
B43: Intangibles — Net Carrying Value | D43: =Drivers!$C$37 -> 914 | E43: =D43-E45 -> 668 | F43: =E43-F45 -> 483 | G43: =F43-G45 -> 313 | H43: =G43-H45 -> 186 | I43: =H43-I45 -> 102 | J43: =I43-J45 -> 85 | K43: =J43-K45 -> 68 | L43: =K43-L45 -> 51 | ... O43: =N43-O45 -> 0
B45: Intangible Amortization | E45: {=TRANSPOSE(Drivers!$C$38:$C$42)} -> 246 | F45: 185 | G45: 170 | H45: 127 | I45: 84 | J45: =Drivers!$C$43/COUNTA($J$4:$O$4) -> 17 | K45: =Drivers!$C$43/COUNTA($J$4:$O$4) -> 17 | L45: =Drivers!$C$43/COUNTA($J$4:$O$4) -> 17 | M45: =Drivers!$C$43/COUNTA($J$4:$O$4) -> 17 | N45: =Drivers!$C$43/COUNTA($J$4:$O$4) -> 17 | O45: =Drivers!$C$43/COUNTA($J$4:$O$4) -> 17
B48: Total D&A
B49: PP&E Depreciation | E49: =E39 -> 330.6 | F49: =F39 -> 406.28143 | G49: =G39 -> 493.30481 | H49: =H39 -> 592.57145 | I49: =I39 -> 704.8824 | J49: =J39 -> 500.30011 | K49: =K39 -> 564.82845 | L49: =L39 -> 632.4779 | ... O49: =O39 -> 844.51458
B50: Intangible Amortization | E50: =E45 -> 246 | F50: =F45 -> 185 | G50: =G45 -> 170 | H50: =H45 -> 127 | I50: =I45 -> 84 | J50: =J45 -> 17 | K50: =K45 -> 17 | L50: =L45 -> 17 | ... O50: =O45 -> 17
...
