Workbook

Sheet Drivers
A2: Projection Inputs
B6: Operating Model Assumptions | C6: 40908 | D6: =EOMONTH(C6,13) -> 41305 | E6: =EOMONTH(D6,12) -> 41670 | F6: =EOMONTH(E6,12) -> 42035 | G6: =EOMONTH(F6,12) -> 42400 | H6: =EOMONTH(G6,12) -> 42766 | I6: =EOMONTH(H6,12) -> 43131 | J6: =EOMONTH(I6,12) -> 43496
B7: Top-Line Growth (YoY %) | E7: ='P&L'!E102 -> 0.96688702 | F7: 1 | G7: 0.772078 | H7: 0.932974 | I7: 0.946124 | J7: 0.767217
B8: Delivery Cost Ratio (% of Sales) | D8: ='P&L'!D105 -> -0.225728 | E8: ='P&L'!E105 -> -0.232448 | F8: -0.191609 | G8: -0.21867 | H8: -0.238979 | I8: -0.238706 | J8: -0.196203
B9: Product Engineering (% of Sales) | D9: ='P&L'!D107 -> -0.533345 | E9: ='P&L'!E107 -> -0.343535 | F9: -0.257327 | G9: -0.29594 | H9: -0.226937 | I9: -0.125974 | J9: -0.086575
B10: Commercial Spend (% of Sales) | D10: ='P&L'!D109 -> -1.374587 | E10: ='P&L'!E109 -> -1.620786 | F10: -1.259474 | G10: -1.245412 | H10: -1 | I10: -0.806052 | J10: -0.804721
B11: G&A Load (% of Sales) | D11: ='P&L'!D111 -> -0.431271 | E11: ='P&L'!E111 -> -0.347697 | F11: -0.269781 | G11: -0.326593 | H11: -0.301588 | I11: -0.212493 | J11: -0.263047
B12: Capital Spend (% of Sales) | D12: ='Debt-Capex-Amort'!D52 -> 0.27890972 | E12: ='Debt-Capex-Amort'!E52 -> 0.18379859 | F12: 0.042093 | G12: 0.047855 | H12: 0.058757 | I12: 0.059184 | J12: 0.053319
B13: Minimum Cash Buffer | C13: 85530

Sheet P&L
A2: Quarterly Income Statement
C4: Period Ending
C5: Apr. 30,2012 | D5: Jul. 31,2012 | E5: Oct. 31,2012 | F5: Jan. 31,2013 | G5: Apr. 30,2013 | H5: Jul. 31,2013 | I5: Oct. 31,2013 | J5: Jan. 31,2014
B6: (USD millions, except per-share figures) | C6: 1932 | D6: 2133 | E6: 2275 | F6: 2234 | G6: 2261 | H6: 2249 | I6: 1870 | J6: 2181
B8: Total Revenue | C8: 11618 | D8: 13858 | E8: 18502 | F8: 22280 | G8: 23639 | H8: 28365 | I8: 37389 | J8: 40929
B9: Cost of delivery | C9: -2545 | D9: -3494 | E9: -3614 | F9: -4087 | G9: -5229 | H9: -6642 | I9: -8535 | J9: -8789
B10: Gross margin ($) | C10: =SUM(C8:C9) -> 9073 | D10: =SUM(D8:D9) -> 10364 | E10: =SUM(E8:E9) -> 14888 | F10: =SUM(F8:F9) -> 18193 | G10: =SUM(G8:G9) -> 18410 | H10: =SUM(H8:H9) -> 21723 | I10: =SUM(I8:I9) -> 28854 | J10: =SUM(J8:J9) -> 32140
B12: Operating cost lines:
B13: Product engineering | C13: -6956 | D13: -6702 | E13: -8464 | F13: -9141 | G13: -9125 | H13: -9340 | I13: -11816 | J13: -14504
B14: Go-to-market | C14: -18687 | D14: -19422 | E14: -22701 | F14: -32462 | G14: -40477 | H14: -40765 | I14: -53103 | J14: -45133
B15: Corporate & administrative | C15: -4419 | D15: -5990 | E15: -9618 | F15: -7245 | G15: -6950 | H15: -9873 | I15: -11133 | J15: -11263
B16: Aggregate operating costs | C16: =SUM(C13:C15) -> -30062 | D16: =SUM(D13:D15) -> -32114 | E16: =SUM(E13:E15) -> -40783 | F16: =SUM(F13:F15) -> -48848 | G16: =SUM(G13:G15) -> -56552 | H16: =SUM(H13:H15) -> -59978 | I16: =SUM(I13:I15) -> -76052 | J16: =SUM(J13:J15) -> -70900
B18: Operating income/(loss) — EBIT | C18: =C10+C16 -> -20989 | D18: =D10+D16 -> -21750 | E18: =E10+E16 -> -25895 | F18: =F10+F16 -> -30655 | G18: =G10+G16 -> -38142 | H18: =H10+H16 -> -38255 | I18: =I10+I16 -> -47198 | J18: =J10+J16 -> -38760
B20: Fair-value change on preferred warrant obligation | C20: 0 | D20: -1617 | E20: -81 | F20: -96 | G20: -800 | H20: -1473 | I20: -3765 | J20: -2817
B21: Net interest, income/(expense) | C21: -261 | D21: -404 | E21: -551 | F21: -653 | G21: -629 | H21: -585 | I21: -2327 | J21: -531
B22: Net other, income/(expense) | C22: 9.388387 | D22: 5.734957 | E22: 0 | F22: 111 | G22: -9.29612 | H22: -79 | I22: 94 | J22: -45
B24: Pre-tax income/(loss) | C24: =SUM(C18:C22) -> -21240.612 | D24: =SUM(D18:D22) -> -23765.265 | E24: =SUM(E18:E22) -> -26527 | F24: =SUM(F18:F22) -> -31293 | G24: =SUM(G18:G22) -> -39580.296 | H24: =SUM(H18:H22) -> -40392 | I24: =SUM(I18:I22) -> -53196 | J24: =SUM(J18:J22) -> -42153
B25: Income tax charge/(credit) | C25: 3.505081 | D25: 0 | E25: 7.044941 | F25: 44 | G25: 5.202842 | H25: -2218 | I25: 62 | J25: 85
B27: Net income/(loss) | C27: =C24-C25 -> -21244.117 | D27: =D24-D25 -> -23765.265 | E27: =E24-E25 -> -26534.045 | F27: =F24-F25 -> -31337 | G27: =G24-G25 -> -39585.499 | H27: =H24-H25 -> -38174 | I27: =I24-I25 -> -53258 | J27: =J24-J25 -> -42238
B28: Preferred-stock accretion charge
B30: Earnings/(loss) to common holders | C30: =SUM(C27:C28) -> -21244.117 | D30: =SUM(D27:D28) -> -23765.265 | E30: =SUM(E27:E28) -> -26534.045 | F30: =SUM(F27:F28) -> -31337 | G30: =SUM(G27:G28) -> -39585.499 | H30: =SUM(H27:H28) -> -38174 | I30: =SUM(I27:I28) -> -53258 | J30: =SUM(J27:J28) -> -42238
B32: EPS to common — basic & diluted | C32: =C30/C34 -> -4.0204611 | D32: =D30/D34 -> -3.8965839 | F32: =F30/F34 -> -4.0782145 | G32: =G30/G34 -> -3.4904769
B34: Weighted-average common shares — basic & diluted | C34: 5284 | D34: 6099 | F34: 7684 | G34: 11341
B36: Pro-forma EPS to common — basic & diluted (unaudited) | G36: -1.978028
B38: Diluted weighted-average shares | G38: 7671
B40: Operating cash earnings (EBITDA) | H40: =H18+'BS-CF-WC'!F59 -> -8961.565 | I40: =I18+'BS-CF-WC'!G59 -> -10816.779 | J40: =J18+'BS-CF-WC'!H59 -> 12902.723
B42: Total Revenue | C42: =C8 -> 11618 | D42: =D8 -> 13858 | E42: =E8 -> 18502 | F42: =F8 -> 22280 | G42: =G8 -> 23639 | H42: =H8 -> 28365 | I42: =I8 -> 37389 | J42: =J8 -> 40929
B43: (YoY %) | F43: =F42/E42-1 -> 0.20419414 | G43: =G42/F42-1 -> 0.060996409 | H43: =H42/G42-1 -> 0.19992385 | I43: =I42/H42-1 -> 0.31813855 | J43: =J42/I42-1 -> 0.094680254
B45: Cost of delivery | C45: =C9 -> -2545 | D45: =D9 -> -3494 | E45: =E9 -> -3614 | F45: =F9 -> -4087 | G45: =G9 -> -5229 | H45: =H9 -> -6642 | I45: =I9 -> -8535 | J45: =J9 -> -8789
B46: % of sales | C46: =C45/C42 -> -0.21905664 | D46: =D45/D42 -> -0.25212873 | E46: =E45/E42 -> -0.19533023 | F46: =F45/F42 -> -0.18343806 | G46: =G45/G42 -> -0.22120225 | H46: =H45/H42 -> -0.23416182 | I46: =I45/I42 -> -0.2282757 | J46: =J45/J42 -> -0.21473772
B47: Product engineering | C47: =C13 -> -6956 | D47: =D13 -> -6702 | E47: =E13 -> -8464 | F47: =F13 -> -9141 | G47: =G13 -> -9125 | H47: =H13 -> -9340 | I47: =I13 -> -11816 | J47: =J13 -> -14504
B48: % of sales | C48: =C47/C42 -> -0.59872611 | D48: =D47/D42 -> -0.48361957 | E48: =E47/E42 -> -0.45746406 | F48: =F47/F42 -> -0.41027828 | G48: =G47/G42 -> -0.38601464 | H48: =H47/H42 -> -0.32927904 | I48: =I47/I42 -> -0.31602878 | J48: =J47/J42 -> -0.35436976
B49: Go-to-market | C49: =C14 -> -18687 | D49: =D14 -> -19422 | E49: =E14 -> -22701 | F49: =F14 -> -32462 | G49: =G14 -> -40477 | H49: =H14 -> -40765 | I49: =I14 -> -53103 | J49: =J14 -> -45133
B50: % of sales | C50: =C49/C42 -> -1.6084524 | D50: =D49/D42 -> -1.4015009 | E50: =E49/E42 -> -1.2269484 | F50: =F49/F42 -> -1.4570018 | G50: =G49/G42 -> -1.7122975 | H50: =H49/H42 -> -1.4371585 | I50: =I49/I42 -> -1.420284 | J50: =J49/J42 -> -1.1027145
B51: Corporate & administrative | C51: =C15 -> -4419 | D51: =D15 -> -5990 | E51: =E15 -> -9618 | F51: =F15 -> -7245 | G51: =G15 -> -6950 | H51: =H15 -> -9873 | I51: =I15 -> -11133 | J51: =J15 -> -11263
B52: % of sales | C52: =C51/C42 -> -0.38035807 | D52: =D51/D42 -> -0.4322413 | E52: =E51/E42 -> -0.51983569 | F52: =F51/F42 -> -0.32517953 | G52: =G51/G42 -> -0.29400567 | H52: =H51/H42 -> -0.3480698 | I52: =I51/I42 -> -0.29776137 | J52: =J51/J42 -> -0.27518385
B54: Aggregate operating costs | C54: =C51+C49+C47+C45 -> -32607 | D54: =D51+D49+D47+D45 -> -35608 | E54: =E51+E49+E47+E45 -> -44397 | F54: =F51+F49+F47+F45 -> -52935 | G54: =G51+G49+G47+G45 -> -61781 | H54: =H51+H49+H47+H45 -> -66620 | I54: =I51+I49+I47+I45 -> -84587 | J54: =J51+J49+J47+J45 -> -79689
B55: % of sales | C55: =C54/C42 -> -2.8065932 | D55: =D54/D42 -> -2.5694905 | E55: =E54/E42 -> -2.3995784 | F55: =F54/F42 -> -2.3758977 | G55: =G54/G42 -> -2.61352 | H55: =H54/H42 -> -2.3486691 | I55: =I54/I42 -> -2.2623499 | J55: =J54/J42 -> -1.9470058
B57: Operating income/(loss) | C57: =C42+C54 -> -20989 | D57: =D42+D54 -> -21750 | E57: =E42+E54 -> -25895 | F57: =F42+F54 -> -30655 | G57: =G42+G54 -> -38142 | H57: =H42+H54 -> -38255 | I57: =I42+I54 -> -47198 | J57: =J42+J54 -> -38760
C58: =C57/C42 -> -1.8065932 | D58: =D57/D42 -> -1.5694905 | E58: =E57/E42 -> -1.3995784 | F58: =F57/F42 -> -1.3758977 | G58: =G57/G42 -> -1.61352 | H58: =H57/H42 -> -1.3486691 | I58: =I57/I42 -> -1.2623499 | J58: =J57/J42 -> -0.94700579
...

Sheet BS-CF-WC
A2: Projected Balance Sheet
C4: ='P&L'!C68 -> 40908 | D4: ='P&L'!D68 -> 41305 | E4: ='P&L'!E68 -> 41670 | F4: ='P&L'!F68 -> 42035 | G4: ='P&L'!G68 -> 42400 | H4: ='P&L'!H68 -> 42766 | I4: ='P&L'!I68 -> 43131 | J4: ='P&L'!J68 -> 43496
B6: ASSET BASE
B7: Short-term assets:
B8: Cash & equivalents | D8: 102958 | E8: 101561 | F8: =F99 -> 206118.43 | G8: =G99 -> 100000 | H8: =H99 -> 100000 | I8: =I99 -> 100000 | J8: =J99 -> 100000
B9: Trade receivables | D9: 17352 | E9: 49977 | F9: =F110 -> 0 | G9: =G110 -> 0 | H9: =H110 -> 0 | I9: =I110 -> 0 | J9: =J110 -> 0
B10: Prepaids & other short-term assets | D10: 8379 | E10: 8437 | F10: =F111 -> 0 | G10: =G111 -> 0 | H10: =H111 -> 0 | I10: =I111 -> 0 | J10: =J111 -> 0
B11: Capitalized commissions | D11: 8246 | E11: 7071 | F11: =F112 -> 0 | G11: =G112 -> 0 | H11: =H112 -> 0 | I11: =I112 -> 0 | J11: =J112 -> 0
B12: Short-term assets — total | D12: =SUM(D8:D11) -> 136935 | E12: =SUM(E8:E11) -> 167046 | F12: =SUM(F8:F11) -> 206118.43 | G12: =SUM(G8:G11) -> 100000 | H12: =SUM(H8:H11) -> 100000 | I12: =SUM(I8:I11) -> 100000 | J12: =SUM(J8:J11) -> 100000
B14: Net fixed assets | D14: 32513 | E14: 35981 | F14: ='Debt-Capex-Amort'!F58 -> 20441.853 | G14: ='Debt-Capex-Amort'!G58 -> 8850.971 | H14: ='Debt-Capex-Amort'!H58 -> 10565.787 | I14: ='Debt-Capex-Amort'!I58 -> 29233.228 | J14: ='Debt-Capex-Amort'!J58 -> 108786.88
B15: Net intangible assets | D15: 715 | E15: 7419 | F15: ='Debt-Capex-Amort'!F148 -> 7242.44 | G15: ='Debt-Capex-Amort'!G148 -> 6864.8475 | H15: ='Debt-Capex-Amort'!H148 -> 10409.872 | I15: ='Debt-Capex-Amort'!I148 -> 18943.418 | J15: ='Debt-Capex-Amort'!J148 -> 34142.196
B16: Acquired goodwill | D16: 0 | E16: 8669 | F16: =E16 -> 8669 | G16: =F16 -> 8669 | H16: =G16 -> 8669 | I16: =H16 -> 8669 | J16: =I16 -> 8669
B17: Other non-current assets | D17: 3318 | E17: 11450 | F17: =E17 -> 11450 | G17: =F17 -> 11450 | H17: =G17 -> 11450 | I17: =H17 -> 11450 | J17: =I17 -> 11450
B19: Asset base — total | D19: =SUM(D12:D17) -> 173481 | E19: =SUM(E12:E17) -> 230565 | F19: =SUM(F12:F17) -> 253921.73 | G19: =SUM(G12:G17) -> 135834.82 | H19: =SUM(H12:H17) -> 141094.66 | I19: =SUM(I12:I17) -> 168295.65 | J19: =SUM(J12:J17) -> 263048.08
B21: OBLIGATIONS
B22: Short-term obligations:
B23: Trade payables | D23: 13726 | E23: 14208 | F23: =F115 -> 0 | G23: =G115 -> 0 | H23: =H115 -> 0 | I23: =I115 -> 0 | J23: =J115 -> 0
B24: Accrued payroll & benefits | D24: 3572 | E24: 18132 | F24: =F116 -> 0 | G24: =G116 -> 0 | H24: =H116 -> 0 | I24: =I116 -> 0 | J24: =J116 -> 0
B25: Accruals & other short-term obligations | D25: 1599 | E25: 16988 | F25: =F117 -> 0 | G25: =G117 -> 0 | H25: =H117 -> 0 | I25: =I117 -> 0 | J25: =J117 -> 0
B26: Unearned revenue | D26: 31625 | E26: 85653 | F26: =F118 -> 0 | G26: =G118 -> 0 | H26: =H118 -> 0 | I26: =I118 -> 0 | J26: =J118 -> 0
B27: Deferred lease cost | D27: 590 | E27: 1222 | F27: =F119 -> 0 | G27: =G119 -> 0 | H27: =H119 -> 0 | I27: =I119 -> 0 | J27: =J119 -> 0
B28: Borrowings | D28: 1132 | F28: ='Debt-Capex-Amort'!F17 -> 0 | G28: ='Debt-Capex-Amort'!G17 -> 165307.84 | H28: ='Debt-Capex-Amort'!H17 -> 489408.45 | I28: ='Debt-Capex-Amort'!I17 -> 885227.88 | J28: ='Debt-Capex-Amort'!J17 -> 1142527.4
B29: Short-term obligations — total | D29: =SUM(D23:D28) -> 52244 | E29: =SUM(E23:E28) -> 136203 | F29: =SUM(F23:F28) -> 0 | G29: =SUM(G23:G28) -> 165307.84 | H29: =SUM(H23:H28) -> 489408.45 | I29: =SUM(I23:I28) -> 885227.88 | J29: =SUM(J23:J28) -> 1142527.4
B31: Non-current borrowings (revolver) | D31: 25423 | E31: 28577 | F31: ='Debt-Capex-Amort'!F23 -> 27091 | G31: ='Debt-Capex-Amort'!G23 -> 13545.5 | H31: ='Debt-Capex-Amort'!H23 -> 0 | I31: ='Debt-Capex-Amort'!I23 -> 0 | J31: ='Debt-Capex-Amort'!J23 -> 0
B32: Unearned revenue, non-current | D32: 1584 | E32: 12747 | F32: =E32 -> 12747 | G32: =F32 -> 12747 | H32: =G32 -> 12747 | I32: =H32 -> 12747 | J32: =I32 -> 12747
B33: Preferred warrant obligation, non-current | D33: 3154 | E33: 0 | F33: =E33 -> 0 | G33: =F33 -> 0 | H33: =G33 -> 0 | I33: =H33 -> 0 | J33: =I33 -> 0
B34: Deferred lease cost, non-current | D34: 5849 | E34: 3465 | F34: =E34 -> 3465 | G34: =F34 -> 3465 | H34: =G34 -> 3465 | I34: =H34 -> 3465 | J34: =I34 -> 3465
B35: Other non-current obligations | D35: 574 | E35: 1478 | F35: =E35 -> 1478 | G35: =F35 -> 1478 | H35: =G35 -> 1478 | I35: =H35 -> 1478 | J35: =I35 -> 1478
B37: Obligations — total | D37: =SUM(D29:D35) -> 88828 | E37: =SUM(E29:E35) -> 182470 | F37: =SUM(F29:F35) -> 44781 | G37: =SUM(G29:G35) -> 196543.34 | H37: =SUM(H29:H35) -> 507098.45 | I37: =SUM(I29:I35) -> 902917.88 | J37: =SUM(J29:J35) -> 1160217.4
B39: Redeemable preferred equity: | D39: 250523 | E39: 0
B40: Common equity/(deficit):
B41: Class A & Class B common shares | D41: 1 | E41: 9
B42: Paid-in capital surplus | D42: 8582 | E42: 340603
B43: Treasury shares (refer Note 10) | D43: -1142 | E43: -1292
B44: Cumulative other comprehensive income | D44: 0 | E44: 16
B45: Retained deficit | D45: -205805 | E45: -322829
B46: Common equity/(deficit) — total | D46: =SUM(D41:D45) -> -198364 | E46: =SUM(E41:E45) -> 16507 | F46: ='Equity-Shares'!F8 -> 16137.301 | G46: ='Equity-Shares'!G8 -> -374212.61 | H46: ='Equity-Shares'!H8 -> -939672.67 | I46: ='Equity-Shares'!I8 -> -1686208.1 | J46: ='Equity-Shares'!J8 -> -2530814.3
B47: Obligations + equity — total | D47: =D46+D39+D37 -> 140987 | E47: =E46+E39+E37 -> 198977 | F47: =F46+F39+F37 -> 60918.301 | G47: =G46+G39+G37 -> -177669.27 | H47: =H46+H39+H37 -> -432574.21 | I47: =I46+I39+I37 -> -783290.25 | J47: =J46+J39+J37 -> -1370597
B49: Balance check | D49: =D47-D19 -> -32494 | E49: =E47-E19 -> -31588 | F49: =F47-F19 -> -193003.43 | G49: =G47-G19 -> -313504.09 | H49: =H47-H19 -> -573668.87 | I49: =I47-I19 -> -951585.9 | J49: =J47-J19 -> -1633645.1
A52: Projected Cash Flow Statement
...

Sheet Debt-Capex-Amort
A2: Borrowings Roll-Forward
C4: ='BS-CF-WC'!C4 -> 40908 | D4: ='BS-CF-WC'!D4 -> 41305 | E4: ='BS-CF-WC'!E4 -> 41670 | F4: ='BS-CF-WC'!F4 -> 42035 | G4: ='BS-CF-WC'!G4 -> 42400 | H4: ='BS-CF-WC'!H4 -> 42766 | I4: ='BS-CF-WC'!I4 -> 43131 | J4: ='BS-CF-WC'!J4 -> 43496
B5: Cash available before financing | F5: ='BS-CF-WC'!F83 -> -151246.57 | G5: ='BS-CF-WC'!G83 -> -272350.78 | H5: ='BS-CF-WC'!H83 -> -325025.11 | I5: ='BS-CF-WC'!I83 -> -410289.42 | J5: ='BS-CF-WC'!J83 -> -271769.48
B6: Equity issued/(repurchased) | F6: ='Equity-Shares'!F7 -> 250000 | G6: ='Equity-Shares'!G7 -> 0 | H6: ='Equity-Shares'!H7 -> 0 | I6: ='Equity-Shares'!I7 -> 0 | J6: ='Equity-Shares'!J7 -> 0
B7: + Opening cash | F7: 108851 | G7: 206118.43 | H7: 100000 | I7: 100000 | J7: 100000
B8: - Minimum cash buffer | F8: =-Drivers!$C$13 -> -85530 | G8: =-Drivers!$C$13 -> -85530 | H8: =-Drivers!$C$13 -> -85530 | I8: =-Drivers!$C$13 -> -85530 | J8: =-Drivers!$C$13 -> -85530
B9: Cash free for debt service | F9: =SUM(F5:F8) -> 122074.43 | G9: =SUM(G5:G8) -> -151762.34 | H9: =SUM(H5:H8) -> -310555.11 | I9: =SUM(I5:I8) -> -395819.42 | J9: =SUM(J5:J8) -> -257299.48
B10: Term-debt drawdowns
B11: Term-debt repayments | F11: =F22 -> -1486 | G11: =G22 -> -13545.5 | H11: =H22 -> -13545.5 | I11: =I22 -> 0 | J11: =J22 -> 0
B12: Cash free for revolver | F12: =F9+F10+F11 -> 120588.43 | G12: =G9+G10+G11 -> -165307.84 | H12: =H9+H10+H11 -> -324100.61 | I12: =I9+I10+I11 -> -395819.42 | J12: =J9+J10+J11 -> -257299.48
B14: Incremental revolver draw
B15: Opening balance | F15: =E17 -> 0 | G15: =F17 -> 0 | H15: =G17 -> 165307.84 | I15: =H17 -> 489408.45 | J15: =I17 -> 885227.88
B16: Discretionary (paydown)/draw | F16: =IF(F12<0,-F12,-MIN(F15,F12)) -> 0 | G16: =IF(G12<0,-G12,-MIN(G15,G12)) -> 165307.84 | H16: =IF(H12<0,-H12,-MIN(H15,H12)) -> 324100.61 | I16: =IF(I12<0,-I12,-MIN(I15,I12)) -> 395819.42 | J16: =IF(J12<0,-J12,-MIN(J15,J12)) -> 257299.48
B17: Closing balance | E17: 0 | F17: =SUM(F15:F16) -> 0 | G17: =SUM(G15:G16) -> 165307.84 | H17: =SUM(H15:H16) -> 489408.45 | I17: =SUM(I15:I16) -> 885227.88 | J17: =SUM(J15:J16) -> 1142527.4
B19: Revolver (committed repayments)
B20: Opening balance | F20: =E23 -> 28577 | G20: =F23 -> 27091 | H20: =G23 -> 13545.5 | I20: =H23 -> 0 | J20: =I23 -> 0
B21: Draws
B22: (Repayment/amortization) | F22: -1486 | G22: =-(E23+F22)/2 -> -13545.5 | H22: =G22 -> -13545.5 | I22: 0 | J22: 0
B23: Closing balance | E23: ='BS-CF-WC'!E31 -> 28577 | F23: =SUM(F20:F22) -> 27091 | G23: =SUM(G20:G22) -> 13545.5 | H23: =SUM(H20:H22) -> 0 | I23: =SUM(I20:I22) -> 0 | J23: =SUM(J20:J22) -> 0
B25: Interest Cost Build
B27: 1) Revolver | F27: 0 | G27: 91244.672 | H27: 353130.4 | I27: 728916.16 | J27: 1069945.6
F28: 0.035 | G28: 0.035 | H28: 0.035 | I28: 0.035 | J28: 0.035
B29: Revolver interest cost | F29: =F28*F27 -> 0 | G29: =G28*G27 -> 3193.5635 | H29: =H28*H27 -> 12359.564 | I29: =I28*I27 -> 25512.066 | J29: =J28*J27 -> 37448.097
B31: 2) Revolver (committed) | F31: 33257 | G31: 24385.5 | H31: 8128.5 | I31: 0 | J31: 0
F32: 0.035 | G32: 0.05 | H32: 0.05 | I32: 0.05 | J32: 0.05
B33: Interest cost | F33: =F32*F31 -> 1163.995 | G33: =G32*G31 -> 1219.275 | H33: =H32*H31 -> 406.425 | I33: =I32*I31 -> 0 | J33: =J32*J31 -> 0
B35: (1) + (2): Total interest cost | F35: =F33+F29 -> 1163.995 | G35: =G33+G29 -> 4412.8385 | H35: =H33+H29 -> 12765.989 | I35: =I33+I29 -> 25512.066 | J35: =J33+J29 -> 37448.097
B38: Cash Balance Roll-Forward Schedule
B40: Cash on hand | E40: 108851 | F40: 206118.43 | G40: 100000 | H40: 100000 | I40: 100000 | J40: 100000
B41: Average cash on hand | F41: 157484.72 | G41: 153059.22 | H41: 100000 | I41: 100000 | J41: 100000
B43: Interest income earned | D43: 0.02 | F43: 3149.6943 | G43: 3061.1843 | H43: 2000 | I43: 2000 | J43: 2000
A46: Fixed-Asset & Depreciation Schedule
C49: ='BS-CF-WC'!C4 -> 40908 | D49: ='BS-CF-WC'!D4 -> 41305 | E49: ='BS-CF-WC'!E4 -> 41670 | F49: ='BS-CF-WC'!F4 -> 42035 | G49: ='BS-CF-WC'!G4 -> 42400 | H49: ='BS-CF-WC'!H4 -> 42766 | I49: ='BS-CF-WC'!I4 -> 43131 | J49: ='BS-CF-WC'!J4 -> 43496
B50: Net revenue | D50: ='P&L'!D70 -> 66258 | E50: ='P&L'!E70 -> 130322 | F50: ='P&L'!F70 -> 260644 | G50: ='P&L'!G70 -> 461881.5 | H50: ='P&L'!H70 -> 892804.93 | I50: ='P&L'!I70 -> 1737509.1 | J50: ='P&L'!J70 -> 3070555.6
B51: Capital spend | D51: =-'BS-CF-WC'!D78 -> 18480 | E51: =-'BS-CF-WC'!E78 -> 23953 | F51: =F52*F50 -> 10971.288 | G51: =G52*G50 -> 22103.339 | H51: =H52*H50 -> 52458.539 | I51: =I52*I50 -> 102832.74 | J51: =J52*J50 -> 163718.95
B52: Capital spend as % of net revenue | D52: =D51/D50 -> 0.27890972 | E52: =E51/E50 -> 0.18379859 | F52: =Drivers!F12 -> 0.042093 | G52: =Drivers!G12 -> 0.047855 | H52: =Drivers!H12 -> 0.058757 | I52: =Drivers!I12 -> 0.059184 | J52: =Drivers!J12 -> 0.053319
B54: Opening net fixed assets | F54: =E58 -> 35981 | G54: =F58 -> 20441.853 | H54: =G58 -> 8850.971 | I54: =H58 -> 10565.787 | J54: =I58 -> 29233.228
B55: Capital spend | F55: =F51 -> 10971.288 | G55: =G51 -> 22103.339 | H55: =H51 -> 52458.539 | I55: =I51 -> 102832.74 | J55: =J51 -> 163718.95
B56: (Depreciation charge) | F56: =-F131 -> -26510.435 | G56: =-G131 -> -33694.221 | H56: =-H131 -> -50743.723 | I56: =-I131 -> -84165.298 | J56: =-J131 -> -84165.298
B57: (Asset disposals)
...

Sheet Equity-Shares
A2: Common Equity Roll-Forward
C4: ='BS-CF-WC'!C4 -> 40908 | D4: ='BS-CF-WC'!D4 -> 41305 | E4: ='BS-CF-WC'!E4 -> 41670 | F4: ='BS-CF-WC'!F4 -> 42035 | G4: ='BS-CF-WC'!G4 -> 42400 | H4: ='BS-CF-WC'!H4 -> 42766 | I4: ='BS-CF-WC'!I4 -> 43131 | J4: ='BS-CF-WC'!J4 -> 43496
B5: Opening equity | F5: =E8 -> 16507 | G5: =F8 -> 16137.301 | H5: =G8 -> -374212.61 | I5: =H8 -> -939672.67 | J5: =I8 -> -1686208.1
B6: Net result | F6: ='P&L'!F92 -> -250369.7 | G6: ='P&L'!G92 -> -390349.91 | H6: ='P&L'!H92 -> -565460.05 | I6: ='P&L'!I92 -> -746535.46 | J6: ='P&L'!J92 -> -844606.22
B7: Equity issued/(repurchased) | F7: =250000 -> 250000 | G7: ='BS-CF-WC'!G90 -> 0 | H7: ='BS-CF-WC'!H90 -> 0 | I7: ='BS-CF-WC'!I90 -> 0 | J7: ='BS-CF-WC'!J90 -> 0
B8: Closing equity | E8: ='BS-CF-WC'!E46 -> 16507 | F8: =SUM(F5:F7) -> 16137.301 | G8: =SUM(G5:G7) -> -374212.61 | H8: =SUM(H5:H7) -> -939672.67 | I8: =SUM(I5:I7) -> -1686208.1 | J8: =SUM(J5:J7) -> -2530814.3
A14: Reconciliation check | B14: =SUM(F5:J8,E8) -> -11013034
A17: Option Valuation Model
A19: Projection Inputs
A21: Black-Scholes model inputs
A22: Current share price = | B22: 17
A23: Option strike price = | B23: =E78 -> 3.65
A24: Option expiry = | B24: =F78/2 -> 4.225
A25: Share-price volatility = | B25: 0.450592
A26: Annualized dividend yield = | B26: 0
A27: Risk-free treasury rate = | B27: 0.023242
A28: Warrants/options outstanding = | B28: =D78/10^3 -> 18427.075
A29: Shares outstanding = | B29: =C67/10^3 -> 91460.679
A31: Option value calculation
A33: Share price = | B33: =B22 -> 17
A34: Strike = | B34: =B23 -> 3.65
A35: Adjusted S = | B35: 19.357064
A36: Adjusted K = | B36: =B34 -> 3.65
A37: Expiry (years) = | B37: =B24 -> 4.225
A39: Options granted | B39: =B28 -> 18427.075
A40: Shares outstanding — total | B40: =B29 -> 91460.679
A41: Treasury rate | B41: =B27 -> 0.023242
A42: Return variance | B42: =B25^2 -> 0.20303315
A43: Annualized dividend yield | B43: =B26 -> 0
A44: Discount rate | B44: =B41-B43 -> 0.023242
A46: d1 = | B46: =(LN(B35/B36)+(B44+(B42/2))*B37)/(((B42)^(0.5))*(B37^0.5)) -> 2.3704118
A47: N (d1) = | B47: =NORMSDIST(B46) -> 0.99111586
A49: d2 = | B49: =B46-((B42^0.5)*(B37^(0.5))) -> 1.4442287
A50: N (d2) = | B50: =NORMSDIST(B49) -> 0.92566267
A52: Value per option = | B52: =((EXP((0-B43)*B37))*B35*B47-B36*(EXP((0-B41)*B37))*B50) -> 16.122431
A54: Aggregate option value = | B54: =B52*B28 -> 297089.25
A57: Share Count Buildup
B59: Common shares
B61: Existing structure
B62: Class A | C62: 0
...

Sheet Valuation
A2: Discounted Cash Flow Valuation
B4: Projected free cash flow | C4: Reported history | F4: Projected periods
B5: (USD millions, except per-share figures) | C5: 40908 | D5: =EOMONTH(C5,13) -> 41305 | E5: =EOMONTH(D5,12) -> 41670 | F5: =EOMONTH(E5,12) -> 42035 | G5: =EOMONTH(F5,12) -> 42400 | H5: =EOMONTH(G5,12) -> 42766 | I5: =EOMONTH(H5,12) -> 43131 | J5: =EOMONTH(I5,12) -> 43496
B7: Operating income (EBIT) | C7: ='P&L'!C84 -> -46882 | D7: ='P&L'!D84 -> -99289 | E7: ='P&L'!E84 -> -162355 | F7: ='P&L'!F84 -> -254959.62 | G7: ='P&L'!G84 -> -501887.36 | H7: ='P&L'!H84 -> -685231.35 | I7: ='P&L'!I84 -> -665856.92 | J7: ='P&L'!J84 -> -1076371
B9: Unlevered free cash flow
B10: EBIT after tax | C10: =C7*(1-'P&L'!C119) -> -46882 | D10: =D7*(1-'P&L'!D119) -> -99289 | E10: =E7*(1-'P&L'!E119) -> -159947.76 | F10: =IF(F7>0,IF(F7<E16,F7,F7-(F7-E16)*'P&L'!F119),F7) -> -254959.62 | G10: =IF(G7>0,IF(G7<F16,G7,G7-(G7-F16)*'P&L'!G119),G7) -> -501887.36 | H10: =IF(H7>0,IF(H7<G16,H7,H7-(H7-G16)*'P&L'!H119),H7) -> -685231.35 | I10: =IF(I7>0,IF(I7<H16,I7,I7-(I7-H16)*'P&L'!I119),I7) -> -665856.92 | J10: =IF(J7>0,IF(J7<I16,J7,J7-(J7-I16)*'P&L'!J119),J7) -> -1076371
B11: Add: depreciation & amortization | C11: ='BS-CF-WC'!C59 -> 3338 | D11: ='BS-CF-WC'!D59 -> 8616 | E11: ='BS-CF-WC'!E59 -> 15964 | F11: ='BS-CF-WC'!F59 -> 29293.435 | G11: ='BS-CF-WC'!G59 -> 36381.221 | H11: ='BS-CF-WC'!H59 -> 51662.723 | I11: ='BS-CF-WC'!I59 -> 84319.298 | J11: ='BS-CF-WC'!J59 -> 84319.298
B12: Less: capital spend | C12: ='BS-CF-WC'!C78+'BS-CF-WC'!C80 -> -15866 | D12: ='BS-CF-WC'!D78+'BS-CF-WC'!D80 -> -18533 | E12: ='BS-CF-WC'!E78+'BS-CF-WC'!E80 -> -32721 | F12: ='BS-CF-WC'!F78+'BS-CF-WC'!F80 -> -13577.728 | G12: ='BS-CF-WC'!G78+'BS-CF-WC'!G80 -> -24412.747 | H12: ='BS-CF-WC'!H78+'BS-CF-WC'!H80 -> -56922.564 | I12: ='BS-CF-WC'!I78+'BS-CF-WC'!I80 -> -111520.28 | J12: ='BS-CF-WC'!J78+'BS-CF-WC'!J80 -> -179071.73
B13: Add: working-capital movement | E13: ='BS-CF-WC'!E124 -> 0 | F13: ='BS-CF-WC'!F124 -> 0 | G13: ='BS-CF-WC'!G124 -> 0 | H13: ='BS-CF-WC'!H124 -> 0 | I13: ='BS-CF-WC'!I124 -> 0 | J13: ='BS-CF-WC'!J124 -> 0
B14: Unlevered FCF | C14: =SUM(C10:C13) -> -59410 | D14: =SUM(D10:D13) -> -109206 | E14: =SUM(E10:E13) -> -176704.76 | F14: =SUM(F10:F13) -> -239243.91 | G14: =SUM(G10:G13) -> -489918.89 | H14: =SUM(H10:H13) -> -690491.19 | I14: =SUM(I10:I13) -> -693057.91 | J14: =SUM(J10:J13) -> -1171123.4
B16: Loss carryforwards | E16: 251543 | F16: =IF(F7<0,E16-F7,IF(E16>0,E16-F7,0)) -> 506502.62 | G16: =IF(G7<0,F16-G7,IF(F16>0,F16-G7,0)) -> 1008390 | H16: =IF(H7<0,G16-H7,IF(G16>0,G16-H7,0)) -> 1693621.3 | I16: =IF(I7<0,H16-I7,IF(H16>0,H16-I7,0)) -> 2359478.3 | J16: =IF(J7<0,I16-J7,IF(I16>0,I16-J7,0)) -> 3435849.2
B18: Discount rate (WACC) | C18: 0.137179
B19: Perpetual growth rate | C19: 0.042337
B21: Unlevered FCF over explicit horizon (2015P-2019P)
C22: =C5 -> 40908 | D22: =D5 -> 41305 | E22: =E5 -> 41670 | F22: =F5 -> 42035 | G22: =G5 -> 42400 | H22: =H5 -> 42766 | I22: =I5 -> 43131 | J22: =J5 -> 43496
B23: Cash flow stream | F23: =F14 -> -239243.91 | G23: =G14 -> -489918.89 | H23: =H14 -> -690491.19 | I23: =I14 -> -693057.91 | J23: =J14 -> -1171123.4
B24: PV of explicit horizon | C24: {=NPV(C18,F23:J23)} -> -2089031.6
B27: Continuing value at perpetual growth (2019) | C27: =C5 -> 40908 | D27: =D5 -> 41305 | E27: =E5 -> 41670 | F27: =F5 -> 42035 | G27: =G5 -> 42400 | H27: =H5 -> 42766 | I27: =I5 -> 43131 | J27: =J5 -> 43496
B28: Continuing value as of 2019 | F28: 0 | G28: 0 | H28: 0 | I28: 0 | J28: =J14*(1+C19)/(C18-C19) -> -12870936
B29: PV of continuing value | C29: {=NPV(C18,F28:J28)} -> -6768087.5
B31: DCF valuation summary
B33: Valuation date | C33: 2014
B34: PV of explicit horizon | C34: =C24 -> -2089031.6 | D34: =C34/$C$36 -> 0.23585904
B35: PV of continuing value | C35: =C29 -> -6768087.5 | D35: =C35/$C$36 -> 0.76414096
B36: Total firm value | C36: =SUM(C34:C35) -> -8857119
B37: Net borrowings | C37: ='Debt-Capex-Amort'!E23-'BS-CF-WC'!E8 -> -72984
B38: Equity value | C38: =C36-C37 -> -8784135
B39: Option value | C39: ='Equity-Shares'!B54 -> 297089.25
B40: Adjusted equity value | C40: =C38-C39 -> -9081224.3
B41: Value per share | C41: =C40/('Equity-Shares'!C67/10^3) -> -99.291022 | D41: not meaningful — unlevered FCF is negative
D43: Sensitivity Grid
E44: WACC
D45: =C41 -> -99.291022 | E45: 0.12 | F45: 0.14 | G45: 0.15 | H45: 0.2 | I45: 0.25
C46: perpetual growth | D46: 0.1 | E46: -118.65164 | F46: -61.186401 | G46: -49.663982 | H46: -26.494771 | I46: -18.66135
D47: 0.08 | E47: -65.283808 | F47: -44.613025 | G47: -38.689545 | H47: -23.794947 | I47: -17.582251
D48: 0.06 | E48: -47.494531 | F48: -36.326337 | G48: -32.592636 | H48: -21.866501 | I48: -16.730331
D49: 0.05 | E49: -42.41188 | F49: -33.564107 | G49: -30.458718 | H49: -21.095123 | I49: -16.368264
D50: 0.03 | E50: -35.635013 | F50: -29.546319 | G50: -27.25784 | H50: -19.824618 | I50: -15.742877
D51: 0.01 | E51: -31.322461 | F51: -26.764773 | G51: -24.971499 | H51: -18.821587 | I51: -15.221722
A54: Comparable Companies
...
