Workbook

Sheet Source Data
B2: Operating Statement Export
B3: Report Run: 03/05/2025 12:09 PM
B5: Virelthorn Owner, LLC
B6: Properties: Active
B7: Date Range: 01/01/2024 to 12/31/2024
B8: Accounting Basis: Accrual
B9: Account Map: Standard chart of accounts
B10: Level of Detail: Detail View
B11: Include Zero-Balance Accounts: No
B13: Account Name | C13: Reported Period
B14: Operating Income & Expense
B15: Income | F15: Purchase Price | G15: 67015280
B16: Gross Potential Rent | C16: 4899934.7 | D16: =SUM(C16:C24) -> 4323174.4 | F16: Mortgage in place | G16: 50938905
B17: Gain/Loss to Lease | C17: -192135.32
B18: Vacancy | C18: -335370.69
B19: CONCESSIONS
B20: One-Time Concessions | C20: -8249 | F20: Analysis Scope
B21: Hometown Hero Discount | C21: -2624.96 | F21: 1. Create financial model including NOI pro-forma, rent sensitivities, value sensitivities, sales comps
B22: Employee Units | C22: -11797.28 | F22: 2. What changed between projections (See OM) and outcome.
B23: Other Concession | C23: -2213 | F23: 2. Estimate refinance options with bank, HUD and agency
B24: Total CONCESSIONS | C24: -24370.04 | F24: 3. Provide recommendation for refinance / sale
B25: Interest Income | C25: 17291.77
B26: OTHER INCOME
B27: Application Fee Income | C27: 29441
B28: CO Inspection Fee | C28: 2766
B29: Monthly Amenity Fee | C29: 106817.24
B30: Annual Amenity Fee | C30: 628
B31: Transfer Fee | C31: 2454
B32: Resident Insurance Services | C32: 5659.59
B33: Resident Insurance Admin Fees | C33: 1039
B34: One-Time Pet Fee | C34: 6302
B35: Pet Rent | C35: 9516.04
B36: Resident Parking | C36: 232901.88
B37: NSF Fees Collected | C37: 1365
B38: Late Fee | C38: 9362
... B47: Total Operating Income | C47: 6456915.2
B48: Expense
B49: PAYROLL COSTS
B50: Property Manager | C50: 20397.49
B51: Assistant Property Manager | C51: 59807.66
...

Sheet Assumptions
B2: Property Address | D2: 1840 Kestrel Row
B3: City | D3: Lindenfen
B4: State | D4: NC
B5: Zip Code | D5: 27604
B6: Year Built | D6: 2021
B8: Property Details
B9: # of Units | D9: =Assumptions!C36 -> 214
B10: Gross SF | D10: 0
B11: NSF | D11: =Assumptions!D36*Assumptions!C36 -> 164300
B12: # of Parking Spaces Covered | D12: 283
B13: # of Parking Spaces uncovered | D13: 0
B15: Acquisition Info
B16: Purchase Price | D16: 85493946
B17: Acquisition Date | D17: 45778
B18: T-12 NOI | D18: ='Source Data'!C150 -> 1965100.7
B19: Going In Cap Rate | D19: =D18/D16 -> 0.022985262
B20: Price/Unit | D20: =D16/D9 -> 399504.42
B21: Price/GSF | D21: =IFERROR(D16/D10,0) -> 0
B22: Price/NSF | D22: =IFERROR(D16/D11,0) -> 520.35268
B23: Closing Cost | D23: 0.008621
B25: Exit Assumptions
B26: Month | D26: 36
B27: Exit Cap Rate | D27: 0.057887
B28: Cost of Sale | D28: 0.0234
B30: Unit Mix
B31: Unit Type | C31: # of Units | D31: SF | E31: Monthly Avg Rent | F31: Annual Rent | G31: Annual $/SF | I31: Existing Loan Info
B32: 1BD | C32: 53 | D32: 650 | E32: 2050 | F32: =E32*C32*12 -> 1303800 | G32: =F32/(D32*C32) -> 37.846154 | I32: Existing Mortgage | K32: 50736714
B33: 1 BD + Den | C33: 70 | D33: 725 | E33: 2150 | F33: =E33*C33*12 -> 1806000 | G33: =F33/(D33*C33) -> 35.586207 | I33: Lender | K33: NYCB
B34: 2 BD | C34: 84 | D34: 850 | E34: 2450 | F34: =E34*C34*12 -> 2469600 | G34: =F34/(D34*C34) -> 34.588235 | I34: Floating/Fixed | K34: Fixed
B35: 2BD + 2 BA | C35: 7 | D35: 1100 | E35: 2800 | F35: =E35*C35*12 -> 235200 | G35: =F35/(D35*C35) -> 30.545455 | I35: Term | K35: 5+5
B36: Total | C36: =SUM(C32:C35) -> 214 | D36: =SUMPRODUCT(C32:C35,D32:D35)/C36 -> 767.75701 | E36: =SUMPRODUCT(E32:E35,$C$32:$C$35)/C36 -> 2264.2523 | F36: =SUM(F32:F35) -> 5814600 | G36: =F36/(D36*C36) -> 35.39014 | I36: Rate | K36: 0.0335
I37: I/O Period (MTHs) | K37: 24
I38: Amortization | K38: 30
B39: Other Income
B40: Item | C40: $/Unit/MTH | D40: Monthly Income | E40: Annual Income
B41: Pet Fees & Rent | C41: 6 | D41: =C41*$C$36 -> 1284 | E41: =D41*12 -> 15408
B42: Application Fee | C42: 12.5 | D42: =C42*$C$36 -> 2675 | E42: =D42*12 -> 32100
B43: Amenity Fees | C43: 45 | D43: =C43*$C$36 -> 9630 | E43: =D43*12 -> 115560
B44: Parking | C44: 83 | D44: =C44*$C$36 -> 17762 | E44: =D44*12 -> 213144
B45: Transfer Fee | C45: 1.15 | D45: =C45*$C$36 -> 246.1 | E45: =D45*12 -> 2953.2
...

Sheet Investment Summary
B2: Unit Mix | H2: Pro Forma
B3: =Assumptions!B31 -> Unit Type | C3: =Assumptions!C31 -> # of Units | D3: =Assumptions!D31 -> SF | E3: =Assumptions!E31 -> Monthly Avg Rent | F3: =Assumptions!F31 -> Annual Rent | G3: =Assumptions!G31 -> Annual $/SF | H3: ='Annual Forecast'!B4 -> Resi Gross Potential Rent | I3: ='Annual Forecast'!C4 -> 5892581.4
B4: =Assumptions!B32 -> 1BD | C4: =Assumptions!C32 -> 53 | D4: =Assumptions!D32 -> 650 | E4: =Assumptions!E32 -> 2050 | F4: =Assumptions!F32 -> 1303800 | G4: =Assumptions!G32 -> 37.846154 | H4: ='Annual Forecast'!B5 -> Vacancy | I4: ='Annual Forecast'!C5 -> -294629.07
B5: =Assumptions!B33 -> 1 BD + Den | C5: =Assumptions!C33 -> 70 | D5: =Assumptions!D33 -> 725 | E5: =Assumptions!E33 -> 2150 | F5: =Assumptions!F33 -> 1806000 | G5: =Assumptions!G33 -> 35.586207 | H5: ='Annual Forecast'!B6 -> Bad Debt | I5: ='Annual Forecast'!C6 -> -353554.88
B6: =Assumptions!B34 -> 2 BD | C6: =Assumptions!C34 -> 84 | D6: =Assumptions!D34 -> 850 | E6: =Assumptions!E34 -> 2450 | F6: =Assumptions!F34 -> 2469600 | G6: =Assumptions!G34 -> 34.588235 | H6: ='Annual Forecast'!B7 -> Net Rental Income | I6: =SUM(I3:I5) -> 5244397.4
B7: =Assumptions!B35 -> 2BD + 2 BA | C7: =Assumptions!C35 -> 7 | D7: =Assumptions!D35 -> 1100 | E7: =Assumptions!E35 -> 2800 | F7: =Assumptions!F35 -> 235200 | G7: =Assumptions!G35 -> 30.545455 | H7: ='Annual Forecast'!B8 -> Other Income | I7: ='Annual Forecast'!C8 -> 438229.2
B8: =Assumptions!B36 -> Total | C8: =Assumptions!C36 -> 214 | D8: =Assumptions!D36 -> 767.75701 | E8: =Assumptions!E36 -> 2264.2523 | F8: =Assumptions!F36 -> 5814600 | G8: =Assumptions!G36 -> 35.39014 | H8: ='Annual Forecast'!B9 -> Net Revenue | I8: =SUM(I6:I7) -> 5682626.6
H10: ='Annual Forecast'!B10 -> Expenses
H11: ='Annual Forecast'!B11 -> Taxes | I11: ='Annual Forecast'!C11 -> -564336.34
B12: Sources and Uses | H12: ='Annual Forecast'!B12 -> Insurance | I12: ='Annual Forecast'!C12 -> -195347.2
B13: Sources | D13: $/Unit | E13: % of Total | H13: ='Annual Forecast'!B13 -> Payroll | I13: ='Annual Forecast'!C13 -> -293020.79
B14: Equity | C14: =C16-C15 -> 35494275 | D14: =C14/Assumptions!$D$9 -> 165861.1 | E14: =C14/$C$16 -> 0.41161856 | H14: ='Annual Forecast'!B14 -> Repairs & Maintenance | I14: ='Annual Forecast'!C14 -> -97673.598
B15: Debt | C15: =Assumptions!K32 -> 50736714 | D15: =C15/Assumptions!$D$9 -> 237087.45 | E15: =C15/$C$16 -> 0.58838144 | H15: ='Annual Forecast'!B15 -> Contract Services | I15: ='Annual Forecast'!C15 -> -164959.85
B16: Total | C16: =C20 -> 86230989 | D16: =C16/Assumptions!$D$9 -> 402948.55 | E16: =C16/$C$16 -> 1 | H16: ='Annual Forecast'!B16 -> Marketing | I16: ='Annual Forecast'!C16 -> -108526.22
B17: Uses | H17: ='Annual Forecast'!B17 -> General & Administrative | I17: ='Annual Forecast'!C17 -> -67286.256
B18: Purchase Price | C18: =Assumptions!D16 -> 85493946 | D18: =C18/Assumptions!$D$9 -> 399504.42 | E18: =C18/$C$20 -> 0.99145269 | H18: ='Annual Forecast'!B18 -> Utilities | I18: ='Annual Forecast'!C18 -> -132401.99
B19: Closing Cost | C19: =Assumptions!D16*Assumptions!D23 -> 737043.31 | D19: =C19/Assumptions!$D$9 -> 3444.1276 | E19: =C19/$C$20 -> 0.0085473136 | H19: ='Annual Forecast'!B19 -> Reserves | I19: ='Annual Forecast'!C19 -> -235901.52
B20: Total | C20: =SUM(C18:C19) -> 86230989 | D20: =C20/Assumptions!$D$9 -> 402948.55 | E20: =C20/$C$20 -> 1 | H20: ='Annual Forecast'!B20 -> Management | I20: ='Annual Forecast'!C20 -> -176926.14
H21: ='Annual Forecast'!B21 -> Total Expenses | I21: =SUM(I11:I20) -> -2036379.9
H22: ='Annual Forecast'!B22 -> Net Operating Income | I22: =I21+I8 -> 3646246.7
A24: Returns | H24: Projected Value | I24: =I22/Assumptions!D27 -> 62989043
A25: Unlevered IRR | C25: =XIRR('Monthly Cash Flow'!F35:BZ35,'Monthly Cash Flow'!F5:BZ5) -> -0.037302348
A26: Levered IRR | C26: =XIRR('Monthly Cash Flow'!F39:BZ39,'Monthly Cash Flow'!F5:BZ5,) -> -0.16650722
A27: Unlevered Equity Multiple | B27: Bank Refinance Loan Info | C27: =SUMIF('Monthly Cash Flow'!F35:BZ35,">0",'Monthly Cash Flow'!F35:BZ35)/ABS(SUMIF('Monthly Cash Flow'!F35:BZ35,"<0",'Monthly Cash Flow'!F35:BZ35)) -> 0.89610398 | E27: HUD Refinance Loan Info | H27: Agency Refinance Loan Info
A28: Levered Equity Multiple | B28: LTV Constraint | C28: =SUMIF('Monthly Cash Flow'!F39:BZ39,">0",'Monthly Cash Flow'!F39:BZ39)/ABS(SUMIF('Monthly Cash Flow'!F39:BZ39,"<0",'Monthly Cash Flow'!F39:BZ39)) -> 0.60441174 | D28: 0.631759 | E28: LTV Constraint | G28: 0.8516 | H28: LTV Constraint | J28: 0.75
B29: DSCR Constraint | D29: 1.25 | E29: DSCR Constraint | G29: 1.15 | H29: DSCR Constraint | J29: 1.2
B30: Debt Yield Constraint | D30: 0.08 | E30: Debt Yield Constraint | H30: Debt Yield Constraint
B31: Cap Rate | D31: =Assumptions!$D$27 -> 0.057887 | E31: Cap Rate | G31: =Assumptions!$D$27 -> 0.057887 | H31: Cap Rate | J31: =Assumptions!$D$27 -> 0.057887
B32: Spread | D32: 0.02 | E32: Spread | G32: 0.0175 | H32: Spread | J32: 0.0175
B33: Rate Index | C33: SOFR | D33: 0.04321 | E33: Rate Index | F33: 10-Year Treasury | G33: 0.04245 | H33: Rate Index | I33: 10-Year Treasury | J33: 0.04245
B34: Projected Rate | D34: =D33+D32 -> 0.06321 | E34: Projected Rate | G34: =G33+G32 -> 0.05995 | H34: Projected Rate | J34: =J33+J32 -> 0.05995
B35: Amortization | D35: 25 | E35: Amortization | G35: 35 | H35: Amortization | J35: 30
B37: Existing Mortgage | D37: =ABS(SUMIF('Monthly Cash Flow'!$F$38:$BZ$38,"<0",'Monthly Cash Flow'!$F$38:$BZ$38)) -> 49624250 | E37: Existing Mortgage | G37: =ABS(SUMIF('Monthly Cash Flow'!$F$38:$BZ$38,"<0",'Monthly Cash Flow'!$F$38:$BZ$38)) -> 49624250 | H37: Existing Mortgage | J37: =ABS(SUMIF('Monthly Cash Flow'!$F$38:$BZ$38,"<0",'Monthly Cash Flow'!$F$38:$BZ$38)) -> 49624250
B39: Loan Sizing | E39: Loan Sizing | H39: Loan Sizing
B40: LTV Proceeds | D40: =D28*'Annual Forecast'!C22/'Investment Summary'!D31 -> 39793895 | E40: LTV Proceeds | G40: =G28*'Annual Forecast'!E22/'Investment Summary'!G31 -> 56342694 | H40: LTV Proceeds | J40: =J28*'Annual Forecast'!C22/'Investment Summary'!J31 -> 47241782
B41: DSCR Proceeds | D41: =PV(D34/12,D35*12,-'Annual Forecast'!C22/'Investment Summary'!D29/12,0,0) -> 36605320 | E41: DSCR Proceeds | G41: =PV(G34/12,G35*12,-'Annual Forecast'!C22/'Investment Summary'!G29/12,0,0) -> 46366401 | H41: DSCR Proceeds | J41: =PV(J34/12,J35*12,-'Annual Forecast'!C22/'Investment Summary'!J29/12,0,0) -> 42256222
B42: Debt Yield Proceeds | D42: ='Annual Forecast'!C22/'Investment Summary'!D30 -> 45578084 | E42: Debt Yield Proceeds | H42: Debt Yield Proceeds
B44: Excess Proceeds/Shortfall | D44: =MIN(D40:D42)-D37 -> -13018929 | G44: =MIN(G40:G42)-G37 -> -3257848.6 | J44: =MIN(J40:J42)-J37 -> -7368028.2

Sheet Annual Forecast
B2: Five-Year Operating Forecast
B3: Year | C3: 1 | D3: =C3+1 -> 2 | E3: =D3+1 -> 3 | F3: =E3+1 -> 4 | G3: =F3+1 -> 5
B4: Resi Gross Potential Rent | C4: =SUMIF('Monthly Cash Flow'!$G$3:$BZ$3,'Annual Forecast'!C3,'Monthly Cash Flow'!$G$6:$BZ$6) -> 5892581.4 | D4: =SUMIF('Monthly Cash Flow'!$G$3:$BZ$3,'Annual Forecast'!D3,'Monthly Cash Flow'!$G$6:$BZ$6) -> 6065911.7 | E4: =SUMIF('Monthly Cash Flow'!$G$3:$BZ$3,'Annual Forecast'!E3,'Monthly Cash Flow'!$G$6:$BZ$6) -> 6244340.5 | F4: =SUMIF('Monthly Cash Flow'!$G$3:$BZ$3,'Annual Forecast'!F3,'Monthly Cash Flow'!$G$6:$BZ$6) -> 6428017.7 | G4: =SUMIF('Monthly Cash Flow'!$G$3:$BZ$3,'Annual Forecast'!G3,'Monthly Cash Flow'!$G$6:$BZ$6) -> 6617097.9
B5: Vacancy | C5: =SUMIF('Monthly Cash Flow'!$G$3:$BZ$3,'Annual Forecast'!C3,'Monthly Cash Flow'!$G$7:$BZ$7) -> -294629.07 | D5: =SUMIF('Monthly Cash Flow'!$G$3:$BZ$3,'Annual Forecast'!D3,'Monthly Cash Flow'!$G7:$BZ7) -> -303295.58 | E5: =SUMIF('Monthly Cash Flow'!$G$3:$BZ$3,'Annual Forecast'!E3,'Monthly Cash Flow'!$G7:$BZ7) -> -312217.02 | F5: =SUMIF('Monthly Cash Flow'!$G$3:$BZ$3,'Annual Forecast'!F3,'Monthly Cash Flow'!$G7:$BZ7) -> -321400.89 | G5: =SUMIF('Monthly Cash Flow'!$G$3:$BZ$3,'Annual Forecast'!G3,'Monthly Cash Flow'!$G7:$BZ7) -> -330854.89
B6: Bad Debt | C6: =SUMIF('Monthly Cash Flow'!$G$3:$BZ$3,'Annual Forecast'!C3,'Monthly Cash Flow'!$G$8:$BZ$8) -> -353554.88 | D6: =SUMIF('Monthly Cash Flow'!$G$3:$BZ$3,'Annual Forecast'!D3,'Monthly Cash Flow'!$G$8:$BZ$8) -> -363954.7 | E6: =SUMIF('Monthly Cash Flow'!$G$3:$BZ$3,'Annual Forecast'!E3,'Monthly Cash Flow'!$G$8:$BZ$8) -> -374660.43 | F6: =SUMIF('Monthly Cash Flow'!$G$3:$BZ$3,'Annual Forecast'!F3,'Monthly Cash Flow'!$G$8:$BZ$8) -> -385681.06 | G6: =SUMIF('Monthly Cash Flow'!$G$3:$BZ$3,'Annual Forecast'!G3,'Monthly Cash Flow'!$G$8:$BZ$8) -> -397025.87
B7: Net Rental Income | C7: =SUM(C4:C6) -> 5244397.4 | D7: =SUM(D4:D6) -> 5398661.4 | E7: =SUM(E4:E6) -> 5557463 | F7: =SUM(F4:F6) -> 5720935.8 | G7: =SUM(G4:G6) -> 5889217.1
B8: Other Income | C8: =SUMIF('Monthly Cash Flow'!$G$3:$BZ$3,'Annual Forecast'!C3,'Monthly Cash Flow'!$G$10:$BZ$10) -> 438229.2 | D8: =SUMIF('Monthly Cash Flow'!$G$3:$BZ$3,'Annual Forecast'!D3,'Monthly Cash Flow'!$G$10:$BZ$10) -> 438229.2 | E8: =SUMIF('Monthly Cash Flow'!$G$3:$BZ$3,'Annual Forecast'!E3,'Monthly Cash Flow'!$G$10:$BZ$10) -> 438229.2 | F8: =SUMIF('Monthly Cash Flow'!$G$3:$BZ$3,'Annual Forecast'!F3,'Monthly Cash Flow'!$G$10:$BZ$10) -> 438229.2 | G8: =SUMIF('Monthly Cash Flow'!$G$3:$BZ$3,'Annual Forecast'!G3,'Monthly Cash Flow'!$G$10:$BZ$10) -> 438229.2
B9: Net Revenue | C9: =SUM(C7:C8) -> 5682626.6 | D9: =SUM(D7:D8) -> 5836890.6 | E9: =SUM(E7:E8) -> 5995692.2 | F9: =SUM(F7:F8) -> 6159165 | G9: =SUM(G7:G8) -> 6327446.3
B10: Expenses
B11: =Assumptions!G57 -> Taxes | C11: =SUMIF('Monthly Cash Flow'!$G$3:$BZ$3,'Annual Forecast'!C$3,'Monthly Cash Flow'!$G13:$BZ13) -> -564336.34 | D11: =SUMIF('Monthly Cash Flow'!$G$3:$BZ$3,'Annual Forecast'!D$3,'Monthly Cash Flow'!$G13:$BZ13) -> -581997.25 | E11: =SUMIF('Monthly Cash Flow'!$G$3:$BZ$3,'Annual Forecast'!E$3,'Monthly Cash Flow'!$G13:$BZ13) -> -600210.85 | F11: =SUMIF('Monthly Cash Flow'!$G$3:$BZ$3,'Annual Forecast'!F$3,'Monthly Cash Flow'!$G13:$BZ13) -> -618994.45 | G11: =SUMIF('Monthly Cash Flow'!$G$3:$BZ$3,'Annual Forecast'!G$3,'Monthly Cash Flow'!$G13:$BZ13) -> -638365.88
B12: =Assumptions!G58 -> Insurance | C12: =SUMIF('Monthly Cash Flow'!$G$3:$BZ$3,'Annual Forecast'!C$3,'Monthly Cash Flow'!$G14:$BZ14) -> -195347.2 | D12: =SUMIF('Monthly Cash Flow'!$G$3:$BZ$3,'Annual Forecast'!D$3,'Monthly Cash Flow'!$G14:$BZ14) -> -201460.59 | E12: =SUMIF('Monthly Cash Flow'!$G$3:$BZ$3,'Annual Forecast'!E$3,'Monthly Cash Flow'!$G14:$BZ14) -> -207765.3 | F12: =SUMIF('Monthly Cash Flow'!$G$3:$BZ$3,'Annual Forecast'!F$3,'Monthly Cash Flow'!$G14:$BZ14) -> -214267.31 | G12: =SUMIF('Monthly Cash Flow'!$G$3:$BZ$3,'Annual Forecast'!G$3,'Monthly Cash Flow'!$G14:$BZ14) -> -220972.81
B13: =Assumptions!G59 -> Payroll | C13: =SUMIF('Monthly Cash Flow'!$G$3:$BZ$3,'Annual Forecast'!C$3,'Monthly Cash Flow'!$G15:$BZ15) -> -293020.79 | D13: =SUMIF('Monthly Cash Flow'!$G$3:$BZ$3,'Annual Forecast'!D$3,'Monthly Cash Flow'!$G15:$BZ15) -> -302190.88 | E13: =SUMIF('Monthly Cash Flow'!$G$3:$BZ$3,'Annual Forecast'!E$3,'Monthly Cash Flow'!$G15:$BZ15) -> -311647.94 | F13: =SUMIF('Monthly Cash Flow'!$G$3:$BZ$3,'Annual Forecast'!F$3,'Monthly Cash Flow'!$G15:$BZ15) -> -321400.97 | G13: =SUMIF('Monthly Cash Flow'!$G$3:$BZ$3,'Annual Forecast'!G$3,'Monthly Cash Flow'!$G15:$BZ15) -> -331459.21
B14: =Assumptions!G60 -> Repairs & Maintenance | C14: =SUMIF('Monthly Cash Flow'!$G$3:$BZ$3,'Annual Forecast'!C$3,'Monthly Cash Flow'!$G16:$BZ16) -> -97673.598 | D14: =SUMIF('Monthly Cash Flow'!$G$3:$BZ$3,'Annual Forecast'!D$3,'Monthly Cash Flow'!$G16:$BZ16) -> -100730.29 | E14: =SUMIF('Monthly Cash Flow'!$G$3:$BZ$3,'Annual Forecast'!E$3,'Monthly Cash Flow'!$G16:$BZ16) -> -103882.65 | F14: =SUMIF('Monthly Cash Flow'!$G$3:$BZ$3,'Annual Forecast'!F$3,'Monthly Cash Flow'!$G16:$BZ16) -> -107133.66 | G14: =SUMIF('Monthly Cash Flow'!$G$3:$BZ$3,'Annual Forecast'!G$3,'Monthly Cash Flow'!$G16:$BZ16) -> -110486.4
B15: =Assumptions!G61 -> Contract Services | C15: =SUMIF('Monthly Cash Flow'!$G$3:$BZ$3,'Annual Forecast'!C$3,'Monthly Cash Flow'!$G17:$BZ17) -> -164959.85 | D15: =SUMIF('Monthly Cash Flow'!$G$3:$BZ$3,'Annual Forecast'!D$3,'Monthly Cash Flow'!$G17:$BZ17) -> -170122.27 | E15: =SUMIF('Monthly Cash Flow'!$G$3:$BZ$3,'Annual Forecast'!E$3,'Monthly Cash Flow'!$G17:$BZ17) -> -175446.25 | F15: =SUMIF('Monthly Cash Flow'!$G$3:$BZ$3,'Annual Forecast'!F$3,'Monthly Cash Flow'!$G17:$BZ17) -> -180936.84 | G15: =SUMIF('Monthly Cash Flow'!$G$3:$BZ$3,'Annual Forecast'!G$3,'Monthly Cash Flow'!$G17:$BZ17) -> -186599.26
B16: =Assumptions!G62 -> Marketing | C16: =SUMIF('Monthly Cash Flow'!$G$3:$BZ$3,'Annual Forecast'!C$3,'Monthly Cash Flow'!$G18:$BZ18) -> -108526.22 | D16: =SUMIF('Monthly Cash Flow'!$G$3:$BZ$3,'Annual Forecast'!D$3,'Monthly Cash Flow'!$G18:$BZ18) -> -111922.55 | E16: =SUMIF('Monthly Cash Flow'!$G$3:$BZ$3,'Annual Forecast'!E$3,'Monthly Cash Flow'!$G18:$BZ18) -> -115425.16 | F16: =SUMIF('Monthly Cash Flow'!$G$3:$BZ$3,'Annual Forecast'!F$3,'Monthly Cash Flow'!$G18:$BZ18) -> -119037.39 | G16: =SUMIF('Monthly Cash Flow'!$G$3:$BZ$3,'Annual Forecast'!G$3,'Monthly Cash Flow'!$G18:$BZ18) -> -122762.67
B17: =Assumptions!G63 -> General & Administrative | C17: =SUMIF('Monthly Cash Flow'!$G$3:$BZ$3,'Annual Forecast'!C$3,'Monthly Cash Flow'!$G19:$BZ19) -> -67286.256 | D17: =SUMIF('Monthly Cash Flow'!$G$3:$BZ$3,'Annual Forecast'!D$3,'Monthly Cash Flow'!$G19:$BZ19) -> -69391.98 | E17: =SUMIF('Monthly Cash Flow'!$G$3:$BZ$3,'Annual Forecast'!E$3,'Monthly Cash Flow'!$G19:$BZ19) -> -71563.602 | F17: =SUMIF('Monthly Cash Flow'!$G$3:$BZ$3,'Annual Forecast'!F$3,'Monthly Cash Flow'!$G19:$BZ19) -> -73803.185 | G17: =SUMIF('Monthly Cash Flow'!$G$3:$BZ$3,'Annual Forecast'!G$3,'Monthly Cash Flow'!$G19:$BZ19) -> -76112.855
B18: =Assumptions!G64 -> Utilities | C18: =SUMIF('Monthly Cash Flow'!$G$3:$BZ$3,'Annual Forecast'!C$3,'Monthly Cash Flow'!$G20:$BZ20) -> -132401.99 | D18: =SUMIF('Monthly Cash Flow'!$G$3:$BZ$3,'Annual Forecast'!D$3,'Monthly Cash Flow'!$G20:$BZ20) -> -136545.51 | E18: =SUMIF('Monthly Cash Flow'!$G$3:$BZ$3,'Annual Forecast'!E$3,'Monthly Cash Flow'!$G20:$BZ20) -> -140818.7 | F18: =SUMIF('Monthly Cash Flow'!$G$3:$BZ$3,'Annual Forecast'!F$3,'Monthly Cash Flow'!$G20:$BZ20) -> -145225.62 | G18: =SUMIF('Monthly Cash Flow'!$G$3:$BZ$3,'Annual Forecast'!G$3,'Monthly Cash Flow'!$G20:$BZ20) -> -149770.46
B19: =Assumptions!G65 -> Reserves | C19: =SUMIF('Monthly Cash Flow'!$G$3:$BZ$3,'Annual Forecast'!C$3,'Monthly Cash Flow'!$G21:$BZ21) -> -235901.52 | D19: =SUMIF('Monthly Cash Flow'!$G$3:$BZ$3,'Annual Forecast'!D$3,'Monthly Cash Flow'!$G21:$BZ21) -> -243284.06 | E19: =SUMIF('Monthly Cash Flow'!$G$3:$BZ$3,'Annual Forecast'!E$3,'Monthly Cash Flow'!$G21:$BZ21) -> -250897.63 | F19: =SUMIF('Monthly Cash Flow'!$G$3:$BZ$3,'Annual Forecast'!F$3,'Monthly Cash Flow'!$G21:$BZ21) -> -258749.47 | G19: =SUMIF('Monthly Cash Flow'!$G$3:$BZ$3,'Annual Forecast'!G$3,'Monthly Cash Flow'!$G21:$BZ21) -> -266847.04
B20: =Assumptions!G66 -> Management | C20: =SUMIF('Monthly Cash Flow'!$G$3:$BZ$3,'Annual Forecast'!C$3,'Monthly Cash Flow'!$G22:$BZ22) -> -176926.14 | D20: =SUMIF('Monthly Cash Flow'!$G$3:$BZ$3,'Annual Forecast'!D$3,'Monthly Cash Flow'!$G22:$BZ22) -> -182463.04 | E20: =SUMIF('Monthly Cash Flow'!$G$3:$BZ$3,'Annual Forecast'!E$3,'Monthly Cash Flow'!$G22:$BZ22) -> -188173.22 | F20: =SUMIF('Monthly Cash Flow'!$G$3:$BZ$3,'Annual Forecast'!F$3,'Monthly Cash Flow'!$G22:$BZ22) -> -194062.1 | G20: =SUMIF('Monthly Cash Flow'!$G$3:$BZ$3,'Annual Forecast'!G$3,'Monthly Cash Flow'!$G22:$BZ22) -> -200135.28
B21: Total Expenses | C21: =SUM(C11:C20) -> -2036379.9 | D21: =SUM(D11:D20) -> -2100108.4 | E21: =SUM(E11:E20) -> -2165831.3 | F21: =SUM(F11:F20) -> -2233611 | G21: =SUM(G11:G20) -> -2303511.9
B22: Net Operating Income | C22: =C21+C9 -> 3646246.7 | D22: =D21+D9 -> 3736782.2 | E22: =E21+E9 -> 3829860.9 | F22: =F21+F9 -> 3925554 | G22: =G21+G9 -> 4023934.5
B24: Exp Ratio | C24: =-C21/C9 -> 0.35835187 | D24: =-D21/D9 -> 0.35979917 | E24: =-E21/E9 -> 0.36123124 | F24: =-F21/F9 -> 0.36264835 | G24: =-G21/G9 -> 0.36405079
B25: NOI/Unit | C25: =C22/Assumptions!$D$9 -> 17038.536 | D25: =D22/Assumptions!$D$9 -> 17461.599 | E25: =E22/Assumptions!$D$9 -> 17896.546 | F25: =F22/Assumptions!$D$9 -> 18343.71 | G25: =G22/Assumptions!$D$9 -> 18803.432
B27: Projected Value | C27: =C22/Assumptions!$D$27 -> 62989043 | D27: =D22/Assumptions!$D$27 -> 64553046 | E27: =E22/Assumptions!$D$27 -> 66160984 | F27: =F22/Assumptions!$D$27 -> 67814086 | G27: =G22/Assumptions!$D$27 -> 69513612
B28: /Unit | C28: =C27/Assumptions!$D$9 -> 294341.32 | D28: =D27/Assumptions!$D$9 -> 301649.75 | E28: =E27/Assumptions!$D$9 -> 309163.48 | F28: =F27/Assumptions!$D$9 -> 316888.25 | G28: =G27/Assumptions!$D$9 -> 324829.96

Sheet Monthly Cash Flow
B2: Rental Growth | C2: 0.029415 | E2: Five-Year Operating Forecast | BN2: 0
B3: Other Income Growth | C3: 0 | E3: Year | G3: 1 | H3: 1 | I3: 1 | J3: 1 | K3: 1 | L3: 1 | M3: 1 | N3: 1 | O3: 1 | P3: 1 | Q3: 1 | R3: 1 | S3: =G3+1 -> 2 | T3: =H3+1 -> 2 | U3: =I3+1 -> 2 | V3: =J3+1 -> 2 | W3: =K3+1 -> 2 | X3: =L3+1 -> 2 | Y3: =M3+1 -> 2 | Z3: =N3+1 -> 2 | ... BZ3: =BN3+1 -> 6
B4: Expense Growth | C4: 0.031295 | E4: Month | F4: 0 | G4: =F4+1 -> 1 | H4: =G4+1 -> 2 | I4: =H4+1 -> 3 | J4: =I4+1 -> 4 | K4: =J4+1 -> 5 | L4: =K4+1 -> 6 | M4: =L4+1 -> 7 | N4: =M4+1 -> 8 | ... BZ4: =BY4+1 -> 72
B5: Vacancy | C5: 0.05 | E5: Month Ending | F5: =Assumptions!D17 -> 45778 | G5: =EOMONTH(F5,1) -> 45838 | H5: =EOMONTH(G5,1) -> 45869 | I5: =EOMONTH(H5,1) -> 45900 | J5: =EOMONTH(I5,1) -> 45930 | K5: =EOMONTH(J5,1) -> 45961 | L5: =EOMONTH(K5,1) -> 45991 | M5: =EOMONTH(L5,1) -> 46022 | N5: =EOMONTH(M5,1) -> 46053 | ... BZ5: =EOMONTH(BY5,1) -> 47999
B6: Bad Debt | C6: 0.06 | E6: Gross Potential Rent | G6: =Assumptions!E36*Assumptions!C36 -> 484550 | H6: =G6*(1+$C$2)^(1/12) -> 485722.03 | I6: =H6*(1+$C$2)^(1/12) -> 486896.9 | J6: =I6*(1+$C$2)^(1/12) -> 488074.62 | K6: =J6*(1+$C$2)^(1/12) -> 489255.18 | L6: =K6*(1+$C$2)^(1/12) -> 490438.59 | M6: =L6*(1+$C$2)^(1/12) -> 491624.87 | N6: =M6*(1+$C$2)^(1/12) -> 492814.02 | O6: =N6*(1+$C$2)^(1/12) -> 494006.04 | ... BZ6: =BY6*(1+$C$2)^(1/12) -> 575217.84
B7: Capital Improvements (% of NOI) | C7: 0.015 | E7: Vacancy | G7: =G6*-$C$5 -> -24227.5 | H7: =H6*-$C$5 -> -24286.102 | I7: =I6*-$C$5 -> -24344.845 | J7: =J6*-$C$5 -> -24403.731 | K7: =K6*-$C$5 -> -24462.759 | L7: =L6*-$C$5 -> -24521.93 | M7: =M6*-$C$5 -> -24581.243 | N7: =N6*-$C$5 -> -24640.701 | ... BZ7: =BZ6*-$C$5 -> -28760.892
E8: Bad Debt | G8: =G6*-$C$6 -> -29073 | H8: =H6*-$C$6 -> -29143.322 | I8: =I6*-$C$6 -> -29213.814 | J8: =J6*-$C$6 -> -29284.477 | K8: =K6*-$C$6 -> -29355.311 | L8: =L6*-$C$6 -> -29426.315 | M8: =M6*-$C$6 -> -29497.492 | N8: =N6*-$C$6 -> -29568.841 | ... BZ8: =BZ6*-$C$6 -> -34513.07
E9: Net Rental Income | G9: =SUM(G6:G8) -> 431249.5 | H9: =SUM(H6:H8) -> 432292.61 | I9: =SUM(I6:I8) -> 433338.24 | J9: =SUM(J6:J8) -> 434386.41 | K9: =SUM(K6:K8) -> 435437.11 | L9: =SUM(L6:L8) -> 436490.35 | M9: =SUM(M6:M8) -> 437546.13 | N9: =SUM(N6:N8) -> 438604.47 | ... BZ9: =SUM(BZ6:BZ8) -> 511943.87
E10: Other Income | G10: =Assumptions!D51 -> 36519.1 | H10: =G10*(1+$C$3)^(1/12) -> 36519.1 | I10: =H10*(1+$C$3)^(1/12) -> 36519.1 | J10: =I10*(1+$C$3)^(1/12) -> 36519.1 | K10: =J10*(1+$C$3)^(1/12) -> 36519.1 | L10: =K10*(1+$C$3)^(1/12) -> 36519.1 | M10: =L10*(1+$C$3)^(1/12) -> 36519.1 | N10: =M10*(1+$C$3)^(1/12) -> 36519.1 | O10: =N10*(1+$C$3)^(1/12) -> 36519.1 | ... BZ10: =BY10*(1+$C$3)^(1/12) -> 36519.1
E11: Net Revenue | G11: =G10+G9 -> 467768.6 | H11: =H10+H9 -> 468811.71 | I11: =I10+I9 -> 469857.34 | J11: =J10+J9 -> 470905.51 | K11: =K10+K9 -> 471956.21 | L11: =L10+L9 -> 473009.45 | M11: =M10+M9 -> 474065.23 | N11: =N10+N9 -> 475123.57 | ... BZ11: =BZ10+BZ9 -> 548462.97
E12: Expenses | BN12: 0 | BO12: 0 | BP12: 0 | BQ12: 0 | BR12: 0 | BS12: 0 | BT12: 0 | BU12: 0 | BV12: 0 | BW12: 0 | BX12: 0 | BY12: 0 | BZ12: 0
E13: =Assumptions!G57 -> Taxes | G13: =-Assumptions!$I57/12*Assumptions!$C$36 -> -46366.667 | H13: =G13*(1+$C$4)^(1/12) -> -46485.887 | I13: =H13*(1+$C$4)^(1/12) -> -46605.413 | J13: =I13*(1+$C$4)^(1/12) -> -46725.247 | K13: =J13*(1+$C$4)^(1/12) -> -46845.389 | L13: =K13*(1+$C$4)^(1/12) -> -46965.839 | M13: =L13*(1+$C$4)^(1/12) -> -47086.6 | N13: =M13*(1+$C$4)^(1/12) -> -47207.671 | O13: =N13*(1+$C$4)^(1/12) -> -47329.053 | ... BZ13: =BY13*(1+$C$4)^(1/12) -> -55640.126
E14: =Assumptions!G58 -> Insurance | G14: =-Assumptions!$I58/12*Assumptions!$C$36 -> -16050 | H14: =G14*(1+$C$4)^(1/12) -> -16091.268 | I14: =H14*(1+$C$4)^(1/12) -> -16132.643 | J14: =I14*(1+$C$4)^(1/12) -> -16174.124 | K14: =J14*(1+$C$4)^(1/12) -> -16215.711 | L14: =K14*(1+$C$4)^(1/12) -> -16257.406 | M14: =L14*(1+$C$4)^(1/12) -> -16299.208 | N14: =M14*(1+$C$4)^(1/12) -> -16341.117 | O14: =N14*(1+$C$4)^(1/12) -> -16383.134 | ... BZ14: =BY14*(1+$C$4)^(1/12) -> -19260.044
E15: =Assumptions!G59 -> Payroll | G15: =-Assumptions!$I59/12*Assumptions!$C$36 -> -24075 | H15: =G15*(1+$C$4)^(1/12) -> -24136.903 | I15: =H15*(1+$C$4)^(1/12) -> -24198.964 | J15: =I15*(1+$C$4)^(1/12) -> -24261.186 | K15: =J15*(1+$C$4)^(1/12) -> -24323.567 | L15: =K15*(1+$C$4)^(1/12) -> -24386.109 | M15: =L15*(1+$C$4)^(1/12) -> -24448.811 | N15: =M15*(1+$C$4)^(1/12) -> -24511.675 | O15: =N15*(1+$C$4)^(1/12) -> -24574.701 | ... BZ15: =BY15*(1+$C$4)^(1/12) -> -28890.065
E16: =Assumptions!G60 -> Repairs & Maintenance | G16: =-Assumptions!$I60/12*Assumptions!$C$36 -> -8025 | H16: =G16*(1+$C$4)^(1/12) -> -8045.6342 | I16: =H16*(1+$C$4)^(1/12) -> -8066.3215 | J16: =I16*(1+$C$4)^(1/12) -> -8087.0619 | K16: =J16*(1+$C$4)^(1/12) -> -8107.8557 | L16: =K16*(1+$C$4)^(1/12) -> -8128.703 | M16: =L16*(1+$C$4)^(1/12) -> -8149.6038 | N16: =M16*(1+$C$4)^(1/12) -> -8170.5584 | O16: =N16*(1+$C$4)^(1/12) -> -8191.5669 | ... BZ16: =BY16*(1+$C$4)^(1/12) -> -9630.0218
E17: =Assumptions!G61 -> Contract Services | G17: =-Assumptions!$I61/12*Assumptions!$C$36 -> -13553.333 | H17: =G17*(1+$C$4)^(1/12) -> -13588.182 | I17: =H17*(1+$C$4)^(1/12) -> -13623.121 | J17: =I17*(1+$C$4)^(1/12) -> -13658.149 | K17: =J17*(1+$C$4)^(1/12) -> -13693.267 | L17: =K17*(1+$C$4)^(1/12) -> -13728.476 | M17: =L17*(1+$C$4)^(1/12) -> -13763.775 | N17: =M17*(1+$C$4)^(1/12) -> -13799.165 | O17: =N17*(1+$C$4)^(1/12) -> -13834.646 | ... BZ17: =BY17*(1+$C$4)^(1/12) -> -16264.037
E18: =Assumptions!G62 -> Marketing | G18: =-Assumptions!$I62/12*Assumptions!$C$36 -> -8916.6667 | H18: =G18*(1+$C$4)^(1/12) -> -8939.5936 | I18: =H18*(1+$C$4)^(1/12) -> -8962.5794 | J18: =I18*(1+$C$4)^(1/12) -> -8985.6244 | K18: =J18*(1+$C$4)^(1/12) -> -9008.7286 | L18: =K18*(1+$C$4)^(1/12) -> -9031.8922 | M18: =L18*(1+$C$4)^(1/12) -> -9055.1154 | N18: =M18*(1+$C$4)^(1/12) -> -9078.3983 | O18: =N18*(1+$C$4)^(1/12) -> -9101.741 | ... BZ18: =BY18*(1+$C$4)^(1/12) -> -10700.024
E19: =Assumptions!G63 -> General & Administrative | G19: =-Assumptions!$I63/12*Assumptions!$C$36 -> -5528.3333 | H19: =G19*(1+$C$4)^(1/12) -> -5542.548 | I19: =H19*(1+$C$4)^(1/12) -> -5556.7992 | J19: =I19*(1+$C$4)^(1/12) -> -5571.0871 | K19: =J19*(1+$C$4)^(1/12) -> -5585.4117 | L19: =K19*(1+$C$4)^(1/12) -> -5599.7732 | M19: =L19*(1+$C$4)^(1/12) -> -5614.1715 | N19: =M19*(1+$C$4)^(1/12) -> -5628.6069 | O19: =N19*(1+$C$4)^(1/12) -> -5643.0794 | ... BZ19: =BY19*(1+$C$4)^(1/12) -> -6634.015
E20: =Assumptions!G64 -> Utilities | G20: =-Assumptions!$I64/12*Assumptions!$C$36 -> -10878.333 | H20: =G20*(1+$C$4)^(1/12) -> -10906.304 | I20: =H20*(1+$C$4)^(1/12) -> -10934.347 | J20: =I20*(1+$C$4)^(1/12) -> -10962.462 | K20: =J20*(1+$C$4)^(1/12) -> -10990.649 | L20: =K20*(1+$C$4)^(1/12) -> -11018.908 | M20: =L20*(1+$C$4)^(1/12) -> -11047.241 | N20: =M20*(1+$C$4)^(1/12) -> -11075.646 | O20: =N20*(1+$C$4)^(1/12) -> -11104.124 | ... BZ20: =BY20*(1+$C$4)^(1/12) -> -13054.03
E21: =Assumptions!G65 -> Reserves | G21: =-Assumptions!$I65/12*Assumptions!$C$36 -> -19382 | H21: =G21*(1+$C$4)^(1/12) -> -19431.836 | I21: =H21*(1+$C$4)^(1/12) -> -19481.8 | J21: =I21*(1+$C$4)^(1/12) -> -19531.892 | K21: =J21*(1+$C$4)^(1/12) -> -19582.113 | L21: =K21*(1+$C$4)^(1/12) -> -19632.464 | M21: =L21*(1+$C$4)^(1/12) -> -19682.943 | N21: =M21*(1+$C$4)^(1/12) -> -19733.553 | O21: =N21*(1+$C$4)^(1/12) -> -19784.293 | ... BZ21: =BY21*(1+$C$4)^(1/12) -> -23258.453
E22: =Assumptions!G66 -> Management | G22: =-Assumptions!$I66/12*Assumptions!$C$36 -> -14536.5 | H22: =G22*(1+$C$4)^(1/12) -> -14573.877 | I22: =H22*(1+$C$4)^(1/12) -> -14611.35 | J22: =I22*(1+$C$4)^(1/12) -> -14648.919 | K22: =J22*(1+$C$4)^(1/12) -> -14686.585 | L22: =K22*(1+$C$4)^(1/12) -> -14724.348 | M22: =L22*(1+$C$4)^(1/12) -> -14762.208 | N22: =M22*(1+$C$4)^(1/12) -> -14800.165 | O22: =N22*(1+$C$4)^(1/12) -> -14838.22 | ... BZ22: =BY22*(1+$C$4)^(1/12) -> -17443.84
E23: Total Expenses | G23: =SUM(G13:G22) -> -167311.83 | H23: =SUM(H13:H22) -> -167742.03 | I23: =SUM(I13:I22) -> -168173.34 | J23: =SUM(J13:J22) -> -168605.75 | K23: =SUM(K13:K22) -> -169039.28 | L23: =SUM(L13:L22) -> -169473.92 | M23: =SUM(M13:M22) -> -169909.68 | N23: =SUM(N13:N22) -> -170346.56 | ... BZ23: =SUM(BZ13:BZ22) -> -200774.66
E24: Exp Ratio | G24: =-G23/G11 -> 0.35768077 | H24: =-H23/H11 -> 0.35780256 | I24: =-I23/I11 -> 0.35792425 | J24: =-J23/J11 -> 0.35804583 | K24: =-K23/K11 -> 0.3581673 | L24: =-L23/L11 -> 0.35828866 | M24: =-M23/M11 -> 0.35840991 | N24: =-N23/N11 -> 0.35853105 | ... BZ24: =-BZ23/BZ11 -> 0.36606784
E25: Net Operating Income | G25: =G11+G23 -> 300456.77 | H25: =H11+H23 -> 301069.68 | I25: =I11+I23 -> 301684.01 | J25: =J11+J23 -> 302299.76 | K25: =K11+K23 -> 302916.93 | L25: =L11+L23 -> 303535.53 | M25: =M11+M23 -> 304155.56 | N25: =N11+N23 -> 304777.02 | ... BZ25: =BZ11+BZ23 -> 347688.32
E26: Capital Improvements | G26: =G25*-$C$7 -> -4506.8515 | H26: =H25*-$C$7 -> -4516.0452 | I26: =I25*-$C$7 -> -4525.2601 | J26: =J25*-$C$7 -> -4534.4963 | K26: =K25*-$C$7 -> -4543.7539 | L26: =L25*-$C$7 -> -4553.0329 | M26: =M25*-$C$7 -> -4562.3334 | N26: =N25*-$C$7 -> -4571.6553 | ... BZ26: =BZ25*-$C$7 -> -5215.3248
E27: Cash Flow Before Debt Service | G27: =SUM(G25:G26) -> 295949.92 | H27: =SUM(H25:H26) -> 296553.63 | I27: =SUM(I25:I26) -> 297158.75 | J27: =SUM(J25:J26) -> 297765.26 | K27: =SUM(K25:K26) -> 298373.17 | L27: =SUM(L25:L26) -> 298982.49 | M27: =SUM(M25:M26) -> 299593.22 | N27: =SUM(N25:N26) -> 300205.36 | ... BZ27: =SUM(BZ25:BZ26) -> 342472.99
E28: Principal Payment | G28: =IF(G4<=Assumptions!$K$37,0,PPMT(Assumptions!$K$36/12,'Monthly Cash Flow'!G4-Assumptions!$K$37,Assumptions!$K$38*12-Assumptions!$K$37,Assumptions!$K$32,0,)) -> 0 | H28: =IF(H4<=Assumptions!$K$37,0,PPMT(Assumptions!$K$36/12,'Monthly Cash Flow'!H4-Assumptions!$K$37,Assumptions!$K$38*12-Assumptions!$K$37,Assumptions!$K$32,0,)) -> 0 | I28: =IF(I4<=Assumptions!$K$37,0,PPMT(Assumptions!$K$36/12,'Monthly Cash Flow'!I4-Assumptions!$K$37,Assumptions!$K$38*12-Assumptions!$K$37,Assumptions!$K$32,0,)) -> 0 | J28: =IF(J4<=Assumptions!$K$37,0,PPMT(Assumptions!$K$36/12,'Monthly Cash Flow'!J4-Assumptions!$K$37,Assumptions!$K$38*12-Assumptions!$K$37,Assumptions!$K$32,0,)) -> 0 | K28: =IF(K4<=Assumptions!$K$37,0,PPMT(Assumptions!$K$36/12,'Monthly Cash Flow'!K4-Assumptions!$K$37,Assumptions!$K$38*12-Assumptions!$K$37,Assumptions!$K$32,0,)) -> 0 | L28: =IF(L4<=Assumptions!$K$37,0,PPMT(Assumptions!$K$36/12,'Monthly Cash Flow'!L4-Assumptions!$K$37,Assumptions!$K$38*12-Assumptions!$K$37,Assumptions!$K$32,0,)) -> 0 | M28: =IF(M4<=Assumptions!$K$37,0,PPMT(Assumptions!$K$36/12,'Monthly Cash Flow'!M4-Assumptions!$K$37,Assumptions!$K$38*12-Assumptions!$K$37,Assumptions!$K$32,0,)) -> 0 | N28: =IF(N4<=Assumptions!$K$37,0,PPMT(Assumptions!$K$36/12,'Monthly Cash Flow'!N4-Assumptions!$K$37,Assumptions!$K$38*12-Assumptions!$K$37,Assumptions!$K$32,0,)) -> 0 | ... BZ28: =IF(BZ4<=Assumptions!$K$37,0,PPMT(Assumptions!$K$36/12,'Monthly Cash Flow'!BZ4-Assumptions!$K$37,Assumptions!$K$38*12-Assumptions!$K$37,Assumptions!$K$32,0,)) -> -104070.92
E29: Interest Payments | G29: =IF(G4<=Assumptions!$K$37,-Assumptions!$K$32*Assumptions!$K$36/12,IPMT(Assumptions!$K$36/12,'Monthly Cash Flow'!G4-Assumptions!$K$37,Assumptions!$K$38*12-Assumptions!$K$37,Assumptions!$K$32,0,)) -> -141639.99 | H29: =IF(H4<=Assumptions!$K$37,-Assumptions!$K$32*Assumptions!$K$36/12,IPMT(Assumptions!$K$36/12,'Monthly Cash Flow'!H4-Assumptions!$K$37,Assumptions!$K$38*12-Assumptions!$K$37,Assumptions!$K$32,0,)) -> -141639.99 | I29: =IF(I4<=Assumptions!$K$37,-Assumptions!$K$32*Assumptions!$K$36/12,IPMT(Assumptions!$K$36/12,'Monthly Cash Flow'!I4-Assumptions!$K$37,Assumptions!$K$38*12-Assumptions!$K$37,Assumptions!$K$32,0,)) -> -141639.99 | J29: =IF(J4<=Assumptions!$K$37,-Assumptions!$K$32*Assumptions!$K$36/12,IPMT(Assumptions!$K$36/12,'Monthly Cash Flow'!J4-Assumptions!$K$37,Assumptions!$K$38*12-Assumptions!$K$37,Assumptions!$K$32,0,)) -> -141639.99 | K29: =IF(K4<=Assumptions!$K$37,-Assumptions!$K$32*Assumptions!$K$36/12,IPMT(Assumptions!$K$36/12,'Monthly Cash Flow'!K4-Assumptions!$K$37,Assumptions!$K$38*12-Assumptions!$K$37,Assumptions!$K$32,0,)) -> -141639.99 | L29: =IF(L4<=Assumptions!$K$37,-Assumptions!$K$32*Assumptions!$K$36/12,IPMT(Assumptions!$K$36/12,'Monthly Cash Flow'!L4-Assumptions!$K$37,Assumptions!$K$38*12-Assumptions!$K$37,Assumptions!$K$32,0,)) -> -141639.99 | M29: =IF(M4<=Assumptions!$K$37,-Assumptions!$K$32*Assumptions!$K$36/12,IPMT(Assumptions!$K$36/12,'Monthly Cash Flow'!M4-Assumptions!$K$37,Assumptions!$K$38*12-Assumptions!$K$37,Assumptions!$K$32,0,)) -> -141639.99 | N29: =IF(N4<=Assumptions!$K$37,-Assumptions!$K$32*Assumptions!$K$36/12,IPMT(Assumptions!$K$36/12,'Monthly Cash Flow'!N4-Assumptions!$K$37,Assumptions!$K$38*12-Assumptions!$K$37,Assumptions!$K$32,0,)) -> -141639.99 | ... BZ29: =IF(BZ4<=Assumptions!$K$37,-Assumptions!$K$32*Assumptions!$K$36/12,IPMT(Assumptions!$K$36/12,'Monthly Cash Flow'!BZ4-Assumptions!$K$37,Assumptions!$K$38*12-Assumptions!$K$37,Assumptions!$K$32,0,)) -> -128859.6
E30: Cash Flow After Debt Service | G30: =SUM(G27:G29) -> 154309.92 | H30: =SUM(H27:H29) -> 154913.64 | I30: =SUM(I27:I29) -> 155518.75 | J30: =SUM(J27:J29) -> 156125.27 | K30: =SUM(K27:K29) -> 156733.18 | L30: =SUM(L27:L29) -> 157342.5 | M30: =SUM(M27:M29) -> 157953.23 | N30: =SUM(N27:N29) -> 158565.37 | ... BZ30: =SUM(BZ27:BZ29) -> 109542.47
E31: Acquisition Price | F31: =-Assumptions!D16 -> -85493946 | BN31: 0
E32: Closing Cost | F32: =-'Investment Summary'!C19 -> -737043.31 | BN32: 0
E33: Sale Proceeds | F33: =IF(F4=Assumptions!$D$26,((SUM(G25:R25)/Assumptions!$D$27)),0) -> 0 | G33: =IF(G4=Assumptions!$D$26,((SUM(H25:S25)/Assumptions!$D$27)),0) -> 0 | H33: =IF(H4=Assumptions!$D$26,((SUM(I25:T25)/Assumptions!$D$27)),0) -> 0 | I33: =IF(I4=Assumptions!$D$26,((SUM(J25:U25)/Assumptions!$D$27)),0) -> 0 | J33: =IF(J4=Assumptions!$D$26,((SUM(K25:V25)/Assumptions!$D$27)),0) -> 0 | K33: =IF(K4=Assumptions!$D$26,((SUM(L25:W25)/Assumptions!$D$27)),0) -> 0 | L33: =IF(L4=Assumptions!$D$26,((SUM(M25:X25)/Assumptions!$D$27)),0) -> 0 | M33: =IF(M4=Assumptions!$D$26,((SUM(N25:Y25)/Assumptions!$D$27)),0) -> 0 | ... BN33: =IF(BN4=Assumptions!$D$26,((SUM(BO25:BZ25)/Assumptions!$D$27)),0) -> 0 | BO33: =IF(BO4=Assumptions!$D$26,((SUM(BP30:BZ30)/Assumptions!$D$27)),0) -> 0 | BP33: =IF(BP4=Assumptions!$D$26,((SUM(BQ30:BZ30)/Assumptions!$D$27)),0) -> 0 | BQ33: =IF(BQ4=Assumptions!$D$26,((SUM(BR30:BZ30)/Assumptions!$D$27)),0) -> 0 | BR33: =IF(BR4=Assumptions!$D$26,((SUM(BS30:BZ30)/Assumptions!$D$27)),0) -> 0 | BS33: =IF(BS4=Assumptions!$D$26,((SUM(BT30:BZ30)/Assumptions!$D$27)),0) -> 0 | BT33: =IF(BT4=Assumptions!$D$26,((SUM(BU30:BZ30)/Assumptions!$D$27)),0) -> 0 | BU33: =IF(BU4=Assumptions!$D$26,((SUM(BV30:BZ30)/Assumptions!$D$27)),0) -> 0 | BV33: =IF(BV4=Assumptions!$D$26,((SUM(BW30:BZ30)/Assumptions!$D$27)),0) -> 0 | BW33: =IF(BW4=Assumptions!$D$26,((SUM(BX30:BZ30)/Assumptions!$D$27)),0) -> 0 | BX33: =IF(BX4=Assumptions!$D$26,((SUM(BY30:BZ30)/Assumptions!$D$27)),0) -> 0 | BY33: =IF(BY4=Assumptions!$D$26,((SUM(BZ30:BZ30)/Assumptions!$D$27)),0) -> 0 | BZ33: =IF(BZ4=Assumptions!$D$26,((SUM(BZ30:BZ30)/Assumptions!$D$27)),0) -> 0
E34: Cost Of Sale | F34: =F33*-Assumptions!$D$28 -> 0 | G34: =G33*-Assumptions!$D$28 -> 0 | H34: =H33*-Assumptions!$D$28 -> 0 | I34: =I33*-Assumptions!$D$28 -> 0 | J34: =J33*-Assumptions!$D$28 -> 0 | K34: =K33*-Assumptions!$D$28 -> 0 | L34: =L33*-Assumptions!$D$28 -> 0 | M34: =M33*-Assumptions!$D$28 -> 0 | ... BZ34: =BZ33*-Assumptions!$D$28 -> 0
E35: Unlevered Cash Flows | F35: =SUM(F31:F34) -> -86230989 | G35: =IF(G4>Assumptions!$D$26,0,SUM(G27,G31:G34)) -> 295949.92 | H35: =IF(H4>Assumptions!$D$26,0,SUM(H27,H31:H34)) -> 296553.63 | I35: =IF(I4>Assumptions!$D$26,0,SUM(I27,I31:I34)) -> 297158.75 | J35: =IF(J4>Assumptions!$D$26,0,SUM(J27,J31:J34)) -> 297765.26 | K35: =IF(K4>Assumptions!$D$26,0,SUM(K27,K31:K34)) -> 298373.17 | L35: =IF(L4>Assumptions!$D$26,0,SUM(L27,L31:L34)) -> 298982.49 | M35: =IF(M4>Assumptions!$D$26,0,SUM(M27,M31:M34)) -> 299593.22 | N35: =IF(N4>Assumptions!$D$26,0,SUM(N27,N31:N34)) -> 300205.36 | ... BZ35: =IF(BZ4>Assumptions!$D$26,0,SUM(BZ27,BZ31:BZ34)) -> 0
E36: Loan Proceeds | F36: =Assumptions!K32 -> 50736714 | BN36: 0
E37: Loan Origination Fee | F37: 0 | BN37: 0
E38: Loan Payoff | F38: 0 | G38: =IF(G4=Assumptions!$D$26,-($F$36+SUM($G$28:G28)),0) -> 0 | H38: =IF(H4=Assumptions!$D$26,-($F$36+SUM($G$28:H28)),0) -> 0 | I38: =IF(I4=Assumptions!$D$26,-($F$36+SUM($G$28:I28)),0) -> 0 | J38: =IF(J4=Assumptions!$D$26,-($F$36+SUM($G$28:J28)),0) -> 0 | K38: =IF(K4=Assumptions!$D$26,-($F$36+SUM($G$28:K28)),0) -> 0 | L38: =IF(L4=Assumptions!$D$26,-($F$36+SUM($G$28:L28)),0) -> 0 | M38: =IF(M4=Assumptions!$D$26,-($F$36+SUM($G$28:M28)),0) -> 0 | N38: =IF(N4=Assumptions!$D$26,-($F$36+SUM($G$28:N28)),0) -> 0 | ... BZ38: =IF(BZ4=Assumptions!$D$26,-($F$36+SUM($G$28:BZ28)),0) -> 0
E39: Total Levered Cash Flows | F39: =IF(F4>Assumptions!$D$26,0,SUM(F30:F34,F36:F38)) -> -35494275 | G39: =IF(G4>Assumptions!$D$26,0,SUM(G30:G34,G36:G38)) -> 154309.92 | H39: =IF(H4>Assumptions!$D$26,0,SUM(H30:H34,H36:H38)) -> 154913.64 | I39: =IF(I4>Assumptions!$D$26,0,SUM(I30:I34,I36:I38)) -> 155518.75 | J39: =IF(J4>Assumptions!$D$26,0,SUM(J30:J34,J36:J38)) -> 156125.27 | K39: =IF(K4>Assumptions!$D$26,0,SUM(K30:K34,K36:K38)) -> 156733.18 | L39: =IF(L4>Assumptions!$D$26,0,SUM(L30:L34,L36:L38)) -> 157342.5 | M39: =IF(M4>Assumptions!$D$26,0,SUM(M30:M34,M36:M38)) -> 157953.23 | ... BZ39: =IF(BZ4>Assumptions!$D$26,0,SUM(BZ30:BZ34,BZ36:BZ38)) -> 0
B41: 1
B42: =B41+1 -> 2
...
