Workbook
Name Cash_Interest_Rate: Drivers!$D$16
Name Company_Name: Drivers!$D$8
Name Debt_Interest_Rate: Drivers!$D$15
Name GM_Improv: Drivers!$D$13
Name Hist_Yr: Drivers!$D$11
Name Tax_Rate: Drivers!$D$14

Sheet Drivers
B2: =Company_Name&" Financial Model" -> Illinois Tool Works Inc. Financial Model
B3: (USD in millions, per-share/per-unit as noted)
B6: Key Assumptions:
C8: Entity Name: | D8: Illinois Tool Works Inc.
C9: Ticker Symbol: | D9: ITW
C10: Share Price: | D10: 124.799
C11: Final Historical Year: | D11: 42369
C13: Annual GM Expansion: | D13: 0.002748
C14: Blended Tax Rate: | D14: 0.329431
C15: Debt Interest Rate: | D15: 0.037096
C16: Cash Yield: | D16: 0.004547
E18: Actual | H18: Forecast
B19: Operating Drivers: | D19: Basis: | E19: =EOMONTH(F19,-12) -> 41639 | F19: =EOMONTH(G19,-12) -> 42004 | G19: =Hist_Yr -> 42369 | H19: =EOMONTH(G19,12) -> 42735 | I19: =EOMONTH(H19,12) -> 43100 | J19: =EOMONTH(I19,12) -> 43465 | K19: =EOMONTH(J19,12) -> 43830 | L19: =EOMONTH(K19,12) -> 44196
B20: P&L Drivers:
C21: Sales Growth: | D21: % | H21: 0.042173 | I21: 0.040973 | J21: 0.033548 | K21: 0.025482 | L21: 0.027872
C22: Gross Profit Margin: | D22: % | E22: =+'Income Statement'!E9/'Income Statement'!E5 -> 0.39483551 | F22: =+'Income Statement'!F9/'Income Statement'!F5 -> 0.40120133 | G22: =+'Income Statement'!G9/'Income Statement'!G5 -> 0.41156285 | H22: =+G22+GM_Improv -> 0.41431085 | I22: =+H22+GM_Improv -> 0.41705885 | J22: =+I22+GM_Improv -> 0.41980685 | K22: =+J22+GM_Improv -> 0.42255485 | L22: =+K22+GM_Improv -> 0.42530285
C23: SG&A % of Sales: | D23: % | H23: 0.15831 | I23: 0.179823 | J23: 0.184024 | K23: 0.190632 | L23: 0.136805
C25: Intangible Amortization: | D25: $ M | H25: 184 | I25: 182 | J25: 162 | K25: 178 | L25: 148
C26: Goodwill Impairment: | D26: $ M | H26: 0 | I26: 0 | J26: 0 | K26: 0 | L26: 0
C28: Debt Paydown Rate: | D28: % | H28: 0.084662 | I28: 0.097678 | J28: 0.105574 | K28: 0.111485 | L28: 0.09602
C30: Opening Debt Balance: | D30: $ M | H30: =+'Statements & Checks'!G29 -> 7422 | I30: =+H32 -> 6793.6386 | J30: =+I32 -> 6068.6725 | K30: =+J32 -> 5285.1023 | L30: =+K32 -> 4457.6606
C31: (-) Debt Repayment: | D31: $ M | H31: =-H28*$H$30 -> -628.36136 | I31: =-I28*$H$30 -> -724.96612 | J31: =-J28*$H$30 -> -783.57023 | K31: =-K28*$H$30 -> -827.44167 | L31: =-L28*$H$30 -> -712.66044
C32: Closing Debt Balance: | D32: $ M | H32: =SUM(H30:H31) -> 6793.6386 | I32: =SUM(I30:I31) -> 6068.6725 | J32: =SUM(J30:J31) -> 5285.1023 | K32: =SUM(K30:K31) -> 4457.6606 | L32: =SUM(L30:L31) -> 3745.0002
C34: Gross Interest Expense: | D34: $ M | H34: =+H30*Debt_Interest_Rate -> 275.32651 | I34: =+I30*Debt_Interest_Rate -> 252.01682 | J34: =+J30*Debt_Interest_Rate -> 225.12348 | K34: =+K30*Debt_Interest_Rate -> 196.05615 | L34: =+L30*Debt_Interest_Rate -> 165.36138
C35: Interest Earned: | D35: $ M | H35: =+'Statements & Checks'!G6*Cash_Interest_Rate -> 14.05023 | I35: =+'Statements & Checks'!H6*Cash_Interest_Rate -> 16.654018 | J35: =+'Statements & Checks'!I6*Cash_Interest_Rate -> 8.3240679 | K35: =+'Statements & Checks'!J6*Cash_Interest_Rate -> -0.36784188 | L35: =+'Statements & Checks'!K6*Cash_Interest_Rate -> -9.8548922
C37: Discontinued Ops Income: | D37: $ M | H37: 0 | I37: 0 | J37: 0 | K37: 0 | L37: 0
B39: Balance Sheet Inputs:
C40: Receivable Days (DSO): | D40: # Days | E40: =+'Statements & Checks'!E7/'Income Statement'!E5*365 -> 61.070039 | F40: =+'Statements & Checks'!F7/'Income Statement'!F5*365 -> 57.784107 | G40: =+'Statements & Checks'!G7/'Income Statement'!G5*365 -> 59.984707 | H40: =AVERAGE(E40:G40) -> 59.612951 | I40: =+H40 -> 59.612951 | J40: =+I40 -> 59.612951 | K40: =+J40 -> 59.612951 | L40: =+K40 -> 59.612951
C41: Inventory Days (DSI): | D41: # Days | E41: =+'Statements & Checks'!E8/'Income Statement'!E7*365 -> 53.20961 | F41: =+'Statements & Checks'!F8/'Income Statement'!F7*365 -> 49.659864 | G41: =+'Statements & Checks'!G8/'Income Statement'!G7*365 -> 50.252282 | H41: 55 | I41: 46 | J41: 44 | K41: 55 | L41: 49
C42: Payable Days (DPO): | D42: # Days | E42: =+'Statements & Checks'!E23/'Income Statement'!E7*365 -> 27.052841 | F42: =+'Statements & Checks'!F23/'Income Statement'!F7*365 -> 21.547331 | G42: =+'Statements & Checks'!G23/'Income Statement'!G7*365 -> 20.776496 | H42: 18 | I42: 22 | J42: 19 | K42: 19 | L42: 21
C44: Prepaids & Other % of SG&A: | D44: % | E44: =+'Statements & Checks'!E9/'Income Statement'!E12 -> 0.91865009 | F44: =+'Statements & Checks'!F9/'Income Statement'!F12 -> 0.14973861 | G44: =+'Statements & Checks'!G9/'Income Statement'!G12 -> 0.14108399 | H44: 0.154303 | I44: 0.10845 | J44: 0.111678 | K44: 0.115705 | L44: 0.092778
C45: Other LT Assets % of Sales: | D45: % | E45: =+'Statements & Checks'!E16/'Income Statement'!E5 -> 0.11008136 | F45: =+'Statements & Checks'!F16/'Income Statement'!F5 -> 0.10004143 | G45: =+'Statements & Checks'!G16/'Income Statement'!G5 -> 0.10690041 | H45: =AVERAGE(E45:G45) -> 0.1056744 | I45: =+H45 -> 0.1056744 | J45: =+I45 -> 0.1056744 | K45: =+J45 -> 0.1056744 | L45: =+K45 -> 0.1056744
C46: Accruals % of SG&A: | D46: % | E46: =+'Statements & Checks'!E24/'Income Statement'!E12 -> 0.45186501 | F46: =+'Statements & Checks'!F24/'Income Statement'!F12 -> 0.48058252 | G46: =+'Statements & Checks'!G24/'Income Statement'!G12 -> 0.47000414 | H46: =AVERAGE(E46:G46) -> 0.46748389 | I46: =+H46 -> 0.46748389 | J46: =+I46 -> 0.46748389 | K46: =+J46 -> 0.46748389 | L46: =+K46 -> 0.46748389
C48: Other Current Liab. % of SG&A: | D48: % | E48: =+'Statements & Checks'!E25/'Income Statement'!E12 -> 0.20497336 | F48: =+'Statements & Checks'!F25/'Income Statement'!F12 -> 0.093353249 | G48: =+'Statements & Checks'!G25/'Income Statement'!G12 -> 0.10633016 | H48: 0.114902 | I48: 0.118239 | J48: 0.105805 | K48: 0.086252 | L48: 0.097828
C49: Other LT Liab. % of SG&A: | D49: % | E49: =+'Statements & Checks'!E31/'Income Statement'!E12 -> 0.32788632 | F49: =+'Statements & Checks'!F31/'Income Statement'!F12 -> 0.37415982 | G49: =+'Statements & Checks'!G31/'Income Statement'!G12 -> 0.40587505 | H49: =AVERAGE(E49:G49) -> 0.36930707 | I49: =+H49 -> 0.36930707 | J49: =+I49 -> 0.36930707 | K49: =+J49 -> 0.36930707 | L49: =+K49 -> 0.36930707
B51: Cash Flow Drivers:
C52: Capex Spend: | D52: $ M | H52: -238 | I52: -306 | J52: -327 | K52: -458 | L52: -533
C53: Depreciation % of Sales: | D53: % | E53: =+'Statements & Checks'!E48/'Income Statement'!E5 -> 0.021153166 | F53: =+'Statements & Checks'!F48/'Income Statement'!F5 -> 0.018088926 | G53: =+'Statements & Checks'!G48/'Income Statement'!G5 -> 0.018202163 | H53: 0.018508 | I53: 0.019907 | J53: 0.015833 | K53: 0.019898 | L53: 0.022891
C55: SBC % of Sales: | D55: % | E55: =+'Statements & Checks'!E52/'Income Statement'!E5 -> 0.0026176158 | F55: =+'Statements & Checks'!F52/'Income Statement'!F5 -> 0.0026926263 | G55: =+'Statements & Checks'!G52/'Income Statement'!G5 -> 0.0030585602 | H55: =AVERAGE(E55:G55) -> 0.0027896008 | I55: =+H55 -> 0.0027896008 | J55: =+I55 -> 0.0027896008 | K55: =+J55 -> 0.0027896008 | L55: =+K55 -> 0.0027896008
C57: Deferred Tax % of Tax: | D57: % | E57: =-'Statements & Checks'!E51/'Income Statement'!E26 -> 0.0083682008 | F57: =-'Statements & Checks'!F51/'Income Statement'!F26 -> 0.067985167 | G57: =-'Statements & Checks'!G51/'Income Statement'!G26 -> -0.013414634 | H57: =AVERAGE(E57:G57) -> 0.020979578 | I57: =+H57 -> 0.020979578 | J57: =+I57 -> 0.020979578 | K57: =+J57 -> 0.020979578 | L57: =+K57 -> 0.020979578
...

Sheet Income Statement
E2: =Drivers!$E$18 -> Actual | H2: =Drivers!$H$18 -> Forecast
B3: Profit & Loss Statement: | D3: =Drivers!$D$19 -> Basis: | E3: =Drivers!$E$19 -> 41639 | F3: =Drivers!$F$19 -> 42004 | G3: =Drivers!$G$19 -> 42369 | H3: =Drivers!$H$19 -> 42735 | I3: =Drivers!$I$19 -> 43100 | J3: =Drivers!$J$19 -> 43465 | K3: =Drivers!$K$19 -> 43830 | L3: =Drivers!$L$19 -> 44196
C5: Total Sales: | D5: $ M | E5: 14135 | F5: 14484 | G5: 13405
C7: Cost of Sales (COGS): | D7: $ M | E7: 8554 | F7: 8673 | G7: 7888
C9: Gross Income: | D9: $ M | E9: 5581 | F9: 5811 | G9: 5517
C11: Operating Costs:
C12: (+) SG&A Expense: | D12: $ M | E12: 2815 | F12: 2678 | G12: 2417
C13: (+) Intangible Amortization: | D13: $ M | E13: 250 | F13: 242 | G13: 231
C14: (+) Goodwill Impairment: | D14: $ M | E14: 2 | F14: 3 | G14: 2
C15: Total Operating Costs: | D15: $ M | E15: 3067 | F15: 2923 | G15: 2650
C17: Operating Profit (EBIT): | D17: $ M | E17: 2514 | F17: 2888 | G17: 2867
C18: EBIT Margin: | D18: % | E18: 0.17785638 | F18: 0.19939243 | G18: 0.21387542
C20: Non-Operating Items:
C21: (-) Interest Cost: | D21: $ M | E21: -239 | F21: -250 | G21: -226
C22: (+) Interest & Other Income: | D22: $ M | E22: 72 | F22: 61 | G22: 78
C23: Total Non-Operating: | D23: $ M | E23: -167 | F23: -189 | G23: -148
C25: Pre-Tax Profit: | D25: $ M | E25: 2347 | F25: 2699 | G25: 2719
C26: (-) Income Tax Provision: | D26: $ M | E26: -717 | F26: -809 | G26: -820
C27: Continuing Ops Income: | D27: $ M | E27: 1630 | F27: 1890 | G27: 1899
C29: (+) Discontinued Ops Income: | D29: $ M | E29: 49 | F29: 1056 | G29: 0
C31: Net Profit: | D31: $ M | E31: 1679 | F31: 2946 | G31: 1899

Sheet Statements & Checks
E2: =Drivers!$E$18 -> Actual | H2: =Drivers!$H$18 -> Forecast
B3: Statement of Financial Position: | D3: =Drivers!$D$19 -> Basis: | E3: =Drivers!$E$19 -> 41639 | F3: =Drivers!$F$19 -> 42004 | G3: =Drivers!$G$19 -> 42369 | H3: =Drivers!$H$19 -> 42735 | I3: =Drivers!$I$19 -> 43100 | J3: =Drivers!$J$19 -> 43465 | K3: =Drivers!$K$19 -> 43830 | L3: =Drivers!$L$19 -> 44196
B4: Asset Base:
C5: Short-Term Assets:
C6: Cash & Cash Equivalents: | D6: $ M | E6: 3618 | F6: 3990 | G6: 3090 | H6: =+H79 -> 3662.6386 | I6: =+I79 -> 1830.6725 | J6: =+J79 -> -80.897708 | K6: =+K79 -> -2167.3394 | L6: =+L79 -> -4213.9998
C7: Trade Receivables: | D7: $ M | E7: 2365 | F7: 2293 | G7: 2203 | H7: =+Drivers!H40/365*'Income Statement'!H5 -> 0 | I7: =+Drivers!I40/365*'Income Statement'!I5 -> 0 | J7: =+Drivers!J40/365*'Income Statement'!J5 -> 0 | K7: =+Drivers!K40/365*'Income Statement'!K5 -> 0 | L7: =+Drivers!L40/365*'Income Statement'!L5 -> 0
C8: Inventories: | D8: $ M | E8: 1247 | F8: 1180 | G8: 1086 | H8: =+Drivers!H41/365*'Income Statement'!H7 -> 0 | I8: =+Drivers!I41/365*'Income Statement'!I7 -> 0 | J8: =+Drivers!J41/365*'Income Statement'!J7 -> 0 | K8: =+Drivers!K41/365*'Income Statement'!K7 -> 0 | L8: =+Drivers!L41/365*'Income Statement'!L7 -> 0
C9: Prepaids & Other Current Assets: | D9: $ M | E9: 2586 | F9: 401 | G9: 341 | H9: =+Drivers!H44*'Income Statement'!H12 -> 0 | I9: =+Drivers!I44*'Income Statement'!I12 -> 0 | J9: =+Drivers!J44*'Income Statement'!J12 -> 0 | K9: =+Drivers!K44*'Income Statement'!K12 -> 0 | L9: =+Drivers!L44*'Income Statement'!L12 -> 0
C10: Total Short-Term Assets: | D10: $ M | E10: 9816 | F10: 7864 | G10: 6720 | H10: =SUM(H6:H9) -> 3662.6386 | I10: =SUM(I6:I9) -> 1830.6725 | J10: =SUM(J6:J9) -> -80.897708 | K10: =SUM(K6:K9) -> -2167.3394 | L10: =SUM(L6:L9) -> -4213.9998
C12: Long-Term Assets:
C13: Net Property & Equipment: | D13: $ M | E13: 1709 | F13: 1686 | G13: 1577 | H13: =+G13-H48-H64-H65 -> 1815 | I13: =+H13-I48-I64-I65 -> 2121 | J13: =+I13-J48-J64-J65 -> 2448 | K13: =+J13-K48-K64-K65 -> 2906 | L13: =+K13-L48-L64-L65 -> 3439
C14: Acquired Goodwill: | D14: $ M | E14: 4886 | F14: 4667 | G14: 4439 | H14: =+G14-H49 -> 4439 | I14: =+H14-I49 -> 4439 | J14: =+I14-J49 -> 4439 | K14: =+J14-K49 -> 4439 | L14: =+K14-L49 -> 4439
C15: Other Intangibles: | D15: $ M | E15: 1999 | F15: 1799 | G15: 1560 | H15: =+G15-H50 -> 1560 | I15: =+H15-I50 -> 1560 | J15: =+I15-J50 -> 1560 | K15: =+J15-K50 -> 1560 | L15: =+K15-L50 -> 1560
C16: Other LT Assets: | D16: $ M | E16: 1556 | F16: 1449 | G16: 1433 | H16: =+Drivers!H45*'Income Statement'!H5 -> 0 | I16: =+Drivers!I45*'Income Statement'!I5 -> 0 | J16: =+Drivers!J45*'Income Statement'!J5 -> 0 | K16: =+Drivers!K45*'Income Statement'!K5 -> 0 | L16: =+Drivers!L45*'Income Statement'!L5 -> 0
C17: Total Long-Term Assets: | D17: $ M | E17: 10150 | F17: 9601 | G17: 9009 | H17: =SUM(H13:H16) -> 7814 | I17: =SUM(I13:I16) -> 8120 | J17: =SUM(J13:J16) -> 8447 | K17: =SUM(K13:K16) -> 8905 | L17: =SUM(L13:L16) -> 9438
C19: Total Asset Base: | D19: $ M | E19: 19966 | F19: 17465 | G19: 15729 | H19: =+H10+H17 -> 11476.639 | I19: =+I10+I17 -> 9950.6725 | J19: =+J10+J17 -> 8366.1023 | K19: =+K10+K17 -> 6737.6606 | L19: =+L10+L17 -> 5224.0002
B21: Liabilities & Shareholders' Equity:
C22: Short-Term Liabilities:
C23: Trade Payables: | D23: $ M | E23: 634 | F23: 512 | G23: 449 | H23: =+Drivers!H42/365*'Income Statement'!H7 -> 0 | I23: =+Drivers!I42/365*'Income Statement'!I7 -> 0 | J23: =+Drivers!J42/365*'Income Statement'!J7 -> 0 | K23: =+Drivers!K42/365*'Income Statement'!K7 -> 0 | L23: =+Drivers!L42/365*'Income Statement'!L7 -> 0
C24: Accrued Liabilities: | D24: $ M | E24: 1272 | F24: 1287 | G24: 1136 | H24: =+Drivers!H46*'Income Statement'!H12 -> 0 | I24: =+Drivers!I46*'Income Statement'!I12 -> 0 | J24: =+Drivers!J46*'Income Statement'!J12 -> 0 | K24: =+Drivers!K46*'Income Statement'!K12 -> 0 | L24: =+Drivers!L46*'Income Statement'!L12 -> 0
C25: Other Short-Term Liabilities: | D25: $ M | E25: 577 | F25: 250 | G25: 257 | H25: =+Drivers!H48*'Income Statement'!H12 -> 0 | I25: =+Drivers!I48*'Income Statement'!I12 -> 0 | J25: =+Drivers!J48*'Income Statement'!J12 -> 0 | K25: =+Drivers!K48*'Income Statement'!K12 -> 0 | L25: =+Drivers!L48*'Income Statement'!L12 -> 0
C26: Total Short-Term Liabilities: | D26: $ M | E26: 2483 | F26: 2049 | G26: 1842 | H26: =SUM(H23:H25) -> 0 | I26: =SUM(I23:I25) -> 0 | J26: =SUM(J23:J25) -> 0 | K26: =SUM(K23:K25) -> 0 | L26: =SUM(L23:L25) -> 0
C28: Long-Term Liabilities:
C29: Long-Term Borrowings: | D29: $ M | E29: 6344 | F29: 7419 | G29: 7422 | H29: =+G29+H71 -> 6793.6386 | I29: =+H29+I71 -> 6068.6725 | J29: =+I29+J71 -> 5285.1023 | K29: =+J29+K71 -> 4457.6606 | L29: =+K29+L71 -> 3745.0002
C30: Deferred Tax Liabilities: | D30: $ M | E30: 507 | F30: 171 | G30: 256 | H30: =+G30+H51 -> 256 | I30: =+H30+I51 -> 256 | J30: =+I30+J51 -> 256 | K30: =+J30+K51 -> 256 | L30: =+K30+L51 -> 256
C31: Other LT Liabilities: | D31: $ M | E31: 923 | F31: 1002 | G31: 981 | H31: =+Drivers!H49*'Income Statement'!H12 -> 0 | I31: =+Drivers!I49*'Income Statement'!I12 -> 0 | J31: =+Drivers!J49*'Income Statement'!J12 -> 0 | K31: =+Drivers!K49*'Income Statement'!K12 -> 0 | L31: =+Drivers!L49*'Income Statement'!L12 -> 0
C32: Total Long-Term Liabilities: | D32: $ M | E32: 7774 | F32: 8592 | G32: 8659 | H32: =SUM(H29:H31) -> 7049.6386 | I32: =SUM(I29:I31) -> 6324.6725 | J32: =SUM(J29:J31) -> 5541.1023 | K32: =SUM(K29:K31) -> 4713.6606 | L32: =SUM(L29:L31) -> 4001.0002
C34: Total Obligations: | D34: $ M | E34: 10257 | F34: 10641 | G34: 10501 | H34: =+H26+H32 -> 7049.6386 | I34: =+I26+I32 -> 6324.6725 | J34: =+J26+J32 -> 5541.1023 | K34: =+K26+K32 -> 4713.6606 | L34: =+L26+L32 -> 4001.0002
C36: Shareholders' Equity: | D36: $ M | E36: 9709 | F36: 6824 | G36: 5228 | H36: =+G36+H46+H52+H53+H69+H70+H72+H75 -> 4427 | I36: =+H36+I46+I52+I53+I69+I70+I72+I75 -> 3626 | J36: =+I36+J46+J52+J53+J69+J70+J72+J75 -> 2825 | K36: =+J36+K46+K52+K53+K69+K70+K72+K75 -> 2024 | L36: =+K36+L46+L52+L53+L69+L70+L72+L75 -> 1223
C38: Total Funding: | D38: $ M | E38: 19966 | F38: 17465 | G38: 15729 | H38: =+H34+H36 -> 11476.639 | I38: =+I34+I36 -> 9950.6725 | J38: =+J34+J36 -> 8366.1023 | K38: =+K34+K36 -> 6737.6606 | L38: =+L34+L36 -> 5224.0002
C40: BS Check: | E40: =E19-E38 -> 0 | F40: =F19-F38 -> 0 | G40: =G19-G38 -> 0 | H40: =H19-H38 -> 0 | I40: =I19-I38 -> 0 | J40: =J19-J38 -> 0 | K40: =K19-K38 -> 0 | L40: =L19-L38 -> 0
E42: =Drivers!$E$18 -> Actual | H42: =Drivers!$H$18 -> Forecast
B43: Statement of Cash Flows: | D43: =Drivers!$D$19 -> Basis: | E43: =Drivers!$E$19 -> 41639 | F43: =Drivers!$F$19 -> 42004 | G43: =Drivers!$G$19 -> 42369 | H43: =Drivers!$H$19 -> 42735 | I43: =Drivers!$I$19 -> 43100 | J43: =Drivers!$J$19 -> 43465 | K43: =Drivers!$K$19 -> 43830 | L43: =Drivers!$L$19 -> 44196
B44: Operating Activities:
C46: Net Profit: | D46: $ M | E46: 1679 | F46: 2946 | G46: 1899 | H46: =+'Income Statement'!H31 -> 0 | I46: =+'Income Statement'!I31 -> 0 | J46: =+'Income Statement'!J31 -> 0 | K46: =+'Income Statement'!K31 -> 0 | L46: =+'Income Statement'!L31 -> 0
C47: Non-Cash Adjustments:
C48: (+) Depreciation Expense: | D48: $ M | E48: 299 | F48: 262 | G48: 244 | H48: =+'Income Statement'!H5*Drivers!H53 -> 0 | I48: =+'Income Statement'!I5*Drivers!I53 -> 0 | J48: =+'Income Statement'!J5*Drivers!J53 -> 0 | K48: =+'Income Statement'!K5*Drivers!K53 -> 0 | L48: =+'Income Statement'!L5*Drivers!L53 -> 0
C49: (+) Goodwill Impairment: | D49: $ M | E49: 2 | F49: 3 | G49: 2 | H49: =+'Income Statement'!H14 -> 0 | I49: =+'Income Statement'!I14 -> 0 | J49: =+'Income Statement'!J14 -> 0 | K49: =+'Income Statement'!K14 -> 0 | L49: =+'Income Statement'!L14 -> 0
C50: (+) Intangible Amortization: | D50: $ M | E50: 312 | F50: 242 | G50: 231 | H50: =+'Income Statement'!H13 -> 0 | I50: =+'Income Statement'!I13 -> 0 | J50: =+'Income Statement'!J13 -> 0 | K50: =+'Income Statement'!K13 -> 0 | L50: =+'Income Statement'!L13 -> 0
C51: (+/-) Deferred Tax: | D51: $ M | E51: 6 | F51: 55 | G51: -11 | H51: =-'Income Statement'!H26*Drivers!H57 -> 0 | I51: =-'Income Statement'!I26*Drivers!I57 -> 0 | J51: =-'Income Statement'!J26*Drivers!J57 -> 0 | K51: =-'Income Statement'!K26*Drivers!K57 -> 0 | L51: =-'Income Statement'!L26*Drivers!L57 -> 0
...
