Workbook

Sheet Google Drivers
B2: Google (Alphabet) — Operating Model Assumptions
B3: 3-Year Historical (2021-2023) | 5-Year Projections (2024-2028)
B5: Case selector
B6: Chosen case: | D6: Base
B8: Actuals | G8: Forecast
D9: 2021 | E9: 2022 | F9: 2023 | G9: 2024 | H9: 2025 | I9: 2026 | J9: 2027 | K9: 2028
B11: Revenue Assumptions — 1
B13: Growth rates — Revenue (%)
C14: Case | D14: 2021 | E14: 2022 | F14: 2023 | G14: 2024 | H14: 2025 | I14: 2026 | J14: 2027 | K14: 2028
B15: Google Search | C15: Base | G15: 0.085 | H15: 0.075 | I15: 0.065 | J15: 0.055 | K15: 0.05
C16: Bull | G16: 0.105 | H16: 0.095 | I16: 0.085 | J16: 0.075 | K16: 0.07
C17: Bear | G17: 0.06 | H17: 0.05 | I17: 0.04 | J17: 0.035 | K17: 0.03
B19: YouTube Ads | C19: Base | G19: 0.15 | H19: 0.13 | I19: 0.11 | J19: 0.1 | K19: 0.09
C20: Bull | G20: 0.18 | H20: 0.16 | I20: 0.14 | J20: 0.12 | K20: 0.11
C21: Bear | G21: 0.12 | H21: 0.1 | I21: 0.08 | J21: 0.07 | K21: 0.06
B23: Google Cloud | C23: Base | G23: 0.28 | H23: 0.25 | I23: 0.22 | J23: 0.2 | K23: 0.18
C24: Bull | G24: 0.32 | H24: 0.3 | I24: 0.27 | J24: 0.24 | K24: 0.22
C25: Bear | G25: 0.24 | H25: 0.2 | I25: 0.17 | J25: 0.15 | K25: 0.14
B27: Other Revenues | C27: Base | G27: 0.05 | H27: 0.045 | I27: 0.04 | J27: 0.035 | K27: 0.03
C28: Bull | G28: 0.07 | H28: 0.06 | I28: 0.055 | J28: 0.05 | K28: 0.045
C29: Bear | G29: 0.03 | H29: 0.025 | I29: 0.02 | J29: 0.015 | K29: 0.01
B31: Operating Expense Assumptions — 2
B33: Expenses — Operating (% of Revenue)
B35: R&D | C35: Base | D35: 0.151 | E35: 0.148 | F35: 0.145 | G35: 0.143 | H35: 0.14 | I35: 0.138 | J35: 0.135 | K35: 0.133
C36: Bull | D36: 0.151 | E36: 0.148 | F36: 0.145 | G36: 0.138 | H36: 0.135 | I36: 0.132 | J36: 0.13 | K36: 0.128
C37: Bear | D37: 0.151 | E37: 0.148 | F37: 0.145 | G37: 0.148 | H37: 0.145 | I37: 0.143 | J37: 0.14 | K37: 0.138
B39: S&M | C39: Base | D39: 0.115 | E39: 0.112 | F39: 0.108 | G39: 0.105 | H39: 0.103 | I39: 0.1 | J39: 0.098 | K39: 0.095
C40: Bull | D40: 0.115 | E40: 0.112 | F40: 0.108 | G40: 0.102 | H40: 0.1 | I40: 0.097 | J40: 0.095 | K40: 0.092
C41: Bear | D41: 0.115 | E41: 0.112 | F41: 0.108 | G41: 0.108 | H41: 0.106 | I41: 0.103 | J41: 0.101 | K41: 0.098
B43: G&A | C43: Base | D43: 0.068 | E43: 0.065 | F43: 0.063 | G43: 0.062 | H43: 0.06 | I43: 0.058 | J43: 0.057 | K43: 0.055
C44: Bull | D44: 0.068 | E44: 0.065 | F44: 0.063 | G44: 0.06 | H44: 0.058 | I44: 0.056 | J44: 0.055 | K44: 0.053
C45: Bear | D45: 0.068 | E45: 0.065 | F45: 0.063 | G45: 0.064 | H45: 0.062 | I45: 0.06 | J45: 0.059 | K45: 0.057
B47: SBC | C47: Base | D47: 0.092 | E47: 0.095 | F47: 0.098 | G47: 0.095 | H47: 0.093 | I47: 0.09 | J47: 0.088 | K47: 0.085
C48: Bull | D48: 0.092 | E48: 0.095 | F48: 0.098 | G48: 0.092 | H48: 0.09 | I48: 0.087 | J48: 0.085 | K48: 0.082
C49: Bear | D49: 0.092 | E49: 0.095 | F49: 0.098 | G49: 0.098 | H49: 0.096 | I49: 0.093 | J49: 0.091 | K49: 0.088
B51: Balance Sheet & Cash Flow Assumptions — 3
B53: Working Capital Metrics
B55: Days Sales Outstanding — DSO | C55: Base | D55: 48 | E55: 47 | F55: 46 | G55: 46 | H55: 45 | I55: 45 | J55: 44 | K55: 44
C56: Bull | D56: 48 | E56: 47 | F56: 46 | G56: 45 | H56: 44 | I56: 43 | J56: 42 | K56: 42
C57: Bear | D57: 48 | E57: 47 | F57: 46 | G57: 47 | H57: 47 | I57: 46 | J57: 46 | K57: 45
...

Sheet Google Model
B2: Google (Alphabet) — Income Statement
B3: Figures in $mm
B5: Chosen case: | D5: ='Google Drivers'!D6 -> Base
B7: Actuals | F7: Forecast
C8: 2021 | D8: 2022 | E8: 2023 | F8: 2024 | G8: 2025 | H8: 2026 | I8: 2027 | J8: 2028
B10: P&L statement
B12: Google Search | C12: 148951 | D12: 162450 | E12: 175033 | F12: =E12*(1+INDEX('Google Drivers'!G$15:G$17,MATCH($D$5,'Google Drivers'!$C$15:$C$17,0))) -> 189910.8 | G12: =F12*(1+INDEX('Google Drivers'!H$15:H$17,MATCH($D$5,'Google Drivers'!$C$15:$C$17,0))) -> 204154.12 | H12: =G12*(1+INDEX('Google Drivers'!I$15:I$17,MATCH($D$5,'Google Drivers'!$C$15:$C$17,0))) -> 217424.13 | I12: =H12*(1+INDEX('Google Drivers'!J$15:J$17,MATCH($D$5,'Google Drivers'!$C$15:$C$17,0))) -> 229382.46 | J12: =I12*(1+INDEX('Google Drivers'!K$15:K$17,MATCH($D$5,'Google Drivers'!$C$15:$C$17,0))) -> 240851.58
B13: YouTube Ads | C13: 28845 | D13: 29243 | E13: 31865 | F13: =E13*(1+INDEX('Google Drivers'!G$19:G$21,MATCH($D$5,'Google Drivers'!$C$19:$C$21,0))) -> 36644.75 | G13: =F13*(1+INDEX('Google Drivers'!H$19:H$21,MATCH($D$5,'Google Drivers'!$C$19:$C$21,0))) -> 41408.567 | H13: =G13*(1+INDEX('Google Drivers'!I$19:I$21,MATCH($D$5,'Google Drivers'!$C$19:$C$21,0))) -> 45963.51 | I13: =H13*(1+INDEX('Google Drivers'!J$19:J$21,MATCH($D$5,'Google Drivers'!$C$19:$C$21,0))) -> 50559.861 | J13: =I13*(1+INDEX('Google Drivers'!K$19:K$21,MATCH($D$5,'Google Drivers'!$C$19:$C$21,0))) -> 55110.248
B14: Google Cloud | C14: 13059 | D14: 19206 | E14: 26280 | F14: =E14*(1+INDEX('Google Drivers'!G$23:G$25,MATCH($D$5,'Google Drivers'!$C$23:$C$25,0))) -> 33638.4 | G14: =F14*(1+INDEX('Google Drivers'!H$23:H$25,MATCH($D$5,'Google Drivers'!$C$23:$C$25,0))) -> 42048 | H14: =G14*(1+INDEX('Google Drivers'!I$23:I$25,MATCH($D$5,'Google Drivers'!$C$23:$C$25,0))) -> 51298.56 | I14: =H14*(1+INDEX('Google Drivers'!J$23:J$25,MATCH($D$5,'Google Drivers'!$C$23:$C$25,0))) -> 61558.272 | J14: =I14*(1+INDEX('Google Drivers'!K$23:K$25,MATCH($D$5,'Google Drivers'!$C$23:$C$25,0))) -> 72638.761
B15: Other Revenues | C15: 28032 | D15: 29071 | E15: 30300 | F15: =E15*(1+INDEX('Google Drivers'!G$27:G$29,MATCH($D$5,'Google Drivers'!$C$27:$C$29,0))) -> 31815 | G15: =F15*(1+INDEX('Google Drivers'!H$27:H$29,MATCH($D$5,'Google Drivers'!$C$27:$C$29,0))) -> 33246.675 | H15: =G15*(1+INDEX('Google Drivers'!I$27:I$29,MATCH($D$5,'Google Drivers'!$C$27:$C$29,0))) -> 34576.542 | I15: =H15*(1+INDEX('Google Drivers'!J$27:J$29,MATCH($D$5,'Google Drivers'!$C$27:$C$29,0))) -> 35786.721 | J15: =I15*(1+INDEX('Google Drivers'!K$27:K$29,MATCH($D$5,'Google Drivers'!$C$27:$C$29,0))) -> 36860.323
B16: Revenue — Total | C16: =SUM(C12:C15) -> 218887 | D16: =SUM(D12:D15) -> 239970 | E16: =SUM(E12:E15) -> 263478 | F16: =SUM(F12:F15) -> 292008.95 | G16: =SUM(G12:G15) -> 320857.36 | H16: =SUM(H12:H15) -> 349262.74 | I16: =SUM(I12:I15) -> 377287.31 | J16: =SUM(J12:J15) -> 405460.92
B17: YoY Growth % | D17: =D16/C16-1 -> 0.096319105 | E17: =E16/D16-1 -> 0.097962245 | F17: =F16/E16-1 -> 0.10828591 | G17: =G16/F16-1 -> 0.09879287 | H17: =H16/G16-1 -> 0.088529642 | I17: =I16/H16-1 -> 0.080239217 | J17: =J16/I16-1 -> 0.074674128
B19: Cost of sales | C19: =C16*(1-C21) -> 99593.585 | D19: =D16*(1-D21) -> 108466.44 | E19: =E16*(1-E21) -> 118565.1 | F19: =F16*(1-F21) -> 130820.01 | G19: =G16*(1-G21) -> 143102.38 | H19: =H16*(1-H21) -> 155072.66 | I19: =I16*(1-I21) -> 166760.99 | J19: =J16*(1-J21) -> 178402.8
B20: Profit — Gross | C20: =C16-C19 -> 119293.41 | D20: =D16-D19 -> 131503.56 | E20: =E16-E19 -> 144912.9 | F20: =F16-F19 -> 161188.94 | G20: =G16-G19 -> 177754.98 | H20: =H16-H19 -> 194190.09 | I20: =I16-I19 -> 210526.32 | J20: =J16-J19 -> 227058.11
B21: Gross Margin (%) | C21: 0.545 | D21: 0.548 | E21: 0.55 | F21: 0.552 | G21: 0.554 | H21: 0.556 | I21: 0.558 | J21: 0.56
B23: R&D | C23: =C16*INDEX('Google Drivers'!D$35:D$37,MATCH($D$5,'Google Drivers'!$C$35:$C$37,0)) -> 33051.937 | D23: =D16*INDEX('Google Drivers'!E$35:E$37,MATCH($D$5,'Google Drivers'!$C$35:$C$37,0)) -> 35515.56 | E23: =E16*INDEX('Google Drivers'!F$35:F$37,MATCH($D$5,'Google Drivers'!$C$35:$C$37,0)) -> 38204.31 | F23: =F16*INDEX('Google Drivers'!G$35:G$37,MATCH($D$5,'Google Drivers'!$C$35:$C$37,0)) -> 41757.281 | G23: =G16*INDEX('Google Drivers'!H$35:H$37,MATCH($D$5,'Google Drivers'!$C$35:$C$37,0)) -> 44920.03 | H23: =H16*INDEX('Google Drivers'!I$35:I$37,MATCH($D$5,'Google Drivers'!$C$35:$C$37,0)) -> 48198.259 | I23: =I16*INDEX('Google Drivers'!J$35:J$37,MATCH($D$5,'Google Drivers'!$C$35:$C$37,0)) -> 50933.787 | J23: =J16*INDEX('Google Drivers'!K$35:K$37,MATCH($D$5,'Google Drivers'!$C$35:$C$37,0)) -> 53926.302
B24: S&M | C24: =C16*INDEX('Google Drivers'!D$39:D$41,MATCH($D$5,'Google Drivers'!$C$39:$C$41,0)) -> 25172.005 | D24: =D16*INDEX('Google Drivers'!E$39:E$41,MATCH($D$5,'Google Drivers'!$C$39:$C$41,0)) -> 26876.64 | E24: =E16*INDEX('Google Drivers'!F$39:F$41,MATCH($D$5,'Google Drivers'!$C$39:$C$41,0)) -> 28455.624 | F24: =F16*INDEX('Google Drivers'!G$39:G$41,MATCH($D$5,'Google Drivers'!$C$39:$C$41,0)) -> 30660.94 | G24: =G16*INDEX('Google Drivers'!H$39:H$41,MATCH($D$5,'Google Drivers'!$C$39:$C$41,0)) -> 33048.308 | H24: =H16*INDEX('Google Drivers'!I$39:I$41,MATCH($D$5,'Google Drivers'!$C$39:$C$41,0)) -> 34926.274 | I24: =I16*INDEX('Google Drivers'!J$39:J$41,MATCH($D$5,'Google Drivers'!$C$39:$C$41,0)) -> 36974.157 | J24: =J16*INDEX('Google Drivers'!K$39:K$41,MATCH($D$5,'Google Drivers'!$C$39:$C$41,0)) -> 38518.787
B25: G&A | C25: =C16*INDEX('Google Drivers'!D$43:D$45,MATCH($D$5,'Google Drivers'!$C$43:$C$45,0)) -> 14884.316 | D25: =D16*INDEX('Google Drivers'!E$43:E$45,MATCH($D$5,'Google Drivers'!$C$43:$C$45,0)) -> 15598.05 | E25: =E16*INDEX('Google Drivers'!F$43:F$45,MATCH($D$5,'Google Drivers'!$C$43:$C$45,0)) -> 16599.114 | F25: =F16*INDEX('Google Drivers'!G$43:G$45,MATCH($D$5,'Google Drivers'!$C$43:$C$45,0)) -> 18104.555 | G25: =G16*INDEX('Google Drivers'!H$43:H$45,MATCH($D$5,'Google Drivers'!$C$43:$C$45,0)) -> 19251.441 | H25: =H16*INDEX('Google Drivers'!I$43:I$45,MATCH($D$5,'Google Drivers'!$C$43:$C$45,0)) -> 20257.239 | I25: =I16*INDEX('Google Drivers'!J$43:J$45,MATCH($D$5,'Google Drivers'!$C$43:$C$45,0)) -> 21505.377 | J25: =J16*INDEX('Google Drivers'!K$43:K$45,MATCH($D$5,'Google Drivers'!$C$43:$C$45,0)) -> 22300.35
B26: SBC | C26: =C16*INDEX('Google Drivers'!D$47:D$49,MATCH($D$5,'Google Drivers'!$C$47:$C$49,0)) -> 20137.604 | D26: =D16*INDEX('Google Drivers'!E$47:E$49,MATCH($D$5,'Google Drivers'!$C$47:$C$49,0)) -> 22797.15 | E26: =E16*INDEX('Google Drivers'!F$47:F$49,MATCH($D$5,'Google Drivers'!$C$47:$C$49,0)) -> 25820.844 | F26: =F16*INDEX('Google Drivers'!G$47:G$49,MATCH($D$5,'Google Drivers'!$C$47:$C$49,0)) -> 27740.851 | G26: =G16*INDEX('Google Drivers'!H$47:H$49,MATCH($D$5,'Google Drivers'!$C$47:$C$49,0)) -> 29839.734 | H26: =H16*INDEX('Google Drivers'!I$47:I$49,MATCH($D$5,'Google Drivers'!$C$47:$C$49,0)) -> 31433.647 | I26: =I16*INDEX('Google Drivers'!J$47:J$49,MATCH($D$5,'Google Drivers'!$C$47:$C$49,0)) -> 33201.284 | J26: =J16*INDEX('Google Drivers'!K$47:K$49,MATCH($D$5,'Google Drivers'!$C$47:$C$49,0)) -> 34464.178
B27: Operating Expenses — Total | C27: =SUM(C23:C26) -> 93245.862 | D27: =SUM(D23:D26) -> 100787.4 | E27: =SUM(E23:E26) -> 109079.89 | F27: =SUM(F23:F26) -> 118263.63 | G27: =SUM(G23:G26) -> 127059.51 | H27: =SUM(H23:H26) -> 134815.42 | I27: =SUM(I23:I26) -> 142614.6 | J27: =SUM(J23:J26) -> 149209.62
B29: EBIT / Operating Income | C29: =C20-C27 -> 26047.553 | D29: =D20-D27 -> 30716.16 | E29: =E20-E27 -> 35833.008 | F29: =F20-F27 -> 42925.316 | G29: =G20-G27 -> 50695.463 | H29: =H20-H27 -> 59374.667 | I29: =I20-I27 -> 67911.717 | J29: =J20-J27 -> 77848.496
B30: Operating Margin (%) | C30: =C29/C16 -> 0.119 | D30: =D29/D16 -> 0.128 | E30: =E29/E16 -> 0.136 | F30: =F29/F16 -> 0.147 | G30: =G29/G16 -> 0.158 | H30: =H29/H16 -> 0.17 | I30: =I29/I16 -> 0.18 | J30: =J29/J16 -> 0.192
B32: Interest (Expense) / Income | C32: =(C$51*INDEX('Google Drivers'!D$88:D$90,MATCH($D$5,'Google Drivers'!$C$88:$C$90,0)))-(C73*INDEX('Google Drivers'!D$92:D$94,MATCH($D$5,'Google Drivers'!$C$92:$C$94,0))) -> 0 | D32: =(D$51*INDEX('Google Drivers'!E$88:E$90,MATCH($D$5,'Google Drivers'!$C$88:$C$90,0)))-(D73*INDEX('Google Drivers'!E$92:E$94,MATCH($D$5,'Google Drivers'!$C$92:$C$94,0))) -> 972.47681 | E32: =(E$51*INDEX('Google Drivers'!F$88:F$90,MATCH($D$5,'Google Drivers'!$C$88:$C$90,0)))-(E73*INDEX('Google Drivers'!F$92:F$94,MATCH($D$5,'Google Drivers'!$C$92:$C$94,0))) -> 2137.5582 | F32: =(F$51*INDEX('Google Drivers'!G$88:G$90,MATCH($D$5,'Google Drivers'!$C$88:$C$90,0)))-(F73*INDEX('Google Drivers'!G$92:G$94,MATCH($D$5,'Google Drivers'!$C$92:$C$94,0))) -> 3647.2704 | G32: =(G$51*INDEX('Google Drivers'!H$88:H$90,MATCH($D$5,'Google Drivers'!$C$88:$C$90,0)))-(G73*INDEX('Google Drivers'!H$92:H$94,MATCH($D$5,'Google Drivers'!$C$92:$C$94,0))) -> 3628.5766 | H32: =(H$51*INDEX('Google Drivers'!I$88:I$90,MATCH($D$5,'Google Drivers'!$C$88:$C$90,0)))-(H73*INDEX('Google Drivers'!I$92:I$94,MATCH($D$5,'Google Drivers'!$C$92:$C$94,0))) -> 3565.6401 | I32: =(I$51*INDEX('Google Drivers'!J$88:J$90,MATCH($D$5,'Google Drivers'!$C$88:$C$90,0)))-(I73*INDEX('Google Drivers'!J$92:J$94,MATCH($D$5,'Google Drivers'!$C$92:$C$94,0))) -> 4272.5338 | J32: =(J$51*INDEX('Google Drivers'!K$88:K$90,MATCH($D$5,'Google Drivers'!$C$88:$C$90,0)))-(J73*INDEX('Google Drivers'!K$92:K$94,MATCH($D$5,'Google Drivers'!$C$92:$C$94,0))) -> 4000.4265
B34: Pre-tax Income | C34: =C29+C32 -> 26047.553 | D34: =D29+D32 -> 31688.637 | E34: =E29+E32 -> 37970.566 | F34: =F29+F32 -> 46572.587 | G34: =G29+G32 -> 54324.039 | H34: =H29+H32 -> 62940.307 | I34: =I29+I32 -> 72184.25 | J34: =J29+J32 -> 81848.922
B35: Tax Expense / Provision | C35: =C34*INDEX('Google Drivers'!D$81:D$83,MATCH($D$5,'Google Drivers'!$C$81:$C$83,0)) -> 4219.7036 | D35: =D34*INDEX('Google Drivers'!E$81:E$83,MATCH($D$5,'Google Drivers'!$C$81:$C$83,0)) -> 5070.1819 | E35: =E34*INDEX('Google Drivers'!F$81:F$83,MATCH($D$5,'Google Drivers'!$C$81:$C$83,0)) -> 5999.3495 | F35: =F34*INDEX('Google Drivers'!G$81:G$83,MATCH($D$5,'Google Drivers'!$C$81:$C$83,0)) -> 7684.4768 | G35: =G34*INDEX('Google Drivers'!H$81:H$83,MATCH($D$5,'Google Drivers'!$C$81:$C$83,0)) -> 9235.0866 | H35: =H34*INDEX('Google Drivers'!I$81:I$83,MATCH($D$5,'Google Drivers'!$C$81:$C$83,0)) -> 11014.554 | I35: =I34*INDEX('Google Drivers'!J$81:J$83,MATCH($D$5,'Google Drivers'!$C$81:$C$83,0)) -> 12993.165 | J35: =J34*INDEX('Google Drivers'!K$81:K$83,MATCH($D$5,'Google Drivers'!$C$81:$C$83,0)) -> 15142.051
B37: Net income | C37: =C34-C35 -> 21827.849 | D37: =D34-D35 -> 26618.455 | E37: =E34-E35 -> 31971.217 | F37: =F34-F35 -> 38888.11 | G37: =G34-G35 -> 45088.952 | H37: =H34-H35 -> 51925.753 | I37: =I34-I35 -> 59191.085 | J37: =J34-J35 -> 66706.872
B38: Net Margin (%) | C38: =C37/C16 -> 0.099722 | D38: =D37/D16 -> 0.11092409 | E38: =E37/E16 -> 0.12134302 | F38: =F37/F16 -> 0.13317437 | G38: =G37/G16 -> 0.14052647 | H38: =H37/H16 -> 0.14867246 | I38: =I37/I16 -> 0.15688597 | J38: =J37/J16 -> 0.16452109
B40: EPS calculation
B42: Basic Shares — Outstanding | C42: 13000 | D42: 12800 | E42: 12600 | F42: 12400 | G42: 12200 | H42: 12000 | I42: 11800 | J42: 11600
B43: EPS — Basic | C43: =C37/C42 -> 1.6790653 | D43: =D37/D42 -> 2.0795668 | E43: =E37/E42 -> 2.5373982 | F43: =F37/F42 -> 3.1361379 | G43: =G37/G42 -> 3.6958158 | H43: =H37/H42 -> 4.3271461 | I43: =I37/I42 -> 5.0161937 | J43: =J37/J42 -> 5.7505924
B46: Balance sheet schedule
B48: Assets section
B50: Assets — Current
B51: Cash and equivalents | C51: 90000 | D51: =D$108 -> 97498.454 | E51: =E$108 -> 106302.33 | F51: =F$108 -> 120279.15 | G51: =G$108 -> 136952.55 | H51: =H$108 -> 158725.6 | I51: =I$108 -> 184101.35 | J51: =J$108 -> 215771.32
B52: Receivables | C52: =C$16*INDEX('Google Drivers'!D$55:D$57,MATCH($D$5,'Google Drivers'!$C$55:$C$57,0))/365 -> 28785.14 | D52: =D$16*INDEX('Google Drivers'!E$55:E$57,MATCH($D$5,'Google Drivers'!$C$55:$C$57,0))/365 -> 30900.247 | E52: =E$16*INDEX('Google Drivers'!F$55:F$57,MATCH($D$5,'Google Drivers'!$C$55:$C$57,0))/365 -> 33205.447 | F52: =F$16*INDEX('Google Drivers'!G$55:G$57,MATCH($D$5,'Google Drivers'!$C$55:$C$57,0))/365 -> 36801.129 | G52: =G$16*INDEX('Google Drivers'!H$55:H$57,MATCH($D$5,'Google Drivers'!$C$55:$C$57,0))/365 -> 39557.756 | H52: =H$16*INDEX('Google Drivers'!I$55:I$57,MATCH($D$5,'Google Drivers'!$C$55:$C$57,0))/365 -> 43059.79 | I52: =I$16*INDEX('Google Drivers'!J$55:J$57,MATCH($D$5,'Google Drivers'!$C$55:$C$57,0))/365 -> 45481.21 | J52: =J$16*INDEX('Google Drivers'!K$55:K$57,MATCH($D$5,'Google Drivers'!$C$55:$C$57,0))/365 -> 48877.48
B53: Other current assets | C53: 8500 | D53: =C53*(1+'Google Drivers'!E$63) -> 9000 | E53: =D53*(1+'Google Drivers'!F$63) -> 9500 | F53: =E53*(1+'Google Drivers'!G$63) -> 9975 | G53: =F53*(1+'Google Drivers'!H$63) -> 10473.75 | H53: =G53*(1+'Google Drivers'!I$63) -> 10997.438 | I53: =H53*(1+'Google Drivers'!J$63) -> 11547.309 | J53: =I53*(1+'Google Drivers'!K$63) -> 12124.675
B54: Current Assets — Total | C54: =SUM(C51:C53) -> 127285.14 | D54: =SUM(D51:D53) -> 137398.7 | E54: =SUM(E51:E53) -> 149007.77 | F54: =SUM(F51:F53) -> 167055.28 | G54: =SUM(G51:G53) -> 186984.06 | H54: =SUM(H51:H53) -> 212782.83 | I54: =SUM(I51:I53) -> 241129.87 | J54: =SUM(J51:J53) -> 276773.48
B56: Assets — Non-current
B57: PP&E (Gross) | C57: 80000 | D57: =C57+D97 -> 111676.04 | E57: =D57+E97 -> 148562.96 | F57: =E57+F97 -> 187984.17 | G57: =F57+G97 -> 229695.63 | H57: =G57+H97 -> 273353.47 | I57: =H57+I97 -> 318627.95 | J57: =I57+J97 -> 365255.95
B58: Less: Accumulated depreciation | C58: 25000 | D58: =C58+D89 -> 44152.613 | E58: =D58+E89 -> 66325.841 | F58: =E58+F89 -> 92146.685 | G58: =F58+G89 -> 119741.53 | H58: =G58+H89 -> 148939.55 | I58: =H58+I89 -> 179500.04 | J58: =I58+J89 -> 211192.17
...

Sheet Meta Drivers
B2: Meta Platforms — Operating Model Assumptions
B3: 3-Year Historical (2021-2023) | 5-Year Projections (2024-2028)
B5: Case selector
B6: Chosen case: | D6: Base
B8: Actuals | G8: Forecast
D9: 2021 | E9: 2022 | F9: 2023 | G9: 2024 | H9: 2025 | I9: 2026 | J9: 2027 | K9: 2028
B11: Revenue Assumptions — 1
B13: Growth rates — Revenue (%)
C14: Case | D14: 2021 | E14: 2022 | F14: 2023 | G14: 2024 | H14: 2025 | I14: 2026 | J14: 2027 | K14: 2028
B15: Family of Apps — FoA | C15: Base | G15: 0.12 | H15: 0.1 | I15: 0.085 | J15: 0.075 | K15: 0.07
B16: Growth rate | C16: Bull | G16: 0.14 | H16: 0.12 | I16: 0.105 | J16: 0.095 | K16: 0.09
C17: Bear | G17: 0.1 | H17: 0.08 | I17: 0.065 | J17: 0.055 | K17: 0.05
B19: Reality Labs | C19: Base | G19: 0.25 | H19: 0.35 | I19: 0.45 | J19: 0.4 | K19: 0.35
B20: % of total revenue | C20: Bull | G20: 0.3 | H20: 0.45 | I20: 0.55 | J20: 0.5 | K20: 0.45 | M20: 0.005
C21: Bear | G21: 0.2 | H21: 0.25 | I21: 0.35 | J21: 0.3 | K21: 0.25 | M21: 0.005
B24: User Growth Metrics
B26: DAU Growth — % | C26: Base | G26: 0.03 | H26: 0.025 | I26: 0.02 | J26: 0.015 | K26: 0.01
C27: Bull | G27: 0.04 | H27: 0.035 | I27: 0.03 | J27: 0.025 | K27: 0.02
C28: Bear | G28: 0.02 | H28: 0.015 | I28: 0.01 | J28: 0.005 | K28: 0
B30: ARPU Growth — % | C30: Base | G30: 0.085 | H30: 0.07 | I30: 0.06 | J30: 0.055 | K30: 0.05
C31: Bull | G31: 0.1 | H31: 0.085 | I31: 0.075 | J31: 0.07 | K31: 0.065
C32: Bear | G32: 0.07 | H32: 0.055 | I32: 0.045 | J32: 0.04 | K32: 0.035
B34: Operating Expense Assumptions — 2
B36: Expenses — Operating (% of Revenue)
B38: R&D | C38: Base | D38: 0.255 | E38: 0.27 | F38: 0.29 | G38: 0.285 | H38: 0.28 | I38: 0.275 | J38: 0.27 | K38: 0.265
C39: Bull | D39: 0.255 | E39: 0.27 | F39: 0.29 | G39: 0.28 | H39: 0.275 | I39: 0.27 | J39: 0.265 | K39: 0.26
C40: Bear | D40: 0.255 | E40: 0.27 | F40: 0.29 | G40: 0.29 | H40: 0.285 | I40: 0.28 | J40: 0.275 | K40: 0.27
B42: S&M | C42: Base | D42: 0.118 | E42: 0.125 | F42: 0.13 | G42: 0.125 | H42: 0.12 | I42: 0.115 | J42: 0.11 | K42: 0.105
C43: Bull | D43: 0.118 | E43: 0.125 | F43: 0.13 | G43: 0.12 | H43: 0.115 | I43: 0.11 | J43: 0.105 | K43: 0.1
C44: Bear | D44: 0.118 | E44: 0.125 | F44: 0.13 | G44: 0.13 | H44: 0.125 | I44: 0.12 | J44: 0.115 | K44: 0.11
B46: G&A | C46: Base | D46: 0.102 | E46: 0.108 | F46: 0.115 | G46: 0.11 | H46: 0.105 | I46: 0.1 | J46: 0.095 | K46: 0.09
C47: Bull | D47: 0.102 | E47: 0.108 | F47: 0.115 | G47: 0.105 | H47: 0.1 | I47: 0.095 | J47: 0.09 | K47: 0.085
C48: Bear | D48: 0.102 | E48: 0.108 | F48: 0.115 | G48: 0.115 | H48: 0.11 | I48: 0.105 | J48: 0.1 | K48: 0.095
B50: SBC | C50: Base | D50: 0.085 | E50: 0.102 | F50: 0.118 | G50: 0.11 | H50: 0.105 | I50: 0.1 | J50: 0.095 | K50: 0.09
C51: Bull | D51: 0.085 | E51: 0.102 | F51: 0.118 | G51: 0.105 | H51: 0.1 | I51: 0.095 | J51: 0.09 | K51: 0.085
C52: Bear | D52: 0.085 | E52: 0.102 | F52: 0.118 | G52: 0.115 | H52: 0.11 | I52: 0.105 | J52: 0.1 | K52: 0.095
B54: Reality Labs Operating Margin
B56: Operating Margin — % | C56: Base | D56: -3.5 | E56: -3 | F56: -2.5 | G56: -2 | H56: -1.5 | I56: -1 | J56: -0.75 | K56: -0.5
C57: Bull | D57: -3.5 | E57: -3 | F57: -2.5 | G57: -1.75 | H57: -1.25 | I57: -0.75 | J57: -0.5 | K57: -0.25
C58: Bear | D58: -3.5 | E58: -3 | F58: -2.5 | G58: -2.25 | H58: -1.75 | I58: -1.25 | J58: -1 | K58: -0.75
...

Sheet Meta Model
B2: Meta Platforms — Income Statement
B3: Figures in $mm
B5: Chosen case: | D5: ='Meta Drivers'!D6 -> Base
B7: Actuals | F7: Forecast
C8: 2021 | D8: 2022 | E8: 2023 | F8: 2024 | G8: 2025 | H8: 2026 | I8: 2027 | J8: 2028
B10: P&L statement
B12: Family of Apps | C12: 115655 | D12: 114450 | E12: 133008 | F12: =E12*(1+INDEX('Meta Drivers'!G$15:G$17,MATCH($D$5,'Meta Drivers'!$C$15:$C$17,0))) -> 148968.96 | G12: =F12*(1+INDEX('Meta Drivers'!H$15:H$17,MATCH($D$5,'Meta Drivers'!$C$15:$C$17,0))) -> 163865.86 | H12: =G12*(1+INDEX('Meta Drivers'!I$15:I$17,MATCH($D$5,'Meta Drivers'!$C$15:$C$17,0))) -> 177794.45 | I12: =H12*(1+INDEX('Meta Drivers'!J$15:J$17,MATCH($D$5,'Meta Drivers'!$C$15:$C$17,0))) -> 191129.04 | J12: =I12*(1+INDEX('Meta Drivers'!K$15:K$17,MATCH($D$5,'Meta Drivers'!$C$15:$C$17,0))) -> 204508.07
B13: Reality Labs | C13: 2274 | D13: 2159 | E13: 1896 | F13: =E13*(1+INDEX('Meta Drivers'!G$19:G$21,MATCH($D$5,'Meta Drivers'!$C$19:$C$21,0))) -> 2370 | G13: =F13*(1+INDEX('Meta Drivers'!H$19:H$21,MATCH($D$5,'Meta Drivers'!$C$19:$C$21,0))) -> 3199.5 | H13: =G13*(1+INDEX('Meta Drivers'!I$19:I$21,MATCH($D$5,'Meta Drivers'!$C$19:$C$21,0))) -> 4639.275 | I13: =H13*(1+INDEX('Meta Drivers'!J$19:J$21,MATCH($D$5,'Meta Drivers'!$C$19:$C$21,0))) -> 6494.985 | J13: =I13*(1+INDEX('Meta Drivers'!K$19:K$21,MATCH($D$5,'Meta Drivers'!$C$19:$C$21,0))) -> 8768.2297
B14: Revenue — Total | C14: =SUM(C12:C13) -> 117929 | D14: =SUM(D12:D13) -> 116609 | E14: =SUM(E12:E13) -> 134904 | F14: =SUM(F12:F13) -> 151338.96 | G14: =SUM(G12:G13) -> 167065.36 | H14: =SUM(H12:H13) -> 182433.73 | I14: =SUM(I12:I13) -> 197624.02 | J14: =SUM(J12:J13) -> 213276.3
B15: YoY Growth % | D15: =D14/C14-1 -> -0.011193176 | E15: =E14/D14-1 -> 0.15689184 | F15: =F14/E14-1 -> 0.12182708 | G15: =G14/F14-1 -> 0.10391505 | H15: =H14/G14-1 -> 0.091990184 | I15: =I14/H14-1 -> 0.083264724 | J15: =J14/I14-1 -> 0.079202301
B17: Cost of sales | C17: =C14*(1-C19) -> 23349.942 | D17: =D14*(1-D19) -> 23555.018 | E17: =E14*(1-E19) -> 27655.32 | F17: =F14*(1-F19) -> 30721.809 | G17: =G14*(1-G19) -> 33580.137 | H17: =H14*(1-H19) -> 36304.312 | I17: =I14*(1-I19) -> 38931.932 | J17: =J14*(1-J19) -> 41588.879
B18: Profit — Gross | C18: =C14-C17 -> 94579.058 | D18: =D14-D17 -> 93053.982 | E18: =E14-E17 -> 107248.68 | F18: =F14-F17 -> 120617.15 | G18: =G14-G17 -> 133485.22 | H18: =H14-H17 -> 146129.42 | I18: =I14-I17 -> 158692.09 | J18: =J14-J17 -> 171687.42
B19: Gross Margin (%) | C19: 0.802 | D19: 0.798 | E19: 0.795 | F19: 0.797 | G19: 0.799 | H19: 0.801 | I19: 0.803 | J19: 0.805
B21: R&D | C21: =C14*INDEX('Meta Drivers'!D$38:D$40,MATCH($D$5,'Meta Drivers'!$C$38:$C$40,0)) -> 30071.895 | D21: =D14*INDEX('Meta Drivers'!E$38:E$40,MATCH($D$5,'Meta Drivers'!$C$38:$C$40,0)) -> 31484.43 | E21: =E14*INDEX('Meta Drivers'!F$38:F$40,MATCH($D$5,'Meta Drivers'!$C$38:$C$40,0)) -> 39122.16 | F21: =F14*INDEX('Meta Drivers'!G$38:G$40,MATCH($D$5,'Meta Drivers'!$C$38:$C$40,0)) -> 43131.604 | G21: =G14*INDEX('Meta Drivers'!H$38:H$40,MATCH($D$5,'Meta Drivers'!$C$38:$C$40,0)) -> 46778.3 | H21: =H14*INDEX('Meta Drivers'!I$38:I$40,MATCH($D$5,'Meta Drivers'!$C$38:$C$40,0)) -> 50169.275 | I21: =I14*INDEX('Meta Drivers'!J$38:J$40,MATCH($D$5,'Meta Drivers'!$C$38:$C$40,0)) -> 53358.486 | J21: =J14*INDEX('Meta Drivers'!K$38:K$40,MATCH($D$5,'Meta Drivers'!$C$38:$C$40,0)) -> 56518.22
B22: S&M | C22: =C14*INDEX('Meta Drivers'!D$42:D$44,MATCH($D$5,'Meta Drivers'!$C$42:$C$44,0)) -> 13915.622 | D22: =D14*INDEX('Meta Drivers'!E$42:E$44,MATCH($D$5,'Meta Drivers'!$C$42:$C$44,0)) -> 14576.125 | E22: =E14*INDEX('Meta Drivers'!F$42:F$44,MATCH($D$5,'Meta Drivers'!$C$42:$C$44,0)) -> 17537.52 | F22: =F14*INDEX('Meta Drivers'!G$42:G$44,MATCH($D$5,'Meta Drivers'!$C$42:$C$44,0)) -> 18917.37 | G22: =G14*INDEX('Meta Drivers'!H$42:H$44,MATCH($D$5,'Meta Drivers'!$C$42:$C$44,0)) -> 20047.843 | H22: =H14*INDEX('Meta Drivers'!I$42:I$44,MATCH($D$5,'Meta Drivers'!$C$42:$C$44,0)) -> 20979.879 | I22: =I14*INDEX('Meta Drivers'!J$42:J$44,MATCH($D$5,'Meta Drivers'!$C$42:$C$44,0)) -> 21738.643 | J22: =J14*INDEX('Meta Drivers'!K$42:K$44,MATCH($D$5,'Meta Drivers'!$C$42:$C$44,0)) -> 22394.012
B23: G&A | C23: =C14*INDEX('Meta Drivers'!D$46:D$48,MATCH($D$5,'Meta Drivers'!$C$46:$C$48,0)) -> 12028.758 | D23: =D14*INDEX('Meta Drivers'!E$46:E$48,MATCH($D$5,'Meta Drivers'!$C$46:$C$48,0)) -> 12593.772 | E23: =E14*INDEX('Meta Drivers'!F$46:F$48,MATCH($D$5,'Meta Drivers'!$C$46:$C$48,0)) -> 15513.96 | F23: =F14*INDEX('Meta Drivers'!G$46:G$48,MATCH($D$5,'Meta Drivers'!$C$46:$C$48,0)) -> 16647.286 | G23: =G14*INDEX('Meta Drivers'!H$46:H$48,MATCH($D$5,'Meta Drivers'!$C$46:$C$48,0)) -> 17541.862 | H23: =H14*INDEX('Meta Drivers'!I$46:I$48,MATCH($D$5,'Meta Drivers'!$C$46:$C$48,0)) -> 18243.373 | I23: =I14*INDEX('Meta Drivers'!J$46:J$48,MATCH($D$5,'Meta Drivers'!$C$46:$C$48,0)) -> 18774.282 | J23: =J14*INDEX('Meta Drivers'!K$46:K$48,MATCH($D$5,'Meta Drivers'!$C$46:$C$48,0)) -> 19194.867
B24: SBC | C24: =C14*INDEX('Meta Drivers'!D$50:D$52,MATCH($D$5,'Meta Drivers'!$C$50:$C$52,0)) -> 10023.965 | D24: =D14*INDEX('Meta Drivers'!E$50:E$52,MATCH($D$5,'Meta Drivers'!$C$50:$C$52,0)) -> 11894.118 | E24: =E14*INDEX('Meta Drivers'!F$50:F$52,MATCH($D$5,'Meta Drivers'!$C$50:$C$52,0)) -> 15918.672 | F24: =F14*INDEX('Meta Drivers'!G$50:G$52,MATCH($D$5,'Meta Drivers'!$C$50:$C$52,0)) -> 16647.286 | G24: =G14*INDEX('Meta Drivers'!H$50:H$52,MATCH($D$5,'Meta Drivers'!$C$50:$C$52,0)) -> 17541.862 | H24: =H14*INDEX('Meta Drivers'!I$50:I$52,MATCH($D$5,'Meta Drivers'!$C$50:$C$52,0)) -> 18243.373 | I24: =I14*INDEX('Meta Drivers'!J$50:J$52,MATCH($D$5,'Meta Drivers'!$C$50:$C$52,0)) -> 18774.282 | J24: =J14*INDEX('Meta Drivers'!K$50:K$52,MATCH($D$5,'Meta Drivers'!$C$50:$C$52,0)) -> 19194.867
B25: Operating Expenses — Total | C25: =SUM(C21:C24) -> 66040.24 | D25: =SUM(D21:D24) -> 70548.445 | E25: =SUM(E21:E24) -> 88092.312 | F25: =SUM(F21:F24) -> 95343.545 | G25: =SUM(G21:G24) -> 101909.87 | H25: =SUM(H21:H24) -> 107635.9 | I25: =SUM(I21:I24) -> 112645.69 | J25: =SUM(J21:J24) -> 117301.97
B27: EBIT / Operating Income | C27: =C18-C25 -> 28538.818 | D27: =D18-D25 -> 22505.537 | E27: =E18-E25 -> 19156.368 | F27: =F18-F25 -> 25273.606 | G27: =G18-G25 -> 31575.352 | H27: =H18-H25 -> 38493.517 | I27: =I18-I25 -> 46046.397 | J27: =J18-J25 -> 54385.457
B28: Operating Margin (%) | C28: =C27/C14 -> 0.242 | D28: =D27/D14 -> 0.193 | E28: =E27/E14 -> 0.142 | F28: =F27/F14 -> 0.167 | G28: =G27/G14 -> 0.189 | H28: =H27/H14 -> 0.211 | I28: =I27/I14 -> 0.233 | J28: =J27/J14 -> 0.255
B30: Interest (Expense) / Income | C30: =(C$49*INDEX('Meta Drivers'!D$99:D$101,MATCH($D$5,'Meta Drivers'!$C$99:$C$101,0)))-(C71*INDEX('Meta Drivers'!D$103:D$105,MATCH($D$5,'Meta Drivers'!$C$103:$C$105,0))) -> -125 | D30: =(D$49*INDEX('Meta Drivers'!E$99:E$101,MATCH($D$5,'Meta Drivers'!$C$99:$C$101,0)))-(D71*INDEX('Meta Drivers'!E$103:E$105,MATCH($D$5,'Meta Drivers'!$C$103:$C$105,0))) -> 277.83077 | E30: =(E$49*INDEX('Meta Drivers'!F$99:F$101,MATCH($D$5,'Meta Drivers'!$C$99:$C$101,0)))-(E71*INDEX('Meta Drivers'!F$103:F$105,MATCH($D$5,'Meta Drivers'!$C$103:$C$105,0))) -> 735.70932 | F30: =(F$49*INDEX('Meta Drivers'!G$99:G$101,MATCH($D$5,'Meta Drivers'!$C$99:$C$101,0)))-(F71*INDEX('Meta Drivers'!G$103:G$105,MATCH($D$5,'Meta Drivers'!$C$103:$C$105,0))) -> 1393.891 | G30: =(G$49*INDEX('Meta Drivers'!H$99:H$101,MATCH($D$5,'Meta Drivers'!$C$99:$C$101,0)))-(G71*INDEX('Meta Drivers'!H$103:H$105,MATCH($D$5,'Meta Drivers'!$C$103:$C$105,0))) -> 1470.867 | H30: =(H$49*INDEX('Meta Drivers'!I$99:I$101,MATCH($D$5,'Meta Drivers'!$C$99:$C$101,0)))-(H71*INDEX('Meta Drivers'!I$103:I$105,MATCH($D$5,'Meta Drivers'!$C$103:$C$105,0))) -> 1547.6923 | I30: =(I$49*INDEX('Meta Drivers'!J$99:J$101,MATCH($D$5,'Meta Drivers'!$C$99:$C$101,0)))-(I71*INDEX('Meta Drivers'!J$103:J$105,MATCH($D$5,'Meta Drivers'!$C$103:$C$105,0))) -> 1974.9617 | J30: =(J$49*INDEX('Meta Drivers'!K$99:K$101,MATCH($D$5,'Meta Drivers'!$C$99:$C$101,0)))-(J71*INDEX('Meta Drivers'!K$103:K$105,MATCH($D$5,'Meta Drivers'!$C$103:$C$105,0))) -> 1947.5673
B32: Pre-tax Income | C32: =C27+C30 -> 28413.818 | D32: =D27+D30 -> 22783.368 | E32: =E27+E30 -> 19892.077 | F32: =F27+F30 -> 26667.497 | G32: =G27+G30 -> 33046.219 | H32: =H27+H30 -> 40041.209 | I32: =I27+I30 -> 48021.359 | J32: =J27+J30 -> 56333.024
B33: Tax Expense / Provision | C33: =C32*INDEX('Meta Drivers'!D$92:D$94,MATCH($D$5,'Meta Drivers'!$C$92:$C$94,0)) -> 4972.4181 | D33: =D32*INDEX('Meta Drivers'!E$92:E$94,MATCH($D$5,'Meta Drivers'!$C$92:$C$94,0)) -> 4328.8399 | E33: =E32*INDEX('Meta Drivers'!F$92:F$94,MATCH($D$5,'Meta Drivers'!$C$92:$C$94,0)) -> 3680.0343 | F33: =F32*INDEX('Meta Drivers'!G$92:G$94,MATCH($D$5,'Meta Drivers'!$C$92:$C$94,0)) -> 5066.8245 | G33: =G32*INDEX('Meta Drivers'!H$92:H$94,MATCH($D$5,'Meta Drivers'!$C$92:$C$94,0)) -> 6444.0128 | H33: =H32*INDEX('Meta Drivers'!I$92:I$94,MATCH($D$5,'Meta Drivers'!$C$92:$C$94,0)) -> 8008.2418 | I33: =I32*INDEX('Meta Drivers'!J$92:J$94,MATCH($D$5,'Meta Drivers'!$C$92:$C$94,0)) -> 9844.3786 | J33: =J32*INDEX('Meta Drivers'!K$92:K$94,MATCH($D$5,'Meta Drivers'!$C$92:$C$94,0)) -> 11829.935
B35: Net income | C35: =C32-C33 -> 23441.4 | D35: =D32-D33 -> 18454.528 | E35: =E32-E33 -> 16212.043 | F35: =F32-F33 -> 21600.673 | G35: =G32-G33 -> 26602.207 | H35: =H32-H33 -> 32032.967 | I35: =I32-I33 -> 38176.98 | J35: =J32-J33 -> 44503.089
B36: Net Margin (%) | C36: =C35/C14 -> 0.19877553 | D36: =D35/D14 -> 0.15825989 | E36: =E35/E14 -> 0.12017467 | F36: =F35/F14 -> 0.14273042 | G36: =G35/G14 -> 0.15923233 | H36: =H35/H14 -> 0.17558687 | I36: =I35/I14 -> 0.19317986 | J36: =J35/J14 -> 0.20866401
B38: EPS calculation
B40: Basic Shares — Outstanding | C40: 2800 | D40: 2750 | E40: 2700 | F40: 2650 | G40: 2600 | H40: 2550 | I40: 2500 | J40: 2450
B41: EPS — Basic | C41: =C35/C40 -> 8.3719285 | D41: =D35/D40 -> 6.7107374 | E41: =E35/E40 -> 6.0044604 | F41: =F35/F40 -> 8.1511973 | G41: =G35/G40 -> 10.231618 | H41: =H35/H40 -> 12.561948 | I41: =I35/I40 -> 15.270792 | J41: =J35/J40 -> 18.164526
B44: Balance sheet schedule
B46: Assets section
B48: Assets — Current
B49: Cash and equivalents | C49: 35000 | D49: =D$106 -> 40688.718 | E49: =E$106 -> 43828.373 | F49: =F$106 -> 50754.029 | G49: =G$106 -> 59695.566 | H49: =H$106 -> 72407.693 | I49: =I$106 -> 87398.469 | J49: =J$106 -> 107128.37
B50: Receivables | C50: =C$14*INDEX('Meta Drivers'!D$64:D$66,MATCH($D$5,'Meta Drivers'!$C$64:$C$66,0))/365 -> 17770.123 | D50: =D$14*INDEX('Meta Drivers'!E$64:E$66,MATCH($D$5,'Meta Drivers'!$C$64:$C$66,0))/365 -> 16932.266 | E50: =E$14*INDEX('Meta Drivers'!F$64:F$66,MATCH($D$5,'Meta Drivers'!$C$64:$C$66,0))/365 -> 18849.6 | F50: =F$14*INDEX('Meta Drivers'!G$64:G$66,MATCH($D$5,'Meta Drivers'!$C$64:$C$66,0))/365 -> 20731.364 | G50: =G$14*INDEX('Meta Drivers'!H$64:H$66,MATCH($D$5,'Meta Drivers'!$C$64:$C$66,0))/365 -> 22427.952 | H50: =H$14*INDEX('Meta Drivers'!I$64:I$66,MATCH($D$5,'Meta Drivers'!$C$64:$C$66,0))/365 -> 23991.285 | I50: =I$14*INDEX('Meta Drivers'!J$64:J$66,MATCH($D$5,'Meta Drivers'!$C$64:$C$66,0))/365 -> 25447.477 | J50: =J$14*INDEX('Meta Drivers'!K$64:K$66,MATCH($D$5,'Meta Drivers'!$C$64:$C$66,0))/365 -> 26878.657
B51: Other current assets | C51: 5000 | D51: =C51*(1+'Meta Drivers'!E$72) -> 5200 | E51: =D51*(1+'Meta Drivers'!F$72) -> 5400 | F51: =E51*(1+'Meta Drivers'!G$72) -> 5616 | G51: =F51*(1+'Meta Drivers'!H$72) -> 5840.64 | H51: =G51*(1+'Meta Drivers'!I$72) -> 6074.2656 | I51: =H51*(1+'Meta Drivers'!J$72) -> 6317.2362 | J51: =I51*(1+'Meta Drivers'!K$72) -> 6569.9257
B52: Current Assets — Total | C52: =SUM(C49:C51) -> 57770.123 | D52: =SUM(D49:D51) -> 62820.984 | E52: =SUM(E49:E51) -> 68077.973 | F52: =SUM(F49:F51) -> 77101.393 | G52: =SUM(G49:G51) -> 87964.158 | H52: =SUM(H49:H51) -> 102473.24 | I52: =SUM(I49:I51) -> 119163.18 | J52: =SUM(J49:J51) -> 140576.95
B54: Assets — Non-current
B55: PP&E (Gross) | C55: 60000 | D55: =C55+D95 -> 85653.98 | E55: =D55+E95 -> 118705.46 | F55: =E55+F95 -> 153513.42 | G55: =F55+G95 -> 189432.47 | H55: =G55+H95 -> 225919.22 | I55: =H55+I95 -> 263467.78 | J55: =I55+J95 -> 301857.52
B56: Less: Accumulated depreciation | C56: 15000 | D56: =C56+D87 -> 29180.962 | E56: =D56+E87 -> 45856.049 | F56: =E56+F87 -> 67339.511 | G56: =F56+G87 -> 89964.686 | H56: =G56+H87 -> 113312.07 | I56: =H56+I87 -> 137028.45 | J56: =I56+J87 -> 161435.02
B57: Net PP&E | C57: =C55-C56 -> 45000 | D57: =D55-D56 -> 56473.018 | E57: =E55-E56 -> 72849.411 | F57: =F55-F56 -> 86173.91 | G57: =G55-G56 -> 99467.787 | H57: =H55-H56 -> 112607.15 | I57: =I55-I56 -> 126439.33 | J57: =J55-J56 -> 140422.5
B59: Other Long-term Assets | C59: 25000 | D59: =C59*(1+'Meta Drivers'!E$73) -> 28000 | E59: =D59*(1+'Meta Drivers'!F$73) -> 32000 | F59: =E59*(1+'Meta Drivers'!G$73) -> 35200 | G59: =F59*(1+'Meta Drivers'!H$73) -> 38720 | H59: =G59*(1+'Meta Drivers'!I$73) -> 42592 | I59: =H59*(1+'Meta Drivers'!J$73) -> 46851.2 | J59: =I59*(1+'Meta Drivers'!K$73) -> 51536.32
...

Sheet Deal Inputs
B2: Deal input deck — Google / Meta combination
B3: Merger model inputs — pro forma
B5: Transaction Overview — 1
B7: Deal structure
B8: Buyer | D8: Google (Alphabet)
B9: Seller / Target | D9: Meta Platforms
B10: Consideration type | D10: Stock & Cash Combination
B11: Announcement timing | D11: Q4 2023
B12: Expected close timing | D12: Q1 2024
B14: Purchase price Calculation — 2
B16: Stock Prices & Premium
B17: Meta Current Stock Price | D17: 520
B18: Premium Offered | D18: 0.3
B19: Offer Price per Share | D19: =D17*(1+D18) -> 676
B20: Meta Shares Outstanding (mm) | D20: 2700
B21: Total Purchase price ($mm) | D21: =D19*D20 -> 1825200
B23: Consideration split
B24: % Cash Consideration | D24: 0.5
B25: % Stock Consideration | D25: 0.5
B26: Cash Required — $mm | D26: =$D$21*D24 -> 912600
B27: Stock Value Required — $mm | D27: =$D$21*D25 -> 912600
B28: Google Stock Price | D28: 175
B29: New Google Shares Issued (mm) | D29: =D27/D28 -> 5214.8571
B31: Sources & Uses Of Funds — 3
B33: Funding Sources ($mm) | F33: Funding Uses ($mm)
B34: Stock Issued | D34: =$D$27 -> 912600 | F34: Purchase price | H34: {=D21} -> 1825200
B35: New Term Loan | D35: 400000 | F35: Transaction Fees | H35: =$D$21*$I$35 -> 36504 | I35: 0.02
B36: Bridge Loan | D36: 100000 | F36: Financing Fees | H36: =(D35+D36)*$I$36 -> 12500 | I36: 0.025
B37: Cash on Hand | D37: =H38-D34-D35-D36 -> 466604 | F37: Integration Costs | H37: 5000
B38: Sources — Total | D38: =SUM(D34:D37) -> 1879204 | F38: Uses — Total | H38: =SUM(H34:H37) -> 1879204
B40: Synergy Assumptions — 4
B42: Revenue Synergies — $mm
D43: Year 1 | E43: Year 2 | F43: Year 3 | G43: Year 4 | H43: Year 5
B44: Cross-Platform Advertising | D44: 2000 | E44: 4000 | F44: 6000 | G44: 7000 | H44: 8000
B45: Data & AI Integration | D45: 1000 | E45: 2500 | F45: 4000 | G45: 5000 | H45: 6000
B46: Market Expansion | D46: 500 | E46: 1500 | F46: 2500 | G46: 3000 | H46: 3500
B47: Total Revenue Synergies | D47: =SUM(D44:D46) -> 3500 | E47: =SUM(E44:E46) -> 8000 | F47: =SUM(F44:F46) -> 12500 | G47: =SUM(G44:G46) -> 15000 | H47: =SUM(H44:H46) -> 17500
B49: Cost Synergies — $mm
B50: Infrastructure & Cloud | D50: 3000 | E50: 5000 | F50: 7000 | G50: 8000 | H50: 8500
B51: R&D Efficiency | D51: 2000 | E51: 3500 | F51: 4500 | G51: 5000 | H51: 5500
...

Sheet Pro Forma
B2: Pro forma company — Google / Meta
B3: Figures in $mm
B5: Transaction snapshot
B7: Purchase price ($mm): | D7: ='Deal Inputs'!$D$21 -> 1825200
B8: Cash Consideration — | D8: ='Deal Inputs'!$D$26 -> 912600
B9: Stock Consideration — | D9: ='Deal Inputs'!$D$27 -> 912600
B10: Total Debt Raised — | D10: ='Deal Inputs'!$D$35+'Deal Inputs'!$D$36 -> 500000
B11: Goodwill Created — | D11: ='Deal Inputs'!$D$75 -> 1663710
B13: Pro Forma Income Statement
B15: For the Year Ending | D15: 2024 | E15: 2025 | F15: 2026 | G15: 2027 | H15: 2028
B17: Revenue — Combined
B18: Google Revenue | D18: ='Google Model'!F$16 -> 292008.95 | E18: ='Google Model'!G$16 -> 320857.36 | F18: ='Google Model'!H$16 -> 349262.74 | G18: ='Google Model'!I$16 -> 377287.31 | H18: ='Google Model'!J$16 -> 405460.92
B19: Meta Revenue | D19: ='Meta Model'!F$14 -> 151338.96 | E19: ='Meta Model'!G$14 -> 167065.36 | F19: ='Meta Model'!H$14 -> 182433.73 | G19: ='Meta Model'!I$14 -> 197624.02 | H19: ='Meta Model'!J$14 -> 213276.3
B20: Revenue synergy contribution | D20: ='Deal Inputs'!D$47 -> 3500 | E20: ='Deal Inputs'!E$47 -> 8000 | F20: ='Deal Inputs'!F$47 -> 12500 | G20: ='Deal Inputs'!G$47 -> 15000 | H20: ='Deal Inputs'!H$47 -> 17500
B21: Combined Revenue — Total | D21: =SUM(D18:D20) -> 446847.91 | E21: =SUM(E18:E20) -> 495922.71 | F21: =SUM(F18:F20) -> 544196.47 | G21: =SUM(G18:G20) -> 589911.34 | H21: =SUM(H18:H20) -> 636237.22
B23: Operating expense build
B24: Cost of sales (Combined) | D24: ='Google Model'!F$19+'Meta Model'!F$17 -> 161541.82 | E24: ='Google Model'!G$19+'Meta Model'!G$17 -> 176682.52 | F24: ='Google Model'!H$19+'Meta Model'!H$17 -> 191376.97 | G24: ='Google Model'!I$19+'Meta Model'!I$17 -> 205692.93 | H24: ='Google Model'!J$19+'Meta Model'!J$17 -> 219991.68
B25: Infrastructure synergy value | D25: =-'Deal Inputs'!D$50 -> -3000 | E25: =-'Deal Inputs'!E$50 -> -5000 | F25: =-'Deal Inputs'!F$50 -> -7000 | G25: =-'Deal Inputs'!G$50 -> -8000 | H25: =-'Deal Inputs'!H$50 -> -8500
B26: Profit — Gross | D26: =D21-D24-D25 -> 288306.09 | E26: =E21-E24-E25 -> 324240.2 | F26: =F21-F24-F25 -> 359819.5 | G26: =G21-G24-G25 -> 392218.41 | H26: =H21-H24-H25 -> 424745.53
B28: R&D — Combined | D28: ='Google Model'!F$23+'Meta Model'!F$21 -> 84888.884 | E28: ='Google Model'!G$23+'Meta Model'!G$21 -> 91698.33 | F28: ='Google Model'!H$23+'Meta Model'!H$21 -> 98367.534 | G28: ='Google Model'!I$23+'Meta Model'!I$21 -> 104292.27 | H28: ='Google Model'!J$23+'Meta Model'!J$21 -> 110444.52
B29: R&D synergy value | D29: =-'Deal Inputs'!D$51 -> -2000 | E29: =-'Deal Inputs'!E$51 -> -3500 | F29: =-'Deal Inputs'!F$51 -> -4500 | G29: =-'Deal Inputs'!G$51 -> -5000 | H29: =-'Deal Inputs'!H$51 -> -5500
B30: S&M — Combined | D30: ='Google Model'!F$24+'Meta Model'!F$22 -> 49578.31 | E30: ='Google Model'!G$24+'Meta Model'!G$22 -> 53096.151 | F30: ='Google Model'!H$24+'Meta Model'!H$22 -> 55906.153 | G30: ='Google Model'!I$24+'Meta Model'!I$22 -> 58712.799 | H30: ='Google Model'!J$24+'Meta Model'!J$22 -> 60912.798
B31: S&M synergy value | D31: =-'Deal Inputs'!D$53 -> -1000 | E31: =-'Deal Inputs'!E$53 -> -2000 | F31: =-'Deal Inputs'!F$53 -> -2500 | G31: =-'Deal Inputs'!G$53 -> -2800 | H31: =-'Deal Inputs'!H$53 -> -3000
B32: G&A — Combined | D32: ='Google Model'!F$25+'Meta Model'!F$23 -> 34751.841 | E32: ='Google Model'!G$25+'Meta Model'!G$23 -> 36793.304 | F32: ='Google Model'!H$25+'Meta Model'!H$23 -> 38500.612 | G32: ='Google Model'!I$25+'Meta Model'!I$23 -> 40279.659 | H32: ='Google Model'!J$25+'Meta Model'!J$23 -> 41495.217
B33: G&A synergy value | D33: =-'Deal Inputs'!D$52 -> -1500 | E33: =-'Deal Inputs'!E$52 -> -2500 | F33: =-'Deal Inputs'!F$52 -> -3000 | G33: =-'Deal Inputs'!G$52 -> -3200 | H33: =-'Deal Inputs'!H$52 -> -3400
B34: SBC (Combined) | D34: ='Google Model'!F$26+'Meta Model'!F$24 -> 44388.136 | E34: ='Google Model'!G$26+'Meta Model'!G$24 -> 47381.597 | F34: ='Google Model'!H$26+'Meta Model'!H$24 -> 49677.02 | G34: ='Google Model'!I$26+'Meta Model'!I$24 -> 51975.566 | H34: ='Google Model'!J$26+'Meta Model'!J$24 -> 53659.045
B35: Dis-synergies & Integration | D35: =-'Deal Inputs'!D$60 -> 6000 | E35: =-'Deal Inputs'!E$60 -> 4300 | F35: =-'Deal Inputs'!F$60 -> 2500 | G35: =-'Deal Inputs'!G$60 -> 1300 | H35: =-'Deal Inputs'!H$60 -> 200
B36: Amortization of new intangibles | D36: ='Deal Inputs'!$D$91 -> 2500 | E36: ='Deal Inputs'!$D$91 -> 2500 | F36: ='Deal Inputs'!$D$91 -> 2500 | G36: ='Deal Inputs'!$D$91 -> 2500 | H36: ='Deal Inputs'!$D$91 -> 2500
B37: EBIT | D37: =D26-SUM(D28:D36) -> 70698.923 | E37: =E26-SUM(E28:E36) -> 96470.815 | F37: =F26-SUM(F28:F36) -> 122368.18 | G37: =G26-SUM(G28:G36) -> 144158.11 | H37: =H26-SUM(H28:H36) -> 167433.95
B39: Existing interest expense / — income | D39: =-('Google Model'!F$32+'Meta Model'!F$30) -> -5041.1614 | E39: =-('Google Model'!G$32+'Meta Model'!G$30) -> -5099.4436 | F39: =-('Google Model'!H$32+'Meta Model'!H$30) -> -5113.3324 | G39: =-('Google Model'!I$32+'Meta Model'!I$30) -> -6247.4956 | H39: =-('Google Model'!J$32+'Meta Model'!J$30) -> -5947.9938
B40: New interest expense | D40: =(('Deal Inputs'!$D$80*((1-'Deal Inputs'!$D$84)^(D$15-$D$15)))*'Deal Inputs'!$D$81)+(('Deal Inputs'!$D$82*((1-'Deal Inputs'!$D$84)^(D$15-$D$15)))*'Deal Inputs'!$D$83) -> 28500 | E40: =(('Deal Inputs'!$D$80*((1-'Deal Inputs'!$D$84)^(E$15-$D$15)))*'Deal Inputs'!$D$81)+(('Deal Inputs'!$D$82*((1-'Deal Inputs'!$D$84)^(E$15-$D$15)))*'Deal Inputs'!$D$83) -> 27075 | F40: =(('Deal Inputs'!$D$80*((1-'Deal Inputs'!$D$84)^(F$15-$D$15)))*'Deal Inputs'!$D$81)+(('Deal Inputs'!$D$82*((1-'Deal Inputs'!$D$84)^(F$15-$D$15)))*'Deal Inputs'!$D$83) -> 25721.25 | G40: =(('Deal Inputs'!$D$80*((1-'Deal Inputs'!$D$84)^(G$15-$D$15)))*'Deal Inputs'!$D$81)+(('Deal Inputs'!$D$82*((1-'Deal Inputs'!$D$84)^(G$15-$D$15)))*'Deal Inputs'!$D$83) -> 24435.187 | H40: =(('Deal Inputs'!$D$80*((1-'Deal Inputs'!$D$84)^(H$15-$D$15)))*'Deal Inputs'!$D$81)+(('Deal Inputs'!$D$82*((1-'Deal Inputs'!$D$84)^(H$15-$D$15)))*'Deal Inputs'!$D$83) -> 23213.428
B41: EBT | D41: =D37-D39-D40 -> 47240.084 | E41: =E37-E39-E40 -> 74495.258 | F41: =F37-F39-F40 -> 101760.27 | G41: =G37-G39-G40 -> 125970.42 | H41: =H37-H39-H40 -> 150168.52
B42: Taxes | D42: =D41*'Deal Inputs'!$D$95 -> 9920.4177 | E42: =E41*'Deal Inputs'!$D$95 -> 15644.004 | F42: =F41*'Deal Inputs'!$D$95 -> 21369.656 | G42: =G41*'Deal Inputs'!$D$95 -> 26453.789 | H42: =H41*'Deal Inputs'!$D$95 -> 31535.389
B44: Net income | D44: =D41-D42 -> 37319.666 | E44: =E41-E42 -> 58851.254 | F44: =F41-F42 -> 80390.61 | G44: =G41-G42 -> 99516.633 | H44: =H41-H42 -> 118633.13
B46: Accretion / dilution workup
B48: Shares — Pro forma (mm) | D48: ='Google Model'!F$42+'Deal Inputs'!$D$29 -> 17614.857 | E48: ='Google Model'!G$42+'Deal Inputs'!$D$29 -> 17414.857 | F48: ='Google Model'!H$42+'Deal Inputs'!$D$29 -> 17214.857 | G48: ='Google Model'!I$42+'Deal Inputs'!$D$29 -> 17014.857 | H48: ='Google Model'!J$42+'Deal Inputs'!$D$29 -> 16814.857
B49: EPS — Pro forma | D49: =D44/D48 -> 2.1186471 | E49: =E44/E48 -> 3.3793705 | F49: =F44/F48 -> 4.6698389 | G49: =G44/G48 -> 5.848808 | H49: =H44/H48 -> 7.0552564
B50: % Accretion — Dilution | D50: =D49/'Google Model'!F$43-1 -> -0.3244407 | E50: =E49/'Google Model'!G$43-1 -> -0.085622584 | F50: =F49/'Google Model'!H$43-1 -> 0.079196041 | G50: =G49/'Google Model'!I$43-1 -> 0.16598529 | H50: =H49/'Google Model'!J$43-1 -> 0.22687473
