Workbook
Name Buyer_Diversification: 'Cash Flow Valuation'!$F$11
Name Company_Name: 'Books & GAAP Bridge'!$F$201
Name Cost_of_Debt: 'Cash Flow Valuation'!$F$8
Name Cost_of_Preferred: 'Cash Flow Valuation'!$F$9
Name Equity_Risk_Premium: 'Cash Flow Valuation'!$F$7
Name Market_Correlation: 'Cash Flow Valuation'!$F$10
Name Risk_Free_Rate: 'Cash Flow Valuation'!$F$6
Name Tax_Rate: 'Books & GAAP Bridge'!$F$200
Name WACC: 'Cash Flow Valuation'!$L$35

Sheet Books & GAAP Bridge
B2: ="Private Company Financial Statements - "&Company_Name -> Private Company Financial Statements - Fennmark Media Partners LLC
B3: (USD, as stated)
G5: Actuals | L5: Forecast
B6: Media Revenue / Expense Driver Deck | F6: Reporting Units: | G6: Year 1 | H6: Year 2 | I6: Year 3 | J6: Year 4 | K6: Year 5 | L6: Year 6 | M6: Year 7 | N6: Year 8 | O6: Year 9 | P6: Year 10
C8: Paid Subscriber Adds: | F8: # Subscribers | G8: 1011 | H8: 2051 | I8: 2978 | J8: 4000 | K8: 4500 | L8: 4800 | M8: 5200 | N8: 5600 | O8: 6000 | P8: 6500
C9: Average Subscriber Value: | F9: $ / Subscriber | G9: =G79/G8 -> 107.23973 | H9: =H79/H8 -> 128.3067 | I9: =I79/I8 -> 145.64084 | J9: =J79/J8 -> 145.75753 | K9: =K79/K8 -> 163.26105 | L9: 200.83542 | M9: 218.04989 | N9: 241.00251 | O9: 258.21697 | P9: 275.43144
C11: Media Revenue Growth Rates:
C12: Media Product Billings Referred by Affiliates: | F12: % | G12: =IFERROR(+G80/F80-1,"N/A") -> N/A | H12: =IFERROR(+H80/G80-1,"N/A") -> 0.30303086 | I12: =IFERROR(+I80/H80-1,"N/A") -> 0.16065863 | J12: =IFERROR(+J80/I80-1,"N/A") -> -0.38024395 | K12: =IFERROR(+K80/J80-1,"N/A") -> 0.26009731 | L12: 0.24201825 | M12: 0.1936146 | N12: 0.14521095 | O12: 0.0968073 | P12: 0.1
C13: Media Production & Advisory Services: | F13: % | G13: =IFERROR(+G81/F81-1,"N/A") -> N/A | H13: =IFERROR(+H81/G81-1,"N/A") -> 0.23227805 | I13: =IFERROR(+I81/H81-1,"N/A") -> 0.23451872 | J13: =IFERROR(+J81/I81-1,"N/A") -> 0.10178854 | K13: =IFERROR(+K81/J81-1,"N/A") -> 0.10258514 | L13: 0.0974845 | M13: 0.0974845 | N13: 0.0779876 | O13: 0.0779876 | P13: 0.06
C14: Institutional & Agency Billings: | F14: % | G14: =IFERROR(+G82/F82-1,"N/A") -> N/A | H14: =IFERROR(+H82/G82-1,"N/A") -> 1.3805371 | I14: =IFERROR(+I82/H82-1,"N/A") -> 0.50885621 | J14: =IFERROR(+J82/I82-1,"N/A") -> 0.73531695 | K14: =IFERROR(+K82/J82-1,"N/A") -> 0.44011121 | L14: 0.324434 | M14: 0.28387975 | N14: 0.2433255 | O14: 0.2433255 | P14: 0.25
C15: Commissions from Other Media Products: | F15: % | G15: =IFERROR(+G83/F83-1,"N/A") -> N/A | H15: =IFERROR(+H83/G83-1,"N/A") -> 0.26961981 | I15: =IFERROR(+I83/H83-1,"N/A") -> 0.25738018 | J15: =IFERROR(+J83/I83-1,"N/A") -> -0.25629274 | K15: =IFERROR(+K83/J83-1,"N/A") -> 0.26009731 | L15: 0.153414 | M15: 0.102276 | N15: 0.102276 | O15: 0.0818208 | P15: 0.08
C17: Expense Ratios:
C18: Affiliate Commission Rate: | F18: % | G18: =IFERROR(-G87/G80,"N/A") -> 0.5 | H18: =IFERROR(-H87/H80,"N/A") -> 0.5 | I18: =IFERROR(-I87/I80,"N/A") -> 0.5 | J18: =IFERROR(-J87/J80,"N/A") -> 0.5 | K18: =IFERROR(-K87/K80,"N/A") -> 0.5 | L18: 0.5 | M18: 0.5 | N18: 0.5 | O18: 0.5 | P18: 0.5
C19: Commission Rate - Content Partners: | F19: % | G19: =IFERROR(-G88/G81,"N/A") -> 0.5 | H19: =IFERROR(-H88/H81,"N/A") -> 0.5 | I19: =IFERROR(-I88/I81,"N/A") -> 0.5 | J19: =IFERROR(-J88/J81,"N/A") -> 0.5 | K19: =IFERROR(-K88/K81,"N/A") -> 0.5 | L19: 0.5 | M19: 0.5 | N19: 0.5 | O19: 0.5 | P19: 0.5
C20: Commission Rate - Sales Reps: | F20: % | G20: =IFERROR(-G89/G82,"N/A") -> 0 | H20: =IFERROR(-H89/H82,"N/A") -> 0.4 | I20: =IFERROR(-I89/I82,"N/A") -> 0.4 | J20: =IFERROR(-J89/J82,"N/A") -> 0.4 | K20: =IFERROR(-K89/K82,"N/A") -> 0.4 | L20: 0.4 | M20: 0.4 | N20: 0.4 | O20: 0.4 | P20: 0.4
C22: Payment Fees % Gross Billings: | F22: % | G22: =IFERROR(-G95/G$84,"N/A") -> 0.029 | H22: =IFERROR(-H95/H$84,"N/A") -> 0.028 | I22: =IFERROR(-I95/I$84,"N/A") -> 0.028 | J22: =IFERROR(-J95/J$84,"N/A") -> 0.028 | K22: =IFERROR(-K95/K$84,"N/A") -> 0.028 | L22: 0.032712372 | M22: 0.032712372 | N22: 0.033880671 | O22: 0.033880671 | P22: 0.03504897
C23: Refunds % Gross Billings: | F23: % | G23: =IFERROR(-G96/G$84,"N/A") -> 0.03 | H23: =IFERROR(-H96/H$84,"N/A") -> 0.031 | I23: =IFERROR(-I96/I$84,"N/A") -> 0.035 | J23: =IFERROR(-J96/J$84,"N/A") -> 0.04 | K23: =IFERROR(-K96/K$84,"N/A") -> 0.041 | L23: 0.04256343 | M23: 0.04256343 | N23: 0.0472927 | O23: 0.0472927 | P23: 0.05675124
C25: Tax & Legal Fees % Gross Billings: | F25: % | G25: =IFERROR(-G102/G$84,"N/A") -> 0.0058799456 | H25: =IFERROR(-H102/H$84,"N/A") -> 0.0037050119 | I25: =IFERROR(-I102/I$84,"N/A") -> 0.0024555102 | J25: =IFERROR(-J102/J$84,"N/A") -> 0.0026413729 | K25: =IFERROR(-K102/K$84,"N/A") -> 0.0023581865 | L25: 0.001763064 | M25: 0.001763064 | N25: 0.002644596 | O25: 0.002644596 | P25: 0.002644596
C26: Online Advertising % Gross Billings: | F26: % | G26: =IFERROR(-G104/G$84,"N/A") -> 0 | H26: =IFERROR(-H104/H$84,"N/A") -> 0.024700079 | I26: =IFERROR(-I104/I$84,"N/A") -> 0.032740137 | J26: =IFERROR(-J104/J$84,"N/A") -> 0.026413729 | K26: =IFERROR(-K104/K$84,"N/A") -> 0.031442487 | L26: 0.026861841 | M26: 0.028594863 | N26: 0.030327885 | O26: 0.030327885 | P26: 0.032060907
C27: IT Infrastructure % Gross Billings: | F27: % | G27: =IFERROR(-G108/G$84,"N/A") -> 0.009407913 | H27: =IFERROR(-H108/H$84,"N/A") -> 0.01235004 | I27: =IFERROR(-I108/I$84,"N/A") -> 0.016370068 | J27: =IFERROR(-J108/J$84,"N/A") -> 0.019810297 | K27: =IFERROR(-K108/K$84,"N/A") -> 0.020961658 | L27: 0.022781748 | M27: 0.024852816 | N27: 0.024852816 | O27: 0.026923884 | P27: 0.026923884
C28: Travel & Moving % Gross Billings: | F28: % | G28: =IFERROR(-G109/G$84,"N/A") -> 0.027132421 | H28: =IFERROR(-H109/H$84,"N/A") -> 0.02173113 | I28: =IFERROR(-I109/I$84,"N/A") -> 0.0098416851 | J28: =IFERROR(-J109/J$84,"N/A") -> 0.0067658766 | K28: =IFERROR(-K109/K$84,"N/A") -> 0.0070881846 | L28: 0.006171599 | M28: 0.005289942 | N28: 0.004408285 | O28: 0.003526628 | P28: 0.003526628
C29: Depr. & Amort. % Gross Billings: | F29: % | G29: =IFERROR(-G110/G$84,"N/A") -> 0.0026718473 | H29: =IFERROR(-H110/H$84,"N/A") -> 0.0019562463 | I29: =IFERROR(-I110/I$84,"N/A") -> 0.0016550139 | J29: =IFERROR(-J110/J$84,"N/A") -> 0.0020114054 | K29: =IFERROR(-K110/K$84,"N/A") -> 0.0021213198 | L29: 0.001677458 | M29: 0.001677458 | N29: 0.002516187 | O29: 0.003354916 | P29: 0.003354916
C31: Tax Rate (Effective): | F31: % | G31: =IFERROR(-G117/G115,"N/A") -> 0.25 | H31: =IFERROR(-H117/H115,"N/A") -> 0.27 | I31: =IFERROR(-I117/I115,"N/A") -> 0.28 | J31: =IFERROR(-J117/J115,"N/A") -> 0.29 | K31: =IFERROR(-K117/K115,"N/A") -> 0.3 | L31: 0.3 | M31: 0.3 | N31: 0.3 | O31: 0.3 | P31: 0.3
C33: Headcount (FTEs):
C34: Subscriber Support: | F34: FTE Count | G34: 0 | H34: 0 | I34: 0.5 | J34: 0.75 | K34: 1 | L34: 1 | M34: 1.5 | N34: 1.5 | O34: 2 | P34: 2
C35: Website Design and Development: | F35: FTE Count | G35: 0 | H35: 0.5 | I35: 1 | J35: 1 | K35: 1 | L35: 1.5 | M35: 1.5 | N35: 2 | O35: 2 | P35: 2
C36: Sales Reps: | F36: FTE Count | G36: 0 | H36: 0.5 | I36: 0.5 | J36: 0.5 | K36: 0.5 | L36: 0.5 | M36: 1 | N36: 1 | O36: 1 | P36: 1
C37: Marketing Personnel: | F37: FTE Count | G37: 0 | H37: 0 | I37: 0.5 | J37: 0.75 | K37: 1 | L37: 1 | M37: 1 | N37: 1 | O37: 1.25 | P37: 1.5
C38: Media Product Creation: | F38: FTE Count | G38: 0 | H38: 0 | I38: 0.5 | J38: 0.5 | K38: 1 | L38: 1 | M38: 1 | N38: 2 | O38: 2 | P38: 2
C39: Content Production: | F39: FTE Count | G39: 0 | H39: 0 | I39: 0.5 | J39: 0.5 | K39: 0.5 | L39: 0.5 | M39: 0.75 | N39: 0.75 | O39: 1 | P39: 1
C40: FTEs — Total: | G40: =SUM(G34:G39) -> 0 | H40: =SUM(H34:H39) -> 1 | I40: =SUM(I34:I39) -> 3.5 | J40: =SUM(J34:J39) -> 4 | K40: =SUM(K34:K39) -> 5 | L40: =SUM(L34:L39) -> 5.5 | M40: =SUM(M34:M39) -> 6.75 | N40: =SUM(N34:N39) -> 8.25 | ... P40: =SUM(P34:P39) -> 9.5
C42: Expense per FTE (Average):
C43: =C34 -> Subscriber Support: | F43: Cost per FTE | G43: =IFERROR(-G103/G34,"N/A") -> N/A | H43: =IFERROR(-H103/H34,"N/A") -> N/A | I43: =IFERROR(-I103/I34,"N/A") -> 60000 | J43: =IFERROR(-J103/J34,"N/A") -> 60000 | K43: =IFERROR(-K103/K34,"N/A") -> 60000 | L43: =K43*(1+L$50) -> 62483.942 | M43: =L43*(1+M$50) -> 65070.718 | N43: =M43*(1+N$50) -> 67764.583 | O43: =N43*(1+O$50) -> 70569.972 | P43: =O43*(1+P$50) -> 73491.501
C44: =C35 -> Website Design and Development: | F44: Cost per FTE | G44: =IFERROR(-G105/G35,"N/A") -> N/A | H44: =IFERROR(-H105/H35,"N/A") -> 60000 | I44: =IFERROR(-I105/I35,"N/A") -> 60000 | J44: =IFERROR(-J105/J35,"N/A") -> 60000 | K44: =IFERROR(-K105/K35,"N/A") -> 60000 | L44: =K44*(1+L$50) -> 62483.942 | M44: =L44*(1+M$50) -> 65070.718 | N44: =M44*(1+N$50) -> 67764.583 | O44: =N44*(1+O$50) -> 70569.972 | P44: =O44*(1+P$50) -> 73491.501
C45: =C36 -> Sales Reps: | F45: Cost per FTE | G45: =IFERROR(-G106/G36,"N/A") -> N/A | H45: =IFERROR(-H106/H36,"N/A") -> 20000 | I45: =IFERROR(-I106/I36,"N/A") -> 24000 | J45: =IFERROR(-J106/J36,"N/A") -> 24000 | K45: =IFERROR(-K106/K36,"N/A") -> 24000 | L45: =K45*(1+L$50) -> 24993.577 | M45: =L45*(1+M$50) -> 26028.287 | N45: =M45*(1+N$50) -> 27105.833 | O45: =N45*(1+O$50) -> 28227.989 | P45: =O45*(1+P$50) -> 29396.6
C46: =C37 -> Marketing Personnel: | F46: Cost per FTE | G46: =IFERROR(-G107/G37,"N/A") -> N/A | H46: =IFERROR(-H107/H37,"N/A") -> N/A | I46: =IFERROR(-I107/I37,"N/A") -> 80000 | J46: =IFERROR(-J107/J37,"N/A") -> 80000 | K46: =IFERROR(-K107/K37,"N/A") -> 80000 | L46: =K46*(1+L$50) -> 83311.923 | M46: =L46*(1+M$50) -> 86760.957 | N46: =M46*(1+N$50) -> 90352.777 | O46: =N46*(1+O$50) -> 94093.295 | P46: =O46*(1+P$50) -> 97988.667
C47: =C38 -> Media Product Creation: | F47: Cost per FTE | G47: =IFERROR(-G111/G38,"N/A") -> N/A | H47: =IFERROR(-H111/H38,"N/A") -> N/A | I47: =IFERROR(-I111/I38,"N/A") -> 80000 | J47: =IFERROR(-J111/J38,"N/A") -> 80000 | K47: =IFERROR(-K111/K38,"N/A") -> 80000 | L47: =K47*(1+L$50) -> 83311.923 | M47: =L47*(1+M$50) -> 86760.957 | N47: =M47*(1+N$50) -> 90352.777 | O47: =N47*(1+O$50) -> 94093.295 | P47: =O47*(1+P$50) -> 97988.667
C48: =C39 -> Content Production: | F48: Cost per FTE | G48: =IFERROR(-G112/G39,"N/A") -> N/A | H48: =IFERROR(-H112/H39,"N/A") -> N/A | I48: =IFERROR(-I112/I39,"N/A") -> 60000 | J48: =IFERROR(-J112/J39,"N/A") -> 60000 | K48: =IFERROR(-K112/K39,"N/A") -> 60000 | L48: =K48*(1+L$50) -> 62483.942 | M48: =L48*(1+M$50) -> 65070.718 | N48: =M48*(1+N$50) -> 67764.583 | O48: =N48*(1+O$50) -> 70569.972 | P48: =O48*(1+P$50) -> 73491.501
C50: Wage Growth Rate: | F50: % | L50: 0.04139904 | M50: 0.04139904 | N50: 0.04139904 | O50: 0.04139904 | P50: 0.04139904
G52: =$G$5 -> Actuals | L52: =$L$5 -> Forecast
...

Sheet Cash Flow Valuation
B2: ="Private Company WACC Analysis - "&Company_Name -> Private Company WACC Analysis - Fennmark Media Partners LLC
B3: ='Books & GAAP Bridge'!$B$196 -> (USD, as stated)
B5: Discount Rate Inputs
B6: Risk-Free Yield: | F6: 0.020767873
B7: Market Risk Premium: | F7: 0.06804861
B8: Cost of Debt (Pre-Tax): | F8: =Risk_Free_Rate+0.4% -> 0.024767873
B9: Preferred Stock Cost: | F9: 0
B10: Market Correlation (R^2) for Comparable Companies: | F10: 0.17644832
B11: Acquirer Portfolio-Diversification Adjustment: | F11: 0.2721385
B13: Unlevered Beta from Comparables
D14: Levered | G14: Preferred | I14: Equity | L14: Unlevered
B15: Name | C15: Ticker | D15: Beta | E15: Debt | F15: % Debt | G15: Stock | H15: % Preferred | I15: Value | J15: % Equity | K15: Tax Rate | L15: Beta
B16: ='Trading Comps'!B8 -> Corvane Broadcasting Inc | C16: ='Trading Comps'!C8 -> NYSE:CRVB | D16: ='Trading Comps'!U8 -> 0.32 | E16: ='Trading Comps'!F8 -> 522.4 | F16: =E16/($E16+$G16+$I16) -> 0.2134774 | G16: ='Trading Comps'!G8 -> 0 | H16: =G16/($E16+$G16+$I16) -> 0 | I16: ='Trading Comps'!E8 -> 1924.6975 | J16: =I16/($E16+$G16+$I16) -> 0.7865226 | K16: 0.4 | L16: =IFERROR(D16/(1+(E16/I16)*(1-K16)+G16/I16),"N/A") -> 0.2751856
B17: ='Trading Comps'!B9 -> Emberwyck Broadcasting Inc | C17: ='Trading Comps'!C9 -> NASDAQ:EMBW | D17: ='Trading Comps'!U9 -> 1.55 | E17: ='Trading Comps'!F9 -> 118.75 | F17: =E17/($E17+$G17+$I17) -> 0.15034272 | G17: ='Trading Comps'!G9 -> 0 | H17: =G17/($E17+$G17+$I17) -> 0 | I17: ='Trading Comps'!E9 -> 671.112 | J17: =I17/($E17+$G17+$I17) -> 0.84965728 | K17: 0.4 | L17: =IFERROR(D17/(1+(E17/I17)*(1-K17)+G17/I17),"N/A") -> 1.401235
B18: ='Trading Comps'!B10 -> Quillhaven Publishing Corp | C18: ='Trading Comps'!C10 -> NASDAQ:QLHV | D18: ='Trading Comps'!U10 -> 1.11 | E18: ='Trading Comps'!F10 -> 0 | F18: =E18/($E18+$G18+$I18) -> 0 | G18: ='Trading Comps'!G10 -> 0 | H18: =G18/($E18+$G18+$I18) -> 0 | I18: ='Trading Comps'!E10 -> 800.496 | J18: =I18/($E18+$G18+$I18) -> 1 | K18: 0.4 | L18: =IFERROR(D18/(1+(E18/I18)*(1-K18)+G18/I18),"N/A") -> 1.11
B19: ='Trading Comps'!B11 -> Vantablu Streaming, Inc. | C19: ='Trading Comps'!C11 -> NASDAQ:VNBU | D19: ='Trading Comps'!U11 -> 1.15 | E19: ='Trading Comps'!F11 -> 0 | F19: =E19/($E19+$G19+$I19) -> 0 | G19: ='Trading Comps'!G11 -> 0 | H19: =G19/($E19+$G19+$I19) -> 0 | I19: ='Trading Comps'!E11 -> 595.1248 | J19: =I19/($E19+$G19+$I19) -> 1 | K19: 0.4 | L19: =IFERROR(D19/(1+(E19/I19)*(1-K19)+G19/I19),"N/A") -> 1.15
B20: ='Trading Comps'!B12 -> Driftwater Networks Corp | C20: ='Trading Comps'!C12 -> NASDAQ:DFWN | D20: ='Trading Comps'!U12 -> 2.11 | E20: ='Trading Comps'!F12 -> 43.904 | F20: =E20/($E20+$G20+$I20) -> 0.45348813 | G20: ='Trading Comps'!G12 -> 0 | H20: =G20/($E20+$G20+$I20) -> 0 | I20: ='Trading Comps'!E12 -> 52.91 | J20: =I20/($E20+$G20+$I20) -> 0.54651187 | K20: 0.4 | L20: =IFERROR(D20/(1+(E20/I20)*(1-K20)+G20/I20),"N/A") -> 1.4086652
B21: ='Trading Comps'!B13 -> Hollowmere Broadcast Group Inc | C21: ='Trading Comps'!C13 -> NASDAQ:HWMB | D21: ='Trading Comps'!U13 -> 1.25 | E21: ='Trading Comps'!F13 -> 12.303 | F21: =E21/($E21+$G21+$I21) -> 0.13034247 | G21: ='Trading Comps'!G13 -> 0 | H21: =G21/($E21+$G21+$I21) -> 0 | I21: ='Trading Comps'!E13 -> 82.0868 | J21: =I21/($E21+$G21+$I21) -> 0.86965753 | K21: 0.4 | L21: =IFERROR(D21/(1+(E21/I21)*(1-K21)+G21/I21),"N/A") -> 1.1468661
B23: Median: | D23: =MEDIAN(D16:D21) -> 1.2 | E23: =MEDIAN(E16:E21) -> 28.1035 | F23: =MEDIAN(F16:F21) -> 0.1403426 | G23: =MEDIAN(G16:G21) -> 0 | H23: =MEDIAN(H16:H21) -> 0 | I23: =MEDIAN(I16:I21) -> 633.1184 | J23: =MEDIAN(J16:J21) -> 0.8596574 | K23: =MEDIAN(K16:K21) -> 0.4 | L23: =MEDIAN(L16:L21) -> 1.148433
B24: Unlevered Beta — Median (Total): | L24: =L23/SQRT(Market_Correlation)*(1-Buyer_Diversification) -> 1.989966
B26: =TEXT(Company_Name,"")& " - Levered Beta & WACC Calculation" -> Fennmark Media Partners LLC - Levered Beta & WACC Calculation
D27: Unlevered | G27: Preferred | I27: Equity | L27: Levered
C28: Ticker | D28: Beta | E28: Debt | F28: % Debt | G28: Stock | H28: % Preferred | I28: Value | J28: % Equity | K28: Tax Rate | L28: Beta
B29: Target Capital Structure: | C29: N/A | D29: =L24 -> 1.989966 | F29: =F23 -> 0.1403426 | H29: =H23 -> 0 | J29: =J23 -> 0.8596574 | K29: =Tax_Rate -> 0.41192095 | L29: =D29*(1+(F29/J29)*(1-Tax_Rate)+(H29/J29)) -> 2.1810153
B31: Cost of Equity — Comps + Target Structure | L31: =Risk_Free_Rate+Equity_Risk_Premium*L29 -> 0.16918293
B33: WACC = Cost of Equity * % Equity + Cost of Debt * % Debt * (1 - Tax Rate) + Cost of Preferred Stock * % Preferred Stock
B35: WACC — Target Structure | L35: =L31*J29+Cost_of_Debt*F29*(1-Tax_Rate)+Cost_of_Preferred*H29 -> 0.14748352
B38: ="Private Company DCF Analysis - "&Company_Name -> Private Company DCF Analysis - Fennmark Media Partners LLC
B39: (USD, as stated)
B41: ="DCF Assumptions - "&Company_Name&":" -> DCF Assumptions - Fennmark Media Partners LLC:
B43: DCF Financial Assumptions: | G43: Operating Assumptions — Extended Period:
B45: Applied Discount Rate: | E45: =WACC -> 0.14748352 | G45: Annual Change in Media Revenue Growth: | J45: -0.0215151
G46: Minimum Media Revenue Growth: | J46: 0.0354558
B47: Going-Concern Discount to Terminal Value: | E47: 0.25061425
G48: EBIT Margin — Annual Change: | J48: -0.005157285
B49: Liquidation-Value Discount to Terminal Value: | E49: 0 | G49: EBIT Margin Floor: | J49: 0.1416552
G51: Depreciation & Amortization % Media Revenue: | J51: 0.004754215
G52: CapEx % Media Revenue: | J52: 0.01167925
G53: Change in WC % Change in Media Revenue: | J53: 0.02688063
B55: Terminal Value — Multiples Method: | G55: Terminal Value — Perpetuity-Growth Method: | L55: Terminal Value — Liquidation Method: | Q55: Terminal Value — Cease-Operations Method:
...

Sheet Trading Comps
B2: Sub-$500mm Regional Media & Content Trading Comps
B3: (USD millions, except per-share amounts in USD as stated)
B5: Operating Metrics | E5: Capitalization
D6: Share | E6: Equity | G6: Preferred | H6: Enterprise | I6: Media Revenue | L6: EBITDA | O6: EBITDA Margin | R6: Net Income
B7: Comparable Company | C7: Ticker | D7: Price | E7: Value | F7: Debt | G7: Stock | H7: Value | I7: LTM | J7: Forward Year 1 | K7: Forward Year 2 | L7: =$I$7 -> LTM | M7: =$J$7 -> Forward Year 1 | N7: =$K$7 -> Forward Year 2 | O7: =$I$7 -> LTM | P7: =$J$7 -> Forward Year 1 | Q7: =$K$7 -> Forward Year 2 | R7: =$I$7 -> LTM | S7: =$J$7 -> Forward Year 1 | T7: =$K$7 -> Forward Year 2 | U7: Beta
B8: Corvane Broadcasting Inc | C8: NYSE:CRVB | D8: 19.69 | E8: 1924.6975 | F8: 522.4 | G8: 0 | H8: 2280.3975 | I8: 474.6 | J8: 542.5 | K8: 616.1 | L8: 127.4 | M8: 143.6 | N8: 169.6 | O8: =IFERROR(+L8/I8,"N/A") -> 0.26843658 | P8: =IFERROR(+M8/J8,"N/A") -> 0.26470046 | Q8: =IFERROR(+N8/K8,"N/A") -> 0.27527999 | R8: 26.3925 | S8: 61.5825 | T8: 78.2 | U8: 0.32
B9: Emberwyck Broadcasting Inc | C9: NASDAQ:EMBW | D9: 62.14 | E9: 671.112 | F9: 118.75 | G9: 0 | H9: 627.582 | I9: 446.041 | J9: 431.62 | K9: 443.6 | L9: 102.377 | M9: 95.6 | N9: 104.3 | O9: =IFERROR(+L9/I9,"N/A") -> 0.22952374 | P9: =IFERROR(+M9/J9,"N/A") -> 0.22149113 | Q9: =IFERROR(+N9/K9,"N/A") -> 0.23512173 | R9: 46.36 | S9: 36.828 | T9: 41.472 | U9: 1.55
B10: Quillhaven Publishing Corp | C10: NASDAQ:QLHV | D10: 65.4 | E10: 800.496 | F10: 0 | G10: 0 | H10: 633.444 | I10: 421.967 | J10: 440.8 | K10: 463.93 | L10: 90.583 | M10: 95 | N10: 99.1 | O10: =IFERROR(+L10/I10,"N/A") -> 0.21466845 | P10: =IFERROR(+M10/J10,"N/A") -> 0.21551724 | Q10: =IFERROR(+N10/K10,"N/A") -> 0.21360981 | R10: 37.943 | S10: 42.228 | T10: 46.512 | U10: 1.11
B11: Vantablu Streaming, Inc. | C11: NASDAQ:VNBU | D11: 34.48 | E11: 595.1248 | F11: 0 | G11: 0 | H11: 474.2958 | I11: 348.72 | J11: 368.86 | K11: 385.2 | L11: 74.1 | M11: 75.3 | N11: 80.1 | O11: =IFERROR(+L11/I11,"N/A") -> 0.2124914 | P11: =IFERROR(+M11/J11,"N/A") -> 0.20414249 | Q11: =IFERROR(+N11/K11,"N/A") -> 0.20794393 | R11: 37.7994 | S11: 40.9062 | T11: 43.4952 | U11: 1.15
B12: Driftwater Networks Corp | C12: NASDAQ:DFWN | D12: 2.2 | E12: 52.91 | F12: 43.904 | G12: 0 | H12: 77.802 | I12: 330.249 | J12: 320 | K12: 339.06 | L12: -34.301 | M12: -45 | N12: -15.6 | O12: =IFERROR(+L12/I12,"N/A") -> -0.10386405 | P12: =IFERROR(+M12/J12,"N/A") -> -0.140625 | Q12: =IFERROR(+N12/K12,"N/A") -> -0.046009556 | R12: -75.39 | S12: -18.759 | T12: -3.367 | U12: 2.11
B13: Hollowmere Broadcast Group Inc | C13: NASDAQ:HWMB | D13: 3.26 | E13: 82.0868 | F13: 12.303 | G13: 0 | H13: 74.6548 | I13: 127.753 | J13: 119.63 | K13: 124.21 | L13: 12.723 | M13: 11.1 | N13: 15.2 | O13: =IFERROR(+L13/I13,"N/A") -> 0.099590616 | P13: =IFERROR(+M13/J13,"N/A") -> 0.09278609 | Q13: =IFERROR(+N13/K13,"N/A") -> 0.1223734 | R13: 3.468 | S13: 6.0432 | T13: 6.7986 | U13: 1.25
B15: Maximum | D15: =MAX(D8:D13) -> 65.4 | E15: =MAX(E8:E13) -> 1924.6975 | F15: =MAX(F8:F13) -> 522.4 | G15: =MAX(G8:G13) -> 0 | H15: =MAX(H8:H13) -> 2280.3975 | I15: =MAX(I8:I13) -> 474.6 | J15: =MAX(J8:J13) -> 542.5 | K15: =MAX(K8:K13) -> 616.1 | ... U15: =MAX(U8:U13) -> 2.11
B16: 75th Percentile | D16: =QUARTILE(D8:D13,3) -> 55.225 | E16: =QUARTILE(E8:E13,3) -> 768.15 | F16: =QUARTILE(F8:F13,3) -> 100.0385 | G16: =QUARTILE(G8:G13,3) -> 0 | H16: =QUARTILE(H8:H13,3) -> 631.9785 | I16: =QUARTILE(I8:I13,3) -> 440.0225 | J16: =QUARTILE(J8:J13,3) -> 438.505 | K16: =QUARTILE(K8:K13,3) -> 458.8475 | ... U16: =QUARTILE(U8:U13,3) -> 1.475
B17: Median | D17: =MEDIAN(D8:D13) -> 27.085 | E17: =MEDIAN(E8:E13) -> 633.1184 | F17: =MEDIAN(F8:F13) -> 28.1035 | G17: =MEDIAN(G8:G13) -> 0 | H17: =MEDIAN(H8:H13) -> 550.9389 | I17: =MEDIAN(I8:I13) -> 385.3435 | J17: =MEDIAN(J8:J13) -> 400.24 | K17: =MEDIAN(K8:K13) -> 414.4 | ... U17: =MEDIAN(U8:U13) -> 1.2
B18: 25th Percentile | D18: =QUARTILE(D8:D13,1) -> 7.3675 | E18: =QUARTILE(E8:E13,1) -> 210.3463 | F18: =QUARTILE(F8:F13,1) -> 3.07575 | G18: =QUARTILE(G8:G13,1) -> 0 | H18: =QUARTILE(H8:H13,1) -> 176.92545 | I18: =QUARTILE(I8:I13,1) -> 334.86675 | J18: =QUARTILE(J8:J13,1) -> 332.215 | K18: =QUARTILE(K8:K13,1) -> 350.595 | ... U18: =QUARTILE(U8:U13,1) -> 1.12
B19: Minimum | D19: =MIN(D8:D13) -> 2.2 | E19: =MIN(E8:E13) -> 52.91 | F19: =MIN(F8:F13) -> 0 | G19: =MIN(G8:G13) -> 0 | H19: =MIN(H8:H13) -> 74.6548 | I19: =MIN(I8:I13) -> 127.753 | J19: =MIN(J8:J13) -> 119.63 | K19: =MIN(K8:K13) -> 124.21 | ... U19: =MIN(U8:U13) -> 0.32
B21: Valuation Metrics | E21: Capitalization | I21: EV / | L21: EV /
D22: =$D$6 -> Share | E22: =$E$6 -> Equity | G22: =$G$6 -> Preferred | H22: =$H$6 -> Enterprise | I22: Media Revenue | L22: EBITDA | O22: P/E Multiple
B23: =$B$7 -> Comparable Company | C23: =$C$7 -> Ticker | D23: =$D$7 -> Price | E23: =$E$7 -> Value | F23: =$F$7 -> Debt | G23: =$G$7 -> Stock | H23: =$H$7 -> Value | I23: =$I$7 -> LTM | J23: =$J$7 -> Forward Year 1 | K23: =$K$7 -> Forward Year 2 | L23: =$I$7 -> LTM | M23: =$J$7 -> Forward Year 1 | N23: =$K$7 -> Forward Year 2 | O23: =$I$7 -> LTM | P23: =$J$7 -> Forward Year 1 | Q23: =$K$7 -> Forward Year 2
B24: =B8 -> Corvane Broadcasting Inc | C24: =C8 -> NYSE:CRVB | D24: =D8 -> 19.69 | E24: =E8 -> 1924.6975 | F24: =F8 -> 522.4 | G24: =G8 -> 0 | H24: =H8 -> 2280.3975 | I24: =IFERROR(IF(OR(+$H24/I8<0,+$H24/I8>=100),"NM",+$H24/I8),"N/A") -> 4.8048831 | J24: =IFERROR(IF(OR(+$H24/J8<0,+$H24/J8>=100),"NM",+$H24/J8),"N/A") -> 4.2034977 | K24: =IFERROR(IF(OR(+$H24/K8<0,+$H24/K8>=100),"NM",+$H24/K8),"N/A") -> 3.7013431 | L24: =IFERROR(IF(OR(+$H24/L8<0,+$H24/L8>=100),"NM",+$H24/L8),"N/A") -> 17.899509 | M24: =IFERROR(IF(OR(+$H24/M8<0,+$H24/M8>=100),"NM",+$H24/M8),"N/A") -> 15.880205 | N24: =IFERROR(IF(OR(+$H24/N8<0,+$H24/N8>=100),"NM",+$H24/N8),"N/A") -> 13.44574 | O24: =IFERROR(IF(OR(+$E24/R8<0,+$E24/R8>=100),"NM",+$E24/R8),"N/A") -> 72.925926 | P24: =IFERROR(IF(OR(+$E24/S8<0,+$E24/S8>=100),"NM",+$E24/S8),"N/A") -> 31.253968 | Q24: =IFERROR(IF(OR(+$E24/T8<0,+$E24/T8>=100),"NM",+$E24/T8),"N/A") -> 24.6125
B25: =B9 -> Emberwyck Broadcasting Inc | C25: =C9 -> NASDAQ:EMBW | D25: =D9 -> 62.14 | E25: =E9 -> 671.112 | F25: =F9 -> 118.75 | G25: =G9 -> 0 | H25: =H9 -> 627.582 | I25: =IFERROR(IF(OR(+$H25/I9<0,+$H25/I9>=100),"NM",+$H25/I9),"N/A") -> 1.4070052 | J25: =IFERROR(IF(OR(+$H25/J9<0,+$H25/J9>=100),"NM",+$H25/J9),"N/A") -> 1.4540151 | K25: =IFERROR(IF(OR(+$H25/K9<0,+$H25/K9>=100),"NM",+$H25/K9),"N/A") -> 1.4147475 | L25: =IFERROR(IF(OR(+$H25/L9<0,+$H25/L9>=100),"NM",+$H25/L9),"N/A") -> 6.1301073 | M25: =IFERROR(IF(OR(+$H25/M9<0,+$H25/M9>=100),"NM",+$H25/M9),"N/A") -> 6.5646653 | N25: =IFERROR(IF(OR(+$H25/N9<0,+$H25/N9>=100),"NM",+$H25/N9),"N/A") -> 6.0170853 | O25: =IFERROR(IF(OR(+$E25/R9<0,+$E25/R9>=100),"NM",+$E25/R9),"N/A") -> 14.4761 | P25: =IFERROR(IF(OR(+$E25/S9<0,+$E25/S9>=100),"NM",+$E25/S9),"N/A") -> 18.222874 | Q25: =IFERROR(IF(OR(+$E25/T9<0,+$E25/T9>=100),"NM",+$E25/T9),"N/A") -> 16.182292
B26: =B10 -> Quillhaven Publishing Corp | C26: =C10 -> NASDAQ:QLHV | D26: =D10 -> 65.4 | E26: =E10 -> 800.496 | F26: =F10 -> 0 | G26: =G10 -> 0 | H26: =H10 -> 633.444 | I26: =IFERROR(IF(OR(+$H26/I10<0,+$H26/I10>=100),"NM",+$H26/I10),"N/A") -> 1.5011695 | J26: =IFERROR(IF(OR(+$H26/J10<0,+$H26/J10>=100),"NM",+$H26/J10),"N/A") -> 1.4370327 | K26: =IFERROR(IF(OR(+$H26/K10<0,+$H26/K10>=100),"NM",+$H26/K10),"N/A") -> 1.365387 | L26: =IFERROR(IF(OR(+$H26/L10<0,+$H26/L10>=100),"NM",+$H26/L10),"N/A") -> 6.9929678 | M26: =IFERROR(IF(OR(+$H26/M10<0,+$H26/M10>=100),"NM",+$H26/M10),"N/A") -> 6.6678316 | N26: =IFERROR(IF(OR(+$H26/N10<0,+$H26/N10>=100),"NM",+$H26/N10),"N/A") -> 6.3919677 | O26: =IFERROR(IF(OR(+$E26/R10<0,+$E26/R10>=100),"NM",+$E26/R10),"N/A") -> 21.09733 | P26: =IFERROR(IF(OR(+$E26/S10<0,+$E26/S10>=100),"NM",+$E26/S10),"N/A") -> 18.956522 | Q26: =IFERROR(IF(OR(+$E26/T10<0,+$E26/T10>=100),"NM",+$E26/T10),"N/A") -> 17.210526
B27: =B11 -> Vantablu Streaming, Inc. | C27: =C11 -> NASDAQ:VNBU | D27: =D11 -> 34.48 | E27: =E11 -> 595.1248 | F27: =F11 -> 0 | G27: =G11 -> 0 | H27: =H11 -> 474.2958 | I27: =IFERROR(IF(OR(+$H27/I11<0,+$H27/I11>=100),"NM",+$H27/I11),"N/A") -> 1.360105 | J27: =IFERROR(IF(OR(+$H27/J11<0,+$H27/J11>=100),"NM",+$H27/J11),"N/A") -> 1.2858423 | K27: =IFERROR(IF(OR(+$H27/K11<0,+$H27/K11>=100),"NM",+$H27/K11),"N/A") -> 1.2312975 | L27: =IFERROR(IF(OR(+$H27/L11<0,+$H27/L11>=100),"NM",+$H27/L11),"N/A") -> 6.400753 | M27: =IFERROR(IF(OR(+$H27/M11<0,+$H27/M11>=100),"NM",+$H27/M11),"N/A") -> 6.298749 | N27: =IFERROR(IF(OR(+$H27/N11<0,+$H27/N11>=100),"NM",+$H27/N11),"N/A") -> 5.9212959 | O27: =IFERROR(IF(OR(+$E27/R11<0,+$E27/R11>=100),"NM",+$E27/R11),"N/A") -> 15.744292 | P27: =IFERROR(IF(OR(+$E27/S11<0,+$E27/S11>=100),"NM",+$E27/S11),"N/A") -> 14.548523 | Q27: =IFERROR(IF(OR(+$E27/T11<0,+$E27/T11>=100),"NM",+$E27/T11),"N/A") -> 13.68254
B28: =B12 -> Driftwater Networks Corp | C28: =C12 -> NASDAQ:DFWN | D28: =D12 -> 2.2 | E28: =E12 -> 52.91 | F28: =F12 -> 43.904 | G28: =G12 -> 0 | H28: =H12 -> 77.802 | I28: =IFERROR(IF(OR(+$H28/I12<0,+$H28/I12>=100),"NM",+$H28/I12),"N/A") -> 0.23558588 | J28: =IFERROR(IF(OR(+$H28/J12<0,+$H28/J12>=100),"NM",+$H28/J12),"N/A") -> 0.24313125 | K28: =IFERROR(IF(OR(+$H28/K12<0,+$H28/K12>=100),"NM",+$H28/K12),"N/A") -> 0.22946381 | L28: =IFERROR(IF(OR(+$H28/L12<0,+$H28/L12>=100),"NM",+$H28/L12),"N/A") -> NM | M28: =IFERROR(IF(OR(+$H28/M12<0,+$H28/M12>=100),"NM",+$H28/M12),"N/A") -> NM | N28: =IFERROR(IF(OR(+$H28/N12<0,+$H28/N12>=100),"NM",+$H28/N12),"N/A") -> NM | O28: =IFERROR(IF(OR(+$E28/R12<0,+$E28/R12>=100),"NM",+$E28/R12),"N/A") -> NM | P28: =IFERROR(IF(OR(+$E28/S12<0,+$E28/S12>=100),"NM",+$E28/S12),"N/A") -> NM | Q28: =IFERROR(IF(OR(+$E28/T12<0,+$E28/T12>=100),"NM",+$E28/T12),"N/A") -> NM
B29: =B13 -> Hollowmere Broadcast Group Inc | C29: =C13 -> NASDAQ:HWMB | D29: =D13 -> 3.26 | E29: =E13 -> 82.0868 | F29: =F13 -> 12.303 | G29: =G13 -> 0 | H29: =H13 -> 74.6548 | I29: =IFERROR(IF(OR(+$H29/I13<0,+$H29/I13>=100),"NM",+$H29/I13),"N/A") -> 0.58436827 | J29: =IFERROR(IF(OR(+$H29/J13<0,+$H29/J13>=100),"NM",+$H29/J13),"N/A") -> 0.62404748 | K29: =IFERROR(IF(OR(+$H29/K13<0,+$H29/K13>=100),"NM",+$H29/K13),"N/A") -> 0.60103695 | L29: =IFERROR(IF(OR(+$H29/L13<0,+$H29/L13>=100),"NM",+$H29/L13),"N/A") -> 5.8677042 | M29: =IFERROR(IF(OR(+$H29/M13<0,+$H29/M13>=100),"NM",+$H29/M13),"N/A") -> 6.7256577 | N29: =IFERROR(IF(OR(+$H29/N13<0,+$H29/N13>=100),"NM",+$H29/N13),"N/A") -> 4.9115 | O29: =IFERROR(IF(OR(+$E29/R13<0,+$E29/R13>=100),"NM",+$E29/R13),"N/A") -> 23.669781 | P29: =IFERROR(IF(OR(+$E29/S13<0,+$E29/S13>=100),"NM",+$E29/S13),"N/A") -> 13.583333 | Q29: =IFERROR(IF(OR(+$E29/T13<0,+$E29/T13>=100),"NM",+$E29/T13),"N/A") -> 12.074074
B31: Maximum | D31: =MAX(D24:D29) -> 65.4 | E31: =MAX(E24:E29) -> 1924.6975 | F31: =MAX(F24:F29) -> 522.4 | G31: =MAX(G24:G29) -> 0 | H31: =MAX(H24:H29) -> 2280.3975 | I31: =MAX(I24:I29) -> 4.8048831 | J31: =MAX(J24:J29) -> 4.2034977 | K31: =MAX(K24:K29) -> 3.7013431 | ... Q31: =MAX(Q24:Q29) -> 24.6125
B32: 75th Percentile | D32: =QUARTILE(D24:D29,3) -> 55.225 | E32: =QUARTILE(E24:E29,3) -> 768.15 | F32: =QUARTILE(F24:F29,3) -> 100.0385 | G32: =QUARTILE(G24:G29,3) -> 0 | H32: =QUARTILE(H24:H29,3) -> 631.9785 | I32: =QUARTILE(I24:I29,3) -> 1.4776284 | J32: =QUARTILE(J24:J29,3) -> 1.4497695 | K32: =QUARTILE(K24:K29,3) -> 1.4024074 | ... Q32: =QUARTILE(Q24:Q29,3) -> 17.210526
B33: Median | D33: =MEDIAN(D24:D29) -> 27.085 | E33: =MEDIAN(E24:E29) -> 633.1184 | F33: =MEDIAN(F24:F29) -> 28.1035 | G33: =MEDIAN(G24:G29) -> 0 | H33: =MEDIAN(H24:H29) -> 550.9389 | I33: =MEDIAN(I24:I29) -> 1.3835551 | J33: =MEDIAN(J24:J29) -> 1.3614375 | K33: =MEDIAN(K24:K29) -> 1.2983423 | ... Q33: =MEDIAN(Q24:Q29) -> 16.182292
B34: 25th Percentile | D34: =QUARTILE(D24:D29,1) -> 7.3675 | E34: =QUARTILE(E24:E29,1) -> 210.3463 | F34: =QUARTILE(F24:F29,1) -> 3.07575 | G34: =QUARTILE(G24:G29,1) -> 0 | H34: =QUARTILE(H24:H29,1) -> 176.92545 | I34: =QUARTILE(I24:I29,1) -> 0.77830244 | J34: =QUARTILE(J24:J29,1) -> 0.78949619 | K34: =QUARTILE(K24:K29,1) -> 0.75860209 | ... Q34: =QUARTILE(Q24:Q29,1) -> 13.68254
B35: Minimum | D35: =MIN(D24:D29) -> 2.2 | E35: =MIN(E24:E29) -> 52.91 | F35: =MIN(F24:F29) -> 0 | G35: =MIN(G24:G29) -> 0 | H35: =MIN(H24:H29) -> 74.6548 | I35: =MIN(I24:I29) -> 0.23558588 | J35: =MIN(J24:J29) -> 0.24313125 | K35: =MIN(K24:K29) -> 0.22946381 | ... Q35: =MIN(Q24:Q29) -> 12.074074

Sheet Valuation Bridge
B2: ="Valuation Summary - "&Company_Name -> Valuation Summary - Fennmark Media Partners LLC
B3: ='Books & GAAP Bridge'!$B$196 -> (USD, as stated)
B5: ="Valuation Statistics - "&TEXT(Company_Name,"") -> Valuation Statistics - Fennmark Media Partners LLC | C5: =TEXT(Company_Name,"")&" - Range of Valuation Multiples" -> Fennmark Media Partners LLC - Range of Valuation Multiples | J5: =TEXT(Company_Name,"")&" - Range of Implied Equity Values" -> Fennmark Media Partners LLC - Range of Implied Equity Values
D7: 75th | F7: 25th | H7: Applicable | I7: Private | K7: 25th | M7: 75th
C8: Maximum | D8: Percentile | E8: Median | F8: Percentile | G8: Minimum | H8: Company | I8: Company | J8: Minimum | K8: Percentile | L8: Median | M8: Percentile | N8: Maximum
B9: Method | C9: Multiple | D9: Multiple | E9: Multiple | F9: Multiple | G9: Multiple | H9: Figure | I9: Discount | J9: Multiple | K9: Multiple | L9: Multiple | M9: Multiple | N9: Multiple
B11: Comparable Public Companies:
B12: LTM EV / Media Revenue:
B13: =TEXT('Trading Comps'!$J$7,"yyyy-mm-dd")&" EV / Revenue:" -> Forward Year 1 EV / Revenue:
B14: =TEXT('Trading Comps'!$K$7,"yyyy-mm-dd")&" EV / Revenue:" -> Forward Year 2 EV / Revenue:
B15: LTM EV/EBITDA:
B16: =TEXT('Trading Comps'!$J$7,"yyyy-mm-dd")&" EV / EBITDA:" -> Forward Year 1 EV / EBITDA:
B17: =TEXT('Trading Comps'!$K$7,"yyyy-mm-dd")&" EV / EBITDA:" -> Forward Year 2 EV / EBITDA:
B18: LTM P/E:
B19: =TEXT('Trading Comps'!$J$7,"yyyy-mm-dd")&" Price / Earnings:" -> Forward Year 1 Price / Earnings:
B20: =TEXT('Trading Comps'!$K$7,"yyyy-mm-dd")&" Price / Earnings:" -> Forward Year 2 Price / Earnings:
B22: Comparable Transactions:
B23: LTM EV / Media Revenue: | C23: 2.5 | D23: 1.7 | E23: 1.5 | F23: 1.4 | G23: 0.9
B24: LTM EV/EBITDA: | C24: 13.5 | D24: 12.1 | E24: 11.1 | F24: 10.1 | G24: 8
B26: DCF Analysis:
B27: Discount Rate 13.5%–15.5%, Perpetuity FCF Growth 2.0%–4.0%:
H29: Implied EV or Equity Value Across a Multiple Range:
G31: Enterprise Value →
G32: Enterprise Value →
G33: Enterprise Value →
G34: Enterprise Value →
G35: Enterprise Value →
G36: Enterprise Value →
G38: Equity Value →
G39: Equity Value →
G40: Equity Value →
G41: Equity Value →
G42: Equity Value →
G43: Equity Value →
... G52: Equity Value →
I55: Min | J55: 25th | K55: Median | L55: 75th | M55: Max | N55: Min Point | O55: 25th Point | P55: Median Point | Q55: 75th Point | R55: Max Point
B57: ='Valuation Bridge'!B27 -> Discount Rate 13.5%–15.5%, Perpetuity FCF Growth 2.0%–4.0%:
B59: ='Valuation Bridge'!B24 -> LTM EV/EBITDA:
B60: ='Valuation Bridge'!B23 -> LTM EV / Media Revenue:
B62: ='Valuation Bridge'!B20 -> Forward Year 2 Price / Earnings:
...
