Workbook

Sheet Cover
A1: Cohort Performance Workbook
B7: Workbook Key
B8: 10 | C8: Manual input
B9: 10 | C9: Cross-sheet calculation
B10: 10 | C10: Calculated result
B16: As of: | C16: 45657.333
B17: Model owner: | C17: shortcut.ai

Sheet Monthly Cohorts
B4: ◆ | C4: Monthly Cohort Detail — Actual Values
F6: Calendar Month | G6: =+$D$56 -> 41640 | H6: =+EDATE(G6,1) -> 41671 | I6: =+EDATE(H6,1) -> 41699 | J6: =+EDATE(I6,1) -> 41730 | K6: =+EDATE(J6,1) -> 41760 | L6: =+EDATE(K6,1) -> 41791 | M6: =+EDATE(L6,1) -> 41821 | N6: =+EDATE(M6,1) -> 41852 | O6: =+EDATE(N6,1) -> 41883 | ... DR6: =+EDATE(DQ6,1) -> 45139
D7: Cohort Start Month | E7: Calendar Year | F7: Months Since Start
D8: =+EDATE($D$56,F8) -> 40179 | E8: =+YEAR(D8) -> 2010 | F8: =+F9-1 -> -48
D9: =+EDATE($D$56,F9) -> 40210 | E9: =+YEAR(D9) -> 2010 | F9: =+F10-1 -> -47
D10: =+EDATE($D$56,F10) -> 40238 | E10: =+YEAR(D10) -> 2010 | F10: =+F11-1 -> -46
D11: =+EDATE($D$56,F11) -> 40269 | E11: =+YEAR(D11) -> 2010 | F11: =+F12-1 -> -45
D12: =+EDATE($D$56,F12) -> 40299 | E12: =+YEAR(D12) -> 2010 | F12: =+F13-1 -> -44
D13: =+EDATE($D$56,F13) -> 40330 | E13: =+YEAR(D13) -> 2010 | F13: =+F14-1 -> -43
D14: =+EDATE($D$56,F14) -> 40360 | E14: =+YEAR(D14) -> 2010 | F14: =+F15-1 -> -42
D15: =+EDATE($D$56,F15) -> 40391 | E15: =+YEAR(D15) -> 2010 | F15: =+F16-1 -> -41
D16: =+EDATE($D$56,F16) -> 40422 | E16: =+YEAR(D16) -> 2010 | F16: =+F17-1 -> -40
D17: =+EDATE($D$56,F17) -> 40452 | E17: =+YEAR(D17) -> 2010 | F17: =+F18-1 -> -39
D18: =+EDATE($D$56,F18) -> 40483 | E18: =+YEAR(D18) -> 2010 | F18: =+F19-1 -> -38
D19: =+EDATE($D$56,F19) -> 40513 | E19: =+YEAR(D19) -> 2010 | F19: =+F20-1 -> -37
... D55: =+EDATE($D$56,F55) -> 41609 | E55: =+YEAR(D55) -> 2013 | F55: =+F56-1 -> -1
D56: 41640 | E56: =+YEAR(D56) -> 2014
D57: =+EDATE($D$56,F57) -> 41671 | E57: =+YEAR(D57) -> 2014 | F57: 1
D58: =+EDATE($D$56,F58) -> 41699 | E58: =+YEAR(D58) -> 2014 | F58: =+F57+1 -> 2
D59: =+EDATE($D$56,F59) -> 41730 | E59: =+YEAR(D59) -> 2014 | F59: =+F58+1 -> 3
D60: =+EDATE($D$56,F60) -> 41760 | E60: =+YEAR(D60) -> 2014 | F60: =+F59+1 -> 4
D61: =+EDATE($D$56,F61) -> 41791 | E61: =+YEAR(D61) -> 2014 | F61: =+F60+1 -> 5
D62: =+EDATE($D$56,F62) -> 41821 | E62: =+YEAR(D62) -> 2014 | F62: =+F61+1 -> 6
D63: =+EDATE($D$56,F63) -> 41852 | E63: =+YEAR(D63) -> 2014 | F63: =+F62+1 -> 7
D64: =+EDATE($D$56,F64) -> 41883 | E64: =+YEAR(D64) -> 2014 | F64: =+F63+1 -> 8
D65: =+EDATE($D$56,F65) -> 41913 | E65: =+YEAR(D65) -> 2014 | F65: =+F64+1 -> 9
D66: =+EDATE($D$56,F66) -> 41944 | E66: =+YEAR(D66) -> 2014 | F66: =+F65+1 -> 10
D67: =+EDATE($D$56,F67) -> 41974 | E67: =+YEAR(D67) -> 2014 | F67: =+F66+1 -> 11
D68: =+EDATE($D$56,F68) -> 42005 | E68: =+YEAR(D68) -> 2015 | F68: =+F67+1 -> 12
D69: =+EDATE($D$56,F69) -> 42036 | E69: =+YEAR(D69) -> 2015 | F69: =+F68+1 -> 13
... D171: =+EDATE($D$56,F171) -> 45139 | E171: =+YEAR(D171) -> 2023 | F171: =+F170+1 -> 115
B173: ◆ | C173: Monthly Cohort Detail — Indexed Values
F175: Cohort Month | G175: 1 | H175: =+G175+1 -> 2 | I175: =+H175+1 -> 3 | J175: =+I175+1 -> 4 | K175: =+J175+1 -> 5 | L175: =+K175+1 -> 6 | M175: =+L175+1 -> 7 | N175: =+M175+1 -> 8 | O175: =+N175+1 -> 9 | ... FN175: =+FM175+1 -> 164
F176: Cohort Year | G176: =+ROUNDUP(G175/12,0) -> 1 | H176: =+ROUNDUP(H175/12,0) -> 1 | I176: =+ROUNDUP(I175/12,0) -> 1 | J176: =+ROUNDUP(J175/12,0) -> 1 | K176: =+ROUNDUP(K175/12,0) -> 1 | L176: =+ROUNDUP(L175/12,0) -> 1 | M176: =+ROUNDUP(M175/12,0) -> 1 | N176: =+ROUNDUP(N175/12,0) -> 1 | ... FN176: =+ROUNDUP(FN175/12,0) -> 14
D177: Cohort Start Month | E177: Calendar Year | F177: Months Since Start
D178: =+D8 -> 40179 | E178: =+YEAR(D178) -> 2010 | F178: =+F8 -> -48 | G178: =+IF(OR($F178+G$175<1,(G$176-1)*12<-$F178),0,OFFSET(G8,0,$F178)) -> 0 | H178: =+IF(OR($F178+H$175<1,(H$176-1)*12<-$F178),0,OFFSET(H8,0,$F178)) -> 0 | I178: =+IF(OR($F178+I$175<1,(I$176-1)*12<-$F178),0,OFFSET(I8,0,$F178)) -> 0 | J178: =+IF(OR($F178+J$175<1,(J$176-1)*12<-$F178),0,OFFSET(J8,0,$F178)) -> 0 | K178: =+IF(OR($F178+K$175<1,(K$176-1)*12<-$F178),0,OFFSET(K8,0,$F178)) -> 0 | L178: =+IF(OR($F178+L$175<1,(L$176-1)*12<-$F178),0,OFFSET(L8,0,$F178)) -> 0 | M178: =+IF(OR($F178+M$175<1,(M$176-1)*12<-$F178),0,OFFSET(M8,0,$F178)) -> 0 | N178: =+IF(OR($F178+N$175<1,(N$176-1)*12<-$F178),0,OFFSET(N8,0,$F178)) -> 0 | ... FN178: =+IF(OR($F178+FN$175<1,(FN$176-1)*12<-$F178),0,OFFSET(FN8,0,$F178)) -> 0
D179: =+D9 -> 40210 | E179: =+YEAR(D179) -> 2010 | F179: =+F9 -> -47 | G179: =+IF(OR($F179+G$175<1,(G$176-1)*12<-$F179),0,OFFSET(G9,0,$F179)) -> 0 | H179: =+IF(OR($F179+H$175<1,(H$176-1)*12<-$F179),0,OFFSET(H9,0,$F179)) -> 0 | I179: =+IF(OR($F179+I$175<1,(I$176-1)*12<-$F179),0,OFFSET(I9,0,$F179)) -> 0 | J179: =+IF(OR($F179+J$175<1,(J$176-1)*12<-$F179),0,OFFSET(J9,0,$F179)) -> 0 | K179: =+IF(OR($F179+K$175<1,(K$176-1)*12<-$F179),0,OFFSET(K9,0,$F179)) -> 0 | L179: =+IF(OR($F179+L$175<1,(L$176-1)*12<-$F179),0,OFFSET(L9,0,$F179)) -> 0 | M179: =+IF(OR($F179+M$175<1,(M$176-1)*12<-$F179),0,OFFSET(M9,0,$F179)) -> 0 | N179: =+IF(OR($F179+N$175<1,(N$176-1)*12<-$F179),0,OFFSET(N9,0,$F179)) -> 0 | ... FN179: =+IF(OR($F179+FN$175<1,(FN$176-1)*12<-$F179),0,OFFSET(FN9,0,$F179)) -> 0
D180: =+D10 -> 40238 | E180: =+YEAR(D180) -> 2010 | F180: =+F10 -> -46 | G180: =+IF(OR($F180+G$175<1,(G$176-1)*12<-$F180),0,OFFSET(G10,0,$F180)) -> 0 | H180: =+IF(OR($F180+H$175<1,(H$176-1)*12<-$F180),0,OFFSET(H10,0,$F180)) -> 0 | I180: =+IF(OR($F180+I$175<1,(I$176-1)*12<-$F180),0,OFFSET(I10,0,$F180)) -> 0 | J180: =+IF(OR($F180+J$175<1,(J$176-1)*12<-$F180),0,OFFSET(J10,0,$F180)) -> 0 | K180: =+IF(OR($F180+K$175<1,(K$176-1)*12<-$F180),0,OFFSET(K10,0,$F180)) -> 0 | L180: =+IF(OR($F180+L$175<1,(L$176-1)*12<-$F180),0,OFFSET(L10,0,$F180)) -> 0 | M180: =+IF(OR($F180+M$175<1,(M$176-1)*12<-$F180),0,OFFSET(M10,0,$F180)) -> 0 | N180: =+IF(OR($F180+N$175<1,(N$176-1)*12<-$F180),0,OFFSET(N10,0,$F180)) -> 0 | ... FN180: =+IF(OR($F180+FN$175<1,(FN$176-1)*12<-$F180),0,OFFSET(FN10,0,$F180)) -> 0
D181: =+D11 -> 40269 | E181: =+YEAR(D181) -> 2010 | F181: =+F11 -> -45 | G181: =+IF(OR($F181+G$175<1,(G$176-1)*12<-$F181),0,OFFSET(G11,0,$F181)) -> 0 | H181: =+IF(OR($F181+H$175<1,(H$176-1)*12<-$F181),0,OFFSET(H11,0,$F181)) -> 0 | I181: =+IF(OR($F181+I$175<1,(I$176-1)*12<-$F181),0,OFFSET(I11,0,$F181)) -> 0 | J181: =+IF(OR($F181+J$175<1,(J$176-1)*12<-$F181),0,OFFSET(J11,0,$F181)) -> 0 | K181: =+IF(OR($F181+K$175<1,(K$176-1)*12<-$F181),0,OFFSET(K11,0,$F181)) -> 0 | L181: =+IF(OR($F181+L$175<1,(L$176-1)*12<-$F181),0,OFFSET(L11,0,$F181)) -> 0 | M181: =+IF(OR($F181+M$175<1,(M$176-1)*12<-$F181),0,OFFSET(M11,0,$F181)) -> 0 | N181: =+IF(OR($F181+N$175<1,(N$176-1)*12<-$F181),0,OFFSET(N11,0,$F181)) -> 0 | ... FN181: =+IF(OR($F181+FN$175<1,(FN$176-1)*12<-$F181),0,OFFSET(FN11,0,$F181)) -> 0
D182: =+D12 -> 40299 | E182: =+YEAR(D182) -> 2010 | F182: =+F12 -> -44 | G182: =+IF(OR($F182+G$175<1,(G$176-1)*12<-$F182),0,OFFSET(G12,0,$F182)) -> 0 | H182: =+IF(OR($F182+H$175<1,(H$176-1)*12<-$F182),0,OFFSET(H12,0,$F182)) -> 0 | I182: =+IF(OR($F182+I$175<1,(I$176-1)*12<-$F182),0,OFFSET(I12,0,$F182)) -> 0 | J182: =+IF(OR($F182+J$175<1,(J$176-1)*12<-$F182),0,OFFSET(J12,0,$F182)) -> 0 | K182: =+IF(OR($F182+K$175<1,(K$176-1)*12<-$F182),0,OFFSET(K12,0,$F182)) -> 0 | L182: =+IF(OR($F182+L$175<1,(L$176-1)*12<-$F182),0,OFFSET(L12,0,$F182)) -> 0 | M182: =+IF(OR($F182+M$175<1,(M$176-1)*12<-$F182),0,OFFSET(M12,0,$F182)) -> 0 | N182: =+IF(OR($F182+N$175<1,(N$176-1)*12<-$F182),0,OFFSET(N12,0,$F182)) -> 0 | ... FN182: =+IF(OR($F182+FN$175<1,(FN$176-1)*12<-$F182),0,OFFSET(FN12,0,$F182)) -> 0
...

Sheet Annual Cohorts
B5: ◆ | C5: Yearly Cohorts — Indexed (Monthly Basis)
F7: Cohort Month | G7: 1 | H7: =+G7+1 -> 2 | I7: =+H7+1 -> 3 | J7: =+I7+1 -> 4 | K7: =+J7+1 -> 5 | L7: =+K7+1 -> 6 | M7: =+L7+1 -> 7 | N7: =+M7+1 -> 8 | O7: =+N7+1 -> 9 | ... FN7: =+FM7+1 -> 164
F8: Cohort Year | G8: =+ROUNDUP(G7/12,0) -> 1 | H8: =+ROUNDUP(H7/12,0) -> 1 | I8: =+ROUNDUP(I7/12,0) -> 1 | J8: =+ROUNDUP(J7/12,0) -> 1 | K8: =+ROUNDUP(K7/12,0) -> 1 | L8: =+ROUNDUP(L7/12,0) -> 1 | M8: =+ROUNDUP(M7/12,0) -> 1 | N8: =+ROUNDUP(N7/12,0) -> 1 | ... FN8: =+ROUNDUP(FN7/12,0) -> 14
D9: Cohort Start Month
D10: 2010 | G10: =+SUMIF('Monthly Cohorts'!$E$178:'Monthly Cohorts'!$E$341,$D10,'Monthly Cohorts'!G$178:'Monthly Cohorts'!G$341) -> 0 | H10: =+SUMIF('Monthly Cohorts'!$E$178:'Monthly Cohorts'!$E$341,$D10,'Monthly Cohorts'!H$178:'Monthly Cohorts'!H$341) -> 0 | I10: =+SUMIF('Monthly Cohorts'!$E$178:'Monthly Cohorts'!$E$341,$D10,'Monthly Cohorts'!I$178:'Monthly Cohorts'!I$341) -> 0 | J10: =+SUMIF('Monthly Cohorts'!$E$178:'Monthly Cohorts'!$E$341,$D10,'Monthly Cohorts'!J$178:'Monthly Cohorts'!J$341) -> 0 | K10: =+SUMIF('Monthly Cohorts'!$E$178:'Monthly Cohorts'!$E$341,$D10,'Monthly Cohorts'!K$178:'Monthly Cohorts'!K$341) -> 0 | L10: =+SUMIF('Monthly Cohorts'!$E$178:'Monthly Cohorts'!$E$341,$D10,'Monthly Cohorts'!L$178:'Monthly Cohorts'!L$341) -> 0 | M10: =+SUMIF('Monthly Cohorts'!$E$178:'Monthly Cohorts'!$E$341,$D10,'Monthly Cohorts'!M$178:'Monthly Cohorts'!M$341) -> 0 | N10: =+SUMIF('Monthly Cohorts'!$E$178:'Monthly Cohorts'!$E$341,$D10,'Monthly Cohorts'!N$178:'Monthly Cohorts'!N$341) -> 0 | ... FN10: =+SUMIF('Monthly Cohorts'!$E$178:'Monthly Cohorts'!$E$341,$D10,'Monthly Cohorts'!FN$178:'Monthly Cohorts'!FN$341) -> 0
D11: =+D10+1 -> 2011 | G11: =+SUMIF('Monthly Cohorts'!$E$178:'Monthly Cohorts'!$E$341,$D11,'Monthly Cohorts'!G$178:'Monthly Cohorts'!G$341) -> 0 | H11: =+SUMIF('Monthly Cohorts'!$E$178:'Monthly Cohorts'!$E$341,$D11,'Monthly Cohorts'!H$178:'Monthly Cohorts'!H$341) -> 0 | I11: =+SUMIF('Monthly Cohorts'!$E$178:'Monthly Cohorts'!$E$341,$D11,'Monthly Cohorts'!I$178:'Monthly Cohorts'!I$341) -> 0 | J11: =+SUMIF('Monthly Cohorts'!$E$178:'Monthly Cohorts'!$E$341,$D11,'Monthly Cohorts'!J$178:'Monthly Cohorts'!J$341) -> 0 | K11: =+SUMIF('Monthly Cohorts'!$E$178:'Monthly Cohorts'!$E$341,$D11,'Monthly Cohorts'!K$178:'Monthly Cohorts'!K$341) -> 0 | L11: =+SUMIF('Monthly Cohorts'!$E$178:'Monthly Cohorts'!$E$341,$D11,'Monthly Cohorts'!L$178:'Monthly Cohorts'!L$341) -> 0 | M11: =+SUMIF('Monthly Cohorts'!$E$178:'Monthly Cohorts'!$E$341,$D11,'Monthly Cohorts'!M$178:'Monthly Cohorts'!M$341) -> 0 | N11: =+SUMIF('Monthly Cohorts'!$E$178:'Monthly Cohorts'!$E$341,$D11,'Monthly Cohorts'!N$178:'Monthly Cohorts'!N$341) -> 0 | ... FN11: =+SUMIF('Monthly Cohorts'!$E$178:'Monthly Cohorts'!$E$341,$D11,'Monthly Cohorts'!FN$178:'Monthly Cohorts'!FN$341) -> 0
D12: =+D11+1 -> 2012 | G12: =+SUMIF('Monthly Cohorts'!$E$178:'Monthly Cohorts'!$E$341,$D12,'Monthly Cohorts'!G$178:'Monthly Cohorts'!G$341) -> 0 | H12: =+SUMIF('Monthly Cohorts'!$E$178:'Monthly Cohorts'!$E$341,$D12,'Monthly Cohorts'!H$178:'Monthly Cohorts'!H$341) -> 0 | I12: =+SUMIF('Monthly Cohorts'!$E$178:'Monthly Cohorts'!$E$341,$D12,'Monthly Cohorts'!I$178:'Monthly Cohorts'!I$341) -> 0 | J12: =+SUMIF('Monthly Cohorts'!$E$178:'Monthly Cohorts'!$E$341,$D12,'Monthly Cohorts'!J$178:'Monthly Cohorts'!J$341) -> 0 | K12: =+SUMIF('Monthly Cohorts'!$E$178:'Monthly Cohorts'!$E$341,$D12,'Monthly Cohorts'!K$178:'Monthly Cohorts'!K$341) -> 0 | L12: =+SUMIF('Monthly Cohorts'!$E$178:'Monthly Cohorts'!$E$341,$D12,'Monthly Cohorts'!L$178:'Monthly Cohorts'!L$341) -> 0 | M12: =+SUMIF('Monthly Cohorts'!$E$178:'Monthly Cohorts'!$E$341,$D12,'Monthly Cohorts'!M$178:'Monthly Cohorts'!M$341) -> 0 | N12: =+SUMIF('Monthly Cohorts'!$E$178:'Monthly Cohorts'!$E$341,$D12,'Monthly Cohorts'!N$178:'Monthly Cohorts'!N$341) -> 0 | ... FN12: =+SUMIF('Monthly Cohorts'!$E$178:'Monthly Cohorts'!$E$341,$D12,'Monthly Cohorts'!FN$178:'Monthly Cohorts'!FN$341) -> 0
D13: =+D12+1 -> 2013 | G13: =+SUMIF('Monthly Cohorts'!$E$178:'Monthly Cohorts'!$E$341,$D13,'Monthly Cohorts'!G$178:'Monthly Cohorts'!G$341) -> 0 | H13: =+SUMIF('Monthly Cohorts'!$E$178:'Monthly Cohorts'!$E$341,$D13,'Monthly Cohorts'!H$178:'Monthly Cohorts'!H$341) -> 0 | I13: =+SUMIF('Monthly Cohorts'!$E$178:'Monthly Cohorts'!$E$341,$D13,'Monthly Cohorts'!I$178:'Monthly Cohorts'!I$341) -> 0 | J13: =+SUMIF('Monthly Cohorts'!$E$178:'Monthly Cohorts'!$E$341,$D13,'Monthly Cohorts'!J$178:'Monthly Cohorts'!J$341) -> 0 | K13: =+SUMIF('Monthly Cohorts'!$E$178:'Monthly Cohorts'!$E$341,$D13,'Monthly Cohorts'!K$178:'Monthly Cohorts'!K$341) -> 0 | L13: =+SUMIF('Monthly Cohorts'!$E$178:'Monthly Cohorts'!$E$341,$D13,'Monthly Cohorts'!L$178:'Monthly Cohorts'!L$341) -> 0 | M13: =+SUMIF('Monthly Cohorts'!$E$178:'Monthly Cohorts'!$E$341,$D13,'Monthly Cohorts'!M$178:'Monthly Cohorts'!M$341) -> 0 | N13: =+SUMIF('Monthly Cohorts'!$E$178:'Monthly Cohorts'!$E$341,$D13,'Monthly Cohorts'!N$178:'Monthly Cohorts'!N$341) -> 0 | ... FN13: =+SUMIF('Monthly Cohorts'!$E$178:'Monthly Cohorts'!$E$341,$D13,'Monthly Cohorts'!FN$178:'Monthly Cohorts'!FN$341) -> 0
D14: =+D13+1 -> 2014 | G14: =+SUMIF('Monthly Cohorts'!$E$178:'Monthly Cohorts'!$E$341,$D14,'Monthly Cohorts'!G$178:'Monthly Cohorts'!G$341) -> 0 | H14: =+SUMIF('Monthly Cohorts'!$E$178:'Monthly Cohorts'!$E$341,$D14,'Monthly Cohorts'!H$178:'Monthly Cohorts'!H$341) -> 0 | I14: =+SUMIF('Monthly Cohorts'!$E$178:'Monthly Cohorts'!$E$341,$D14,'Monthly Cohorts'!I$178:'Monthly Cohorts'!I$341) -> 0 | J14: =+SUMIF('Monthly Cohorts'!$E$178:'Monthly Cohorts'!$E$341,$D14,'Monthly Cohorts'!J$178:'Monthly Cohorts'!J$341) -> 0 | K14: =+SUMIF('Monthly Cohorts'!$E$178:'Monthly Cohorts'!$E$341,$D14,'Monthly Cohorts'!K$178:'Monthly Cohorts'!K$341) -> 0 | L14: =+SUMIF('Monthly Cohorts'!$E$178:'Monthly Cohorts'!$E$341,$D14,'Monthly Cohorts'!L$178:'Monthly Cohorts'!L$341) -> 0 | M14: =+SUMIF('Monthly Cohorts'!$E$178:'Monthly Cohorts'!$E$341,$D14,'Monthly Cohorts'!M$178:'Monthly Cohorts'!M$341) -> 0 | N14: =+SUMIF('Monthly Cohorts'!$E$178:'Monthly Cohorts'!$E$341,$D14,'Monthly Cohorts'!N$178:'Monthly Cohorts'!N$341) -> 0 | ... FN14: =+SUMIF('Monthly Cohorts'!$E$178:'Monthly Cohorts'!$E$341,$D14,'Monthly Cohorts'!FN$178:'Monthly Cohorts'!FN$341) -> 0
D15: =+D14+1 -> 2015 | G15: =+SUMIF('Monthly Cohorts'!$E$178:'Monthly Cohorts'!$E$341,$D15,'Monthly Cohorts'!G$178:'Monthly Cohorts'!G$341) -> 0 | H15: =+SUMIF('Monthly Cohorts'!$E$178:'Monthly Cohorts'!$E$341,$D15,'Monthly Cohorts'!H$178:'Monthly Cohorts'!H$341) -> 0 | I15: =+SUMIF('Monthly Cohorts'!$E$178:'Monthly Cohorts'!$E$341,$D15,'Monthly Cohorts'!I$178:'Monthly Cohorts'!I$341) -> 0 | J15: =+SUMIF('Monthly Cohorts'!$E$178:'Monthly Cohorts'!$E$341,$D15,'Monthly Cohorts'!J$178:'Monthly Cohorts'!J$341) -> 0 | K15: =+SUMIF('Monthly Cohorts'!$E$178:'Monthly Cohorts'!$E$341,$D15,'Monthly Cohorts'!K$178:'Monthly Cohorts'!K$341) -> 0 | L15: =+SUMIF('Monthly Cohorts'!$E$178:'Monthly Cohorts'!$E$341,$D15,'Monthly Cohorts'!L$178:'Monthly Cohorts'!L$341) -> 0 | M15: =+SUMIF('Monthly Cohorts'!$E$178:'Monthly Cohorts'!$E$341,$D15,'Monthly Cohorts'!M$178:'Monthly Cohorts'!M$341) -> 0 | N15: =+SUMIF('Monthly Cohorts'!$E$178:'Monthly Cohorts'!$E$341,$D15,'Monthly Cohorts'!N$178:'Monthly Cohorts'!N$341) -> 0 | ... FN15: =+SUMIF('Monthly Cohorts'!$E$178:'Monthly Cohorts'!$E$341,$D15,'Monthly Cohorts'!FN$178:'Monthly Cohorts'!FN$341) -> 0
D16: =+D15+1 -> 2016 | G16: =+SUMIF('Monthly Cohorts'!$E$178:'Monthly Cohorts'!$E$341,$D16,'Monthly Cohorts'!G$178:'Monthly Cohorts'!G$341) -> 0 | H16: =+SUMIF('Monthly Cohorts'!$E$178:'Monthly Cohorts'!$E$341,$D16,'Monthly Cohorts'!H$178:'Monthly Cohorts'!H$341) -> 0 | I16: =+SUMIF('Monthly Cohorts'!$E$178:'Monthly Cohorts'!$E$341,$D16,'Monthly Cohorts'!I$178:'Monthly Cohorts'!I$341) -> 0 | J16: =+SUMIF('Monthly Cohorts'!$E$178:'Monthly Cohorts'!$E$341,$D16,'Monthly Cohorts'!J$178:'Monthly Cohorts'!J$341) -> 0 | K16: =+SUMIF('Monthly Cohorts'!$E$178:'Monthly Cohorts'!$E$341,$D16,'Monthly Cohorts'!K$178:'Monthly Cohorts'!K$341) -> 0 | L16: =+SUMIF('Monthly Cohorts'!$E$178:'Monthly Cohorts'!$E$341,$D16,'Monthly Cohorts'!L$178:'Monthly Cohorts'!L$341) -> 0 | M16: =+SUMIF('Monthly Cohorts'!$E$178:'Monthly Cohorts'!$E$341,$D16,'Monthly Cohorts'!M$178:'Monthly Cohorts'!M$341) -> 0 | N16: =+SUMIF('Monthly Cohorts'!$E$178:'Monthly Cohorts'!$E$341,$D16,'Monthly Cohorts'!N$178:'Monthly Cohorts'!N$341) -> 0 | ... FN16: =+SUMIF('Monthly Cohorts'!$E$178:'Monthly Cohorts'!$E$341,$D16,'Monthly Cohorts'!FN$178:'Monthly Cohorts'!FN$341) -> 0
D17: =+D16+1 -> 2017 | G17: =+SUMIF('Monthly Cohorts'!$E$178:'Monthly Cohorts'!$E$341,$D17,'Monthly Cohorts'!G$178:'Monthly Cohorts'!G$341) -> 0 | H17: =+SUMIF('Monthly Cohorts'!$E$178:'Monthly Cohorts'!$E$341,$D17,'Monthly Cohorts'!H$178:'Monthly Cohorts'!H$341) -> 0 | I17: =+SUMIF('Monthly Cohorts'!$E$178:'Monthly Cohorts'!$E$341,$D17,'Monthly Cohorts'!I$178:'Monthly Cohorts'!I$341) -> 0 | J17: =+SUMIF('Monthly Cohorts'!$E$178:'Monthly Cohorts'!$E$341,$D17,'Monthly Cohorts'!J$178:'Monthly Cohorts'!J$341) -> 0 | K17: =+SUMIF('Monthly Cohorts'!$E$178:'Monthly Cohorts'!$E$341,$D17,'Monthly Cohorts'!K$178:'Monthly Cohorts'!K$341) -> 0 | L17: =+SUMIF('Monthly Cohorts'!$E$178:'Monthly Cohorts'!$E$341,$D17,'Monthly Cohorts'!L$178:'Monthly Cohorts'!L$341) -> 0 | M17: =+SUMIF('Monthly Cohorts'!$E$178:'Monthly Cohorts'!$E$341,$D17,'Monthly Cohorts'!M$178:'Monthly Cohorts'!M$341) -> 0 | N17: =+SUMIF('Monthly Cohorts'!$E$178:'Monthly Cohorts'!$E$341,$D17,'Monthly Cohorts'!N$178:'Monthly Cohorts'!N$341) -> 0 | ... FN17: =+SUMIF('Monthly Cohorts'!$E$178:'Monthly Cohorts'!$E$341,$D17,'Monthly Cohorts'!FN$178:'Monthly Cohorts'!FN$341) -> 0
D18: =+D17+1 -> 2018 | G18: =+SUMIF('Monthly Cohorts'!$E$178:'Monthly Cohorts'!$E$341,$D18,'Monthly Cohorts'!G$178:'Monthly Cohorts'!G$341) -> 0 | H18: =+SUMIF('Monthly Cohorts'!$E$178:'Monthly Cohorts'!$E$341,$D18,'Monthly Cohorts'!H$178:'Monthly Cohorts'!H$341) -> 0 | I18: =+SUMIF('Monthly Cohorts'!$E$178:'Monthly Cohorts'!$E$341,$D18,'Monthly Cohorts'!I$178:'Monthly Cohorts'!I$341) -> 0 | J18: =+SUMIF('Monthly Cohorts'!$E$178:'Monthly Cohorts'!$E$341,$D18,'Monthly Cohorts'!J$178:'Monthly Cohorts'!J$341) -> 0 | K18: =+SUMIF('Monthly Cohorts'!$E$178:'Monthly Cohorts'!$E$341,$D18,'Monthly Cohorts'!K$178:'Monthly Cohorts'!K$341) -> 0 | L18: =+SUMIF('Monthly Cohorts'!$E$178:'Monthly Cohorts'!$E$341,$D18,'Monthly Cohorts'!L$178:'Monthly Cohorts'!L$341) -> 0 | M18: =+SUMIF('Monthly Cohorts'!$E$178:'Monthly Cohorts'!$E$341,$D18,'Monthly Cohorts'!M$178:'Monthly Cohorts'!M$341) -> 0 | N18: =+SUMIF('Monthly Cohorts'!$E$178:'Monthly Cohorts'!$E$341,$D18,'Monthly Cohorts'!N$178:'Monthly Cohorts'!N$341) -> 0 | ... FN18: =+SUMIF('Monthly Cohorts'!$E$178:'Monthly Cohorts'!$E$341,$D18,'Monthly Cohorts'!FN$178:'Monthly Cohorts'!FN$341) -> 0
D19: =+D18+1 -> 2019 | G19: =+SUMIF('Monthly Cohorts'!$E$178:'Monthly Cohorts'!$E$341,$D19,'Monthly Cohorts'!G$178:'Monthly Cohorts'!G$341) -> 0 | H19: =+SUMIF('Monthly Cohorts'!$E$178:'Monthly Cohorts'!$E$341,$D19,'Monthly Cohorts'!H$178:'Monthly Cohorts'!H$341) -> 0 | I19: =+SUMIF('Monthly Cohorts'!$E$178:'Monthly Cohorts'!$E$341,$D19,'Monthly Cohorts'!I$178:'Monthly Cohorts'!I$341) -> 0 | J19: =+SUMIF('Monthly Cohorts'!$E$178:'Monthly Cohorts'!$E$341,$D19,'Monthly Cohorts'!J$178:'Monthly Cohorts'!J$341) -> 0 | K19: =+SUMIF('Monthly Cohorts'!$E$178:'Monthly Cohorts'!$E$341,$D19,'Monthly Cohorts'!K$178:'Monthly Cohorts'!K$341) -> 0 | L19: =+SUMIF('Monthly Cohorts'!$E$178:'Monthly Cohorts'!$E$341,$D19,'Monthly Cohorts'!L$178:'Monthly Cohorts'!L$341) -> 0 | M19: =+SUMIF('Monthly Cohorts'!$E$178:'Monthly Cohorts'!$E$341,$D19,'Monthly Cohorts'!M$178:'Monthly Cohorts'!M$341) -> 0 | N19: =+SUMIF('Monthly Cohorts'!$E$178:'Monthly Cohorts'!$E$341,$D19,'Monthly Cohorts'!N$178:'Monthly Cohorts'!N$341) -> 0 | ... FN19: =+SUMIF('Monthly Cohorts'!$E$178:'Monthly Cohorts'!$E$341,$D19,'Monthly Cohorts'!FN$178:'Monthly Cohorts'!FN$341) -> 0
D20: =+D19+1 -> 2020 | G20: =+SUMIF('Monthly Cohorts'!$E$178:'Monthly Cohorts'!$E$341,$D20,'Monthly Cohorts'!G$178:'Monthly Cohorts'!G$341) -> 0 | H20: =+SUMIF('Monthly Cohorts'!$E$178:'Monthly Cohorts'!$E$341,$D20,'Monthly Cohorts'!H$178:'Monthly Cohorts'!H$341) -> 0 | I20: =+SUMIF('Monthly Cohorts'!$E$178:'Monthly Cohorts'!$E$341,$D20,'Monthly Cohorts'!I$178:'Monthly Cohorts'!I$341) -> 0 | J20: =+SUMIF('Monthly Cohorts'!$E$178:'Monthly Cohorts'!$E$341,$D20,'Monthly Cohorts'!J$178:'Monthly Cohorts'!J$341) -> 0 | K20: =+SUMIF('Monthly Cohorts'!$E$178:'Monthly Cohorts'!$E$341,$D20,'Monthly Cohorts'!K$178:'Monthly Cohorts'!K$341) -> 0 | L20: =+SUMIF('Monthly Cohorts'!$E$178:'Monthly Cohorts'!$E$341,$D20,'Monthly Cohorts'!L$178:'Monthly Cohorts'!L$341) -> 0 | M20: =+SUMIF('Monthly Cohorts'!$E$178:'Monthly Cohorts'!$E$341,$D20,'Monthly Cohorts'!M$178:'Monthly Cohorts'!M$341) -> 0 | N20: =+SUMIF('Monthly Cohorts'!$E$178:'Monthly Cohorts'!$E$341,$D20,'Monthly Cohorts'!N$178:'Monthly Cohorts'!N$341) -> 0 | ... FN20: =+SUMIF('Monthly Cohorts'!$E$178:'Monthly Cohorts'!$E$341,$D20,'Monthly Cohorts'!FN$178:'Monthly Cohorts'!FN$341) -> 0
D21: =+D20+1 -> 2021 | G21: =+SUMIF('Monthly Cohorts'!$E$178:'Monthly Cohorts'!$E$341,$D21,'Monthly Cohorts'!G$178:'Monthly Cohorts'!G$341) -> 0 | H21: =+SUMIF('Monthly Cohorts'!$E$178:'Monthly Cohorts'!$E$341,$D21,'Monthly Cohorts'!H$178:'Monthly Cohorts'!H$341) -> 0 | I21: =+SUMIF('Monthly Cohorts'!$E$178:'Monthly Cohorts'!$E$341,$D21,'Monthly Cohorts'!I$178:'Monthly Cohorts'!I$341) -> 0 | J21: =+SUMIF('Monthly Cohorts'!$E$178:'Monthly Cohorts'!$E$341,$D21,'Monthly Cohorts'!J$178:'Monthly Cohorts'!J$341) -> 0 | K21: =+SUMIF('Monthly Cohorts'!$E$178:'Monthly Cohorts'!$E$341,$D21,'Monthly Cohorts'!K$178:'Monthly Cohorts'!K$341) -> 0 | L21: =+SUMIF('Monthly Cohorts'!$E$178:'Monthly Cohorts'!$E$341,$D21,'Monthly Cohorts'!L$178:'Monthly Cohorts'!L$341) -> 0 | M21: =+SUMIF('Monthly Cohorts'!$E$178:'Monthly Cohorts'!$E$341,$D21,'Monthly Cohorts'!M$178:'Monthly Cohorts'!M$341) -> 0 | N21: =+SUMIF('Monthly Cohorts'!$E$178:'Monthly Cohorts'!$E$341,$D21,'Monthly Cohorts'!N$178:'Monthly Cohorts'!N$341) -> 0 | ... FN21: =+SUMIF('Monthly Cohorts'!$E$178:'Monthly Cohorts'!$E$341,$D21,'Monthly Cohorts'!FN$178:'Monthly Cohorts'!FN$341) -> 0
D22: =+D21+1 -> 2022 | G22: =+SUMIF('Monthly Cohorts'!$E$178:'Monthly Cohorts'!$E$341,$D22,'Monthly Cohorts'!G$178:'Monthly Cohorts'!G$341) -> 0 | H22: =+SUMIF('Monthly Cohorts'!$E$178:'Monthly Cohorts'!$E$341,$D22,'Monthly Cohorts'!H$178:'Monthly Cohorts'!H$341) -> 0 | I22: =+SUMIF('Monthly Cohorts'!$E$178:'Monthly Cohorts'!$E$341,$D22,'Monthly Cohorts'!I$178:'Monthly Cohorts'!I$341) -> 0 | J22: =+SUMIF('Monthly Cohorts'!$E$178:'Monthly Cohorts'!$E$341,$D22,'Monthly Cohorts'!J$178:'Monthly Cohorts'!J$341) -> 0 | K22: =+SUMIF('Monthly Cohorts'!$E$178:'Monthly Cohorts'!$E$341,$D22,'Monthly Cohorts'!K$178:'Monthly Cohorts'!K$341) -> 0 | L22: =+SUMIF('Monthly Cohorts'!$E$178:'Monthly Cohorts'!$E$341,$D22,'Monthly Cohorts'!L$178:'Monthly Cohorts'!L$341) -> 0 | M22: =+SUMIF('Monthly Cohorts'!$E$178:'Monthly Cohorts'!$E$341,$D22,'Monthly Cohorts'!M$178:'Monthly Cohorts'!M$341) -> 0 | N22: =+SUMIF('Monthly Cohorts'!$E$178:'Monthly Cohorts'!$E$341,$D22,'Monthly Cohorts'!N$178:'Monthly Cohorts'!N$341) -> 0 | ... FN22: =+SUMIF('Monthly Cohorts'!$E$178:'Monthly Cohorts'!$E$341,$D22,'Monthly Cohorts'!FN$178:'Monthly Cohorts'!FN$341) -> 0
D23: =+D22+1 -> 2023 | G23: =+SUMIF('Monthly Cohorts'!$E$178:'Monthly Cohorts'!$E$341,$D23,'Monthly Cohorts'!G$178:'Monthly Cohorts'!G$341) -> 0 | H23: =+SUMIF('Monthly Cohorts'!$E$178:'Monthly Cohorts'!$E$341,$D23,'Monthly Cohorts'!H$178:'Monthly Cohorts'!H$341) -> 0 | I23: =+SUMIF('Monthly Cohorts'!$E$178:'Monthly Cohorts'!$E$341,$D23,'Monthly Cohorts'!I$178:'Monthly Cohorts'!I$341) -> 0 | J23: =+SUMIF('Monthly Cohorts'!$E$178:'Monthly Cohorts'!$E$341,$D23,'Monthly Cohorts'!J$178:'Monthly Cohorts'!J$341) -> 0 | K23: =+SUMIF('Monthly Cohorts'!$E$178:'Monthly Cohorts'!$E$341,$D23,'Monthly Cohorts'!K$178:'Monthly Cohorts'!K$341) -> 0 | L23: =+SUMIF('Monthly Cohorts'!$E$178:'Monthly Cohorts'!$E$341,$D23,'Monthly Cohorts'!L$178:'Monthly Cohorts'!L$341) -> 0 | M23: =+SUMIF('Monthly Cohorts'!$E$178:'Monthly Cohorts'!$E$341,$D23,'Monthly Cohorts'!M$178:'Monthly Cohorts'!M$341) -> 0 | N23: =+SUMIF('Monthly Cohorts'!$E$178:'Monthly Cohorts'!$E$341,$D23,'Monthly Cohorts'!N$178:'Monthly Cohorts'!N$341) -> 0 | ... FN23: =+SUMIF('Monthly Cohorts'!$E$178:'Monthly Cohorts'!$E$341,$D23,'Monthly Cohorts'!FN$178:'Monthly Cohorts'!FN$341) -> 0
B25: ◆ | C25: Yearly Cohorts — Indexed (Annual Basis)
C27: ◆ | D27: Cohort Revenue
F29: Cohort Year | G29: 1 | H29: =+G29+1 -> 2 | I29: =+H29+1 -> 3 | J29: =+I29+1 -> 4 | K29: =+J29+1 -> 5 | L29: =+K29+1 -> 6 | M29: =+L29+1 -> 7 | N29: =+M29+1 -> 8 | O29: =+N29+1 -> 9 | ... T29: =+S29+1 -> 14
D30: Cohort Start | E30: Account Count
D31: 2010 | E31: =+COUNTIF('Data Set'!$DS$5:'Data Set'!$DS$220,D31) -> 6 | G31: =+SUMIF($G$8:$FN$8,G$29,$G10:$FN10) -> 0 | H31: =+SUMIF($G$8:$FN$8,H$29,$G10:$FN10) -> 0 | I31: =+SUMIF($G$8:$FN$8,I$29,$G10:$FN10) -> 0 | J31: =+SUMIF($G$8:$FN$8,J$29,$G10:$FN10) -> 0 | K31: =+SUMIF($G$8:$FN$8,K$29,$G10:$FN10) -> 0 | L31: =+SUMIF($G$8:$FN$8,L$29,$G10:$FN10) -> 0 | M31: =+SUMIF($G$8:$FN$8,M$29,$G10:$FN10) -> 0 | N31: =+SUMIF($G$8:$FN$8,N$29,$G10:$FN10) -> 0 | ... T31: =+SUMIF($G$8:$FN$8,T$29,$G10:$FN10) -> 0
D32: =+D31+1 -> 2011 | E32: =+COUNTIF('Data Set'!$DS$5:'Data Set'!$DS$220,D32) -> 9 | G32: =+SUMIF($G$8:$FN$8,G$29,$G11:$FN11) -> 0 | H32: =+SUMIF($G$8:$FN$8,H$29,$G11:$FN11) -> 0 | I32: =+SUMIF($G$8:$FN$8,I$29,$G11:$FN11) -> 0 | J32: =+SUMIF($G$8:$FN$8,J$29,$G11:$FN11) -> 0 | K32: =+SUMIF($G$8:$FN$8,K$29,$G11:$FN11) -> 0 | L32: =+SUMIF($G$8:$FN$8,L$29,$G11:$FN11) -> 0 | M32: =+SUMIF($G$8:$FN$8,M$29,$G11:$FN11) -> 0 | N32: =+SUMIF($G$8:$FN$8,N$29,$G11:$FN11) -> 0 | ... T32: =+SUMIF($G$8:$FN$8,T$29,$G11:$FN11) -> 0
D33: =+D32+1 -> 2012 | E33: =+COUNTIF('Data Set'!$DS$5:'Data Set'!$DS$220,D33) -> 10 | G33: =+SUMIF($G$8:$FN$8,G$29,$G12:$FN12) -> 0 | H33: =+SUMIF($G$8:$FN$8,H$29,$G12:$FN12) -> 0 | I33: =+SUMIF($G$8:$FN$8,I$29,$G12:$FN12) -> 0 | J33: =+SUMIF($G$8:$FN$8,J$29,$G12:$FN12) -> 0 | K33: =+SUMIF($G$8:$FN$8,K$29,$G12:$FN12) -> 0 | L33: =+SUMIF($G$8:$FN$8,L$29,$G12:$FN12) -> 0 | M33: =+SUMIF($G$8:$FN$8,M$29,$G12:$FN12) -> 0 | N33: =+SUMIF($G$8:$FN$8,N$29,$G12:$FN12) -> 0 | ... T33: =+SUMIF($G$8:$FN$8,T$29,$G12:$FN12) -> 0
D34: =+D33+1 -> 2013 | E34: =+COUNTIF('Data Set'!$DS$5:'Data Set'!$DS$220,D34) -> 20 | G34: =+SUMIF($G$8:$FN$8,G$29,$G13:$FN13) -> 0 | H34: =+SUMIF($G$8:$FN$8,H$29,$G13:$FN13) -> 0 | I34: =+SUMIF($G$8:$FN$8,I$29,$G13:$FN13) -> 0 | J34: =+SUMIF($G$8:$FN$8,J$29,$G13:$FN13) -> 0 | K34: =+SUMIF($G$8:$FN$8,K$29,$G13:$FN13) -> 0 | L34: =+SUMIF($G$8:$FN$8,L$29,$G13:$FN13) -> 0 | M34: =+SUMIF($G$8:$FN$8,M$29,$G13:$FN13) -> 0 | N34: =+SUMIF($G$8:$FN$8,N$29,$G13:$FN13) -> 0 | ... T34: =+SUMIF($G$8:$FN$8,T$29,$G13:$FN13) -> 0
D35: =+D34+1 -> 2014 | E35: =+COUNTIF('Data Set'!$DS$5:'Data Set'!$DS$220,D35) -> 23 | G35: =+SUMIF($G$8:$FN$8,G$29,$G14:$FN14) -> 0 | H35: =+SUMIF($G$8:$FN$8,H$29,$G14:$FN14) -> 0 | I35: =+SUMIF($G$8:$FN$8,I$29,$G14:$FN14) -> 0 | J35: =+SUMIF($G$8:$FN$8,J$29,$G14:$FN14) -> 0 | K35: =+SUMIF($G$8:$FN$8,K$29,$G14:$FN14) -> 0 | L35: =+SUMIF($G$8:$FN$8,L$29,$G14:$FN14) -> 0 | M35: =+SUMIF($G$8:$FN$8,M$29,$G14:$FN14) -> 0 | N35: =+SUMIF($G$8:$FN$8,N$29,$G14:$FN14) -> 0 | ... T35: =+SUMIF($G$8:$FN$8,T$29,$G14:$FN14) -> 0
D36: =+D35+1 -> 2015 | E36: =+COUNTIF('Data Set'!$DS$5:'Data Set'!$DS$220,D36) -> 17 | G36: =+SUMIF($G$8:$FN$8,G$29,$G15:$FN15) -> 0 | H36: =+SUMIF($G$8:$FN$8,H$29,$G15:$FN15) -> 0 | I36: =+SUMIF($G$8:$FN$8,I$29,$G15:$FN15) -> 0 | J36: =+SUMIF($G$8:$FN$8,J$29,$G15:$FN15) -> 0 | K36: =+SUMIF($G$8:$FN$8,K$29,$G15:$FN15) -> 0 | L36: =+SUMIF($G$8:$FN$8,L$29,$G15:$FN15) -> 0 | M36: =+SUMIF($G$8:$FN$8,M$29,$G15:$FN15) -> 0 | N36: =+SUMIF($G$8:$FN$8,N$29,$G15:$FN15) -> 0 | ... T36: =+SUMIF($G$8:$FN$8,T$29,$G15:$FN15) -> 0
D37: =+D36+1 -> 2016 | E37: =+COUNTIF('Data Set'!$DS$5:'Data Set'!$DS$220,D37) -> 16 | G37: =+SUMIF($G$8:$FN$8,G$29,$G16:$FN16) -> 0 | H37: =+SUMIF($G$8:$FN$8,H$29,$G16:$FN16) -> 0 | I37: =+SUMIF($G$8:$FN$8,I$29,$G16:$FN16) -> 0 | J37: =+SUMIF($G$8:$FN$8,J$29,$G16:$FN16) -> 0 | K37: =+SUMIF($G$8:$FN$8,K$29,$G16:$FN16) -> 0 | L37: =+SUMIF($G$8:$FN$8,L$29,$G16:$FN16) -> 0 | M37: =+SUMIF($G$8:$FN$8,M$29,$G16:$FN16) -> 0 | N37: =+SUMIF($G$8:$FN$8,N$29,$G16:$FN16) -> 0 | ... T37: =+SUMIF($G$8:$FN$8,T$29,$G16:$FN16) -> 0
D38: =+D37+1 -> 2017 | E38: =+COUNTIF('Data Set'!$DS$5:'Data Set'!$DS$220,D38) -> 19 | G38: =+SUMIF($G$8:$FN$8,G$29,$G17:$FN17) -> 0 | H38: =+SUMIF($G$8:$FN$8,H$29,$G17:$FN17) -> 0 | I38: =+SUMIF($G$8:$FN$8,I$29,$G17:$FN17) -> 0 | J38: =+SUMIF($G$8:$FN$8,J$29,$G17:$FN17) -> 0 | K38: =+SUMIF($G$8:$FN$8,K$29,$G17:$FN17) -> 0 | L38: =+SUMIF($G$8:$FN$8,L$29,$G17:$FN17) -> 0 | M38: =+SUMIF($G$8:$FN$8,M$29,$G17:$FN17) -> 0 | N38: =+SUMIF($G$8:$FN$8,N$29,$G17:$FN17) -> 0 | ... T38: =+SUMIF($G$8:$FN$8,T$29,$G17:$FN17) -> 0
D39: =+D38+1 -> 2018 | E39: =+COUNTIF('Data Set'!$DS$5:'Data Set'!$DS$220,D39) -> 15 | G39: =+SUMIF($G$8:$FN$8,G$29,$G18:$FN18) -> 0 | H39: =+SUMIF($G$8:$FN$8,H$29,$G18:$FN18) -> 0 | I39: =+SUMIF($G$8:$FN$8,I$29,$G18:$FN18) -> 0 | J39: =+SUMIF($G$8:$FN$8,J$29,$G18:$FN18) -> 0 | K39: =+SUMIF($G$8:$FN$8,K$29,$G18:$FN18) -> 0 | L39: =+SUMIF($G$8:$FN$8,L$29,$G18:$FN18) -> 0 | M39: =+SUMIF($G$8:$FN$8,M$29,$G18:$FN18) -> 0 | N39: =+SUMIF($G$8:$FN$8,N$29,$G18:$FN18) -> 0 | ... T39: =+SUMIF($G$8:$FN$8,T$29,$G18:$FN18) -> 0
D40: =+D39+1 -> 2019 | E40: =+COUNTIF('Data Set'!$DS$5:'Data Set'!$DS$220,D40) -> 13 | G40: =+SUMIF($G$8:$FN$8,G$29,$G19:$FN19) -> 0 | H40: =+SUMIF($G$8:$FN$8,H$29,$G19:$FN19) -> 0 | I40: =+SUMIF($G$8:$FN$8,I$29,$G19:$FN19) -> 0 | J40: =+SUMIF($G$8:$FN$8,J$29,$G19:$FN19) -> 0 | K40: =+SUMIF($G$8:$FN$8,K$29,$G19:$FN19) -> 0 | L40: =+SUMIF($G$8:$FN$8,L$29,$G19:$FN19) -> 0 | M40: =+SUMIF($G$8:$FN$8,M$29,$G19:$FN19) -> 0 | N40: =+SUMIF($G$8:$FN$8,N$29,$G19:$FN19) -> 0 | ... T40: =+SUMIF($G$8:$FN$8,T$29,$G19:$FN19) -> 0
D41: =+D40+1 -> 2020 | E41: =+COUNTIF('Data Set'!$DS$5:'Data Set'!$DS$220,D41) -> 16 | G41: =+SUMIF($G$8:$FN$8,G$29,$G20:$FN20) -> 0 | H41: =+SUMIF($G$8:$FN$8,H$29,$G20:$FN20) -> 0 | I41: =+SUMIF($G$8:$FN$8,I$29,$G20:$FN20) -> 0 | J41: =+SUMIF($G$8:$FN$8,J$29,$G20:$FN20) -> 0 | K41: =+SUMIF($G$8:$FN$8,K$29,$G20:$FN20) -> 0 | L41: =+SUMIF($G$8:$FN$8,L$29,$G20:$FN20) -> 0 | M41: =+SUMIF($G$8:$FN$8,M$29,$G20:$FN20) -> 0 | N41: =+SUMIF($G$8:$FN$8,N$29,$G20:$FN20) -> 0 | ... T41: =+SUMIF($G$8:$FN$8,T$29,$G20:$FN20) -> 0
D42: =+D41+1 -> 2021 | E42: =+COUNTIF('Data Set'!$DS$5:'Data Set'!$DS$220,D42) -> 15 | G42: =+SUMIF($G$8:$FN$8,G$29,$G21:$FN21) -> 0 | H42: =+SUMIF($G$8:$FN$8,H$29,$G21:$FN21) -> 0 | I42: =+SUMIF($G$8:$FN$8,I$29,$G21:$FN21) -> 0 | J42: =+SUMIF($G$8:$FN$8,J$29,$G21:$FN21) -> 0 | K42: =+SUMIF($G$8:$FN$8,K$29,$G21:$FN21) -> 0 | L42: =+SUMIF($G$8:$FN$8,L$29,$G21:$FN21) -> 0 | M42: =+SUMIF($G$8:$FN$8,M$29,$G21:$FN21) -> 0 | N42: =+SUMIF($G$8:$FN$8,N$29,$G21:$FN21) -> 0 | ... T42: =+SUMIF($G$8:$FN$8,T$29,$G21:$FN21) -> 0
D43: =+D42+1 -> 2022 | E43: =+COUNTIF('Data Set'!$DS$5:'Data Set'!$DS$220,D43) -> 2 | G43: =+SUMIF($G$8:$FN$8,G$29,$G22:$FN22) -> 0 | H43: =+SUMIF($G$8:$FN$8,H$29,$G22:$FN22) -> 0 | I43: =+SUMIF($G$8:$FN$8,I$29,$G22:$FN22) -> 0 | J43: =+SUMIF($G$8:$FN$8,J$29,$G22:$FN22) -> 0 | K43: =+SUMIF($G$8:$FN$8,K$29,$G22:$FN22) -> 0 | L43: =+SUMIF($G$8:$FN$8,L$29,$G22:$FN22) -> 0 | M43: =+SUMIF($G$8:$FN$8,M$29,$G22:$FN22) -> 0 | N43: =+SUMIF($G$8:$FN$8,N$29,$G22:$FN22) -> 0 | ... T43: =+SUMIF($G$8:$FN$8,T$29,$G22:$FN22) -> 0
D44: =+D43+1 -> 2023 | E44: =+COUNTIF('Data Set'!$DS$5:'Data Set'!$DS$220,D44) -> 3 | G44: =+SUMIF($G$8:$FN$8,G$29,$G23:$FN23) -> 0 | H44: =+SUMIF($G$8:$FN$8,H$29,$G23:$FN23) -> 0 | I44: =+SUMIF($G$8:$FN$8,I$29,$G23:$FN23) -> 0 | J44: =+SUMIF($G$8:$FN$8,J$29,$G23:$FN23) -> 0 | K44: =+SUMIF($G$8:$FN$8,K$29,$G23:$FN23) -> 0 | L44: =+SUMIF($G$8:$FN$8,L$29,$G23:$FN23) -> 0 | M44: =+SUMIF($G$8:$FN$8,M$29,$G23:$FN23) -> 0 | N44: =+SUMIF($G$8:$FN$8,N$29,$G23:$FN23) -> 0 | ... T44: =+SUMIF($G$8:$FN$8,T$29,$G23:$FN23) -> 0
C46: ◆ | D46: Revenue per Account
F48: Cohort Year | G48: 1 | H48: =+G48+1 -> 2 | I48: =+H48+1 -> 3 | J48: =+I48+1 -> 4 | K48: =+J48+1 -> 5 | L48: =+K48+1 -> 6 | M48: =+L48+1 -> 7 | N48: =+M48+1 -> 8 | O48: =+N48+1 -> 9 | ... T48: =+S48+1 -> 14
D49: Cohort Start | E49: Account Count
D50: 2010 | E50: =+E31 -> 6 | G50: =+IFERROR(G31/$E50,"-") -> 0 | H50: =+IFERROR(H31/$E50,"-") -> 0 | I50: =+IFERROR(I31/$E50,"-") -> 0 | J50: =+IFERROR(J31/$E50,"-") -> 0 | K50: =+IFERROR(K31/$E50,"-") -> 0 | L50: =+IFERROR(L31/$E50,"-") -> 0 | M50: =+IFERROR(M31/$E50,"-") -> 0 | N50: =+IFERROR(N31/$E50,"-") -> 0 | ... T50: =+IFERROR(T31/$E50,"-") -> 0
...

Sheet Data Set
B2: Currency in $000s
C3: Start Date | D3: 2014 | E3: 2014 | F3: 2014 | G3: 2014 | H3: 2014 | I3: 2014 | J3: 2014 | K3: 2014 | L3: 2014 | M3: 2014 | N3: 2014 | O3: 2014 | P3: 2015 | Q3: 2015 | R3: 2015 | S3: 2015 | T3: 2015 | U3: 2015 | V3: 2015 | W3: 2015 | X3: 2015 | Y3: 2015 | Z3: 2015 | AA3: 2015 | AB3: 2016 | AC3: 2016 | AD3: 2016 | AE3: 2016 | AF3: 2016 | AG3: 2016 | AH3: 2016 | AI3: 2016 | AJ3: 2016 | AK3: 2016 | AL3: 2016 | AM3: 2016 | AN3: 2017 | AO3: 2017 | AP3: 2017 | AQ3: 2017 | AR3: 2017 | AS3: 2017 | AT3: 2017 | AU3: 2017 | AV3: 2017 | AW3: 2017 | AX3: 2017 | AY3: 2017 | AZ3: 2018 | BA3: 2018 | BB3: 2018 | BC3: 2018 | BD3: 2018 | BE3: 2018 | BF3: 2018 | BG3: 2018 | BH3: 2018 | BI3: 2018 | BJ3: 2018 | BK3: 2018 | BL3: 2019 | BM3: 2019 | BN3: 2019 | BO3: 2019 | BP3: 2019 | BQ3: 2019 | BR3: 2019 | BS3: 2019 | BT3: 2019 | BU3: 2019 | BV3: 2019 | BW3: 2019 | BX3: 2020 | BY3: 2020 | BZ3: 2020 | CA3: 2020 | CB3: 2020 | CC3: 2020 | CD3: 2020 | CE3: 2020 | CF3: 2020 | CG3: 2020 | CH3: 2020 | CI3: 2020 | CJ3: 2021 | CK3: 2021 | CL3: 2021 | CM3: 2021 | CN3: 2021 | CO3: 2021 | CP3: 2021 | CQ3: 2021 | CR3: 2021 | CS3: 2021 | CT3: 2021 | CU3: 2021 | CV3: 2022 | CW3: 2022 | CX3: 2022 | CY3: 2022 | CZ3: 2022 | DA3: 2022 | DB3: 2022 | DC3: 2022 | DD3: 2022 | DE3: 2022 | DF3: 2022 | DG3: 2022 | DH3: 2023 | DI3: 2023 | DJ3: 2023 | DK3: 2023 | DL3: 2023 | DM3: 2023 | DN3: 2023 | DO3: 2023 | DS3: Cohort Year | DU3: Aggregate Revenue
B4: Account ID | D4: 41640 | E4: =EDATE(D4,1) -> 41671 | F4: =EDATE(E4,1) -> 41699 | G4: =EDATE(F4,1) -> 41730 | H4: =EDATE(G4,1) -> 41760 | I4: =EDATE(H4,1) -> 41791 | J4: =EDATE(I4,1) -> 41821 | K4: =EDATE(J4,1) -> 41852 | L4: =EDATE(K4,1) -> 41883 | ... DO4: =EDATE(DN4,1) -> 45139 | DU4: 2014 | DV4: =+DU4+1 -> 2015 | DW4: =+DV4+1 -> 2016 | DX4: =+DW4+1 -> 2017 | DY4: =+DX4+1 -> 2018 | DZ4: =+DY4+1 -> 2019 | EA4: =+DZ4+1 -> 2020 | EB4: =+EA4+1 -> 2021 | EC4: =+EB4+1 -> 2022 | ED4: =+EC4+1 -> 2023
B5: 1000000001 | C5: 39114 | D5: 216.8777 | E5: 592.95201 | F5: 426.71004 | G5: 318.89921 | H5: 194.78325 | I5: 179.77501 | J5: 190.03586 | K5: 199.60495 | L5: 205.00504 | M5: 211.09326 | N5: 206.93226 | O5: 194.41793 | P5: 234.17574 | Q5: 1074.1153 | R5: 386.51786 | S5: 339.28338 | T5: 194.83279 | U5: 209.28961 | V5: 221.07427 | W5: 203.87905 | X5: 230.051 | Y5: 255.75825 | Z5: 246.40994 | AA5: 228.43949 | AB5: 230.41587 | AC5: 602.34359 | AD5: 420.38102 | AE5: 385.70143 | AF5: 301.1191 | AG5: 262.55584 | AH5: 234.6741 | AI5: 240.44848 | AJ5: 293.15556 | AK5: 304.98367 | AL5: 281.34613 | AM5: 245.07083 | AN5: 259.08683 | AO5: 492.64464 | AP5: 558.84936 | AQ5: 423.1166 | AR5: 292.70546 | AS5: 301.49283 | AT5: 334.51809 | AU5: 361.14883 | AV5: 395.11309 | AW5: 386.01932 | AX5: 374.57818 | AY5: 372.49293 | AZ5: 382.38673 | BA5: 668.81381 | BB5: 892.92401 | BC5: 487.36257 | BD5: 391.72604 | BE5: 337.19667 | BF5: 324.53084 | BG5: 327.26804 | BH5: 343.27967 | BI5: 343.7572 | BJ5: 315.96241 | BK5: 298.80933 | BL5: 330.27731 | BM5: 728.55553 | BN5: 628.06454 | BO5: 515.72593 | BP5: 413.08609 | BQ5: 322.73376 | BR5: 329.92336 | BS5: 332.34514 | BT5: 330.92434 | BU5: 399.31022 | BV5: 375.37686 | BW5: 339.68596 | BX5: 488.47291 | BY5: 719.08124 | BZ5: 572.12965 | CA5: 427.80714 | CB5: 403.42353 | CC5: 367.42026 | CD5: 418.58202 | CE5: 363.74317 | CF5: 402.36325 | CG5: 377.19251 | CH5: 364.27616 | CI5: 345.80252 | CJ5: 369.79 | CK5: 1323.2583 | CL5: 702.58217 | CM5: 536.92041 | CN5: 478.00961 | CO5: 374.79373 | CP5: 336.80264 | CQ5: 441.62743 | CR5: 409.55899 | CS5: 426.87884 | CT5: 422.53557 | CU5: 369.00835 | CV5: 421.07871 | CW5: 737.43923 | CX5: 654.93212 | CY5: 637.55328 | CZ5: 376.16342 | DA5: 377.73162 | DB5: 306.76492 | DC5: 350.98019 | DD5: 402.73059 | DE5: 401.4426 | DF5: 363.90194 | DG5: 350.37574 | DH5: 430.72608 | DI5: 637.2068 | DJ5: 640.02123 | DK5: 489.11481 | DL5: 367.28817 | DM5: 364.2452 | DN5: 343.90971 | DO5: 456.45299 | DS5: =+YEAR(C5) -> 2007 | DU5: =+SUMIF($D$3:$DO$3,DU$4,$D5:$DO5) -> 3137.0865 | DV5: =+SUMIF($D$3:$DO$3,DV$4,$D5:$DO5) -> 3823.8267 | DW5: =+SUMIF($D$3:$DO$3,DW$4,$D5:$DO5) -> 3802.1956 | DX5: =+SUMIF($D$3:$DO$3,DX$4,$D5:$DO5) -> 4551.7662 | DY5: =+SUMIF($D$3:$DO$3,DY$4,$D5:$DO5) -> 5114.0173 | DZ5: =+SUMIF($D$3:$DO$3,DZ$4,$D5:$DO5) -> 5046.009 | EA5: =+SUMIF($D$3:$DO$3,EA$4,$D5:$DO5) -> 5250.2943 | EB5: =+SUMIF($D$3:$DO$3,EB$4,$D5:$DO5) -> 6191.766 | ... ED5: =+SUMIF($D$3:$DO$3,ED$4,$D5:$DO5) -> 3728.965
B6: =B5+1 -> 1000000002 | C6: 39753 | D6: 136.86552 | E6: 352.23388 | F6: 261.6418 | G6: 193.08209 | H6: 157.19118 | I6: 153.88373 | J6: 139.3323 | K6: 156.68806 | L6: 151.36944 | M6: 156.2621 | N6: 142.05149 | O6: 138.93684 | P6: 156.096 | Q6: 935.58065 | R6: 280.24123 | S6: 234.85697 | T6: 182.2917 | U6: 163.65148 | V6: 177.42667 | W6: 187.22902 | X6: 190.47354 | Y6: 224.41989 | Z6: 227.52207 | AA6: 165.48034 | AB6: 200.76054 | AC6: 679.35101 | AD6: 386.53358 | AE6: 287.29895 | AF6: 249.76918 | AG6: 183.51868 | AH6: 202.42407 | AI6: 241.2177 | AJ6: 252.27521 | AK6: 282.09389 | AL6: 261.33521 | AM6: 192.19872 | AN6: 259.94694 | AO6: 509.47387 | AP6: 467.83897 | AQ6: 311.66695 | AR6: 266.15532 | AS6: 261.14723 | AT6: 276.54797 | AU6: 276.68618 | AV6: 274.07721 | AW6: 297.73813 | AX6: 279.57382 | AY6: 234.29215 | AZ6: 292.51516 | BA6: 536.61892 | BB6: 437.60502 | BC6: 432.68174 | BD6: 343.77889 | BE6: 297.37067 | BF6: 249.80967 | BG6: 280.92043 | BH6: 309.84184 | BI6: 299.45303 | BJ6: 255.81221 | BK6: 247.1649 | BL6: 286.66426 | BM6: 610.02929 | BN6: 464.3002 | BO6: 408.86561 | BP6: 336.07499 | BQ6: 284.50697 | BR6: 277.36868 | BS6: 293.71234 | BT6: 300.50696 | BU6: 286.98797 | BV6: 270.73283 | BW6: 273.8412 | BX6: 416.17495 | BY6: 562.66369 | BZ6: 419.12117 | CA6: 371.16771 | CB6: 430.4572 | CC6: 371.40946 | CD6: 380.2258 | CE6: 369.53553 | CF6: 348.03757 | CG6: 390.80667 | CH6: 328.79609 | CI6: 331.42172 | CJ6: 1084.7521 | CK6: 809.98111 | CL6: 569.26324 | CM6: 521.5357 | CN6: 423.51727 | CO6: 355.69549 | CP6: 392.1648 | CQ6: 393.23668 | CR6: 376.49358 | CS6: 362.67516 | CT6: 334.7628 | CU6: 321.38153 | CV6: 450.72957 | CW6: 571.75753 | CX6: 489.27955 | CY6: 469.78053 | CZ6: 344.57734 | DA6: 305.26167 | DB6: 340.31683 | DC6: 422.76734 | DD6: 332.2144 | DE6: 330.986 | DF6: 317.77033 | DG6: 303.53293 | DH6: 458.31578 | DI6: 628.525 | DJ6: 528.79092 | DK6: 485.5414 | DL6: 404.44087 | DM6: 381.56824 | DN6: 389.50885 | DO6: 385.61114 | DS6: =+YEAR(C6) -> 2008 | DU6: =+SUMIF($D$3:$DO$3,DU$4,$D6:$DO6) -> 2139.5384 | DV6: =+SUMIF($D$3:$DO$3,DV$4,$D6:$DO6) -> 3125.2696 | DW6: =+SUMIF($D$3:$DO$3,DW$4,$D6:$DO6) -> 3418.7767 | DX6: =+SUMIF($D$3:$DO$3,DX$4,$D6:$DO6) -> 3715.1447 | DY6: =+SUMIF($D$3:$DO$3,DY$4,$D6:$DO6) -> 3983.5725 | DZ6: =+SUMIF($D$3:$DO$3,DZ$4,$D6:$DO6) -> 4093.5913 | EA6: =+SUMIF($D$3:$DO$3,EA$4,$D6:$DO6) -> 4719.8175 | EB6: =+SUMIF($D$3:$DO$3,EB$4,$D6:$DO6) -> 5945.4595 | ... ED6: =+SUMIF($D$3:$DO$3,ED$4,$D6:$DO6) -> 3662.3022
B7: =B6+1 -> 1000000003 | C7: 41275 | D7: 6.8024819 | E7: 24.05632 | F7: 21.18155 | G7: 24.63273 | H7: 13.994624 | I7: 9.8346392 | J7: 17.281513 | K7: 14.624922 | L7: 17.292283 | M7: 12.791255 | N7: 10.316032 | O7: 19.469019 | P7: 26.987381 | Q7: 121.33007 | R7: 35.166813 | S7: 42.034199 | T7: 22.791445 | U7: 23.805379 | V7: 34.55554 | W7: 37.575652 | X7: 31.597123 | Y7: 26.822939 | Z7: 36.294265 | AA7: 22.531948 | AB7: 56.493274 | AC7: 107.8859 | AD7: 71.949283 | AE7: 81.2144 | AF7: 48.450364 | AG7: 37.957261 | AH7: 62.888874 | AI7: 53.452823 | AJ7: 71.560357 | AK7: 39.349239 | AL7: 40.568143 | AM7: 33.971437 | AN7: 60.051368 | AO7: 119.71255 | AP7: 116.75928 | AQ7: 96.404195 | AR7: 72.533574 | AS7: 79.161315 | AT7: 73.18804 | AU7: 71.365518 | AV7: 101.62814 | AW7: 82.884676 | AX7: 82.322301 | AY7: 62.477169 | AZ7: 96.240429 | BA7: 175.52999 | BB7: 172.72525 | BC7: 168.9641 | BD7: 112.12559 | BE7: 110.94328 | BF7: 122.775 | BG7: 122.08638 | BH7: 122.25063 | BI7: 110.93116 | BJ7: 127.60603 | BK7: 89.39342 | BL7: 160.4715 | BM7: 290.98528 | BN7: 246.43377 | BO7: 262.9072 | BP7: 123.7517 | BQ7: 143.48613 | BR7: 166.15001 | BS7: 136.68892 | BT7: 153.61613 | BU7: 142.13543 | BV7: 127.42801 | BW7: 132.89887 | BX7: 165.77328 | BY7: 424.33731 | BZ7: 221.74183 | CA7: 207.79954 | CB7: 200.95324 | CC7: 237.56208 | CD7: 239.80516 | CE7: 189.85491 | CF7: 203.84749 | CG7: 214.73552 | CH7: 170.68935 | CI7: 196.13215 | CJ7: 362.6591 | CK7: 308.50105 | CL7: 306.18472 | CM7: 306.81182 | CN7: 305.37024 | CO7: 218.54103 | CP7: 233.89966 | CQ7: 179.46898 | CR7: 217.98909 | CS7: 224.60088 | CT7: 141.57824 | CU7: 175.38356 | CV7: 612.65375 | CW7: 319.86196 | CX7: 307.81375 | CY7: 413.28153 | CZ7: 197.47688 | DA7: 228.20513 | DB7: 194.35714 | DC7: 275.28444 | DD7: 254.4059 | DE7: 349.93946 | DF7: 262.77222 | DG7: 213.9156 | DH7: 670.39661 | DI7: 432.79815 | DJ7: 459.08752 | DK7: 610.79265 | DL7: 379.64135 | DM7: 398.56678 | DN7: 360.12469 | DO7: 311.02588 | DS7: =+YEAR(C7) -> 2013 | DU7: =+SUMIF($D$3:$DO$3,DU$4,$D7:$DO7) -> 192.27737 | DV7: =+SUMIF($D$3:$DO$3,DV$4,$D7:$DO7) -> 461.49275 | DW7: =+SUMIF($D$3:$DO$3,DW$4,$D7:$DO7) -> 705.74136 | DX7: =+SUMIF($D$3:$DO$3,DX$4,$D7:$DO7) -> 1018.4881 | DY7: =+SUMIF($D$3:$DO$3,DY$4,$D7:$DO7) -> 1531.5713 | DZ7: =+SUMIF($D$3:$DO$3,DZ$4,$D7:$DO7) -> 2086.9529 | EA7: =+SUMIF($D$3:$DO$3,EA$4,$D7:$DO7) -> 2673.2319 | EB7: =+SUMIF($D$3:$DO$3,EB$4,$D7:$DO7) -> 2980.9884 | ... ED7: =+SUMIF($D$3:$DO$3,ED$4,$D7:$DO7) -> 3622.4336
B8: =B7+1 -> 1000000004 | C8: 40909 | D8: 204.88458 | E8: 613.64986 | F8: 248.64671 | G8: 145.52233 | H8: 81.212261 | I8: 80.86998 | J8: 75.973459 | K8: 94.653049 | L8: 90.011334 | M8: 90.810578 | N8: 116.84934 | O8: 99.029226 | P8: 243.60703 | Q8: 1425.3432 | R8: 357.34029 | S8: 215.38222 | T8: 149.1059 | U8: 126.70824 | V8: 135.2933 | W8: 149.10853 | X8: 144.19032 | Y8: 141.21757 | Z8: 149.51465 | AA8: 111.31066 | AB8: 243.73297 | AC8: 713.20531 | AD8: 348.50733 | AE8: 223.96814 | AF8: 171.85587 | AG8: 152.39805 | AH8: 166.95634 | AI8: 165.12733 | AJ8: 192.68195 | AK8: 203.7142 | AL8: 165.64077 | AM8: 156.21751 | AN8: 251.49263 | AO8: 635.43914 | AP8: 503.49688 | AQ8: 293.67264 | AR8: 222.90332 | AS8: 241.16892 | AT8: 191.34303 | AU8: 213.55996 | AV8: 200.30024 | AW8: 209.96821 | AX8: 184.90439 | AY8: 185.08767 | AZ8: 301.48667 | BA8: 628.94871 | BB8: 443.01956 | BC8: 400.62512 | BD8: 236.07399 | BE8: 211.46166 | BF8: 195.76495 | BG8: 204.11265 | BH8: 227.33222 | BI8: 207.14691 | BJ8: 211.21387 | BK8: 183.33795 | BL8: 186.37089 | BM8: 356.22957 | BN8: 344.84179 | BO8: 304.98795 | BP8: 248.6475 | BQ8: 235.91807 | BR8: 242.39754 | BS8: 233.63393 | BT8: 257.70104 | BU8: 251.90118 | BV8: 225.78102 | BW8: 230.05678 | BX8: 288.36978 | BY8: 534.13405 | BZ8: 335.08703 | CA8: 378.38215 | CB8: 359.20983 | CC8: 340.06588 | CD8: 350.99546 | CE8: 346.25937 | CF8: 351.48916 | CG8: 365.47191 | CH8: 307.62041 | CI8: 291.91549 | CJ8: 611.61209 | CK8: 892.71004 | CL8: 476.67759 | CM8: 464.97786 | CN8: 387.97465 | CO8: 318.57836 | CP8: 335.17086 | CQ8: 364.71672 | CR8: 361.17139 | CS8: 364.32506 | CT8: 324.50157 | CU8: 301.2259 | CV8: 348.53255 | CW8: 468.63844 | CX8: 475.93993 | CY8: 464.53805 | CZ8: 325.50939 | DA8: 324.03429 | DB8: 370.02435 | DC8: 346.93248 | DD8: 368.23084 | DE8: 396.07978 | DF8: 337.92536 | DG8: 296.51615 | DH8: 397.66584 | DI8: 476.1511 | DJ8: 467.03166 | DK8: 399.1391 | DL8: 349.86118 | DM8: 314.6495 | DN8: 362.89578 | DO8: 368.06838 | DS8: =+YEAR(C8) -> 2012 | DU8: =+SUMIF($D$3:$DO$3,DU$4,$D8:$DO8) -> 1942.1127 | DV8: =+SUMIF($D$3:$DO$3,DV$4,$D8:$DO8) -> 3348.1219 | DW8: =+SUMIF($D$3:$DO$3,DW$4,$D8:$DO8) -> 2904.0058 | DX8: =+SUMIF($D$3:$DO$3,DX$4,$D8:$DO8) -> 3333.337 | DY8: =+SUMIF($D$3:$DO$3,DY$4,$D8:$DO8) -> 3450.5243 | DZ8: =+SUMIF($D$3:$DO$3,DZ$4,$D8:$DO8) -> 3118.4673 | EA8: =+SUMIF($D$3:$DO$3,EA$4,$D8:$DO8) -> 4249.0005 | EB8: =+SUMIF($D$3:$DO$3,EB$4,$D8:$DO8) -> 5203.6421 | ... ED8: =+SUMIF($D$3:$DO$3,ED$4,$D8:$DO8) -> 3135.4625
B9: =B8+1 -> 1000000005 | C9: 38899 | D9: 162.51761 | E9: 687.1462 | F9: 325.37486 | G9: 301.26444 | H9: 185.99064 | I9: 151.25633 | J9: 145.35218 | K9: 158.02311 | L9: 149.77456 | M9: 157.74962 | N9: 124.54817 | O9: 133.78447 | P9: 191.07922 | Q9: 964.81215 | R9: 310.46858 | S9: 274.50051 | T9: 173.24601 | U9: 143.00459 | V9: 168.45133 | W9: 153.51413 | X9: 179.70379 | Y9: 187.43526 | Z9: 154.4294 | AA9: 144.99264 | AB9: 159.39997 | AC9: 491.98706 | AD9: 346.44115 | AE9: 257.78946 | AF9: 203.83158 | AG9: 179.83434 | AH9: 197.30599 | AI9: 199.03233 | AJ9: 211.03543 | AK9: 230.24895 | AL9: 181.34566 | AM9: 180.58593 | AN9: 202.19669 | AO9: 362.22499 | AP9: 322.06699 | AQ9: 274.46865 | AR9: 172.37137 | AS9: 172.16636 | AT9: 203.42288 | AU9: 187.89264 | AV9: 192.96306 | AW9: 207.34288 | AX9: 219.33221 | AY9: 213.53692 | AZ9: 230.18219 | BA9: 369.38399 | BB9: 347.13156 | BC9: 360.36843 | BD9: 276.20062 | BE9: 196.2671 | BF9: 229.52532 | BG9: 209.64105 | BH9: 216.19415 | BI9: 238.89353 | BJ9: 209.91196 | BK9: 224.44533 | BL9: 226.03984 | BM9: 435.55036 | BN9: 326.05664 | BO9: 330.06603 | BP9: 240.89287 | BQ9: 182.30863 | BR9: 208.39933 | BS9: 241.1374 | BT9: 221.42594 | BU9: 237.18021 | BV9: 210.56196 | BW9: 197.6545 | BX9: 306.2899 | BY9: 424.45596 | BZ9: 286.91997 | CA9: 237.87997 | CB9: 225.3313 | CC9: 230.41921 | CD9: 259.45422 | CE9: 255.51571 | CF9: 249.83049 | CG9: 311.85898 | CH9: 261.82118 | CI9: 212.22649 | CJ9: 241.01945 | CK9: 542.0255 | CL9: 391.51071 | CM9: 345.9742 | CN9: 290.68356 | CO9: 259.10691 | CP9: 205.36181 | CQ9: 252.88678 | CR9: 268.19846 | CS9: 300.91615 | CT9: 275.98886 | CU9: 264.96092 | CV9: 366.83417 | CW9: 457.51263 | CX9: 377.79699 | CY9: 388.23594 | CZ9: 282.50038 | DA9: 260.97349 | DB9: 273.3108 | DC9: 294.11144 | DD9: 296.12703 | DE9: 325.39505 | DF9: 272.18477 | DG9: 278.29581 | DH9: 430.57045 | DI9: 546.62496 | DJ9: 485.98039 | DK9: 408.78005 | DL9: 369.30868 | DM9: 385.88786 | DN9: 329.77077 | DO9: 388.28679 | DS9: =+YEAR(C9) -> 2006 | DU9: =+SUMIF($D$3:$DO$3,DU$4,$D9:$DO9) -> 2682.7822 | DV9: =+SUMIF($D$3:$DO$3,DV$4,$D9:$DO9) -> 3045.6376 | DW9: =+SUMIF($D$3:$DO$3,DW$4,$D9:$DO9) -> 2838.8378 | DX9: =+SUMIF($D$3:$DO$3,DX$4,$D9:$DO9) -> 2729.9856 | DY9: =+SUMIF($D$3:$DO$3,DY$4,$D9:$DO9) -> 3108.1452 | DZ9: =+SUMIF($D$3:$DO$3,DZ$4,$D9:$DO9) -> 3057.2737 | EA9: =+SUMIF($D$3:$DO$3,EA$4,$D9:$DO9) -> 3262.0034 | EB9: =+SUMIF($D$3:$DO$3,EB$4,$D9:$DO9) -> 3638.6333 | ... ED9: =+SUMIF($D$3:$DO$3,ED$4,$D9:$DO9) -> 3345.21
B10: =B9+1 -> 1000000006 | C10: 39753 | D10: 149.25657 | E10: 254.02759 | F10: 247.63049 | G10: 198.55394 | H10: 158.34697 | I10: 176.13522 | J10: 163.04865 | K10: 169.64787 | L10: 191.49603 | M10: 177.74467 | N10: 152.32472 | O10: 138.384 | P10: 155.64763 | Q10: 574.69516 | R10: 258.09489 | S10: 199.04554 | T10: 178.70719 | U10: 177.81841 | V10: 200.56252 | W10: 216.35874 | X10: 260.85839 | Y10: 259.42791 | Z10: 220.01928 | AA10: 191.95648 | AB10: 196.05425 | AC10: 323.12164 | AD10: 308.83279 | AE10: 281.46929 | AF10: 264.27058 | AG10: 266.76089 | AH10: 258.27183 | AI10: 295.23484 | AJ10: 312.8716 | AK10: 294.49016 | AL10: 269.32284 | AM10: 247.12572 | AN10: 282.91902 | AO10: 390.73346 | AP10: 427.24941 | AQ10: 309.25005 | AR10: 302.7866 | AS10: 308.76847 | AT10: 322.53491 | AU10: 356.72504 | AV10: 351.81812 | AW10: 317.72995 | AX10: 300.90523 | AY10: 267.19567 | AZ10: 307.71648 | BA10: 425.96281 | BB10: 441.58293 | BC10: 350.64612 | BD10: 320.3715 | BE10: 308.80438 | BF10: 352.45442 | BG10: 325.07704 | BH10: 322.64768 | BI10: 301.11111 | BJ10: 284.89998 | BK10: 266.22107 | BL10: 324.59486 | BM10: 409.99021 | BN10: 452.92852 | BO10: 376.85455 | BP10: 390.40499 | BQ10: 320.48926 | BR10: 336.42489 | BS10: 336.25385 | BT10: 363.80272 | BU10: 355.56805 | BV10: 340.72339 | BW10: 329.21451 | BX10: 385.28244 | BY10: 422.75878 | BZ10: 443.77317 | CA10: 343.49016 | CB10: 344.09696 | CC10: 415.80081 | CD10: 412.65997 | CE10: 378.29835 | CF10: 412.23457 | CG10: 386.12694 | CH10: 327.58927 | CI10: 322.85764 | CJ10: 333.78647 | CK10: 406.19555 | CL10: 438.67472 | CM10: 427.72221 | CN10: 394.73369 | CO10: 385.68101 | CP10: 365.0467 | CQ10: 373.7894 | CR10: 391.57905 | CS10: 389.39139 | CT10: 375.89311 | CU10: 350.57077 | CV10: 378.90463 | CW10: 416.12796 | CX10: 419.30284 | CY10: 367.71965 | CZ10: 372.74181 | DA10: 380.09956 | DB10: 356.91597 | DC10: 384.99341 | DD10: 418.76005 | DE10: 358.05134 | DF10: 373.00134 | DG10: 348.11416 | DH10: 347.13445 | DI10: 407.58794 | DJ10: 429.81617 | DK10: 304.42066 | DL10: 317.74234 | DM10: 349.82223 | DN10: 334.51043 | DO10: 372.98164 | DS10: =+YEAR(C10) -> 2008 | DU10: =+SUMIF($D$3:$DO$3,DU$4,$D10:$DO10) -> 2176.5967 | DV10: =+SUMIF($D$3:$DO$3,DV$4,$D10:$DO10) -> 2893.1921 | DW10: =+SUMIF($D$3:$DO$3,DW$4,$D10:$DO10) -> 3317.8264 | DX10: =+SUMIF($D$3:$DO$3,DX$4,$D10:$DO10) -> 3938.6159 | DY10: =+SUMIF($D$3:$DO$3,DY$4,$D10:$DO10) -> 4007.4955 | DZ10: =+SUMIF($D$3:$DO$3,DZ$4,$D10:$DO10) -> 4337.2498 | EA10: =+SUMIF($D$3:$DO$3,EA$4,$D10:$DO10) -> 4594.9691 | EB10: =+SUMIF($D$3:$DO$3,EB$4,$D10:$DO10) -> 4633.0641 | ... ED10: =+SUMIF($D$3:$DO$3,ED$4,$D10:$DO10) -> 2864.0159
B11: =B10+1 -> 1000000007 | C11: 40969 | D11: 153.42658 | E11: 177.8741 | F11: 191.64884 | G11: 172.79681 | H11: 191.59544 | I11: 227.52218 | J11: 213.10142 | K11: 238.41975 | L11: 231.80571 | M11: 228.70435 | N11: 219.35198 | O11: 172.82158 | P11: 203.45278 | Q11: 496.78523 | R11: 254.64652 | S11: 238.18149 | T11: 243.08244 | U11: 272.31601 | V11: 253.38461 | W11: 274.81194 | X11: 249.28208 | Y11: 230.85542 | Z11: 222.58468 | AA11: 208.05247 | AB11: 208.40976 | AC11: 233.20891 | AD11: 252.47279 | AE11: 228.9685 | AF11: 249.52739 | AG11: 255.56536 | AH11: 278.08007 | AI11: 260.29703 | AJ11: 252.56555 | AK11: 230.36701 | AL11: 206.51102 | AM11: 210.86742 | AN11: 205.5476 | AO11: 222.5219 | AP11: 272.31769 | AQ11: 256.50638 | AR11: 273.16306 | AS11: 279.1817 | AT11: 273.7493 | AU11: 253.01163 | AV11: 231.08279 | AW11: 278.63104 | AX11: 240.56155 | AY11: 208.96872 | AZ11: 185.52575 | BA11: 292.69402 | BB11: 307.77735 | BC11: 341.21368 | BD11: 297.41349 | BE11: 298.60278 | BF11: 267.27962 | BG11: 262.26692 | BH11: 265.95823 | BI11: 274.97669 | BJ11: 216.72523 | BK11: 225.07199 | BL11: 192.36425 | BM11: 239.37293 | BN11: 268.35157 | BO11: 243.23942 | BP11: 271.2209 | BQ11: 249.6134 | BR11: 270.84999 | BS11: 298.33905 | BT11: 310.94622 | BU11: 319.04643 | BV11: 327.40835 | BW11: 267.1762 | BX11: 320.3414 | BY11: 345.73947 | BZ11: 319.3003 | CA11: 326.29809 | CB11: 474.95733 | CC11: 470.37382 | CD11: 410.38863 | CE11: 398.71242 | CF11: 390.67045 | CG11: 371.81036 | CH11: 387.57893 | CI11: 346.56885 | CJ11: 298.24301 | CK11: 306.55101 | CL11: 353.6922 | CM11: 430.72146 | CN11: 422.65356 | CO11: 389.34336 | CP11: 383.12252 | CQ11: 350.70943 | CR11: 382.85278 | CS11: 380.41403 | CT11: 368.44988 | CU11: 296.45513 | CV11: 271.72909 | CW11: 345.0644 | CX11: 371.31925 | CY11: 380.50349 | CZ11: 372.62105 | DA11: 337.12533 | DB11: 363.94559 | DC11: 354.7118 | DD11: 346.60889 | DE11: 389.71603 | DF11: 339.98693 | DG11: 306.89528 | DH11: 298.73991 | DI11: 328.27117 | DJ11: 294.4798 | DK11: 333.03732 | DL11: 367.53363 | DM11: 353.93166 | DN11: 339.62581 | DO11: 329.93431 | DS11: =+YEAR(C11) -> 2012 | DU11: =+SUMIF($D$3:$DO$3,DU$4,$D11:$DO11) -> 2419.0687 | DV11: =+SUMIF($D$3:$DO$3,DV$4,$D11:$DO11) -> 3147.4357 | DW11: =+SUMIF($D$3:$DO$3,DW$4,$D11:$DO11) -> 2866.8408 | DX11: =+SUMIF($D$3:$DO$3,DX$4,$D11:$DO11) -> 2995.2434 | DY11: =+SUMIF($D$3:$DO$3,DY$4,$D11:$DO11) -> 3235.5057 | DZ11: =+SUMIF($D$3:$DO$3,DZ$4,$D11:$DO11) -> 3257.9287 | EA11: =+SUMIF($D$3:$DO$3,EA$4,$D11:$DO11) -> 4562.7401 | EB11: =+SUMIF($D$3:$DO$3,EB$4,$D11:$DO11) -> 4363.2084 | ... ED11: =+SUMIF($D$3:$DO$3,ED$4,$D11:$DO11) -> 2645.5536
B12: =B11+1 -> 1000000008 | C12: 42005 | D12: -8 | E12: -8 | F12: -8 | G12: -8 | H12: -8 | I12: -8 | J12: -8 | K12: -8 | L12: -8 | M12: -8 | N12: -8 | O12: -8 | P12: -3.1890771 | Q12: 115.19603 | R12: 83.83095 | S12: 63.214268 | T12: 37.342461 | U12: 55.125126 | V12: 54.870845 | W12: 64.308284 | X12: 62.682177 | Y12: 66.294385 | Z12: 61.076447 | AA12: 51.498245 | AB12: 69.713593 | AC12: 146.46965 | AD12: 141.70635 | AE12: 81.147078 | AF12: 92.20462 | AG12: 82.159961 | AH12: 72.757121 | AI12: 98.168063 | AJ12: 101.53263 | AK12: 101.16896 | AL12: 101.65418 | AM12: 89.74133 | AN12: 121.0983 | AO12: 150.26818 | AP12: 150.34275 | AQ12: 122.32051 | AR12: 120.85532 | AS12: 99.356871 | AT12: 111.43735 | AU12: 140.62247 | AV12: 134.77919 | AW12: 126.66062 | AX12: 125.18939 | AY12: 136.12062 | AZ12: 134.94757 | BA12: 214.11206 | BB12: 221.1595 | BC12: 283.97356 | BD12: 209.36703 | BE12: 156.36177 | BF12: 132.267 | BG12: 154.11793 | BH12: 161.39901 | BI12: 157.66676 | BJ12: 164.89782 | BK12: 131.56135 | BL12: 140.20536 | BM12: 227.72273 | BN12: 222.60484 | BO12: 205.81396 | BP12: 190.40614 | BQ12: 170.02862 | BR12: 162.9572 | BS12: 203.34962 | BT12: 196.20161 | BU12: 174.53726 | BV12: 216.94772 | BW12: 190.16589 | BX12: 193.46168 | BY12: 323.25944 | BZ12: 261.38891 | CA12: 195.238 | CB12: 195.83813 | CC12: 248.1994 | CD12: 268.26019 | CE12: 247.4379 | CF12: 260.04027 | CG12: 239.30591 | CH12: 212.89946 | CI12: 199.72105 | CJ12: 219.59711 | CK12: 279.63675 | CL12: 315.06755 | CM12: 242.90764 | CN12: 237.3359 | CO12: 227.99251 | CP12: 239.9499 | CQ12: 232.42839 | CR12: 286.46106 | CS12: 219.95481 | CT12: 217.67713 | CU12: 260.80158 | CV12: 269.15269 | CW12: 280.79182 | CX12: 296.1521 | CY12: 287.45634 | CZ12: 238.38027 | DA12: 207.09528 | DB12: 221.99214 | DC12: 258.24571 | DD12: 291.38846 | DE12: 312.77849 | DF12: 272.97572 | DG12: 244.88691 | DH12: 324.8565 | DI12: 376.52904 | DJ12: 421.08505 | DK12: 395.73254 | DL12: 350.32561 | DM12: 342.42496 | DN12: 320.29329 | DO12: 352.54892 | DS12: =+YEAR(C12) -> 2015 | DU12: =+SUMIF($D$3:$DO$3,DU$4,$D12:$DO12) -> -96 | DV12: =+SUMIF($D$3:$DO$3,DV$4,$D12:$DO12) -> 712.25014 | DW12: =+SUMIF($D$3:$DO$3,DW$4,$D12:$DO12) -> 1178.4235 | DX12: =+SUMIF($D$3:$DO$3,DX$4,$D12:$DO12) -> 1539.0516 | DY12: =+SUMIF($D$3:$DO$3,DY$4,$D12:$DO12) -> 2121.8313 | DZ12: =+SUMIF($D$3:$DO$3,DZ$4,$D12:$DO12) -> 2300.941 | EA12: =+SUMIF($D$3:$DO$3,EA$4,$D12:$DO12) -> 2845.0503 | EB12: =+SUMIF($D$3:$DO$3,EB$4,$D12:$DO12) -> 2979.8103 | ... ED12: =+SUMIF($D$3:$DO$3,ED$4,$D12:$DO12) -> 2883.7959
B13: =B12+1 -> 1000000009 | C13: 39479 | D13: 126.06841 | E13: 237.75635 | F13: 189.6356 | G13: 161.32306 | H13: 166.82005 | I13: 157.61854 | J13: 153.91349 | K13: 131.80092 | L13: 158.10616 | M13: 178.48657 | N13: 155.13322 | O13: 148.52443 | P13: 168.87084 | Q13: 626.24724 | R13: 269.66441 | S13: 270.45735 | T13: 209.47454 | U13: 197.38029 | V13: 195.34447 | W13: 170.16439 | X13: 189.7137 | Y13: 217.8576 | Z13: 197.63986 | AA13: 183.39214 | AB13: 219.0917 | AC13: 422.77481 | AD13: 369.87109 | AE13: 318.73578 | AF13: 236.85046 | AG13: 220.72374 | AH13: 240.47993 | AI13: 198.33024 | AJ13: 236.18429 | AK13: 256.13907 | AL13: 232.84767 | AM13: 228.55961 | AN13: 257.10835 | AO13: 509.61163 | AP13: 459.20768 | AQ13: 386.32903 | AR13: 299.94065 | AS13: 304.31926 | AT13: 294.5815 | AU13: 284.54127 | AV13: 297.23719 | AW13: 295.99948 | AX13: 288.09771 | AY13: 250.39062 | AZ13: 268.34714 | BA13: 500.18864 | BB13: 2277.3387 | BC13: 386.3607 | BD13: 348.83486 | BE13: 307.73292 | BF13: 282.88998 | BG13: 291.90862 | BH13: 299.28524 | BI13: 301.35281 | BJ13: 246.52717 | BK13: 256.75226 | BL13: 292.70573 | BM13: 1822.0059 | BN13: 430.81164 | BO13: 392.39503 | BP13: 366.53328 | BQ13: 309.9435 | BR13: 361.5351 | BS13: 344.28707 | BT13: 325.4343 | BU13: 316.90204 | BV13: 326.64787 | BW13: 307.73491 | BX13: 376.0735 | BY13: 854.5712 | BZ13: 382.77543 | CA13: 380.90154 | CB13: 338.41546 | CC13: 381.783 | CD13: 398.21546 | CE13: 365.78909 | CF13: 364.42822 | CG13: 368.02271 | CH13: 323.03462 | CI13: 276.5062 | CJ13: 797.59963 | CK13: 438.70444 | CL13: 642.61496 | CM13: 446.38023 | CN13: 354.00041 | CO13: 335.7427 | CP13: 303.65575 | CQ13: 332.8916 | CR13: 319.88579 | CS13: 334.30929 | CT13: 337.6453 | CU13: 303.68983 | CV13: 307.31059 | CW13: 494.9218 | CX13: 456.71084 | CY13: 393.92398 | CZ13: 297.83491 | DA13: 267.10047 | DB13: 272.87684 | DC13: 281.92783 | DD13: 324.13989 | DE13: 284.09785 | DF13: 294.96585 | DG13: 291.8923 | DH13: 394.78589 | DI13: 452.03051 | DJ13: 427.88031 | DK13: 328.96455 | DL13: 258.57696 | DM13: 270.90072 | DN13: 279.41516 | DO13: 325.0558 | DS13: =+YEAR(C13) -> 2008 | DU13: =+SUMIF($D$3:$DO$3,DU$4,$D13:$DO13) -> 1965.1868 | DV13: =+SUMIF($D$3:$DO$3,DV$4,$D13:$DO13) -> 2896.2068 | DW13: =+SUMIF($D$3:$DO$3,DW$4,$D13:$DO13) -> 3180.5884 | DX13: =+SUMIF($D$3:$DO$3,DX$4,$D13:$DO13) -> 3927.3643 | DY13: =+SUMIF($D$3:$DO$3,DY$4,$D13:$DO13) -> 5767.519 | DZ13: =+SUMIF($D$3:$DO$3,DZ$4,$D13:$DO13) -> 5596.9363 | EA13: =+SUMIF($D$3:$DO$3,EA$4,$D13:$DO13) -> 4810.5164 | EB13: =+SUMIF($D$3:$DO$3,EB$4,$D13:$DO13) -> 4947.1199 | ... ED13: =+SUMIF($D$3:$DO$3,ED$4,$D13:$DO13) -> 2737.6099
B14: =B13+1 -> 1000000010 | C14: 38899 | D14: 157.91661 | E14: 212.08708 | F14: 204.88428 | G14: 183.498 | H14: 216.48934 | I14: 235.97297 | J14: 218.46744 | K14: 232.24102 | L14: 230.0612 | M14: 185.63833 | N14: 198.46796 | O14: 158.48507 | P14: 159.95078 | Q14: 450.14337 | R14: 226.2575 | S14: 229.59426 | T14: 237.84458 | U14: 224.20377 | V14: 258.62713 | W14: 275.97857 | X14: 228.96843 | Y14: 275.62042 | Z14: 268.63696 | AA14: 247.20595 | AB14: 265.63873 | AC14: 309.02766 | AD14: 305.8994 | AE14: 248.40936 | AF14: 282.02638 | AG14: 320.83094 | AH14: 333.1156 | AI14: 338.47224 | AJ14: 276.64073 | AK14: 287.82155 | AL14: 304.8628 | AM14: 266.1611 | AN14: 270.6043 | AO14: 292.84739 | AP14: 331.69537 | AQ14: 324.93279 | AR14: 311.77571 | AS14: 338.91104 | AT14: 339.05679 | AU14: 339.24653 | AV14: 314.9806 | AW14: 307.6901 | AX14: 313.69156 | AY14: 278.32985 | AZ14: 248.67539 | BA14: 326.84669 | BB14: 409.74235 | BC14: 449.04687 | BD14: 388.46459 | BE14: 362.35806 | BF14: 326.74391 | BG14: 336.70567 | BH14: 372.25858 | BI14: 343.60923 | BJ14: 319.84631 | BK14: 307.09192 | BL14: 243.46882 | BM14: 332.59623 | BN14: 313.30259 | BO14: 335.3949 | BP14: 316.54644 | BQ14: 360.44198 | BR14: 341.17345 | BS14: 368.14028 | BT14: 365.28788 | BU14: 403.73691 | BV14: 364.54868 | BW14: 358.43959 | BX14: 354.38735 | BY14: 513.30838 | BZ14: 359.01131 | CA14: 324.31233 | CB14: 443.41843 | CC14: 487.68932 | CD14: 503.60465 | CE14: 457.94671 | CF14: 400.94714 | CG14: 414.04632 | CH14: 411.8721 | CI14: 331.99678 | CJ14: 418.47068 | CK14: 323.0321 | CL14: 371.06365 | CM14: 414.59661 | CN14: 372.07695 | CO14: 408.10836 | CP14: 359.28642 | CQ14: 357.22861 | CR14: 417.54152 | CS14: 415.1475 | CT14: 360.98499 | CU14: 353.5302 | CV14: 314.53039 | CW14: 366.68935 | CX14: 403.54106 | CY14: 346.61624 | CZ14: 358.99469 | DA14: 352.31141 | DB14: 327.33319 | DC14: 342.02148 | DD14: 352.22833 | DE14: 319.75069 | DF14: 276.78363 | DG14: 274.52865 | DH14: 275.55632 | DI14: 315.20553 | DJ14: 306.13349 | DK14: 309.96463 | DL14: 318.15494 | DM14: 308.57746 | DN14: 308.57164 | DO14: 285.30332 | DS14: =+YEAR(C14) -> 2006 | DU14: =+SUMIF($D$3:$DO$3,DU$4,$D14:$DO14) -> 2434.2093 | DV14: =+SUMIF($D$3:$DO$3,DV$4,$D14:$DO14) -> 3083.0317 | DW14: =+SUMIF($D$3:$DO$3,DW$4,$D14:$DO14) -> 3538.9065 | DX14: =+SUMIF($D$3:$DO$3,DX$4,$D14:$DO14) -> 3763.762 | DY14: =+SUMIF($D$3:$DO$3,DY$4,$D14:$DO14) -> 4191.3896 | DZ14: =+SUMIF($D$3:$DO$3,DZ$4,$D14:$DO14) -> 4103.0778 | EA14: =+SUMIF($D$3:$DO$3,EA$4,$D14:$DO14) -> 5002.5408 | EB14: =+SUMIF($D$3:$DO$3,EB$4,$D14:$DO14) -> 4571.0676 | ... ED14: =+SUMIF($D$3:$DO$3,ED$4,$D14:$DO14) -> 2427.4673
