Workbook
Name Scenarios: 'Formula Audit'!$C$4:$C$6

Sheet Control Center
A2: NAVIGATION | B2: Integrated Operating Model & Analysis
C3: This operating model provides a multi-year projection framework for strategic planning. It includes: - A scenario-driven approach - A first-year 3-statement build - A multi-year forecast - Budget-versus-actual variance - Breakeven analysis - Ratio analysis and valuation - Chart-based presentation
C4: Contents | E4: Overview
C5: Summary Overview | E5: Business Category | F5: Financials
C6: Valuation Detail | E6: Entity Name
C7: Performance Dashboard | E7: Jurisdiction | F7: United Kingdom
C8: Revenue by Business Unit | E8: Fiscal Year | F8: 2025
C9: Scenario Planning | E9: Reporting Periods | F9: 10
C10: Trailing 12-Month Actuals | E10: Reporting Currency | F10: USD
C11: Forward 12-Month Projection
C12: Budget vs. Actual Variance
C13: Multi-Year Forecast
C14: Breakeven Detail | E14: Notes:
C15: Ratio Detail | E15: figures | F15: enter inputs only in the blue-shaded cells
A21: NAVIGATION | B21: ='Control Center'!F6
C23: Scenario Planning
C24: ='Formula Audit'!A3 -> Figures in USD
D25: Planning Case | E25: Central Case | G25: Key Assumptions
C26: Selected Case | G26: ='Formula Audit'!C9 -> 2025 | H26: ='Formula Audit'!D9 -> 2026 | I26: ='Formula Audit'!E9 -> 2027 | J26: ='Formula Audit'!F9 -> 2028 | K26: ='Formula Audit'!G9 -> 2029 | L26: ='Formula Audit'!H9 -> 2030 | M26: ='Formula Audit'!I9 -> 2031 | N26: ='Formula Audit'!J9 -> 2032 | ... P26: ='Formula Audit'!L9 -> 2034
C27: Statement of Operations
D28: Revenue Growth Rate | E28: % Chg | G28: ='Formula Audit'!C45 -> 0 | H28: ='Formula Audit'!D45 -> 0.067019 | I28: ='Formula Audit'!E45 -> 0.055849 | J28: ='Formula Audit'!F45 -> 0.044679 | K28: ='Formula Audit'!G45 -> 0.03351 | L28: ='Formula Audit'!H45 -> 0.03351 | M28: ='Formula Audit'!I45 -> 0.02234 | N28: ='Formula Audit'!J45 -> 0.02234 | ... P28: ='Formula Audit'!L45 -> 0.02234
D29: Service Costs | E29: share of service revenue | H29: ='Formula Audit'!D49 -> 0.265943 | I29: ='Formula Audit'!E49 -> 0.265943 | J29: ='Formula Audit'!F49 -> 0.255305 | K29: ='Formula Audit'!G49 -> 0.255305 | L29: ='Formula Audit'!H49 -> 0.244668 | M29: ='Formula Audit'!I49 -> 0.244668 | N29: ='Formula Audit'!J49 -> 0.23403 | O29: ='Formula Audit'!K49 -> 0.23403 | P29: ='Formula Audit'!L49 -> 0.223392
D30: Product Costs | E30: share of product revenue | H30: ='Formula Audit'!D53 -> 0.33648 | I30: ='Formula Audit'!E53 -> 0.319656 | J30: ='Formula Audit'!F53 -> 0.311244 | K30: ='Formula Audit'!G53 -> 0.302832 | L30: ='Formula Audit'!H53 -> 0.29442 | M30: ='Formula Audit'!I53 -> 0.29442 | N30: ='Formula Audit'!J53 -> 0.286008 | O30: ='Formula Audit'!K53 -> 0.286008 | P30: ='Formula Audit'!L53 -> 0.286008
D31: Direct Labour Costs | E31: share of total revenue | G31: ='Formula Audit'!C57 -> 0.190469 | H31: ='Formula Audit'!D57 -> 0.190469 | I31: ='Formula Audit'!E57 -> 0.190469 | J31: ='Formula Audit'!F57 -> 0.190469 | K31: ='Formula Audit'!G57 -> 0.190469 | L31: ='Formula Audit'!H57 -> 0.190469 | M31: ='Formula Audit'!I57 -> 0.190469 | N31: ='Formula Audit'!J57 -> 0.190469 | ... P31: ='Formula Audit'!L57 -> 0.190469
D32: Discounts & Promotions | E32: share of total revenue | G32: ='Formula Audit'!C61 -> 0.137193 | H32: ='Formula Audit'!D61 -> 0.12576 | I32: ='Formula Audit'!E61 -> 0.114327 | J32: ='Formula Audit'!F61 -> 0.102895 | K32: ='Formula Audit'!G61 -> 0.102895 | L32: ='Formula Audit'!H61 -> 0.091462 | M32: ='Formula Audit'!I61 -> 0.091462 | N32: ='Formula Audit'!J61 -> 0.080029 | ... P32: ='Formula Audit'!L61 -> 0.080029
D33: Salaries & Benefits | E33: ='Control Center'!$F$10 -> USD | G33: ='Formula Audit'!C65 -> 58749 | H33: ='Formula Audit'!D65 -> 58749 | I33: ='Formula Audit'!E65 -> 58749 | J33: ='Formula Audit'!F65 -> 58749 | K33: ='Formula Audit'!G65 -> 58749 | L33: ='Formula Audit'!H65 -> 58749 | M33: ='Formula Audit'!I65 -> 58749 | N33: ='Formula Audit'!J65 -> 58749 | ... P33: ='Formula Audit'!L65 -> 58749
D34: Sales & Marketing | E34: share of total revenue | G34: ='Formula Audit'!C69 -> 0.045594 | H34: ='Formula Audit'!D69 -> 0.045594 | I34: ='Formula Audit'!E69 -> 0.039895 | J34: ='Formula Audit'!F69 -> 0.039895 | K34: ='Formula Audit'!G69 -> 0.039895 | L34: ='Formula Audit'!H69 -> 0.039895 | M34: ='Formula Audit'!I69 -> 0.034195 | N34: ='Formula Audit'!J69 -> 0.034195 | ... P34: ='Formula Audit'!L69 -> 0.034195
D35: General & Administrative | E35: ='Control Center'!$F$10 -> USD | G35: ='Formula Audit'!C73 -> 34135 | H35: ='Formula Audit'!D73 -> 34135 | I35: ='Formula Audit'!E73 -> 34135 | J35: ='Formula Audit'!F73 -> 34135 | K35: ='Formula Audit'!G73 -> 34135 | L35: ='Formula Audit'!H73 -> 34135 | M35: ='Formula Audit'!I73 -> 34135 | N35: ='Formula Audit'!J73 -> 34135 | ... P35: ='Formula Audit'!L73 -> 34135
D36: Card Processing Fees | E36: share of total revenue | G36: ='Formula Audit'!C77 -> 0.007054 | H36: ='Formula Audit'!D77 -> 0.007054 | I36: ='Formula Audit'!E77 -> 0.007054 | J36: ='Formula Audit'!F77 -> 0.007054 | K36: ='Formula Audit'!G77 -> 0.007054 | L36: ='Formula Audit'!H77 -> 0.007054 | M36: ='Formula Audit'!I77 -> 0.007054 | N36: ='Formula Audit'!J77 -> 0.007054 | ... P36: ='Formula Audit'!L77 -> 0.007054
D37: Depreciation & Amortization | E37: share of PP&E | G37: ='Formula Audit'!C81 -> 0.414517 | H37: ='Formula Audit'!D81 -> 0.414517 | I37: ='Formula Audit'!E81 -> 0.414517 | J37: ='Formula Audit'!F81 -> 0.414517 | K37: ='Formula Audit'!G81 -> 0.414517 | L37: ='Formula Audit'!H81 -> 0.414517 | M37: ='Formula Audit'!I81 -> 0.414517 | N37: ='Formula Audit'!J81 -> 0.414517 | ... P37: ='Formula Audit'!L81 -> 0.414517
D38: Effective Tax Rate | E38: share of EBT | G38: ='Formula Audit'!C85 -> 0.264834 | H38: ='Formula Audit'!D85 -> 0.264834 | I38: ='Formula Audit'!E85 -> 0.264834 | J38: ='Formula Audit'!F85 -> 0.264834 | K38: ='Formula Audit'!G85 -> 0.264834 | L38: ='Formula Audit'!H85 -> 0.264834 | M38: ='Formula Audit'!I85 -> 0.264834 | N38: ='Formula Audit'!J85 -> 0.264834 | ... P38: ='Formula Audit'!L85 -> 0.264834
C40: Statement of Financial Position
D41: Trade Receivables | E41: days | G41: ='Formula Audit'!C89 -> 37 | H41: ='Formula Audit'!D89 -> 37 | I41: ='Formula Audit'!E89 -> 37 | J41: ='Formula Audit'!F89 -> 37 | K41: ='Formula Audit'!G89 -> 37 | L41: ='Formula Audit'!H89 -> 32 | M41: ='Formula Audit'!I89 -> 32 | N41: ='Formula Audit'!J89 -> 32 | ... P41: ='Formula Audit'!L89 -> 32
D42: Inventories | E42: days | G42: ='Formula Audit'!C93 -> 66 | H42: ='Formula Audit'!D93 -> 66 | I42: ='Formula Audit'!E93 -> 66 | J42: ='Formula Audit'!F93 -> 71 | K42: ='Formula Audit'!G93 -> 71 | L42: ='Formula Audit'!H93 -> 71 | M42: ='Formula Audit'!I93 -> 76 | N42: ='Formula Audit'!J93 -> 76 | ... P42: ='Formula Audit'!L93 -> 81
D43: Property, Plant & Equipment | E43: USD (opening) | G43: ='Formula Audit'!C97 -> 13917
D44: Trade Payables | E44: days | G44: ='Formula Audit'!C101 -> 53 | H44: ='Formula Audit'!D101 -> 53 | I44: ='Formula Audit'!E101 -> 53 | J44: ='Formula Audit'!F101 -> 53 | K44: ='Formula Audit'!G101 -> 53 | L44: ='Formula Audit'!H101 -> 48 | M44: ='Formula Audit'!I101 -> 48 | N44: ='Formula Audit'!J101 -> 48 | ... P44: ='Formula Audit'!L101 -> 48
D45: Accrued & Other Liabilities | E45: share of total revenue | G45: ='Formula Audit'!C105 -> 0.050563 | H45: ='Formula Audit'!D105 -> 0.050563 | I45: ='Formula Audit'!E105 -> 0.050563 | J45: ='Formula Audit'!F105 -> 0.050563 | K45: ='Formula Audit'!G105 -> 0.050563 | L45: ='Formula Audit'!H105 -> 0.050563 | M45: ='Formula Audit'!I105 -> 0.050563 | N45: ='Formula Audit'!J105 -> 0.050563 | ... P45: ='Formula Audit'!L105 -> 0.050563
D46: Capex Outlays | E46: ='Control Center'!$F$10 -> USD | G46: ='Formula Audit'!C109 -> 6975 | H46: ='Formula Audit'!D109 -> 8719 | I46: ='Formula Audit'!E109 -> 10463 | J46: ='Formula Audit'!F109 -> 10463 | K46: ='Formula Audit'!G109 -> 13078 | L46: ='Formula Audit'!H109 -> 15694 | M46: ='Formula Audit'!I109 -> 13078 | N46: ='Formula Audit'!J109 -> 10463 | ... P46: ='Formula Audit'!L109 -> 6975
C48: Financing Activities
D49: Interest Rate (% of Borrowings) | E49: % | G49: ='Formula Audit'!C113 -> 0.06294 | H49: ='Formula Audit'!D113 -> 0.06294 | I49: ='Formula Audit'!E113 -> 0.06294 | J49: ='Formula Audit'!F113 -> 0.06294 | K49: ='Formula Audit'!G113 -> 0.06294 | L49: ='Formula Audit'!H113 -> 0.06294 | M49: ='Formula Audit'!I113 -> 0.06294 | N49: ='Formula Audit'!J113 -> 0.06294 | ... P49: ='Formula Audit'!L113 -> 0.06294
...

Sheet Forecast Model
A2: NAVIGATION | B2: ='Control Center'!F6
C4: Trailing 12-Month Actuals
C5: ='Formula Audit'!A3 -> Figures in USD
H6: ='Control Center'!F8 -> 2025
C7: Statement of Operations | H7: ='Formula Audit'!C41 -> January | I7: ='Formula Audit'!D41 -> February | J7: ='Formula Audit'!E41 -> March | K7: ='Formula Audit'!F41 -> April | L7: ='Formula Audit'!G41 -> May | M7: ='Formula Audit'!H41 -> June | N7: ='Formula Audit'!I41 -> July | O7: ='Formula Audit'!J41 -> August | ... S7: ='Formula Audit'!N41 -> December | T7: FY
D8: Service Revenue | H8: 31629 | I8: 31629 | J8: 31629 | K8: 31629 | L8: 31629 | M8: 31629 | N8: 31629 | O8: 31629 | P8: 31629 | Q8: 31629 | R8: 31629 | S8: 31629 | T8: =SUM(H8:S8) -> 379548
D9: Product Revenue | H9: 8537 | I9: 8537 | J9: 8537 | K9: 8537 | L9: 8537 | M9: 8537 | N9: 8537 | O9: 8537 | P9: 8537 | Q9: 8537 | R9: 8537 | S9: 8537 | T9: =SUM(H9:S9) -> 102444
C10: Sales — Total | H10: =SUM(H8:H9) -> 40166 | I10: =SUM(I8:I9) -> 40166 | J10: =SUM(J8:J9) -> 40166 | K10: =SUM(K8:K9) -> 40166 | L10: =SUM(L8:L9) -> 40166 | M10: =SUM(M8:M9) -> 40166 | N10: =SUM(N8:N9) -> 40166 | O10: =SUM(O8:O9) -> 40166 | ... T10: =SUM(T8:T9) -> 481992
D12: Service Costs | H12: 7381 | I12: 7381 | J12: 7381 | K12: 7381 | L12: 7381 | M12: 7381 | N12: 7381 | O12: 7381 | P12: 7381 | Q12: 7381 | R12: 7381 | S12: 7381 | T12: =SUM(H12:S12) -> 88572
D13: Product Costs | H13: 4129 | I13: 4129 | J13: 4129 | K13: 4129 | L13: 4129 | M13: 4129 | N13: 4129 | O13: 4129 | P13: 4129 | Q13: 4129 | R13: 4129 | S13: 4129 | T13: =SUM(H13:S13) -> 49548
D14: Direct Labour Costs | H14: 9051 | I14: 9051 | J14: 9051 | K14: 9051 | L14: 9051 | M14: 9051 | N14: 9051 | O14: 9051 | P14: 9051 | Q14: 9051 | R14: 9051 | S14: 9051 | T14: =SUM(H14:S14) -> 108612
D15: Discounts & Promotions | H15: 6076 | I15: 6076 | J15: 6076 | K15: 6076 | L15: 6076 | M15: 6076 | N15: 6076 | O15: 6076 | P15: 6076 | Q15: 6076 | R15: 6076 | S15: 6076 | T15: =SUM(H15:S15) -> 72912
C16: Total Sales Costs | H16: =SUM(H12:H15) -> 26637 | I16: =SUM(I12:I15) -> 26637 | J16: =SUM(J12:J15) -> 26637 | K16: =SUM(K12:K15) -> 26637 | L16: =SUM(L12:L15) -> 26637 | M16: =SUM(M12:M15) -> 26637 | N16: =SUM(N12:N15) -> 26637 | O16: =SUM(O12:O15) -> 26637 | ... T16: =SUM(T12:T15) -> 319644
C18: Gross Income | H18: =H10-H16 -> 13529 | I18: =I10-I16 -> 13529 | J18: =J10-J16 -> 13529 | K18: =K10-K16 -> 13529 | L18: =L10-L16 -> 13529 | M18: =M10-M16 -> 13529 | N18: =N10-N16 -> 13529 | O18: =O10-O16 -> 13529 | ... T18: =T10-T16 -> 162348
C19: Gross Margin Rate | H19: =IFERROR(H18/H10,0) -> 0.33682717 | I19: =IFERROR(I18/I10,0) -> 0.33682717 | J19: =IFERROR(J18/J10,0) -> 0.33682717 | K19: =IFERROR(K18/K10,0) -> 0.33682717 | L19: =IFERROR(L18/L10,0) -> 0.33682717 | M19: =IFERROR(M18/M10,0) -> 0.33682717 | N19: =IFERROR(N18/N10,0) -> 0.33682717 | O19: =IFERROR(O18/O10,0) -> 0.33682717 | ... T19: =IFERROR(T18/T10,0) -> 0.33682717
D21: Salaries & Benefits | H21: 3648 | I21: 3648 | J21: 3648 | K21: 3648 | L21: 3648 | M21: 3648 | N21: 3648 | O21: 3648 | P21: 3648 | Q21: 3648 | R21: 3648 | S21: 3648 | T21: =SUM(H21:S21) -> 43776
D22: Sales & Marketing | H22: 2019 | I22: 2019 | J22: 2019 | K22: 2019 | L22: 2019 | M22: 2019 | N22: 2019 | O22: 2019 | P22: 2019 | Q22: 2019 | R22: 2019 | S22: 2019 | T22: =SUM(H22:S22) -> 24228
D23: General & Administrative | H23: 3647 | I23: 3647 | J23: 3647 | K23: 3647 | L23: 3647 | M23: 3647 | N23: 3647 | O23: 3647 | P23: 3647 | Q23: 3647 | R23: 3647 | S23: 3647 | T23: =SUM(H23:S23) -> 43764
D24: Card Processing Fees | H24: 440 | I24: 440 | J24: 440 | K24: 440 | L24: 440 | M24: 440 | N24: 440 | O24: 440 | P24: 440 | Q24: 440 | R24: 440 | S24: 440 | T24: =SUM(H24:S24) -> 5280
D25: Depreciation & Amortization | H25: 871 | I25: 871 | J25: 871 | K25: 871 | L25: 871 | M25: 871 | N25: 871 | O25: 871 | P25: 871 | Q25: 871 | R25: 871 | S25: 871 | T25: =SUM(H25:S25) -> 10452
C26: Operating Expenses — Total | H26: =SUM(H21:H25) -> 10625 | I26: =SUM(I21:I25) -> 10625 | J26: =SUM(J21:J25) -> 10625 | K26: =SUM(K21:K25) -> 10625 | L26: =SUM(L21:L25) -> 10625 | M26: =SUM(M21:M25) -> 10625 | N26: =SUM(N21:N25) -> 10625 | O26: =SUM(O21:O25) -> 10625 | ... T26: =SUM(T21:T25) -> 127500
C28: Operating Income (EBIT) | H28: =H18-H26 -> 2904 | I28: =I18-I26 -> 2904 | J28: =J18-J26 -> 2904 | K28: =K18-K26 -> 2904 | L28: =L18-L26 -> 2904 | M28: =M18-M26 -> 2904 | N28: =N18-N26 -> 2904 | O28: =O18-O26 -> 2904 | ... T28: =T18-T26 -> 34848
C29: Operating Margin Rate | H29: =IFERROR(H28/H10,0) -> 0.072299955 | I29: =IFERROR(I28/I10,0) -> 0.072299955 | J29: =IFERROR(J28/J10,0) -> 0.072299955 | K29: =IFERROR(K28/K10,0) -> 0.072299955 | L29: =IFERROR(L28/L10,0) -> 0.072299955 | M29: =IFERROR(M28/M10,0) -> 0.072299955 | N29: =IFERROR(N28/N10,0) -> 0.072299955 | O29: =IFERROR(O28/O10,0) -> 0.072299955 | ... T29: =IFERROR(T28/T10,0) -> 0.072299955
D31: Interest Expense | H31: 383 | I31: 383 | J31: 383 | K31: 383 | L31: 383 | M31: 383 | N31: 383 | O31: 383 | P31: 383 | Q31: 383 | R31: 383 | S31: 383 | T31: =SUM(H31:S31) -> 4596
C32: Pre-Tax Earnings (EBT) | H32: =H28-H31 -> 2521 | I32: =I28-I31 -> 2521 | J32: =J28-J31 -> 2521 | K32: =K28-K31 -> 2521 | L32: =L28-L31 -> 2521 | M32: =M28-M31 -> 2521 | N32: =N28-N31 -> 2521 | O32: =O28-O31 -> 2521 | ... T32: =T28-T31 -> 30252
D34: Income Tax Expense | H34: 1717 | I34: 1717 | J34: 1717 | K34: 1717 | L34: 1717 | M34: 1717 | N34: 1717 | O34: 1717 | P34: 1717 | Q34: 1717 | R34: 1717 | S34: 1717 | T34: =SUM(H34:S34) -> 20604
C35: Net Earnings | H35: =H32-H34 -> 804 | I35: =I32-I34 -> 804 | J35: =J32-J34 -> 804 | K35: =K32-K34 -> 804 | L35: =L32-L34 -> 804 | M35: =M32-M34 -> 804 | N35: =N32-N34 -> 804 | O35: =O32-O34 -> 804 | ... T35: =T32-T34 -> 9648
C36: Net Margin Rate | H36: =IFERROR(H35/H10,0) -> 0.02001693 | I36: =IFERROR(I35/I10,0) -> 0.02001693 | J36: =IFERROR(J35/J10,0) -> 0.02001693 | K36: =IFERROR(K35/K10,0) -> 0.02001693 | L36: =IFERROR(L35/L10,0) -> 0.02001693 | M36: =IFERROR(M35/M10,0) -> 0.02001693 | N36: =IFERROR(N35/N10,0) -> 0.02001693 | O36: =IFERROR(O35/O10,0) -> 0.02001693 | ... T36: =IFERROR(T35/T10,0) -> 0.02001693
C38: Statement of Financial Position
C39: Short-Term Assets
D40: Cash & Equivalents | H40: =H91 -> 155456 | I40: =I91 -> 150020 | J40: =J91 -> 144585 | K40: =K91 -> 139151 | L40: =L91 -> 133716 | M40: =M91 -> 128281 | N40: =N91 -> 122846 | O40: =O91 -> 117411 | ... S40: =S91 -> 95671 | T40: =S40 -> 95671
D41: Trade Receivables | H41: 5865 | I41: 11729 | J41: 17594 | K41: 23458 | L41: 29323 | M41: 35187 | N41: 41052 | O41: 46916 | P41: 52781 | Q41: 58645 | R41: 64510 | S41: 70374 | T41: =S41 -> 70374
D42: Inventories | H42: 4935 | I42: 9871 | J42: 14806 | K42: 19741 | L42: 24676 | M42: 29612 | N42: 34547 | O42: 39482 | P42: 44418 | Q42: 49353 | R42: 54288 | S42: 59223 | T42: =S42 -> 59223
D43: Current Assets — Total | H43: =SUM(H40:H42) -> 166256 | I43: =SUM(I40:I42) -> 171620 | J43: =SUM(J40:J42) -> 176985 | K43: =SUM(K40:K42) -> 182350 | L43: =SUM(L40:L42) -> 187715 | M43: =SUM(M40:M42) -> 193080 | N43: =SUM(N40:N42) -> 198445 | O43: =SUM(O40:O42) -> 203809 | ... T43: =SUM(T40:T42) -> 225268
C45: Long-Term Assets
D46: Property, Plant & Equipment | H46: 1659 | I46: 3317 | J46: 4976 | K46: 6634 | L46: 8293 | M46: 9952 | N46: 11610 | O46: 13269 | P46: 14927 | Q46: 16586 | R46: 18244 | S46: 19903 | T46: =S46 -> 19903
D47: Long-Term Assets — Total | H47: =SUM(H46) -> 1659 | I47: =SUM(I46) -> 3317 | J47: =SUM(J46) -> 4976 | K47: =SUM(K46) -> 6634 | L47: =SUM(L46) -> 8293 | M47: =SUM(M46) -> 9952 | N47: =SUM(N46) -> 11610 | O47: =SUM(O46) -> 13269 | ... T47: =SUM(T46) -> 19903
C48: Total Asset Base | H48: =H43+H47 -> 167915 | I48: =I43+I47 -> 174937 | J48: =J43+J47 -> 181961 | K48: =K43+K47 -> 188984 | L48: =L43+L47 -> 196008 | M48: =M43+M47 -> 203032 | N48: =N43+N47 -> 210055 | O48: =O43+O47 -> 217078 | ... T48: =T43+T47 -> 245171
C50: Short-Term Liabilities
D51: Trade Payable | H51: 4205 | I51: 8410 | J51: 12615 | K51: 16820 | L51: 21026 | M51: 25231 | N51: 29436 | O51: 33641 | P51: 37846 | Q51: 42051 | R51: 46256 | S51: 50461 | T51: =S51 -> 50461
...

Sheet Outputs
A2: NAVIGATION | B2: ='Control Center'!F6
C4: Summary Overview
C5: ='Formula Audit'!A3 -> Figures in USD
C6: Planning Case | D6: ='Control Center'!E25 -> Central Case
C7: Headline Financials | E7: ='Control Center'!F8 -> 2025 | F7: ='Formula Audit'!D9 -> 2026 | G7: ='Formula Audit'!E9 -> 2027 | H7: ='Formula Audit'!F9 -> 2028 | I7: ='Formula Audit'!G9 -> 2029 | J7: ='Formula Audit'!H9 -> 2030 | K7: ='Formula Audit'!I9 -> 2031 | L7: ='Formula Audit'!J9 -> 2032 | M7: ='Formula Audit'!K9 -> 2033 | N7: ='Formula Audit'!L9 -> 2034
C9: Revenue (Net) | E9: ='Forecast Model'!H219 -> 402045.22 | F9: ='Forecast Model'!I219 -> 428989.89 | G9: ='Forecast Model'!J219 -> 452948.55 | H9: ='Forecast Model'!K219 -> 473185.84 | I9: ='Forecast Model'!L219 -> 489042.3 | J9: ='Forecast Model'!M219 -> 505430.1 | K9: ='Forecast Model'!N219 -> 516721.41 | L9: ='Forecast Model'!O219 -> 528264.97 | ... N9: ='Forecast Model'!Q219 -> 552131.49
C10: Gross Income | E10: ='Forecast Model'!H227 -> 179209.12 | F10: ='Forecast Model'!I227 -> 163518.18 | G10: ='Forecast Model'!J227 -> 181789.36 | H10: ='Forecast Model'!K227 -> 199807.34 | I10: ='Forecast Model'!L227 -> 208640.82 | J10: ='Forecast Model'!M227 -> 226202.77 | K10: ='Forecast Model'!N227 -> 231256.14 | L10: ='Forecast Model'!O227 -> 247470.62 | ... N10: ='Forecast Model'!Q227 -> 261472.22
C11: Gross Income Margin | E11: =IFERROR('Forecast Model'!H228, "") -> 0.4457437 | F11: =IFERROR('Forecast Model'!I228, "") -> 0.38117024 | G11: =IFERROR('Forecast Model'!J228, "") -> 0.4013466 | H11: =IFERROR('Forecast Model'!K228, "") -> 0.42225976 | I11: =IFERROR('Forecast Model'!L228, "") -> 0.42663143 | J11: =IFERROR('Forecast Model'!M228, "") -> 0.44754511 | K11: =IFERROR('Forecast Model'!N228, "") -> 0.44754511 | L11: =IFERROR('Forecast Model'!O228, "") -> 0.46845927 | ... N11: =IFERROR('Forecast Model'!Q228, "") -> 0.47356875
C12: EBITDA (Operating) | E12: ='Forecast Model'!H238+'Forecast Model'!H234 -> 65158.248 | F12: ='Forecast Model'!I238+'Forecast Model'!I234 -> 48048.722 | G12: ='Forecast Model'!J238+'Forecast Model'!J234 -> 67639.878 | H12: ='Forecast Model'!K238+'Forecast Model'!K234 -> 84707.735 | I12: ='Forecast Model'!L238+'Forecast Model'!L234 -> 92796.769 | J12: ='Forecast Model'!M238+'Forecast Model'!M234 -> 109589.33 | K12: ='Forecast Model'!N238+'Forecast Model'!N234 -> 117057.9 | L12: ='Forecast Model'!O238+'Forecast Model'!O234 -> 132796.22 | ... N12: ='Forecast Model'!Q238+'Forecast Model'!Q234 -> 145813.35
C13: Net Earnings | E13: ='Forecast Model'!H245 -> 38377.846 | F13: ='Forecast Model'!I245 -> 25914.797 | G13: ='Forecast Model'!J245 -> 40029.927 | H13: ='Forecast Model'!K245 -> 52514.671 | I13: ='Forecast Model'!L245 -> 57733.132 | J13: ='Forecast Model'!M245 -> 68960.272 | K13: ='Forecast Model'!N245 -> 74698.861 | L13: ='Forecast Model'!O245 -> 87316.637 | ... N13: ='Forecast Model'!Q245 -> 99505.442
C14: Net Profit Margin Rate | E14: =IFERROR('Forecast Model'!H228,"") -> 0.4457437 | F14: =IFERROR('Forecast Model'!I228,"") -> 0.38117024 | G14: =IFERROR('Forecast Model'!J228,"") -> 0.4013466 | H14: =IFERROR('Forecast Model'!K228,"") -> 0.42225976 | I14: =IFERROR('Forecast Model'!L228,"") -> 0.42663143 | J14: =IFERROR('Forecast Model'!M228,"") -> 0.44754511 | K14: =IFERROR('Forecast Model'!N228,"") -> 0.44754511 | L14: =IFERROR('Forecast Model'!O228,"") -> 0.46845927 | ... N14: =IFERROR('Forecast Model'!Q228,"") -> 0.47356875
C16: Running Cash Flow | E16: ='Forecast Model'!H301 -> 178578.55 | F16: ='Forecast Model'!I301 -> 163839.58 | G16: ='Forecast Model'!J301 -> 189931.21 | H16: ='Forecast Model'!K301 -> 223641.76 | I16: ='Forecast Model'!L301 -> 264213.03 | J16: ='Forecast Model'!M301 -> 317061.08 | K16: ='Forecast Model'!N301 -> 370368.6 | L16: ='Forecast Model'!O301 -> 440597.54 | ... N16: ='Forecast Model'!Q301 -> 591162.38
C17: Free Cash Flows | E17: ='Valuation & Breakeven'!K17 -> 30441.127 | F17: ='Valuation & Breakeven'!L17 -> -1256.5348 | G17: ='Valuation & Breakeven'!M17 -> 41336.785 | H17: ='Valuation & Breakeven'!N17 -> 50474.859 | I17: ='Valuation & Breakeven'!O17 -> 57769.203 | J17: ='Valuation & Breakeven'!P17 -> 71377.25 | K17: ='Valuation & Breakeven'!Q17 -> 72348.047 | L17: ='Valuation & Breakeven'!R17 -> 90808.492 | ... N17: ='Valuation & Breakeven'!T17 -> 102220.34
C18: EV / Revenue | E18: =IFERROR('Valuation & Breakeven'!$K$40/E9,0) -> 0.72698649 | F18: =IFERROR('Valuation & Breakeven'!$K$40/F9,0) -> 0.68132478 | G18: =IFERROR('Valuation & Breakeven'!$K$40/G9,0) -> 0.6452862 | H18: =IFERROR('Valuation & Breakeven'!$K$40/H9,0) -> 0.61768849 | I18: =IFERROR('Valuation & Breakeven'!$K$40/I9,0) -> 0.59766088 | J18: =IFERROR('Valuation & Breakeven'!$K$40/J9,0) -> 0.57828262 | K18: =IFERROR('Valuation & Breakeven'!$K$40/K9,0) -> 0.56564609 | L18: =IFERROR('Valuation & Breakeven'!$K$40/L9,0) -> 0.55328569 | ... N18: =IFERROR('Valuation & Breakeven'!$K$40/N9,0) -> 0.52936927
C19: EV / EBITDA | E19: =IFERROR('Valuation & Breakeven'!$K$40/E12,0) -> 4.4857168 | F19: =IFERROR('Valuation & Breakeven'!$K$40/F12,0) -> 6.0830223 | G19: =IFERROR('Valuation & Breakeven'!$K$40/G12,0) -> 4.3211409 | H19: =IFERROR('Valuation & Breakeven'!$K$40/H12,0) -> 3.4504694 | I19: =IFERROR('Valuation & Breakeven'!$K$40/I12,0) -> 3.1496942 | J19: =IFERROR('Valuation & Breakeven'!$K$40/J12,0) -> 2.6670611 | K19: =IFERROR('Valuation & Breakeven'!$K$40/K12,0) -> 2.4968964 | L19: =IFERROR('Valuation & Breakeven'!$K$40/L12,0) -> 2.2009772 | ... N19: =IFERROR('Valuation & Breakeven'!$K$40/N12,0) -> 2.0044903
C21: Return on Shareholder Equity (ROE) | E21: =IFERROR('Formula Audit'!C213,"") -> 0.30592764 | F21: =IFERROR('Formula Audit'!D213,"") -> 0.17570453 | G21: =IFERROR('Formula Audit'!E213,"") -> 0.22050135 | H21: =IFERROR('Formula Audit'!F213,"") -> 0.23215024 | I21: =IFERROR('Formula Audit'!G213,"") -> 0.20969613 | J21: =IFERROR('Formula Audit'!H213,"") -> 0.20648262 | K21: =IFERROR('Formula Audit'!I213,"") -> 0.18791432 | L21: =IFERROR('Formula Audit'!J213,"") -> 0.18507613 | ... N21: =IFERROR('Formula Audit'!L213,"") -> 0.15672221
C22: Return on Capital (ROCE) | E22: =IFERROR('Formula Audit'!C215,"") -> 0.21767949 | F22: =IFERROR('Formula Audit'!D215,"") -> 0.13956251 | G22: =IFERROR('Formula Audit'!E215,"") -> 0.18142553 | H22: =IFERROR('Formula Audit'!F215,"") -> 0.20005099 | I22: =IFERROR('Formula Audit'!G215,"") -> 0.18825168 | J22: =IFERROR('Formula Audit'!H215,"") -> 0.19084711 | K22: =IFERROR('Formula Audit'!I215,"") -> 0.17783704 | L22: =IFERROR('Formula Audit'!J215,"") -> 0.17810306 | ... N22: =IFERROR('Formula Audit'!L215,"") -> 0.15441628
A27: NAVIGATION | B27: ='Control Center'!F6
C29: Performance Dashboard
C30: ='Formula Audit'!A3 -> Figures in USD
E31: Fiscal Year (Yr) | F31: 2025
D33: Revenue — Total | F33: Total Operating Costs | L33: Ending Cash Balance | N33: Long-Term Borrowings
D34: ='Formula Audit'!C238 -> 402045.22 | F34: ='Formula Audit'!C242 -> 0 | L34: ='Formula Audit'!C254 -> 178578.55 | N34: ='Formula Audit'!C258 -> 65363
D35: ='Formula Audit'!C240 -> 0 | F35: ='Formula Audit'!C244 -> 0 | J35: Net Margin Rate | L35: ='Formula Audit'!C256 -> 0 | N35: ='Formula Audit'!C260 -> 0
D36: vs. Preceding Year | F36: vs. Preceding Year | J36: ='Formula Audit'!C270 -> 0.09545654 | L36: vs. Preceding Year | N36: vs. Preceding Year
D38: Net Profit for Period | F38: EBITDA (Operating) | J38: ='Formula Audit'!C272 -> 0 | L38: Working Capital Ratio | N38: Acid-Test Ratio
D39: ='Formula Audit'!C246 -> 38377.846 | F39: ='Formula Audit'!C250 -> 0 | J39: vs. Preceding Year | L39: ='Formula Audit'!C262 | N39: ='Formula Audit'!C266
D40: ='Formula Audit'!C248 -> 0 | F40: ='Formula Audit'!C252 -> 0 | L40: ='Formula Audit'!C264 -> 0 | N40: ='Formula Audit'!C268 -> 0
D41: vs. Preceding Year | F41: vs. Preceding Year | L41: vs. Preceding Year | N41: vs. Preceding Year
M71: Statement of Operations | O71: ='Formula Audit'!C305 -> 2025
M72: Sales — Total | O72: ='Formula Audit'!C306 -> 402045.22
M73: Total Sales Costs | O73: ='Formula Audit'!C307 -> 222836.1
M74: Gross Income | O74: ='Formula Audit'!C308 -> 179209.12
M75: Operating Expenses — Total | O75: ='Formula Audit'!C309 -> 122710.97
M76: Operating Income (EBIT) | O76: ='Formula Audit'!C310 -> 56498.159
M77: Interest Expense | O77: ='Formula Audit'!C311 -> 4295.1919
M78: Pre-Tax Earnings (EBT) | O78: ='Formula Audit'!C312 -> 52202.967
M79: Income Tax Expense | O79: ='Formula Audit'!C313 -> 13825.12
M80: Net Earnings | O80: ='Formula Audit'!C314 -> 38377.846
M81: Statement of Cash Flows
...

Sheet Valuation & Breakeven
A2: NAVIGATION | B2: ='Control Center'!F6
C4: Valuation Detail
C5: ='Formula Audit'!A3 -> Figures in USD
D6: Planning Case | E6: ='Control Center'!E25 -> Central Case
C7: DCF Valuation | K7: ='Control Center'!F8 -> 2025 | L7: ='Formula Audit'!D9 -> 2026 | M7: ='Formula Audit'!E9 -> 2027 | N7: ='Formula Audit'!F9 -> 2028 | O7: ='Formula Audit'!G9 -> 2029 | P7: ='Formula Audit'!H9 -> 2030 | Q7: ='Formula Audit'!I9 -> 2031 | R7: ='Formula Audit'!J9 -> 2032 | S7: ='Formula Audit'!K9 -> 2033 | T7: ='Formula Audit'!L9 -> 2034
D9: Pre-Tax Income (EBT) | K9: ='Forecast Model'!H242 -> 52202.967 | L9: ='Forecast Model'!I242 -> 35250.266 | M9: ='Forecast Model'!J242 -> 54450.189 | N9: ='Forecast Model'!K242 -> 71432.4 | O9: ='Forecast Model'!L242 -> 78530.743 | P9: ='Forecast Model'!M242 -> 93802.314 | Q9: ='Forecast Model'!N242 -> 101608.16 | R9: ='Forecast Model'!O242 -> 118771.32 | ... T9: ='Forecast Model'!Q242 -> 135350.98
D10: Interest Expense | K10: ='Forecast Model'!H241 -> 4295.1919 | L10: ='Forecast Model'!I241 -> 4113.9472 | M10: ='Forecast Model'!J241 -> 3767.966 | N10: ='Forecast Model'!K241 -> 3421.9849 | O10: ='Forecast Model'!L241 -> 3076.0037 | P10: ='Forecast Model'!M241 -> 2730.0225 | Q10: ='Forecast Model'!N241 -> 2384.0413 | R10: ='Forecast Model'!O241 -> 2038.0601 | ... T10: ='Forecast Model'!Q241 -> 1346.0978
C11: EBIT (Operating Income) | K11: =SUM(K9+K10) -> 56498.159 | L11: =SUM(L9+L10) -> 39364.213 | M11: =SUM(M9+M10) -> 58218.155 | N11: =SUM(N9+N10) -> 74854.384 | O11: =SUM(O9+O10) -> 81606.747 | P11: =SUM(P9+P10) -> 96532.336 | Q11: =SUM(Q9+Q10) -> 103992.2 | R11: =SUM(R9+R10) -> 120809.38 | ... T11: =SUM(T9+T10) -> 136697.08
D12: Less: Cash Tax | K12: ='Forecast Model'!H244 -> 13825.12 | L12: ='Forecast Model'!I244 -> 9335.4689 | M12: ='Forecast Model'!J244 -> 14420.261 | N12: ='Forecast Model'!K244 -> 18917.728 | O12: ='Forecast Model'!L244 -> 20797.611 | P12: ='Forecast Model'!M244 -> 24842.042 | Q12: ='Forecast Model'!N244 -> 26909.294 | R12: ='Forecast Model'!O244 -> 31454.684 | ... T12: ='Forecast Model'!Q244 -> 35845.543
D13: Plus: Depreciation & Amortization | K13: ='Forecast Model'!H234 -> 8660.0892 | L13: ='Forecast Model'!I234 -> 8684.5087 | M13: ='Forecast Model'!J234 -> 9421.7236 | N13: ='Forecast Model'!K234 -> 9853.3504 | O13: ='Forecast Model'!L234 -> 11190.022 | P13: ='Forecast Model'!M234 -> 13056.998 | Q13: ='Forecast Model'!N234 -> 13065.704 | R13: ='Forecast Model'!O234 -> 11986.839 | ... T13: ='Forecast Model'!Q234 -> 9116.2659
C14: EBITDA (Operating) | K14: =K11-K12+K13 -> 51333.127 | L14: =L11-L12+L13 -> 38713.253 | M14: =M11-M12+M13 -> 53219.617 | N14: =N11-N12+N13 -> 65790.007 | O14: =O11-O12+O13 -> 71999.158 | P14: =P11-P12+P13 -> 84747.292 | Q14: =Q11-Q12+Q13 -> 90148.606 | R14: =R11-R12+R13 -> 101341.54 | ... T14: =T11-T12+T13 -> 109967.81
D15: Less: Capital Expenditure | K15: =-'Forecast Model'!H290 -> 20892 | L15: =-'Forecast Model'!I290 -> 8719 | M15: =-'Forecast Model'!J290 -> 10463 | N15: =-'Forecast Model'!K290 -> 10463 | O15: =-'Forecast Model'!L290 -> 13078 | P15: =-'Forecast Model'!M290 -> 15694 | Q15: =-'Forecast Model'!N290 -> 13078 | R15: =-'Forecast Model'!O290 -> 10463 | ... T15: =-'Forecast Model'!Q290 -> 6975
D16: Less: Working Capital Movement | K16: =-SUM('Forecast Model'!H283:H286) -> 0 | L16: =-SUM('Forecast Model'!I283:I286) -> 31250.788 | M16: =-SUM('Forecast Model'!J283:J286) -> 1419.8319 | N16: =-SUM('Forecast Model'!K283:K286) -> 4852.1481 | O16: =-SUM('Forecast Model'!L283:L286) -> 1151.9555 | P16: =-SUM('Forecast Model'!M283:M286) -> -2323.9582 | Q16: =-SUM('Forecast Model'!N283:N286) -> 4722.5592 | R16: =-SUM('Forecast Model'!O283:O286) -> 70.043607 | ... T16: =-SUM('Forecast Model'!Q283:Q286) -> 772.46816
C17: Firm Free Cash Flow (FCFF) | K17: =K14-K15-K16 -> 30441.127 | L17: =L14-L15-L16 -> -1256.5348 | M17: =M14-M15-M16 -> 41336.785 | N17: =N14-N15-N16 -> 50474.859 | O17: =O14-O15-O16 -> 57769.203 | P17: =P14-P15-P16 -> 71377.25 | Q17: =Q14-Q15-Q16 -> 72348.047 | R17: =R14-R15-R16 -> 90808.492 | ... T17: =T14-T15-T16 -> 102220.34
D18: Terminal Worth (EBITDA Multiple Approach) | K18: =K14*$K$26*'Formula Audit'!C12 -> 0 | L18: =L14*$K$26*'Formula Audit'!D12 -> 0 | M18: =M14*$K$26*'Formula Audit'!E12 -> 0 | N18: =N14*$K$26*'Formula Audit'!F12 -> 0 | O18: =O14*$K$26*'Formula Audit'!G12 -> 0 | P18: =P14*$K$26*'Formula Audit'!H12 -> 0 | Q18: =Q14*$K$26*'Formula Audit'!I12 -> 0 | R18: =R14*$K$26*'Formula Audit'!J12 -> 0 | ... T18: =T14*$K$26*'Formula Audit'!L12 -> 351392.99
C19: Net Free Cash Flow | J19: =-K40 -> -292281.45 | K19: =K17+K18 -> 30441.127 | L19: =L17+L18 -> -1256.5348 | M19: =M17+M18 -> 41336.785 | N19: =N17+N18 -> 50474.859 | O19: =O17+O18 -> 57769.203 | P19: =P17+P18 -> 71377.25 | Q19: =Q17+Q18 -> 72348.047 | R19: =R17+R18 -> 90808.492 | ... T19: =T17+T18 -> 453613.33
D21: PV of Terminal Worth | K21: =K18/(1+$E$40)^'Formula Audit'!C13 -> 0 | L21: =L18/(1+$E$40)^'Formula Audit'!D13 -> 0 | M21: =M18/(1+$E$40)^'Formula Audit'!E13 -> 0 | N21: =N18/(1+$E$40)^'Formula Audit'!F13 -> 0 | O21: =O18/(1+$E$40)^'Formula Audit'!G13 -> 0 | P21: =P18/(1+$E$40)^'Formula Audit'!H13 -> 0 | Q21: =Q18/(1+$E$40)^'Formula Audit'!I13 -> 0 | R21: =R18/(1+$E$40)^'Formula Audit'!J13 -> 0 | ... T21: =T18/(1+$E$40)^'Formula Audit'!L13 -> 169548.04
D22: PV of Net Free Cash Flow | K22: =K19/(1+$E$40)^'Formula Audit'!C13 -> 30441.127 | L22: =L19/(1+$E$40)^'Formula Audit'!D13 -> -1158.7982 | M22: =M19/(1+$E$40)^'Formula Audit'!E13 -> 35156.311 | N22: =N19/(1+$E$40)^'Formula Audit'!F13 -> 39589.043 | O22: =O19/(1+$E$40)^'Formula Audit'!G13 -> 41785.882 | P22: =P19/(1+$E$40)^'Formula Audit'!H13 -> 47613.083 | Q22: =Q19/(1+$E$40)^'Formula Audit'!I13 -> 44506.824 | R22: =R19/(1+$E$40)^'Formula Audit'!J13 -> 51518.066 | ... T22: =T19/(1+$E$40)^'Formula Audit'!L13 -> 218869.63
C24: Valuation Detail
C25: WACC Build-Up | G25: Valuation Inputs | M25: Equity Worth Sensitivity
G26: EV / EBITDA Multiple | K26: 3.195417 | O26: Cost of Capital, Weighted Avg. (WACC)
D27: Borrowings to Total Capital | E27: =E43/E45 -> 0.43296286 | G27: Prevailing Price | K27: 10 | M27: EV / EBITDA Multiple
D28: Equity Share of Capital | E28: =E44/E45 -> 0.56703714 | G28: Outstanding Shares | K28: 40000 | P28: =R28-2% -> 0.064343054 | Q28: =R28-1% -> 0.074343054 | R28: =E40 -> 0.084343054 | S28: =R28+1% -> 0.094343054 | T28: =R28+2% -> 0.10434305
C29: Borrowings / Equity | E29: =E27/E28 -> 0.7635529 | N29: =K26-2 -> 1.195417 | O29: x | P29: ='Formula Audit'!N19 -> -679429.15 | Q29: ='Formula Audit'!O19 -> -636892.3 | R29: ='Formula Audit'!P19 -> -597375.89 | S29: ='Formula Audit'!Q19 -> -560622.81 | T29: ='Formula Audit'!R19 -> -526400.69
G30: Fundamental Value | N30: =K26-1 -> 2.195417 | O30: x | P30: ='Formula Audit'!N20 -> -627809.17 | Q30: ='Formula Audit'!O20 -> -585272.32 | R30: ='Formula Audit'!P20 -> -545755.91 | S30: ='Formula Audit'!Q20 -> -509002.83 | T30: ='Formula Audit'!R20 -> -474780.71
D31: Pre-Tax Debt Cost | E31: ='Control Center'!G49 -> 0.06294 | H31: Sum of PV of Free Cash Flows | K31: =SUM(K22:T22) -> 555946.38 | N31: =K26 -> 3.195417 | O31: x | P31: ='Formula Audit'!N21 -> -584879.21 | Q31: ='Formula Audit'!O21 -> -542342.36 | R31: ='Formula Audit'!P21 -> -502825.96 | S31: ='Formula Audit'!Q21 -> -466072.87 | T31: ='Formula Audit'!R21 -> -431850.75
D32: Effective Tax Rate | E32: ='Control Center'!G38 -> 0.264834 | H32: Plus: PV of Terminal Worth | K32: =SUM(K21:T21) -> 169548.04 | N32: =K26+1 -> 4.195417 | O32: x | P32: ='Formula Audit'!N22 -> -549471.88 | Q32: ='Formula Audit'!O22 -> -506935.03 | R32: ='Formula Audit'!P22 -> -467418.62 | S32: ='Formula Audit'!Q22 -> -430665.54 | T32: ='Formula Audit'!R22 -> -396443.42
C33: Post-Tax Debt Cost | E33: =E31*(1-E32) -> 0.046271348 | H33: Less: Net Borrowings | K33: =K38-K39 -> -107718.55 | N33: =K26+2 -> 5.195417 | O33: x | P33: ='Formula Audit'!N23 -> -520570.49 | Q33: ='Formula Audit'!O23 -> -478033.65 | R33: ='Formula Audit'!P23 -> -438517.24 | S33: ='Formula Audit'!Q23 -> -401764.15 | T33: ='Formula Audit'!R23 -> -367542.03
G34: Equity Worth | K34: =K31+K32-K33 -> 833212.98
D35: Risk-Free Rate | E35: 0.024138
D36: Market Risk Premium | E36: 0.073205 | G36: Market Worth
D37: Equity Beta | E37: 1.219518 | H37: Market Capitalization | K37: =K27*K28 -> 400000
C38: Equity Cost | E38: =E35+(E36*E37) -> 0.11341282 | H38: Plus: Borrowings | K38: =E43 -> 70860
H39: Less: Cash Balance | K39: ='Forecast Model'!T191 -> 178578.55
C40: WACC (Discounting Rate) | E40: =(E27*E33)+(E28*E38) -> 0.084343054 | G40: Enterprise Value | K40: =K37+K38-K39 -> 292281.45
C42: Capital Structure (Initial Outlay) | G42: Return Rate
D43: Borrowings | E43: ='Control Center'!G50 -> 70860 | H43: Prevailing Share Price | K43: =K27 -> 10
D44: Shareholder Equity | E44: ='Control Center'!G51 -> 92803 | H44: Upside Potential | K44: =K45-K43 -> 10.830325
C45: Total Amount | E45: =SUM(E43:E44) -> 163663 | H45: Implied Share Price | K45: =K34/K28 -> 20.830325
H46: Target Price Upside Rate | K46: =K44/K43 -> 1.0830325
...

Sheet Formula Audit
A3: ="Figures in"&" "&'Control Center'!F10 -> Figures in USD | T3: WACC Rate | U3: EV / EBITDA Multiple | V3: Equity Worth
A4: Planning Cases | C4: Central Case | T4: =$A$19 -> 0.064343054 | U4: =$A$14 -> 1.195417 | V4: =N19 -> -679429.15
C5: Upside Case | T5: =$A$19 -> 0.064343054 | U5: =$A$15 -> 2.195417 | V5: =N20 -> -627809.17
C6: Downside Case | T6: =$A$19 -> 0.064343054 | U6: =$A$16 -> 3.195417 | V6: =N21 -> -584879.21
A7: Summary Overview | T7: =$A$19 -> 0.064343054 | U7: =$A$17 -> 4.195417 | V7: =N22 -> -549471.88
A8: Headline Financial | C8: =IF(('Control Center'!$F$9-COUNTBLANK($B2:B2))>=0,1,0) -> 1 | D8: =IF(('Control Center'!$F$9-COUNTBLANK($B2:C2))>=0,1,0) -> 1 | E8: =IF(('Control Center'!$F$9-COUNTBLANK($B2:D2))>=0,1,0) -> 1 | F8: =IF(('Control Center'!$F$9-COUNTBLANK($B2:E2))>=0,1,0) -> 1 | G8: =IF(('Control Center'!$F$9-COUNTBLANK($B2:F2))>=0,1,0) -> 1 | H8: =IF(('Control Center'!$F$9-COUNTBLANK($B2:G2))>=0,1,0) -> 1 | I8: =IF(('Control Center'!$F$9-COUNTBLANK($B2:H2))>=0,1,0) -> 1 | J8: =IF(('Control Center'!$F$9-COUNTBLANK($B2:I2))>=0,1,0) -> 1 | ... L8: =IF(('Control Center'!$F$9-COUNTBLANK($B2:K2))>=0,1,0) -> 1 | T8: =$A$19 -> 0.064343054 | U8: =$A$18 -> 5.195417 | V8: =N23 -> -520570.49
A9: Fiscal Years | C9: ='Control Center'!$F$8 -> 2025 | D9: =(C9+1)*D$8 -> 2026 | E9: =(D9+1)*E$8 -> 2027 | F9: =(E9+1)*F$8 -> 2028 | G9: =(F9+1)*G$8 -> 2029 | H9: =(G9+1)*H$8 -> 2030 | I9: =(H9+1)*I$8 -> 2031 | J9: =(I9+1)*J$8 -> 2032 | K9: =(J9+1)*K$8 -> 2033 | L9: =(K9+1)*L$8 -> 2034 | T9: =$A$20 -> 0.074343054 | U9: =$A$14 -> 1.195417 | V9: =O19 -> -636892.3
T10: =$A$20 -> 0.074343054 | U10: =$A$15 -> 2.195417 | V10: =O20 -> -585272.32
A11: Valuation Analysis | T11: =$A$20 -> 0.074343054 | U11: =$A$16 -> 3.195417 | V11: =O21 -> -542342.36
A12: Terminal Worth | C12: =IF(COUNT($C8:C8)='Control Center'!$F$9,1,0) -> 0 | D12: =IF(COUNT($C8:D8)='Control Center'!$F$9,1,0) -> 0 | E12: =IF(COUNT($C8:E8)='Control Center'!$F$9,1,0) -> 0 | F12: =IF(COUNT($C8:F8)='Control Center'!$F$9,1,0) -> 0 | G12: =IF(COUNT($C8:G8)='Control Center'!$F$9,1,0) -> 0 | H12: =IF(COUNT($C8:H8)='Control Center'!$F$9,1,0) -> 0 | I12: =IF(COUNT($C8:I8)='Control Center'!$F$9,1,0) -> 0 | J12: =IF(COUNT($C8:J8)='Control Center'!$F$9,1,0) -> 0 | ... L12: =IF(COUNT($C8:L8)='Control Center'!$F$9,1,0) -> 1 | T12: =$A$20 -> 0.074343054 | U12: =$A$17 -> 4.195417 | V12: =O22 -> -506935.03
A13: Reporting Period | C13: 0 | D13: =COUNT($C$8:C8)*C8 -> 1 | E13: =COUNT($C$8:D8)*D8 -> 2 | F13: =COUNT($C$8:E8)*E8 -> 3 | G13: =COUNT($C$8:F8)*F8 -> 4 | H13: =COUNT($C$8:G8)*G8 -> 5 | I13: =COUNT($C$8:H8)*H8 -> 6 | J13: =COUNT($C$8:I8)*I8 -> 7 | K13: =COUNT($C$8:J8)*J8 -> 8 | L13: =COUNT($C$8:K8)*K8 -> 9 | T13: =$A$20 -> 0.074343054 | U13: =$A$18 -> 5.195417 | V13: =O23 -> -478033.65
A14: ='Valuation & Breakeven'!N29 -> 1.195417 | B14: Terminal Worth | C14: ='Valuation & Breakeven'!K$14*$A14*'Formula Audit'!C$12 -> 0 | D14: ='Valuation & Breakeven'!L$14*$A14*'Formula Audit'!D$12 -> 0 | E14: ='Valuation & Breakeven'!M$14*$A14*'Formula Audit'!E$12 -> 0 | F14: ='Valuation & Breakeven'!N$14*$A14*'Formula Audit'!F$12 -> 0 | G14: ='Valuation & Breakeven'!O$14*$A14*'Formula Audit'!G$12 -> 0 | H14: ='Valuation & Breakeven'!P$14*$A14*'Formula Audit'!H$12 -> 0 | I14: ='Valuation & Breakeven'!Q$14*$A14*'Formula Audit'!I$12 -> 0 | J14: ='Valuation & Breakeven'!R$14*$A14*'Formula Audit'!J$12 -> 0 | ... L14: ='Valuation & Breakeven'!T$14*$A14*'Formula Audit'!L$12 -> 131457.38 | T14: =$A$21 -> 0.084343054 | U14: =$A$14 -> 1.195417 | V14: =P19 -> -597375.89
A15: ='Valuation & Breakeven'!N30 -> 2.195417 | B15: Terminal Worth | C15: ='Valuation & Breakeven'!K$14*$A15*'Formula Audit'!C$12 -> 0 | D15: ='Valuation & Breakeven'!L$14*$A15*'Formula Audit'!D$12 -> 0 | E15: ='Valuation & Breakeven'!M$14*$A15*'Formula Audit'!E$12 -> 0 | F15: ='Valuation & Breakeven'!N$14*$A15*'Formula Audit'!F$12 -> 0 | G15: ='Valuation & Breakeven'!O$14*$A15*'Formula Audit'!G$12 -> 0 | H15: ='Valuation & Breakeven'!P$14*$A15*'Formula Audit'!H$12 -> 0 | I15: ='Valuation & Breakeven'!Q$14*$A15*'Formula Audit'!I$12 -> 0 | J15: ='Valuation & Breakeven'!R$14*$A15*'Formula Audit'!J$12 -> 0 | ... L15: ='Valuation & Breakeven'!T$14*$A15*'Formula Audit'!L$12 -> 241425.19 | T15: =$A$21 -> 0.084343054 | U15: =$A$15 -> 2.195417 | V15: =P20 -> -545755.91
A16: ='Valuation & Breakeven'!N31 -> 3.195417 | B16: Terminal Worth | C16: ='Valuation & Breakeven'!K$14*$A16*'Formula Audit'!C$12 -> 0 | D16: ='Valuation & Breakeven'!L$14*$A16*'Formula Audit'!D$12 -> 0 | E16: ='Valuation & Breakeven'!M$14*$A16*'Formula Audit'!E$12 -> 0 | F16: ='Valuation & Breakeven'!N$14*$A16*'Formula Audit'!F$12 -> 0 | G16: ='Valuation & Breakeven'!O$14*$A16*'Formula Audit'!G$12 -> 0 | H16: ='Valuation & Breakeven'!P$14*$A16*'Formula Audit'!H$12 -> 0 | I16: ='Valuation & Breakeven'!Q$14*$A16*'Formula Audit'!I$12 -> 0 | J16: ='Valuation & Breakeven'!R$14*$A16*'Formula Audit'!J$12 -> 0 | ... L16: ='Valuation & Breakeven'!T$14*$A16*'Formula Audit'!L$12 -> 351392.99 | T16: =$A$21 -> 0.084343054 | U16: =$A$16 -> 3.195417 | V16: =P21 -> -502825.96
A17: ='Valuation & Breakeven'!N32 -> 4.195417 | B17: Terminal Worth | C17: ='Valuation & Breakeven'!K$14*$A17*'Formula Audit'!C$12 -> 0 | D17: ='Valuation & Breakeven'!L$14*$A17*'Formula Audit'!D$12 -> 0 | E17: ='Valuation & Breakeven'!M$14*$A17*'Formula Audit'!E$12 -> 0 | F17: ='Valuation & Breakeven'!N$14*$A17*'Formula Audit'!F$12 -> 0 | G17: ='Valuation & Breakeven'!O$14*$A17*'Formula Audit'!G$12 -> 0 | H17: ='Valuation & Breakeven'!P$14*$A17*'Formula Audit'!H$12 -> 0 | I17: ='Valuation & Breakeven'!Q$14*$A17*'Formula Audit'!I$12 -> 0 | J17: ='Valuation & Breakeven'!R$14*$A17*'Formula Audit'!J$12 -> 0 | ... L17: ='Valuation & Breakeven'!T$14*$A17*'Formula Audit'!L$12 -> 461360.8 | T17: =$A$21 -> 0.084343054 | U17: =$A$17 -> 4.195417 | V17: =P22 -> -467418.62
A18: ='Valuation & Breakeven'!N33 -> 5.195417 | B18: Terminal Worth | C18: ='Valuation & Breakeven'!K$14*$A18*'Formula Audit'!C$12 -> 0 | D18: ='Valuation & Breakeven'!L$14*$A18*'Formula Audit'!D$12 -> 0 | E18: ='Valuation & Breakeven'!M$14*$A18*'Formula Audit'!E$12 -> 0 | F18: ='Valuation & Breakeven'!N$14*$A18*'Formula Audit'!F$12 -> 0 | G18: ='Valuation & Breakeven'!O$14*$A18*'Formula Audit'!G$12 -> 0 | H18: ='Valuation & Breakeven'!P$14*$A18*'Formula Audit'!H$12 -> 0 | I18: ='Valuation & Breakeven'!Q$14*$A18*'Formula Audit'!I$12 -> 0 | J18: ='Valuation & Breakeven'!R$14*$A18*'Formula Audit'!J$12 -> 0 | ... L18: ='Valuation & Breakeven'!T$14*$A18*'Formula Audit'!L$12 -> 571328.61 | M18: ='Valuation & Breakeven'!$K$33 -> -107718.55 | N18: -862145.81 | O18: -819608.96 | P18: -780092.56 | Q18: -743339.47 | R18: -709117.35 | T18: =$A$21 -> 0.084343054 | U18: =$A$18 -> 5.195417 | V18: =P23 -> -438517.24
A19: ='Valuation & Breakeven'!P28 -> 0.064343054 | B19: PV of Terminal Worth | C19: =C14/(1+$A19)^'Formula Audit'!C$13 -> 0 | D19: =D14/(1+$A19)^'Formula Audit'!D$13 -> 0 | E19: =E14/(1+$A19)^'Formula Audit'!E$13 -> 0 | F19: =F14/(1+$A19)^'Formula Audit'!F$13 -> 0 | G19: =G14/(1+$A19)^'Formula Audit'!G$13 -> 0 | H19: =H14/(1+$A19)^'Formula Audit'!H$13 -> 0 | I19: =I14/(1+$A19)^'Formula Audit'!I$13 -> 0 | J19: =J14/(1+$A19)^'Formula Audit'!J$13 -> 0 | ... L19: =L14/(1+$A19)^'Formula Audit'!L$13 -> 74998.109 | M19: =SUM(C19:L19) -> 74998.109 | N19: =N$18+$M19-$M$18 -> -679429.15 | O19: =O$18+$M19-$M$18 -> -636892.3 | P19: =P$18+$M19-$M$18 -> -597375.89 | Q19: =Q$18+$M19-$M$18 -> -560622.81 | R19: =R$18+$M19-$M$18 -> -526400.69 | T19: =$A$22 -> 0.094343054 | U19: =$A$14 -> 1.195417 | V19: =Q19 -> -560622.81
A20: ='Valuation & Breakeven'!Q28 -> 0.074343054 | B20: PV of Terminal Worth | C20: =C15/(1+$A20)^'Formula Audit'!C$13 -> 0 | D20: =D15/(1+$A20)^'Formula Audit'!D$13 -> 0 | E20: =E15/(1+$A20)^'Formula Audit'!E$13 -> 0 | F20: =F15/(1+$A20)^'Formula Audit'!F$13 -> 0 | G20: =G15/(1+$A20)^'Formula Audit'!G$13 -> 0 | H20: =H15/(1+$A20)^'Formula Audit'!H$13 -> 0 | I20: =I15/(1+$A20)^'Formula Audit'!I$13 -> 0 | J20: =J15/(1+$A20)^'Formula Audit'!J$13 -> 0 | ... L20: =L15/(1+$A20)^'Formula Audit'!L$13 -> 126618.09 | M20: =SUM(C20:L20) -> 126618.09 | N20: =N$18+$M20-$M$18 -> -627809.17 | O20: =O$18+$M20-$M$18 -> -585272.32 | P20: =P$18+$M20-$M$18 -> -545755.91 | Q20: =Q$18+$M20-$M$18 -> -509002.83 | R20: =R$18+$M20-$M$18 -> -474780.71 | T20: =$A$22 -> 0.094343054 | U20: =$A$15 -> 2.195417 | V20: =Q20 -> -509002.83
A21: ='Valuation & Breakeven'!R28 -> 0.084343054 | B21: PV of Terminal Worth | C21: =C16/(1+$A21)^'Formula Audit'!C$13 -> 0 | D21: =D16/(1+$A21)^'Formula Audit'!D$13 -> 0 | E21: =E16/(1+$A21)^'Formula Audit'!E$13 -> 0 | F21: =F16/(1+$A21)^'Formula Audit'!F$13 -> 0 | G21: =G16/(1+$A21)^'Formula Audit'!G$13 -> 0 | H21: =H16/(1+$A21)^'Formula Audit'!H$13 -> 0 | I21: =I16/(1+$A21)^'Formula Audit'!I$13 -> 0 | J21: =J16/(1+$A21)^'Formula Audit'!J$13 -> 0 | ... L21: =L16/(1+$A21)^'Formula Audit'!L$13 -> 169548.04 | M21: =SUM(C21:L21) -> 169548.04 | N21: =N$18+$M21-$M$18 -> -584879.21 | O21: =O$18+$M21-$M$18 -> -542342.36 | P21: =P$18+$M21-$M$18 -> -502825.96 | Q21: =Q$18+$M21-$M$18 -> -466072.87 | R21: =R$18+$M21-$M$18 -> -431850.75 | T21: =$A$22 -> 0.094343054 | U21: =$A$16 -> 3.195417 | V21: =Q21 -> -466072.87
A22: ='Valuation & Breakeven'!S28 -> 0.094343054 | B22: PV of Terminal Worth | C22: =C17/(1+$A22)^'Formula Audit'!C$13 -> 0 | D22: =D17/(1+$A22)^'Formula Audit'!D$13 -> 0 | E22: =E17/(1+$A22)^'Formula Audit'!E$13 -> 0 | F22: =F17/(1+$A22)^'Formula Audit'!F$13 -> 0 | G22: =G17/(1+$A22)^'Formula Audit'!G$13 -> 0 | H22: =H17/(1+$A22)^'Formula Audit'!H$13 -> 0 | I22: =I17/(1+$A22)^'Formula Audit'!I$13 -> 0 | J22: =J17/(1+$A22)^'Formula Audit'!J$13 -> 0 | ... L22: =L17/(1+$A22)^'Formula Audit'!L$13 -> 204955.38 | M22: =SUM(C22:L22) -> 204955.38 | N22: =N$18+$M22-$M$18 -> -549471.88 | O22: =O$18+$M22-$M$18 -> -506935.03 | P22: =P$18+$M22-$M$18 -> -467418.62 | Q22: =Q$18+$M22-$M$18 -> -430665.54 | R22: =R$18+$M22-$M$18 -> -396443.42 | T22: =$A$22 -> 0.094343054 | U22: =$A$17 -> 4.195417 | V22: =Q22 -> -430665.54
A23: ='Valuation & Breakeven'!T28 -> 0.10434305 | B23: PV of Terminal Worth | C23: =C18/(1+$A23)^'Formula Audit'!C$13 -> 0 | D23: =D18/(1+$A23)^'Formula Audit'!D$13 -> 0 | E23: =E18/(1+$A23)^'Formula Audit'!E$13 -> 0 | F23: =F18/(1+$A23)^'Formula Audit'!F$13 -> 0 | G23: =G18/(1+$A23)^'Formula Audit'!G$13 -> 0 | H23: =H18/(1+$A23)^'Formula Audit'!H$13 -> 0 | I23: =I18/(1+$A23)^'Formula Audit'!I$13 -> 0 | J23: =J18/(1+$A23)^'Formula Audit'!J$13 -> 0 | ... L23: =L18/(1+$A23)^'Formula Audit'!L$13 -> 233856.76 | M23: =SUM(C23:L23) -> 233856.76 | N23: =N$18+$M23-$M$18 -> -520570.49 | O23: =O$18+$M23-$M$18 -> -478033.65 | P23: =P$18+$M23-$M$18 -> -438517.24 | Q23: =Q$18+$M23-$M$18 -> -401764.15 | R23: =R$18+$M23-$M$18 -> -367542.03 | T23: =$A$22 -> 0.094343054 | U23: =$A$18 -> 5.195417 | V23: =Q23 -> -401764.15
A24: ='Valuation & Breakeven'!P28 -> 0.064343054 | B24: PV of Net Free Cash Flow | C24: ='Valuation & Breakeven'!K$19/(1+'Formula Audit'!$A24)^'Formula Audit'!C$13 -> 30441.127 | D24: ='Valuation & Breakeven'!L$19/(1+'Formula Audit'!$A24)^'Formula Audit'!D$13 -> -1180.5731 | E24: ='Valuation & Breakeven'!M$19/(1+'Formula Audit'!$A24)^'Formula Audit'!E$13 -> 36489.964 | F24: ='Valuation & Breakeven'!N$19/(1+'Formula Audit'!$A24)^'Formula Audit'!F$13 -> 41862.988 | G24: ='Valuation & Breakeven'!O$19/(1+'Formula Audit'!$A24)^'Formula Audit'!G$13 -> 45016.306 | H24: ='Valuation & Breakeven'!P$19/(1+'Formula Audit'!$A24)^'Formula Audit'!H$13 -> 52257.865 | I24: ='Valuation & Breakeven'!Q$19/(1+'Formula Audit'!$A24)^'Formula Audit'!I$13 -> 49766.492 | J24: ='Valuation & Breakeven'!R$19/(1+'Formula Audit'!$A24)^'Formula Audit'!J$13 -> 58688.776 | ... L24: ='Valuation & Breakeven'!T$19/(1+'Formula Audit'!$A24)^'Formula Audit'!L$13 -> 258792.17 | M24: =SUM(C24:L24) -> 627408.7 | T24: =$A$23 -> 0.10434305 | U24: =$A$14 -> 1.195417 | V24: =R19 -> -526400.69
A25: ='Valuation & Breakeven'!Q28 -> 0.074343054 | B25: PV of Net Free Cash Flow | C25: ='Valuation & Breakeven'!K$19/(1+'Formula Audit'!$A25)^'Formula Audit'!C$13 -> 30441.127 | D25: ='Valuation & Breakeven'!L$19/(1+'Formula Audit'!$A25)^'Formula Audit'!D$13 -> -1169.5843 | E25: ='Valuation & Breakeven'!M$19/(1+'Formula Audit'!$A25)^'Formula Audit'!E$13 -> 35813.827 | F25: ='Valuation & Breakeven'!N$19/(1+'Formula Audit'!$A25)^'Formula Audit'!F$13 -> 40704.851 | G25: ='Valuation & Breakeven'!O$19/(1+'Formula Audit'!$A25)^'Formula Audit'!G$13 -> 43363.513 | H25: ='Valuation & Breakeven'!P$19/(1+'Formula Audit'!$A25)^'Formula Audit'!H$13 -> 49870.637 | I25: ='Valuation & Breakeven'!Q$19/(1+'Formula Audit'!$A25)^'Formula Audit'!I$13 -> 47051.008 | J25: ='Valuation & Breakeven'!R$19/(1+'Formula Audit'!$A25)^'Formula Audit'!J$13 -> 54969.983 | ... L25: ='Valuation & Breakeven'!T$19/(1+'Formula Audit'!$A25)^'Formula Audit'!L$13 -> 237902.49 | M25: =SUM(C25:L25) -> 590237.15 | T25: =$A$23 -> 0.10434305 | U25: =$A$15 -> 2.195417 | V25: =R20 -> -474780.71
A26: ='Valuation & Breakeven'!R28 -> 0.084343054 | B26: PV of Net Free Cash Flow | C26: ='Valuation & Breakeven'!K$19/(1+'Formula Audit'!$A26)^'Formula Audit'!C$13 -> 30441.127 | D26: ='Valuation & Breakeven'!L$19/(1+'Formula Audit'!$A26)^'Formula Audit'!D$13 -> -1158.7982 | E26: ='Valuation & Breakeven'!M$19/(1+'Formula Audit'!$A26)^'Formula Audit'!E$13 -> 35156.311 | F26: ='Valuation & Breakeven'!N$19/(1+'Formula Audit'!$A26)^'Formula Audit'!F$13 -> 39589.043 | G26: ='Valuation & Breakeven'!O$19/(1+'Formula Audit'!$A26)^'Formula Audit'!G$13 -> 41785.882 | H26: ='Valuation & Breakeven'!P$19/(1+'Formula Audit'!$A26)^'Formula Audit'!H$13 -> 47613.083 | I26: ='Valuation & Breakeven'!Q$19/(1+'Formula Audit'!$A26)^'Formula Audit'!I$13 -> 44506.824 | J26: ='Valuation & Breakeven'!R$19/(1+'Formula Audit'!$A26)^'Formula Audit'!J$13 -> 51518.066 | ... L26: ='Valuation & Breakeven'!T$19/(1+'Formula Audit'!$A26)^'Formula Audit'!L$13 -> 218869.63 | M26: =SUM(C26:L26) -> 555946.38 | T26: =$A$23 -> 0.10434305 | U26: =$A$16 -> 3.195417 | V26: =R21 -> -431850.75
A27: ='Valuation & Breakeven'!S28 -> 0.094343054 | B27: PV of Net Free Cash Flow | C27: ='Valuation & Breakeven'!K$19/(1+'Formula Audit'!$A27)^'Formula Audit'!C$13 -> 30441.127 | D27: ='Valuation & Breakeven'!L$19/(1+'Formula Audit'!$A27)^'Formula Audit'!D$13 -> -1148.2093 | E27: ='Valuation & Breakeven'!M$19/(1+'Formula Audit'!$A27)^'Formula Audit'!E$13 -> 34516.736 | F27: ='Valuation & Breakeven'!N$19/(1+'Formula Audit'!$A27)^'Formula Audit'!F$13 -> 38513.648 | G27: ='Valuation & Breakeven'!O$19/(1+'Formula Audit'!$A27)^'Formula Audit'!G$13 -> 40279.348 | H27: ='Valuation & Breakeven'!P$19/(1+'Formula Audit'!$A27)^'Formula Audit'!H$13 -> 45477.06 | I27: ='Valuation & Breakeven'!Q$19/(1+'Formula Audit'!$A27)^'Formula Audit'!I$13 -> 42121.701 | J27: ='Valuation & Breakeven'!R$19/(1+'Formula Audit'!$A27)^'Formula Audit'!J$13 -> 48311.672 | ... L27: ='Valuation & Breakeven'!T$19/(1+'Formula Audit'!$A27)^'Formula Audit'!L$13 -> 201513.64 | M27: =SUM(C27:L27) -> 524279.72 | T27: =$A$23 -> 0.10434305 | U27: =$A$17 -> 4.195417 | V27: =R22 -> -396443.42
A28: ='Valuation & Breakeven'!T28 -> 0.10434305 | B28: PV of Net Free Cash Flow | C28: ='Valuation & Breakeven'!K$19/(1+'Formula Audit'!$A28)^'Formula Audit'!C$13 -> 30441.127 | D28: ='Valuation & Breakeven'!L$19/(1+'Formula Audit'!$A28)^'Formula Audit'!D$13 -> -1137.812 | E28: ='Valuation & Breakeven'!M$19/(1+'Formula Audit'!$A28)^'Formula Audit'!E$13 -> 33894.458 | F28: ='Valuation & Breakeven'!N$19/(1+'Formula Audit'!$A28)^'Formula Audit'!F$13 -> 37476.852 | G28: ='Valuation & Breakeven'!O$19/(1+'Formula Audit'!$A28)^'Formula Audit'!G$13 -> 38840.102 | H28: ='Valuation & Breakeven'!P$19/(1+'Formula Audit'!$A28)^'Formula Audit'!H$13 -> 43455.004 | I28: ='Valuation & Breakeven'!Q$19/(1+'Formula Audit'!$A28)^'Formula Audit'!I$13 -> 39884.375 | J28: ='Valuation & Breakeven'!R$19/(1+'Formula Audit'!$A28)^'Formula Audit'!J$13 -> 45331.327 | ... L28: ='Valuation & Breakeven'!T$19/(1+'Formula Audit'!$A28)^'Formula Audit'!L$13 -> 185673.44 | M28: =SUM(C28:L28) -> 495005.91 | T28: =$A$23 -> 0.10434305 | U28: =$A$18 -> 5.195417 | V28: =R23 -> -367542.03
C30: x | D30: x | E30: x | F30: x | G30: x | H30: x | I30: x | J30: x | K30: x | L30: x
B31: Reporting Period | C31: =C9 -> 2025 | D31: =D9 -> 2026 | E31: =E9 -> 2027 | F31: =F9 -> 2028 | G31: =G9 -> 2029 | H31: =H9 -> 2030 | I31: =I9 -> 2031 | J31: =J9 -> 2032 | ... L31: =L9 -> 2034
B32: Cumulative Cash Position | C32: =Outputs!E16 -> 178578.55 | D32: =Outputs!F16 -> 163839.58 | E32: =Outputs!G16 -> 189931.21 | F32: =Outputs!H16 -> 223641.76 | G32: =Outputs!I16 -> 264213.03 | H32: =Outputs!J16 -> 317061.08 | I32: =Outputs!K16 -> 370368.6 | J32: =Outputs!L16 -> 440597.54 | ... L32: =Outputs!N16 -> 591162.38
B33: delta | C33: =C32 -> 178578.55 | D33: =D32-C32 -> -14738.971 | E33: =E32-D32 -> 26091.628 | F33: =F32-E32 -> 33710.549 | G33: =G32-F32 -> 40571.273 | H33: =H32-G32 -> 52848.046 | I33: =I32-H32 -> 53307.519 | J33: =J32-I32 -> 70228.937 | K33: =K32-J32 -> 70053.017 | L33: =L32-K32 -> 80511.823
B34: Revenue (Net) | C34: =Outputs!E9 -> 402045.22 | D34: =Outputs!F9 -> 428989.89 | E34: =Outputs!G9 -> 452948.55 | F34: =Outputs!H9 -> 473185.84 | G34: =Outputs!I9 -> 489042.3 | H34: =Outputs!J9 -> 505430.1 | I34: =Outputs!K9 -> 516721.41 | J34: =Outputs!L9 -> 528264.97 | ... L34: =Outputs!N9 -> 552131.49
B35: EBITDA (Operating) | C35: 0 | D35: -92884 | E35: -92884 | F35: -92884 | G35: -92884 | H35: -92884 | I35: -92884 | J35: -92884 | K35: -92884 | L35: -92884
B36: EV / Revenue | C36: =Outputs!E18 -> 0.72698649 | D36: =Outputs!F18 -> 0.68132478 | E36: =Outputs!G18 -> 0.6452862 | F36: =Outputs!H18 -> 0.61768849 | G36: =Outputs!I18 -> 0.59766088 | H36: =Outputs!J18 -> 0.57828262 | I36: =Outputs!K18 -> 0.56564609 | J36: =Outputs!L18 -> 0.55328569 | ... L36: =Outputs!N18 -> 0.52936927
B37: EV / EBITDA | C37: =Outputs!E19 -> 4.4857168 | D37: =Outputs!F19 -> 6.0830223 | E37: =Outputs!G19 -> 4.3211409 | F37: =Outputs!H19 -> 3.4504694 | G37: =Outputs!I19 -> 3.1496942 | H37: =Outputs!J19 -> 2.6670611 | I37: =Outputs!K19 -> 2.4968964 | J37: =Outputs!L19 -> 2.2009772 | ... L37: =Outputs!N19 -> 2.0044903
B39: IRR-Based Valuation | C39: =IF('Valuation & Breakeven'!$K$47 >= 15%, "Attractive Investment", IF('Valuation & Breakeven'!$K$47 >= 10%, "Adequate Investment", IF('Valuation & Breakeven'!$K$47 >= 5%, "Modest Return", "Not Advised"))) -> Attractive Investment
A41: Revenue (Net) | C41: January | D41: February | E41: March | F41: April | G41: May | H41: June | I41: July | J41: August | K41: September | L41: October | M41: November | N41: December
A42: Service & Products | C42: =1+'Control Center'!G155 -> 1.018551 | D42: =1+'Control Center'!H155 -> 1.027827 | E42: =1+'Control Center'!I155 -> 1.037103 | F42: =1+'Control Center'!J155 -> 1.046378 | G42: =1+'Control Center'!K155 -> 1.092757 | H42: =1+'Control Center'!L155 -> 1.111308 | I42: =1+'Control Center'!M155 -> 1.074205 | J42: =1+'Control Center'!N155 -> 1.046378 | ... N42: =1+'Control Center'!R155 -> 1.111308
A44: Planning Case | C44: ='Control Center'!F8 -> 2025 | D44: =(C44+1)*D$8 -> 2026 | E44: =(D44+1)*E$8 -> 2027 | F44: =(E44+1)*F$8 -> 2028 | G44: =(F44+1)*G$8 -> 2029 | H44: =(G44+1)*H$8 -> 2030 | I44: =(H44+1)*I$8 -> 2031 | J44: =(I44+1)*J$8 -> 2032 | K44: =(J44+1)*K$8 -> 2033 | L44: =(K44+1)*L$8 -> 2034
A45: Revenue Growth Rate | C45: =INDEX(C46:C48, MATCH('Control Center'!$E$25, 'Formula Audit'!$C$4:$C$6, 0))*C$8 -> 0 | D45: =INDEX(D46:D48, MATCH('Control Center'!$E$25, 'Formula Audit'!$C$4:$C$6, 0))*D$8 -> 0.067019 | E45: =INDEX(E46:E48, MATCH('Control Center'!$E$25, 'Formula Audit'!$C$4:$C$6, 0))*E$8 -> 0.055849 | F45: =INDEX(F46:F48, MATCH('Control Center'!$E$25, 'Formula Audit'!$C$4:$C$6, 0))*F$8 -> 0.044679 | G45: =INDEX(G46:G48, MATCH('Control Center'!$E$25, 'Formula Audit'!$C$4:$C$6, 0))*G$8 -> 0.03351 | H45: =INDEX(H46:H48, MATCH('Control Center'!$E$25, 'Formula Audit'!$C$4:$C$6, 0))*H$8 -> 0.03351 | I45: =INDEX(I46:I48, MATCH('Control Center'!$E$25, 'Formula Audit'!$C$4:$C$6, 0))*I$8 -> 0.02234 | J45: =INDEX(J46:J48, MATCH('Control Center'!$E$25, 'Formula Audit'!$C$4:$C$6, 0))*J$8 -> 0.02234 | ... L45: =INDEX(L46:L48, MATCH('Control Center'!$E$25, 'Formula Audit'!$C$4:$C$6, 0))*L$8 -> 0.02234
B46: Central Case | C46: ='Control Center'!G58 -> 0 | D46: ='Control Center'!H58 -> 0.067019 | E46: ='Control Center'!I58 -> 0.055849 | F46: ='Control Center'!J58 -> 0.044679 | G46: ='Control Center'!K58 -> 0.03351 | H46: ='Control Center'!L58 -> 0.03351 | I46: ='Control Center'!M58 -> 0.02234 | J46: ='Control Center'!N58 -> 0.02234 | ... L46: ='Control Center'!P58 -> 0.02234
...
